<?xml version="1.0" ?>
<!-- Generated using onshape-to-robot -->
<!-- Onshape https://cad.onshape.com/documents/026f9a33ba6a25a983a9d639/w/b83e0182bd0a887a03df3198/e/e49783848224d44e064e4a49 -->
<robot name="C:\Users\gata2\OneDrive\Documents\hexapod\hexapod_py\platform\simulation">
  <!-- Link base_link -->
  <link name="base_link">
    <inertial>
      <origin xyz="0.00470178 -0.0163199 -0.0259802" rpy="0 0 0"/>
      <mass value="2.35252"/>
      <inertia ixx="0.0190385" ixy="0.000445297" ixz="-2.34169e-05" iyy="0.0182501" iyz="-2.1661e-05" izz="0.0246171"/>
    </inertial>
    <!-- Part mobile_bracket -->
    <visual>
      <origin xyz="0.111152 0.033155 -0.0136886" rpy="1.13446 1.5708 0"/>
      <geometry>
        <mesh filename="package://meshes\mobile_bracket.stl"/>
      </geometry>
      <material name="mobile_bracket_material">
        <color rgba="0.647059 0.647059 0.647059 1"/>
      </material>
    </visual>
    <collision>
      <origin xyz="0.111152 0.033155 -0.0136886" rpy="1.13446 1.5708 0"/>
      <geometry>
        <mesh filename="package://meshes\mobile_bracket.stl"/>
      </geometry>
    </collision>
    <!-- Part top_cover -->
    <visual>
      <origin xyz="0.0050986 -0.0162986 0.0213114" rpy="-2.42931e-14 2.46385e-14 2.00713"/>
      <geometry>
        <mesh filename="package://meshes\top_cover.stl"/>
      </geometry>
      <material name="top_cover_material">
        <color rgba="0.282353 0.54902 0.160784 1"/>
      </material>
    </visual>
    <collision>
      <origin xyz="0.0050986 -0.0162986 0.0213114" rpy="-2.42931e-14 2.46385e-14 2.00713"/>
      <geometry>
        <mesh filename="package://meshes\top_cover.stl"/>
      </geometry>
    </collision>
    <!-- Part mobile_bracket_2 -->
    <visual>
      <origin xyz="0.100953 -0.0834168 -0.0136886" rpy="2.18166 1.5708 0"/>
      <geometry>
        <mesh filename="package://meshes\mobile_bracket.stl"/>
      </geometry>
      <material name="mobile_bracket_2_material">
        <color rgba="0.647059 0.647059 0.647059 1"/>
      </material>
    </visual>
    <collision>
      <origin xyz="0.100953 -0.0834168 -0.0136886" rpy="2.18166 1.5708 0"/>
      <geometry>
        <mesh filename="package://meshes\mobile_bracket.stl"/>
      </geometry>
    </collision>
    <!-- Part camera -->
    <visual>
      <origin xyz="-0.0382198 0.076598 -0.0256886" rpy="3.14159 -6.80112e-15 0.436332"/>
      <geometry>
        <mesh filename="package://meshes\camera.stl"/>
      </geometry>
      <material name="camera_material">
        <color rgba="0.262745 0.282353 0.301961 1"/>
      </material>
    </visual>
    <collision>
      <origin xyz="-0.0382198 0.076598 -0.0256886" rpy="3.14159 -6.80112e-15 0.436332"/>
      <geometry>
        <mesh filename="package://meshes\camera.stl"/>
      </geometry>
    </collision>
    <!-- Part camera_2 -->
    <visual>
      <origin xyz="0.048417 -0.109195 -0.0256886" rpy="-3.14159 6.80112e-15 -2.70526"/>
      <geometry>
        <mesh filename="package://meshes\camera.stl"/>
      </geometry>
      <material name="camera_2_material">
        <color rgba="0.262745 0.282353 0.301961 1"/>
      </material>
    </visual>
    <collision>
      <origin xyz="0.048417 -0.109195 -0.0256886" rpy="-3.14159 6.80112e-15 -2.70526"/>
      <geometry>
        <mesh filename="package://meshes\camera.stl"/>
      </geometry>
    </collision>
    <!-- Part bottom_cover -->
    <visual>
      <origin xyz="0.0050986 -0.0162986 -0.0486886" rpy="-3.14159 -2.1605e-14 -1.13446"/>
      <geometry>
        <mesh filename="package://meshes\bottom_cover.stl"/>
      </geometry>
      <material name="bottom_cover_material">
        <color rgba="0.282353 0.54902 0.160784 1"/>
      </material>
    </visual>
    <collision>
      <origin xyz="0.0050986 -0.0162986 -0.0486886" rpy="-3.14159 -2.1605e-14 -1.13446"/>
      <geometry>
        <mesh filename="package://meshes\bottom_cover.stl"/>
      </geometry>
    </collision>
    <!-- Part left_speaker -->
    <visual>
      <origin xyz="-0.0234341 -0.0570474 0.00105654" rpy="1.5708 0.523599 -0.610865"/>
      <geometry>
        <mesh filename="package://meshes\left_speaker.stl"/>
      </geometry>
      <material name="left_speaker_material">
        <color rgba="0.262745 0.282353 0.301961 1"/>
      </material>
    </visual>
    <collision>
      <origin xyz="-0.0234341 -0.0570474 0.00105654" rpy="1.5708 0.523599 -0.610865"/>
      <geometry>
        <mesh filename="package://meshes\left_speaker.stl"/>
      </geometry>
    </collision>
    <!-- Part body_power -->
    <visual>
      <origin xyz="0.0050986 -0.0162986 -0.0136886" rpy="2.46385e-14 2.42931e-14 -2.70526"/>
      <geometry>
        <mesh filename="package://meshes\body_power.stl"/>
      </geometry>
      <material name="body_power_material">
        <color rgba="0.282353 0.54902 0.160784 1"/>
      </material>
    </visual>
    <collision>
      <origin xyz="0.0050986 -0.0162986 -0.0136886" rpy="2.46385e-14 2.42931e-14 -2.70526"/>
      <geometry>
        <mesh filename="package://meshes\body_power.stl"/>
      </geometry>
    </collision>
    <!-- Part mobile_bracket_3 -->
    <visual>
      <origin xyz="-0.00510011 -0.13287 -0.0136886" rpy="3.05433 -1.5708 0"/>
      <geometry>
        <mesh filename="package://meshes\mobile_bracket.stl"/>
      </geometry>
      <material name="mobile_bracket_3_material">
        <color rgba="0.647059 0.647059 0.647059 1"/>
      </material>
    </visual>
    <collision>
      <origin xyz="-0.00510011 -0.13287 -0.0136886" rpy="3.05433 -1.5708 0"/>
      <geometry>
        <mesh filename="package://meshes\mobile_bracket.stl"/>
      </geometry>
    </collision>
    <!-- Part mobile_bracket_4 -->
    <visual>
      <origin xyz="0.0152973 0.100273 -0.0136886" rpy="0.0872665 1.5708 0"/>
      <geometry>
        <mesh filename="package://meshes\mobile_bracket.stl"/>
      </geometry>
      <material name="mobile_bracket_4_material">
        <color rgba="0.647059 0.647059 0.647059 1"/>
      </material>
    </visual>
    <collision>
      <origin xyz="0.0152973 0.100273 -0.0136886" rpy="0.0872665 1.5708 0"/>
      <geometry>
        <mesh filename="package://meshes\mobile_bracket.stl"/>
      </geometry>
    </collision>
    <!-- Part mobile_bracket_5 -->
    <visual>
      <origin xyz="-0.100955 -0.0657521 -0.0136886" rpy="2.00713 -1.5708 0"/>
      <geometry>
        <mesh filename="package://meshes\mobile_bracket.stl"/>
      </geometry>
      <material name="mobile_bracket_5_material">
        <color rgba="0.647059 0.647059 0.647059 1"/>
      </material>
    </visual>
    <collision>
      <origin xyz="-0.100955 -0.0657521 -0.0136886" rpy="2.00713 -1.5708 0"/>
      <geometry>
        <mesh filename="package://meshes\mobile_bracket.stl"/>
      </geometry>
    </collision>
    <!-- Part mobile_bracket_6 -->
    <visual>
      <origin xyz="-0.0907562 0.0508196 -0.0136886" rpy="0.959931 -1.5708 0"/>
      <geometry>
        <mesh filename="package://meshes\mobile_bracket.stl"/>
      </geometry>
      <material name="mobile_bracket_6_material">
        <color rgba="0.647059 0.647059 0.647059 1"/>
      </material>
    </visual>
    <collision>
      <origin xyz="-0.0907562 0.0508196 -0.0136886" rpy="0.959931 -1.5708 0"/>
      <geometry>
        <mesh filename="package://meshes\mobile_bracket.stl"/>
      </geometry>
    </collision>
    <!-- Part body_brain -->
    <visual>
      <origin xyz="0.0050986 -0.0162986 -0.0136886" rpy="2.1605e-14 6.80112e-15 -2.70526"/>
      <geometry>
        <mesh filename="package://meshes\body_brain.stl"/>
      </geometry>
      <material name="body_brain_material">
        <color rgba="0.282353 0.54902 0.160784 1"/>
      </material>
    </visual>
    <collision>
      <origin xyz="0.0050986 -0.0162986 -0.0136886" rpy="2.1605e-14 6.80112e-15 -2.70526"/>
      <geometry>
        <mesh filename="package://meshes\body_brain.stl"/>
      </geometry>
    </collision>
    <!-- Part left_speaker_2 -->
    <visual>
      <origin xyz="0.0546545 -0.0206342 0.00105654" rpy="1.5708 0.523599 1.48353"/>
      <geometry>
        <mesh filename="package://meshes\left_speaker.stl"/>
      </geometry>
      <material name="left_speaker_2_material">
        <color rgba="0.262745 0.282353 0.301961 1"/>
      </material>
    </visual>
    <collision>
      <origin xyz="0.0546545 -0.0206342 0.00105654" rpy="1.5708 0.523599 1.48353"/>
      <geometry>
        <mesh filename="package://meshes\left_speaker.stl"/>
      </geometry>
    </collision>
  </link>
  <!-- Link hip_assembly -->
  <link name="hip_assembly">
    <inertial>
      <origin xyz="0.0271153 0.000490209 -0.0317796" rpy="0 0 0"/>
      <mass value="0.38056"/>
      <inertia ixx="0.000187069" ixy="-3.08523e-06" ixz="7.85466e-06" iyy="0.000328441" iyz="1.17914e-06" izz="0.000302664"/>
    </inertial>
    <!-- Part hip -->
    <visual>
      <origin xyz="0.0575 -4.64906e-16 -0.0045" rpy="1.16453e-15 -4.14381e-15 -3.14159"/>
      <geometry>
        <mesh filename="package://meshes\hip.stl"/>
      </geometry>
      <material name="hip_material">
        <color rgba="0.282353 0.54902 0.160784 1"/>
      </material>
    </visual>
    <collision>
      <origin xyz="0.0575 -4.64906e-16 -0.0045" rpy="1.16453e-15 -4.14381e-15 -3.14159"/>
      <geometry>
        <mesh filename="package://meshes\hip.stl"/>
      </geometry>
    </collision>
    <!-- Part mobile_bracket_7 -->
    <visual>
      <origin xyz="0.0575 3.81639e-17 -0.0305" rpy="-3.75284e-15 -9.18037e-16 -1.5708"/>
      <geometry>
        <mesh filename="package://meshes\mobile_bracket.stl"/>
      </geometry>
      <material name="mobile_bracket_7_material">
        <color rgba="0.647059 0.647059 0.647059 1"/>
      </material>
    </visual>
    <collision>
      <origin xyz="0.0575 3.81639e-17 -0.0305" rpy="-3.75284e-15 -9.18037e-16 -1.5708"/>
      <geometry>
        <mesh filename="package://meshes\mobile_bracket.stl"/>
      </geometry>
    </collision>
    <!-- Part servo_wheel -->
    <visual>
      <origin xyz="1.38778e-16 -3.46945e-17 -0.0025" rpy="-3.14159 -4.26305e-15 -3.14159"/>
      <geometry>
        <mesh filename="package://meshes\servo_wheel.stl"/>
      </geometry>
      <material name="servo_wheel_material">
        <color rgba="0.647059 0.647059 0.647059 1"/>
      </material>
    </visual>
    <collision>
      <origin xyz="1.38778e-16 -3.46945e-17 -0.0025" rpy="-3.14159 -4.26305e-15 -3.14159"/>
      <geometry>
        <mesh filename="package://meshes\servo_wheel.stl"/>
      </geometry>
    </collision>
    <!-- Part servo -->
    <visual>
      <origin xyz="0.0175 0.00140442 -0.0305" rpy="-3.14159 -4.05481e-15 -3.14159"/>
      <geometry>
        <mesh filename="package://meshes\servo.stl"/>
      </geometry>
      <material name="servo_material">
        <color rgba="0.109804 0.109804 0.105882 1"/>
      </material>
    </visual>
    <collision>
      <origin xyz="0.0175 0.00140442 -0.0305" rpy="-3.14159 -4.05481e-15 -3.14159"/>
      <geometry>
        <mesh filename="package://meshes\servo.stl"/>
      </geometry>
    </collision>
    <!-- Part fixed_bracket -->
    <visual>
      <origin xyz="0.0575 1.45717e-16 -0.0305" rpy="-1.5708 1.5708 0"/>
      <geometry>
        <mesh filename="package://meshes\fixed_bracket.stl"/>
      </geometry>
      <material name="fixed_bracket_material">
        <color rgba="0.647059 0.647059 0.647059 1"/>
      </material>
    </visual>
    <collision>
      <origin xyz="0.0575 1.45717e-16 -0.0305" rpy="-1.5708 1.5708 0"/>
      <geometry>
        <mesh filename="package://meshes\fixed_bracket.stl"/>
      </geometry>
    </collision>
    <!-- Part servo_wheel_2 -->
    <visual>
      <origin xyz="-1.38778e-16 -1.38778e-17 -0.0585" rpy="-3.14159 -1.97331e-15 3.14159"/>
      <geometry>
        <mesh filename="package://meshes\servo_wheel.stl"/>
      </geometry>
      <material name="servo_wheel_2_material">
        <color rgba="0.647059 0.647059 0.647059 1"/>
      </material>
    </visual>
    <collision>
      <origin xyz="-1.38778e-16 -1.38778e-17 -0.0585" rpy="-3.14159 -1.97331e-15 3.14159"/>
      <geometry>
        <mesh filename="package://meshes\servo_wheel.stl"/>
      </geometry>
    </collision>
  </link>
  <!-- Link ties_assembly -->
  <link name="ties_assembly">
    <inertial>
      <origin xyz="0.0639313 0.001561 -0.0314406" rpy="0 0 0"/>
      <mass value="0.581468"/>
      <inertia ixx="0.000317042" ixy="-2.4027e-05" ixz="2.78889e-05" iyy="0.00207548" iyz="-4.55023e-07" izz="0.00186094"/>
    </inertial>
    <!-- Part mobile_bracket_8 -->
    <visual>
      <origin xyz="0.1568 0.000117091 -0.0322436" rpy="1.5708 1.5708 0"/>
      <geometry>
        <mesh filename="package://meshes\mobile_bracket.stl"/>
      </geometry>
      <material name="mobile_bracket_8_material">
        <color rgba="0.647059 0.647059 0.647059 1"/>
      </material>
    </visual>
    <collision>
      <origin xyz="0.1568 0.000117091 -0.0322436" rpy="1.5708 1.5708 0"/>
      <geometry>
        <mesh filename="package://meshes\mobile_bracket.stl"/>
      </geometry>
    </collision>
    <!-- Part low_tie -->
    <visual>
      <origin xyz="0.0268 0.000117091 -0.0322436" rpy="1.50389e-15 1.5708 0"/>
      <geometry>
        <mesh filename="package://meshes\low_tie.stl"/>
      </geometry>
      <material name="low_tie_material">
        <color rgba="0.282353 0.54902 0.160784 1"/>
      </material>
    </visual>
    <collision>
      <origin xyz="0.0268 0.000117091 -0.0322436" rpy="1.50389e-15 1.5708 0"/>
      <geometry>
        <mesh filename="package://meshes\low_tie.stl"/>
      </geometry>
    </collision>
    <!-- Part top_tie -->
    <visual>
      <origin xyz="0.0275 -1.38778e-17 -0.0305" rpy="1.50389e-15 1.5708 0"/>
      <geometry>
        <mesh filename="package://meshes\top_tie.stl"/>
      </geometry>
      <material name="top_tie_material">
        <color rgba="0.282353 0.54902 0.160784 1"/>
      </material>
    </visual>
    <collision>
      <origin xyz="0.0275 -1.38778e-17 -0.0305" rpy="1.50389e-15 1.5708 0"/>
      <geometry>
        <mesh filename="package://meshes\top_tie.stl"/>
      </geometry>
    </collision>
    <!-- Part servo_wheel_3 -->
    <visual>
      <origin xyz="1.11022e-16 3.46945e-17 -0.0025" rpy="-3.14159 -1.50856e-16 3.14159"/>
      <geometry>
        <mesh filename="package://meshes\servo_wheel.stl"/>
      </geometry>
      <material name="servo_wheel_3_material">
        <color rgba="0.647059 0.647059 0.647059 1"/>
      </material>
    </visual>
    <collision>
      <origin xyz="1.11022e-16 3.46945e-17 -0.0025" rpy="-3.14159 -1.50856e-16 3.14159"/>
      <geometry>
        <mesh filename="package://meshes\servo_wheel.stl"/>
      </geometry>
    </collision>
    <!-- Part servo_2 -->
    <visual>
      <origin xyz="0.0175 0.00140442 -0.0305" rpy="3.14159 1.73711e-14 3.14159"/>
      <geometry>
        <mesh filename="package://meshes\servo.stl"/>
      </geometry>
      <material name="servo_2_material">
        <color rgba="0.109804 0.109804 0.105882 1"/>
      </material>
    </visual>
    <collision>
      <origin xyz="0.0175 0.00140442 -0.0305" rpy="3.14159 1.73711e-14 3.14159"/>
      <geometry>
        <mesh filename="package://meshes\servo.stl"/>
      </geometry>
    </collision>
    <!-- Part fixed_bracket_2 -->
    <visual>
      <origin xyz="0.0575 -5.72459e-17 -0.0305" rpy="-1.5708 1.5708 0"/>
      <geometry>
        <mesh filename="package://meshes\fixed_bracket.stl"/>
      </geometry>
      <material name="fixed_bracket_2_material">
        <color rgba="0.647059 0.647059 0.647059 1"/>
      </material>
    </visual>
    <collision>
      <origin xyz="0.0575 -5.72459e-17 -0.0305" rpy="-1.5708 1.5708 0"/>
      <geometry>
        <mesh filename="package://meshes\fixed_bracket.stl"/>
      </geometry>
    </collision>
    <!-- Part servo_wheel_4 -->
    <visual>
      <origin xyz="1.11022e-16 3.46945e-17 -0.0585" rpy="3.14159 -3.68117e-15 3.14159"/>
      <geometry>
        <mesh filename="package://meshes\servo_wheel.stl"/>
      </geometry>
      <material name="servo_wheel_4_material">
        <color rgba="0.647059 0.647059 0.647059 1"/>
      </material>
    </visual>
    <collision>
      <origin xyz="1.11022e-16 3.46945e-17 -0.0585" rpy="3.14159 -3.68117e-15 3.14159"/>
      <geometry>
        <mesh filename="package://meshes\servo_wheel.stl"/>
      </geometry>
    </collision>
  </link>
  <!-- Link foot_assembly -->
  <link name="foot_assembly">
    <inertial>
      <origin xyz="-0.0719605 -0.00210262 -0.0306706" rpy="0 0 0"/>
      <mass value="0.628062"/>
      <inertia ixx="0.000268406" ixy="-1.55227e-05" ixz="4.14924e-06" iyy="0.0031862" iyz="-2.26544e-07" izz="0.00302315"/>
    </inertial>
    <!-- Part foot -->
    <visual>
      <origin xyz="-0.04425 2.08167e-17 -0.0305" rpy="-2.22045e-16 1.5708 0"/>
      <geometry>
        <mesh filename="package://meshes\foot.stl"/>
      </geometry>
      <material name="foot_material">
        <color rgba="0.282353 0.54902 0.160784 1"/>
      </material>
    </visual>
    <collision>
      <origin xyz="-0.04425 2.08167e-17 -0.0305" rpy="-2.22045e-16 1.5708 0"/>
      <geometry>
        <mesh filename="package://meshes\foot.stl"/>
      </geometry>
    </collision>
    <!-- Part ir_sensor_cap -->
    <visual>
      <origin xyz="-0.0442455 6.98571e-05 -0.0305" rpy="3.33067e-16 1.5708 0"/>
      <geometry>
        <mesh filename="package://meshes\ir_sensor_cap.stl"/>
      </geometry>
      <material name="ir_sensor_cap_material">
        <color rgba="0.282353 0.54902 0.160784 1"/>
      </material>
    </visual>
    <collision>
      <origin xyz="-0.0442455 6.98571e-05 -0.0305" rpy="3.33067e-16 1.5708 0"/>
      <geometry>
        <mesh filename="package://meshes\ir_sensor_cap.stl"/>
      </geometry>
    </collision>
    <!-- Part rubber_foot -->
    <visual>
      <origin xyz="-0.04375 3.88231e-15 -0.03" rpy="-1.83225e-14 1.5708 0"/>
      <geometry>
        <mesh filename="package://meshes\rubber_foot.stl"/>
      </geometry>
      <material name="rubber_foot_material">
        <color rgba="0.262745 0.282353 0.301961 1"/>
      </material>
    </visual>
    <collision>
      <origin xyz="-0.04375 3.88231e-15 -0.03" rpy="-1.83225e-14 1.5708 0"/>
      <geometry>
        <mesh filename="package://meshes\rubber_foot.stl"/>
      </geometry>
    </collision>
    <!-- Part servo_wheel_5 -->
    <visual>
      <origin xyz="5.55112e-17 1.73472e-18 -0.0025" rpy="-3.14159 -6.35086e-17 5.73157e-30"/>
      <geometry>
        <mesh filename="package://meshes\servo_wheel.stl"/>
      </geometry>
      <material name="servo_wheel_5_material">
        <color rgba="0.647059 0.647059 0.647059 1"/>
      </material>
    </visual>
    <collision>
      <origin xyz="5.55112e-17 1.73472e-18 -0.0025" rpy="-3.14159 -6.35086e-17 5.73157e-30"/>
      <geometry>
        <mesh filename="package://meshes\servo_wheel.stl"/>
      </geometry>
    </collision>
    <!-- Part servo_3 -->
    <visual>
      <origin xyz="-0.0175 -0.00140442 -0.0305" rpy="3.14159 3.94279e-16 -2.22045e-16"/>
      <geometry>
        <mesh filename="package://meshes\servo.stl"/>
      </geometry>
      <material name="servo_3_material">
        <color rgba="0.109804 0.109804 0.105882 1"/>
      </material>
    </visual>
    <collision>
      <origin xyz="-0.0175 -0.00140442 -0.0305" rpy="3.14159 3.94279e-16 -2.22045e-16"/>
      <geometry>
        <mesh filename="package://meshes\servo.stl"/>
      </geometry>
    </collision>
    <!-- Part fixed_bracket_3 -->
    <visual>
      <origin xyz="-0.0575 1.9082e-17 -0.0305" rpy="1.5708 1.5708 0"/>
      <geometry>
        <mesh filename="package://meshes\fixed_bracket.stl"/>
      </geometry>
      <material name="fixed_bracket_3_material">
        <color rgba="0.647059 0.647059 0.647059 1"/>
      </material>
    </visual>
    <collision>
      <origin xyz="-0.0575 1.9082e-17 -0.0305" rpy="1.5708 1.5708 0"/>
      <geometry>
        <mesh filename="package://meshes\fixed_bracket.stl"/>
      </geometry>
    </collision>
    <!-- Part servo_wheel_6 -->
    <visual>
      <origin xyz="5.55112e-17 8.1532e-17 -0.0585" rpy="3.14159 -9.79955e-18 1.11022e-16"/>
      <geometry>
        <mesh filename="package://meshes\servo_wheel.stl"/>
      </geometry>
      <material name="servo_wheel_6_material">
        <color rgba="0.647059 0.647059 0.647059 1"/>
      </material>
    </visual>
    <collision>
      <origin xyz="5.55112e-17 8.1532e-17 -0.0585" rpy="3.14159 -9.79955e-18 1.11022e-16"/>
      <geometry>
        <mesh filename="package://meshes\servo_wheel.stl"/>
      </geometry>
    </collision>
  </link>
  <!-- Joint from ties_assembly to foot_assembly -->
  <joint name="foot_1" type="revolute">
    <origin xyz="0.1918 0.000117091 -0.00186036" rpy="-1.83367e-15 -1.8597e-15 3.14159"/>
    <parent link="ties_assembly"/>
    <child link="foot_assembly"/>
    <axis xyz="0 0 1"/>
    <limit effort="10" velocity="10" lower="-2.0944" upper="2.0944"/>
  </joint>
  <!-- Joint from hip_assembly to ties_assembly -->
  <joint name="ties_1" type="revolute">
    <origin xyz="0.0925 -0.0311167 -0.0305" rpy="1.5708 3.75284e-15 1.25724e-15"/>
    <parent link="hip_assembly"/>
    <child link="ties_assembly"/>
    <axis xyz="0 0 1"/>
    <limit effort="10" velocity="10" lower="-1.74533" upper="1.74533"/>
  </joint>
  <!-- Joint from base_link to hip_assembly -->
  <joint name="hip_1" type="revolute">
    <origin xyz="0.142873 0.0479466 0.0166947" rpy="-2.41992e-14 -2.85159e-14 0.436332"/>
    <parent link="base_link"/>
    <child link="hip_assembly"/>
    <axis xyz="0 0 1"/>
    <limit effort="10" velocity="10" lower="-1.5708" upper="1.5708"/>
  </joint>
  <!-- Link hip_assembly_2 -->
  <link name="hip_assembly_2">
    <inertial>
      <origin xyz="-0.0271153 -0.000490209 -0.0317796" rpy="0 0 0"/>
      <mass value="0.38056"/>
      <inertia ixx="0.000187069" ixy="-3.08523e-06" ixz="-7.85466e-06" iyy="0.000328441" iyz="-1.17914e-06" izz="0.000302664"/>
    </inertial>
    <!-- Part hip_2 -->
    <visual>
      <origin xyz="-0.0575 3.64292e-17 -0.0045" rpy="6.66109e-15 2.55513e-15 -1.09316e-16"/>
      <geometry>
        <mesh filename="package://meshes\hip.stl"/>
      </geometry>
      <material name="hip_2_material">
        <color rgba="0.282353 0.54902 0.160784 1"/>
      </material>
    </visual>
    <collision>
      <origin xyz="-0.0575 3.64292e-17 -0.0045" rpy="6.66109e-15 2.55513e-15 -1.09316e-16"/>
      <geometry>
        <mesh filename="package://meshes\hip.stl"/>
      </geometry>
    </collision>
    <!-- Part mobile_bracket_9 -->
    <visual>
      <origin xyz="-0.0575 2.25514e-17 -0.0305" rpy="2.48572e-15 -7.17397e-15 1.5708"/>
      <geometry>
        <mesh filename="package://meshes\mobile_bracket.stl"/>
      </geometry>
      <material name="mobile_bracket_9_material">
        <color rgba="0.647059 0.647059 0.647059 1"/>
      </material>
    </visual>
    <collision>
      <origin xyz="-0.0575 2.25514e-17 -0.0305" rpy="2.48572e-15 -7.17397e-15 1.5708"/>
      <geometry>
        <mesh filename="package://meshes\mobile_bracket.stl"/>
      </geometry>
    </collision>
    <!-- Part servo_wheel_7 -->
    <visual>
      <origin xyz="0 -3.46945e-18 -0.0025" rpy="3.14159 -4.9326e-31 3.23512e-17"/>
      <geometry>
        <mesh filename="package://meshes\servo_wheel.stl"/>
      </geometry>
      <material name="servo_wheel_7_material">
        <color rgba="0.647059 0.647059 0.647059 1"/>
      </material>
    </visual>
    <collision>
      <origin xyz="0 -3.46945e-18 -0.0025" rpy="3.14159 -4.9326e-31 3.23512e-17"/>
      <geometry>
        <mesh filename="package://meshes\servo_wheel.stl"/>
      </geometry>
    </collision>
    <!-- Part servo_4 -->
    <visual>
      <origin xyz="-0.0175 -0.00140442 -0.0305" rpy="-3.14159 2.31536e-15 -2.90032e-17"/>
      <geometry>
        <mesh filename="package://meshes\servo.stl"/>
      </geometry>
      <material name="servo_4_material">
        <color rgba="0.109804 0.109804 0.105882 1"/>
      </material>
    </visual>
    <collision>
      <origin xyz="-0.0175 -0.00140442 -0.0305" rpy="-3.14159 2.31536e-15 -2.90032e-17"/>
      <geometry>
        <mesh filename="package://meshes\servo.stl"/>
      </geometry>
    </collision>
    <!-- Part fixed_bracket_4 -->
    <visual>
      <origin xyz="-0.0575 3.1225e-17 -0.0305" rpy="1.5708 1.5708 0"/>
      <geometry>
        <mesh filename="package://meshes\fixed_bracket.stl"/>
      </geometry>
      <material name="fixed_bracket_4_material">
        <color rgba="0.647059 0.647059 0.647059 1"/>
      </material>
    </visual>
    <collision>
      <origin xyz="-0.0575 3.1225e-17 -0.0305" rpy="1.5708 1.5708 0"/>
      <geometry>
        <mesh filename="package://meshes\fixed_bracket.stl"/>
      </geometry>
    </collision>
    <!-- Part servo_wheel_8 -->
    <visual>
      <origin xyz="0 1.56125e-17 -0.0585" rpy="-3.14159 2.31536e-15 -8.92377e-17"/>
      <geometry>
        <mesh filename="package://meshes\servo_wheel.stl"/>
      </geometry>
      <material name="servo_wheel_8_material">
        <color rgba="0.647059 0.647059 0.647059 1"/>
      </material>
    </visual>
    <collision>
      <origin xyz="0 1.56125e-17 -0.0585" rpy="-3.14159 2.31536e-15 -8.92377e-17"/>
      <geometry>
        <mesh filename="package://meshes\servo_wheel.stl"/>
      </geometry>
    </collision>
  </link>
  <!-- Link ties_assembly_2 -->
  <link name="ties_assembly_2">
    <inertial>
      <origin xyz="0.0639313 0.001561 -0.0314406" rpy="0 0 0"/>
      <mass value="0.581468"/>
      <inertia ixx="0.000317042" ixy="-2.4027e-05" ixz="2.78889e-05" iyy="0.00207548" iyz="-4.55023e-07" izz="0.00186094"/>
    </inertial>
    <!-- Part mobile_bracket_10 -->
    <visual>
      <origin xyz="0.1568 0.000117091 -0.0322436" rpy="1.5708 1.5708 0"/>
      <geometry>
        <mesh filename="package://meshes\mobile_bracket.stl"/>
      </geometry>
      <material name="mobile_bracket_10_material">
        <color rgba="0.647059 0.647059 0.647059 1"/>
      </material>
    </visual>
    <collision>
      <origin xyz="0.1568 0.000117091 -0.0322436" rpy="1.5708 1.5708 0"/>
      <geometry>
        <mesh filename="package://meshes\mobile_bracket.stl"/>
      </geometry>
    </collision>
    <!-- Part low_tie_2 -->
    <visual>
      <origin xyz="0.0268 0.000117091 -0.0322436" rpy="5.55857e-15 1.5708 0"/>
      <geometry>
        <mesh filename="package://meshes\low_tie.stl"/>
      </geometry>
      <material name="low_tie_2_material">
        <color rgba="0.282353 0.54902 0.160784 1"/>
      </material>
    </visual>
    <collision>
      <origin xyz="0.0268 0.000117091 -0.0322436" rpy="5.55857e-15 1.5708 0"/>
      <geometry>
        <mesh filename="package://meshes\low_tie.stl"/>
      </geometry>
    </collision>
    <!-- Part top_tie_2 -->
    <visual>
      <origin xyz="0.0275 -1.68268e-16 -0.0305" rpy="5.55857e-15 1.5708 0"/>
      <geometry>
        <mesh filename="package://meshes\top_tie.stl"/>
      </geometry>
      <material name="top_tie_2_material">
        <color rgba="0.282353 0.54902 0.160784 1"/>
      </material>
    </visual>
    <collision>
      <origin xyz="0.0275 -1.68268e-16 -0.0305" rpy="5.55857e-15 1.5708 0"/>
      <geometry>
        <mesh filename="package://meshes\top_tie.stl"/>
      </geometry>
    </collision>
    <!-- Part servo_wheel_9 -->
    <visual>
      <origin xyz="5.55112e-17 0 -0.0025" rpy="-3.14159 7.62056e-15 3.14159"/>
      <geometry>
        <mesh filename="package://meshes\servo_wheel.stl"/>
      </geometry>
      <material name="servo_wheel_9_material">
        <color rgba="0.647059 0.647059 0.647059 1"/>
      </material>
    </visual>
    <collision>
      <origin xyz="5.55112e-17 0 -0.0025" rpy="-3.14159 7.62056e-15 3.14159"/>
      <geometry>
        <mesh filename="package://meshes\servo_wheel.stl"/>
      </geometry>
    </collision>
    <!-- Part servo_5 -->
    <visual>
      <origin xyz="0.0175 0.00140442 -0.0305" rpy="3.14159 -1.19866e-15 3.14159"/>
      <geometry>
        <mesh filename="package://meshes\servo.stl"/>
      </geometry>
      <material name="servo_5_material">
        <color rgba="0.109804 0.109804 0.105882 1"/>
      </material>
    </visual>
    <collision>
      <origin xyz="0.0175 0.00140442 -0.0305" rpy="3.14159 -1.19866e-15 3.14159"/>
      <geometry>
        <mesh filename="package://meshes\servo.stl"/>
      </geometry>
    </collision>
    <!-- Part fixed_bracket_5 -->
    <visual>
      <origin xyz="0.0575 -3.36536e-16 -0.0305" rpy="-1.5708 1.5708 0"/>
      <geometry>
        <mesh filename="package://meshes\fixed_bracket.stl"/>
      </geometry>
      <material name="fixed_bracket_5_material">
        <color rgba="0.647059 0.647059 0.647059 1"/>
      </material>
    </visual>
    <collision>
      <origin xyz="0.0575 -3.36536e-16 -0.0305" rpy="-1.5708 1.5708 0"/>
      <geometry>
        <mesh filename="package://meshes\fixed_bracket.stl"/>
      </geometry>
    </collision>
    <!-- Part servo_wheel_10 -->
    <visual>
      <origin xyz="5.55112e-17 -1.73472e-18 -0.0585" rpy="-3.14159 -1.48331e-15 3.14159"/>
      <geometry>
        <mesh filename="package://meshes\servo_wheel.stl"/>
      </geometry>
      <material name="servo_wheel_10_material">
        <color rgba="0.647059 0.647059 0.647059 1"/>
      </material>
    </visual>
    <collision>
      <origin xyz="5.55112e-17 -1.73472e-18 -0.0585" rpy="-3.14159 -1.48331e-15 3.14159"/>
      <geometry>
        <mesh filename="package://meshes\servo_wheel.stl"/>
      </geometry>
    </collision>
  </link>
  <!-- Link foot_assembly_2 -->
  <link name="foot_assembly_2">
    <inertial>
      <origin xyz="-0.0719605 -0.00210262 -0.0306706" rpy="0 0 0"/>
      <mass value="0.628062"/>
      <inertia ixx="0.000268406" ixy="-1.55227e-05" ixz="4.14924e-06" iyy="0.0031862" iyz="-2.26544e-07" izz="0.00302315"/>
    </inertial>
    <!-- Part foot_2 -->
    <visual>
      <origin xyz="-0.04425 8.67362e-18 -0.0305" rpy="1.52211e-27 1.5708 0"/>
      <geometry>
        <mesh filename="package://meshes\foot.stl"/>
      </geometry>
      <material name="foot_2_material">
        <color rgba="0.282353 0.54902 0.160784 1"/>
      </material>
    </visual>
    <collision>
      <origin xyz="-0.04425 8.67362e-18 -0.0305" rpy="1.52211e-27 1.5708 0"/>
      <geometry>
        <mesh filename="package://meshes\foot.stl"/>
      </geometry>
    </collision>
    <!-- Part ir_sensor_cap_2 -->
    <visual>
      <origin xyz="-0.0442455 6.98571e-05 -0.0305" rpy="2.33863e-15 1.5708 0"/>
      <geometry>
        <mesh filename="package://meshes\ir_sensor_cap.stl"/>
      </geometry>
      <material name="ir_sensor_cap_2_material">
        <color rgba="0.282353 0.54902 0.160784 1"/>
      </material>
    </visual>
    <collision>
      <origin xyz="-0.0442455 6.98571e-05 -0.0305" rpy="2.33863e-15 1.5708 0"/>
      <geometry>
        <mesh filename="package://meshes\ir_sensor_cap.stl"/>
      </geometry>
    </collision>
    <!-- Part rubber_foot_2 -->
    <visual>
      <origin xyz="-0.04375 1.59595e-16 -0.03" rpy="-7.21645e-16 1.5708 0"/>
      <geometry>
        <mesh filename="package://meshes\rubber_foot.stl"/>
      </geometry>
      <material name="rubber_foot_2_material">
        <color rgba="0.262745 0.282353 0.301961 1"/>
      </material>
    </visual>
    <collision>
      <origin xyz="-0.04375 1.59595e-16 -0.03" rpy="-7.21645e-16 1.5708 0"/>
      <geometry>
        <mesh filename="package://meshes\rubber_foot.stl"/>
      </geometry>
    </collision>
    <!-- Part servo_wheel_11 -->
    <visual>
      <origin xyz="0 0 -0.0025" rpy="3.14159 6.46282e-17 5.1276e-30"/>
      <geometry>
        <mesh filename="package://meshes\servo_wheel.stl"/>
      </geometry>
      <material name="servo_wheel_11_material">
        <color rgba="0.647059 0.647059 0.647059 1"/>
      </material>
    </visual>
    <collision>
      <origin xyz="0 0 -0.0025" rpy="3.14159 6.46282e-17 5.1276e-30"/>
      <geometry>
        <mesh filename="package://meshes\servo_wheel.stl"/>
      </geometry>
    </collision>
    <!-- Part servo_6 -->
    <visual>
      <origin xyz="-0.0175 -0.00140442 -0.0305" rpy="-3.14159 1.76144e-14 -1.18329e-30"/>
      <geometry>
        <mesh filename="package://meshes\servo.stl"/>
      </geometry>
      <material name="servo_6_material">
        <color rgba="0.109804 0.109804 0.105882 1"/>
      </material>
    </visual>
    <collision>
      <origin xyz="-0.0175 -0.00140442 -0.0305" rpy="-3.14159 1.76144e-14 -1.18329e-30"/>
      <geometry>
        <mesh filename="package://meshes\servo.stl"/>
      </geometry>
    </collision>
    <!-- Part fixed_bracket_6 -->
    <visual>
      <origin xyz="-0.0575 8.67362e-18 -0.0305" rpy="1.5708 1.5708 0"/>
      <geometry>
        <mesh filename="package://meshes\fixed_bracket.stl"/>
      </geometry>
      <material name="fixed_bracket_6_material">
        <color rgba="0.647059 0.647059 0.647059 1"/>
      </material>
    </visual>
    <collision>
      <origin xyz="-0.0575 8.67362e-18 -0.0305" rpy="1.5708 1.5708 0"/>
      <geometry>
        <mesh filename="package://meshes\fixed_bracket.stl"/>
      </geometry>
    </collision>
    <!-- Part servo_wheel_12 -->
    <visual>
      <origin xyz="5.55112e-17 0 -0.0585" rpy="-3.14159 1.53408e-14 -1.18329e-30"/>
      <geometry>
        <mesh filename="package://meshes\servo_wheel.stl"/>
      </geometry>
      <material name="servo_wheel_12_material">
        <color rgba="0.647059 0.647059 0.647059 1"/>
      </material>
    </visual>
    <collision>
      <origin xyz="5.55112e-17 0 -0.0585" rpy="-3.14159 1.53408e-14 -1.18329e-30"/>
      <geometry>
        <mesh filename="package://meshes\servo_wheel.stl"/>
      </geometry>
    </collision>
  </link>
  <!-- Joint from ties_assembly_2 to foot_assembly_2 -->
  <joint name="foot_2" type="revolute">
    <origin xyz="0.1918 0.000117091 -0.00186036" rpy="-6.33457e-15 -1.83953e-14 3.14159"/>
    <parent link="ties_assembly_2"/>
    <child link="foot_assembly_2"/>
    <axis xyz="0 0 1"/>
    <limit effort="10" velocity="10" lower="-2.0944" upper="2.0944"/>
  </joint>
  <!-- Joint from hip_assembly_2 to ties_assembly_2 -->
  <joint name="ties_2" type="revolute">
    <origin xyz="-0.0925 0.0311167 -0.0305" rpy="1.5708 -2.48572e-15 3.14159"/>
    <parent link="hip_assembly_2"/>
    <child link="ties_assembly_2"/>
    <axis xyz="0 0 1"/>
    <limit effort="10" velocity="10" lower="-1.74533" upper="1.74533"/>
  </joint>
  <!-- Joint from base_link to hip_assembly_2 -->
  <joint name="hip_2" type="revolute">
    <origin xyz="0.129624 -0.103492 0.0166947" rpy="-1.34586e-14 3.21607e-14 2.53073"/>
    <parent link="base_link"/>
    <child link="hip_assembly_2"/>
    <axis xyz="0 0 1"/>
    <limit effort="10" velocity="10" lower="-1.5708" upper="1.5708"/>
  </joint>
  <!-- Link hip_assembly_3 -->
  <link name="hip_assembly_3">
    <inertial>
      <origin xyz="0.0271153 0.000490209 -0.0317796" rpy="0 0 0"/>
      <mass value="0.38056"/>
      <inertia ixx="0.000187069" ixy="-3.08523e-06" ixz="7.85466e-06" iyy="0.000328441" iyz="1.17914e-06" izz="0.000302664"/>
    </inertial>
    <!-- Part hip_3 -->
    <visual>
      <origin xyz="0.0575 3.81639e-16 -0.0045" rpy="-2.65273e-14 2.74219e-14 -3.14159"/>
      <geometry>
        <mesh filename="package://meshes\hip.stl"/>
      </geometry>
      <material name="hip_3_material">
        <color rgba="0.282353 0.54902 0.160784 1"/>
      </material>
    </visual>
    <collision>
      <origin xyz="0.0575 3.81639e-16 -0.0045" rpy="-2.65273e-14 2.74219e-14 -3.14159"/>
      <geometry>
        <mesh filename="package://meshes\hip.stl"/>
      </geometry>
    </collision>
    <!-- Part mobile_bracket_11 -->
    <visual>
      <origin xyz="0.0575 6.75675e-16 -0.0305" rpy="2.74219e-14 5.37076e-14 -1.5708"/>
      <geometry>
        <mesh filename="package://meshes\mobile_bracket.stl"/>
      </geometry>
      <material name="mobile_bracket_11_material">
        <color rgba="0.647059 0.647059 0.647059 1"/>
      </material>
    </visual>
    <collision>
      <origin xyz="0.0575 6.75675e-16 -0.0305" rpy="2.74219e-14 5.37076e-14 -1.5708"/>
      <geometry>
        <mesh filename="package://meshes\mobile_bracket.stl"/>
      </geometry>
    </collision>
    <!-- Part servo_wheel_13 -->
    <visual>
      <origin xyz="2.498e-16 1.5439e-16 -0.0025" rpy="3.14159 2.70114e-14 -3.14159"/>
      <geometry>
        <mesh filename="package://meshes\servo_wheel.stl"/>
      </geometry>
      <material name="servo_wheel_13_material">
        <color rgba="0.647059 0.647059 0.647059 1"/>
      </material>
    </visual>
    <collision>
      <origin xyz="2.498e-16 1.5439e-16 -0.0025" rpy="3.14159 2.70114e-14 -3.14159"/>
      <geometry>
        <mesh filename="package://meshes\servo_wheel.stl"/>
      </geometry>
    </collision>
    <!-- Part servo_7 -->
    <visual>
      <origin xyz="0.0175 0.00140442 -0.0305" rpy="3.14159 2.74219e-14 -3.14159"/>
      <geometry>
        <mesh filename="package://meshes\servo.stl"/>
      </geometry>
      <material name="servo_7_material">
        <color rgba="0.109804 0.109804 0.105882 1"/>
      </material>
    </visual>
    <collision>
      <origin xyz="0.0175 0.00140442 -0.0305" rpy="3.14159 2.74219e-14 -3.14159"/>
      <geometry>
        <mesh filename="package://meshes\servo.stl"/>
      </geometry>
    </collision>
    <!-- Part fixed_bracket_7 -->
    <visual>
      <origin xyz="0.0575 6.75675e-16 -0.0305" rpy="-1.5708 1.5708 0"/>
      <geometry>
        <mesh filename="package://meshes\fixed_bracket.stl"/>
      </geometry>
      <material name="fixed_bracket_7_material">
        <color rgba="0.647059 0.647059 0.647059 1"/>
      </material>
    </visual>
    <collision>
      <origin xyz="0.0575 6.75675e-16 -0.0305" rpy="-1.5708 1.5708 0"/>
      <geometry>
        <mesh filename="package://meshes\fixed_bracket.stl"/>
      </geometry>
    </collision>
    <!-- Part servo_wheel_14 -->
    <visual>
      <origin xyz="2.498e-16 1.7087e-16 -0.0585" rpy="3.14159 2.74219e-14 -3.14159"/>
      <geometry>
        <mesh filename="package://meshes\servo_wheel.stl"/>
      </geometry>
      <material name="servo_wheel_14_material">
        <color rgba="0.647059 0.647059 0.647059 1"/>
      </material>
    </visual>
    <collision>
      <origin xyz="2.498e-16 1.7087e-16 -0.0585" rpy="3.14159 2.74219e-14 -3.14159"/>
      <geometry>
        <mesh filename="package://meshes\servo_wheel.stl"/>
      </geometry>
    </collision>
  </link>
  <!-- Link ties_assembly_3 -->
  <link name="ties_assembly_3">
    <inertial>
      <origin xyz="0.0639313 0.001561 -0.0314406" rpy="0 0 0"/>
      <mass value="0.581468"/>
      <inertia ixx="0.000317042" ixy="-2.4027e-05" ixz="2.78889e-05" iyy="0.00207548" iyz="-4.55023e-07" izz="0.00186094"/>
    </inertial>
    <!-- Part mobile_bracket_12 -->
    <visual>
      <origin xyz="0.1568 0.000117091 -0.0322436" rpy="1.5708 1.5708 0"/>
      <geometry>
        <mesh filename="package://meshes\mobile_bracket.stl"/>
      </geometry>
      <material name="mobile_bracket_12_material">
        <color rgba="0.647059 0.647059 0.647059 1"/>
      </material>
    </visual>
    <collision>
      <origin xyz="0.1568 0.000117091 -0.0322436" rpy="1.5708 1.5708 0"/>
      <geometry>
        <mesh filename="package://meshes\mobile_bracket.stl"/>
      </geometry>
    </collision>
    <!-- Part low_tie_3 -->
    <visual>
      <origin xyz="0.0268 0.000117091 -0.0322436" rpy="-4.35426e-15 1.5708 0"/>
      <geometry>
        <mesh filename="package://meshes\low_tie.stl"/>
      </geometry>
      <material name="low_tie_3_material">
        <color rgba="0.282353 0.54902 0.160784 1"/>
      </material>
    </visual>
    <collision>
      <origin xyz="0.0268 0.000117091 -0.0322436" rpy="-4.35426e-15 1.5708 0"/>
      <geometry>
        <mesh filename="package://meshes\low_tie.stl"/>
      </geometry>
    </collision>
    <!-- Part top_tie_3 -->
    <visual>
      <origin xyz="0.0275 4.28477e-16 -0.0305" rpy="-3.79915e-15 1.5708 0"/>
      <geometry>
        <mesh filename="package://meshes\top_tie.stl"/>
      </geometry>
      <material name="top_tie_3_material">
        <color rgba="0.282353 0.54902 0.160784 1"/>
      </material>
    </visual>
    <collision>
      <origin xyz="0.0275 4.28477e-16 -0.0305" rpy="-3.79915e-15 1.5708 0"/>
      <geometry>
        <mesh filename="package://meshes\top_tie.stl"/>
      </geometry>
    </collision>
    <!-- Part servo_wheel_15 -->
    <visual>
      <origin xyz="1.11022e-16 3.10516e-16 -0.0025" rpy="-3.14159 2.4762e-16 -3.14159"/>
      <geometry>
        <mesh filename="package://meshes\servo_wheel.stl"/>
      </geometry>
      <material name="servo_wheel_15_material">
        <color rgba="0.647059 0.647059 0.647059 1"/>
      </material>
    </visual>
    <collision>
      <origin xyz="1.11022e-16 3.10516e-16 -0.0025" rpy="-3.14159 2.4762e-16 -3.14159"/>
      <geometry>
        <mesh filename="package://meshes\servo_wheel.stl"/>
      </geometry>
    </collision>
    <!-- Part servo_8 -->
    <visual>
      <origin xyz="0.0175 0.00140442 -0.0305" rpy="3.14159 -3.09451e-15 -3.14159"/>
      <geometry>
        <mesh filename="package://meshes\servo.stl"/>
      </geometry>
      <material name="servo_8_material">
        <color rgba="0.109804 0.109804 0.105882 1"/>
      </material>
    </visual>
    <collision>
      <origin xyz="0.0175 0.00140442 -0.0305" rpy="3.14159 -3.09451e-15 -3.14159"/>
      <geometry>
        <mesh filename="package://meshes\servo.stl"/>
      </geometry>
    </collision>
    <!-- Part fixed_bracket_8 -->
    <visual>
      <origin xyz="0.0575 4.80518e-16 -0.0305" rpy="-1.5708 1.5708 0"/>
      <geometry>
        <mesh filename="package://meshes\fixed_bracket.stl"/>
      </geometry>
      <material name="fixed_bracket_8_material">
        <color rgba="0.647059 0.647059 0.647059 1"/>
      </material>
    </visual>
    <collision>
      <origin xyz="0.0575 4.80518e-16 -0.0305" rpy="-1.5708 1.5708 0"/>
      <geometry>
        <mesh filename="package://meshes\fixed_bracket.stl"/>
      </geometry>
    </collision>
    <!-- Part servo_wheel_16 -->
    <visual>
      <origin xyz="-5.55112e-17 1.45717e-16 -0.0585" rpy="3.14159 -3.16517e-15 -3.14159"/>
      <geometry>
        <mesh filename="package://meshes\servo_wheel.stl"/>
      </geometry>
      <material name="servo_wheel_16_material">
        <color rgba="0.647059 0.647059 0.647059 1"/>
      </material>
    </visual>
    <collision>
      <origin xyz="-5.55112e-17 1.45717e-16 -0.0585" rpy="3.14159 -3.16517e-15 -3.14159"/>
      <geometry>
        <mesh filename="package://meshes\servo_wheel.stl"/>
      </geometry>
    </collision>
  </link>
  <!-- Link foot_assembly_3 -->
  <link name="foot_assembly_3">
    <inertial>
      <origin xyz="-0.0719605 -0.00210262 -0.0306706" rpy="0 0 0"/>
      <mass value="0.628062"/>
      <inertia ixx="0.000268406" ixy="-1.55227e-05" ixz="4.14924e-06" iyy="0.0031862" iyz="-2.26544e-07" izz="0.00302315"/>
    </inertial>
    <!-- Part foot_3 -->
    <visual>
      <origin xyz="-0.04425 6.93889e-18 -0.0305" rpy="1.66533e-16 1.5708 0"/>
      <geometry>
        <mesh filename="package://meshes\foot.stl"/>
      </geometry>
      <material name="foot_3_material">
        <color rgba="0.282353 0.54902 0.160784 1"/>
      </material>
    </visual>
    <collision>
      <origin xyz="-0.04425 6.93889e-18 -0.0305" rpy="1.66533e-16 1.5708 0"/>
      <geometry>
        <mesh filename="package://meshes\foot.stl"/>
      </geometry>
    </collision>
    <!-- Part ir_sensor_cap_3 -->
    <visual>
      <origin xyz="-0.0442455 6.98571e-05 -0.0305" rpy="-3.01108e-15 1.5708 0"/>
      <geometry>
        <mesh filename="package://meshes\ir_sensor_cap.stl"/>
      </geometry>
      <material name="ir_sensor_cap_3_material">
        <color rgba="0.282353 0.54902 0.160784 1"/>
      </material>
    </visual>
    <collision>
      <origin xyz="-0.0442455 6.98571e-05 -0.0305" rpy="-3.01108e-15 1.5708 0"/>
      <geometry>
        <mesh filename="package://meshes\ir_sensor_cap.stl"/>
      </geometry>
    </collision>
    <!-- Part rubber_foot_3 -->
    <visual>
      <origin xyz="-0.04375 5.93275e-16 -0.03" rpy="-2.61596e-15 1.5708 0"/>
      <geometry>
        <mesh filename="package://meshes\rubber_foot.stl"/>
      </geometry>
      <material name="rubber_foot_3_material">
        <color rgba="0.262745 0.282353 0.301961 1"/>
      </material>
    </visual>
    <collision>
      <origin xyz="-0.04375 5.93275e-16 -0.03" rpy="-2.61596e-15 1.5708 0"/>
      <geometry>
        <mesh filename="package://meshes\rubber_foot.stl"/>
      </geometry>
    </collision>
    <!-- Part servo_wheel_17 -->
    <visual>
      <origin xyz="-5.55112e-17 0 -0.0025" rpy="3.14159 1.61186e-18 8.08582e-30"/>
      <geometry>
        <mesh filename="package://meshes\servo_wheel.stl"/>
      </geometry>
      <material name="servo_wheel_17_material">
        <color rgba="0.647059 0.647059 0.647059 1"/>
      </material>
    </visual>
    <collision>
      <origin xyz="-5.55112e-17 0 -0.0025" rpy="3.14159 1.61186e-18 8.08582e-30"/>
      <geometry>
        <mesh filename="package://meshes\servo_wheel.stl"/>
      </geometry>
    </collision>
    <!-- Part servo_9 -->
    <visual>
      <origin xyz="-0.0175 -0.00140442 -0.0305" rpy="-3.14159 5.27312e-16 5.55112e-17"/>
      <geometry>
        <mesh filename="package://meshes\servo.stl"/>
      </geometry>
      <material name="servo_9_material">
        <color rgba="0.109804 0.109804 0.105882 1"/>
      </material>
    </visual>
    <collision>
      <origin xyz="-0.0175 -0.00140442 -0.0305" rpy="-3.14159 5.27312e-16 5.55112e-17"/>
      <geometry>
        <mesh filename="package://meshes\servo.stl"/>
      </geometry>
    </collision>
    <!-- Part fixed_bracket_9 -->
    <visual>
      <origin xyz="-0.0575 -2.94903e-16 -0.0305" rpy="1.5708 1.5708 0"/>
      <geometry>
        <mesh filename="package://meshes\fixed_bracket.stl"/>
      </geometry>
      <material name="fixed_bracket_9_material">
        <color rgba="0.647059 0.647059 0.647059 1"/>
      </material>
    </visual>
    <collision>
      <origin xyz="-0.0575 -2.94903e-16 -0.0305" rpy="1.5708 1.5708 0"/>
      <geometry>
        <mesh filename="package://meshes\fixed_bracket.stl"/>
      </geometry>
    </collision>
    <!-- Part servo_wheel_18 -->
    <visual>
      <origin xyz="-3.33067e-16 1.5439e-16 -0.0585" rpy="-3.14159 6.25977e-17 1.11022e-16"/>
      <geometry>
        <mesh filename="package://meshes\servo_wheel.stl"/>
      </geometry>
      <material name="servo_wheel_18_material">
        <color rgba="0.647059 0.647059 0.647059 1"/>
      </material>
    </visual>
    <collision>
      <origin xyz="-3.33067e-16 1.5439e-16 -0.0585" rpy="-3.14159 6.25977e-17 1.11022e-16"/>
      <geometry>
        <mesh filename="package://meshes\servo_wheel.stl"/>
      </geometry>
    </collision>
  </link>
  <!-- Joint from ties_assembly_3 to foot_assembly_3 -->
  <joint name="foot_3" type="revolute">
    <origin xyz="0.1918 0.000117091 -0.00186036" rpy="1.26193e-15 -1.75295e-15 -3.14159"/>
    <parent link="ties_assembly_3"/>
    <child link="foot_assembly_3"/>
    <axis xyz="0 0 1"/>
    <limit effort="10" velocity="10" lower="-2.0944" upper="2.0944"/>
  </joint>
  <!-- Joint from hip_assembly_3 to ties_assembly_3 -->
  <joint name="ties_3" type="revolute">
    <origin xyz="0.0925 -0.0311167 -0.0305" rpy="1.5708 -2.74219e-14 9.4696e-15"/>
    <parent link="hip_assembly_3"/>
    <child link="ties_assembly_3"/>
    <axis xyz="0 0 1"/>
    <limit effort="10" velocity="10" lower="-1.74533" upper="1.74533"/>
  </joint>
  <!-- Joint from base_link to hip_assembly_3 -->
  <joint name="hip_3" type="revolute">
    <origin xyz="-0.00815056 -0.167737 0.0174281" rpy="7.71669e-15 -8.74693e-15 -1.65806"/>
    <parent link="base_link"/>
    <child link="hip_assembly_3"/>
    <axis xyz="0 0 1"/>
    <limit effort="10" velocity="10" lower="-1.5708" upper="1.5708"/>
  </joint>
  <!-- Link hip_assembly_4 -->
  <link name="hip_assembly_4">
    <inertial>
      <origin xyz="0.0271153 0.000490209 -0.0317796" rpy="0 0 0"/>
      <mass value="0.38056"/>
      <inertia ixx="0.000187069" ixy="-3.08523e-06" ixz="7.85466e-06" iyy="0.000328441" iyz="1.17914e-06" izz="0.000302664"/>
    </inertial>
    <!-- Part hip_4 -->
    <visual>
      <origin xyz="0.0575 -5.55112e-17 -0.0045" rpy="-1.00936e-15 -9.85854e-16 3.14159"/>
      <geometry>
        <mesh filename="package://meshes\hip.stl"/>
      </geometry>
      <material name="hip_4_material">
        <color rgba="0.282353 0.54902 0.160784 1"/>
      </material>
    </visual>
    <collision>
      <origin xyz="0.0575 -5.55112e-17 -0.0045" rpy="-1.00936e-15 -9.85854e-16 3.14159"/>
      <geometry>
        <mesh filename="package://meshes\hip.stl"/>
      </geometry>
    </collision>
    <!-- Part mobile_bracket_13 -->
    <visual>
      <origin xyz="0.0575 3.1225e-17 -0.0305" rpy="-6.85694e-16 -8.32515e-16 -1.5708"/>
      <geometry>
        <mesh filename="package://meshes\mobile_bracket.stl"/>
      </geometry>
      <material name="mobile_bracket_13_material">
        <color rgba="0.647059 0.647059 0.647059 1"/>
      </material>
    </visual>
    <collision>
      <origin xyz="0.0575 3.1225e-17 -0.0305" rpy="-6.85694e-16 -8.32515e-16 -1.5708"/>
      <geometry>
        <mesh filename="package://meshes\mobile_bracket.stl"/>
      </geometry>
    </collision>
    <!-- Part servo_wheel_19 -->
    <visual>
      <origin xyz="5.55112e-17 -1.73472e-17 -0.0025" rpy="3.14159 -2.71148e-16 -3.14159"/>
      <geometry>
        <mesh filename="package://meshes\servo_wheel.stl"/>
      </geometry>
      <material name="servo_wheel_19_material">
        <color rgba="0.647059 0.647059 0.647059 1"/>
      </material>
    </visual>
    <collision>
      <origin xyz="5.55112e-17 -1.73472e-17 -0.0025" rpy="3.14159 -2.71148e-16 -3.14159"/>
      <geometry>
        <mesh filename="package://meshes\servo_wheel.stl"/>
      </geometry>
    </collision>
    <!-- Part servo_10 -->
    <visual>
      <origin xyz="0.0175 0.00140442 -0.0305" rpy="3.14159 -3.37018e-16 -3.14159"/>
      <geometry>
        <mesh filename="package://meshes\servo.stl"/>
      </geometry>
      <material name="servo_10_material">
        <color rgba="0.109804 0.109804 0.105882 1"/>
      </material>
    </visual>
    <collision>
      <origin xyz="0.0175 0.00140442 -0.0305" rpy="3.14159 -3.37018e-16 -3.14159"/>
      <geometry>
        <mesh filename="package://meshes\servo.stl"/>
      </geometry>
    </collision>
    <!-- Part fixed_bracket_10 -->
    <visual>
      <origin xyz="0.0575 3.1225e-17 -0.0305" rpy="-1.5708 1.5708 0"/>
      <geometry>
        <mesh filename="package://meshes\fixed_bracket.stl"/>
      </geometry>
      <material name="fixed_bracket_10_material">
        <color rgba="0.647059 0.647059 0.647059 1"/>
      </material>
    </visual>
    <collision>
      <origin xyz="0.0575 3.1225e-17 -0.0305" rpy="-1.5708 1.5708 0"/>
      <geometry>
        <mesh filename="package://meshes\fixed_bracket.stl"/>
      </geometry>
    </collision>
    <!-- Part servo_wheel_20 -->
    <visual>
      <origin xyz="2.77556e-17 -1.38778e-17 -0.0585" rpy="3.14159 -2.71148e-16 -3.14159"/>
      <geometry>
        <mesh filename="package://meshes\servo_wheel.stl"/>
      </geometry>
      <material name="servo_wheel_20_material">
        <color rgba="0.647059 0.647059 0.647059 1"/>
      </material>
    </visual>
    <collision>
      <origin xyz="2.77556e-17 -1.38778e-17 -0.0585" rpy="3.14159 -2.71148e-16 -3.14159"/>
      <geometry>
        <mesh filename="package://meshes\servo_wheel.stl"/>
      </geometry>
    </collision>
  </link>
  <!-- Link ties_assembly_4 -->
  <link name="ties_assembly_4">
    <inertial>
      <origin xyz="0.0639313 0.001561 -0.0314406" rpy="0 0 0"/>
      <mass value="0.581468"/>
      <inertia ixx="0.000317042" ixy="-2.4027e-05" ixz="2.78889e-05" iyy="0.00207548" iyz="-4.55023e-07" izz="0.00186094"/>
    </inertial>
    <!-- Part mobile_bracket_14 -->
    <visual>
      <origin xyz="0.1568 0.000117091 -0.0322436" rpy="1.5708 1.5708 0"/>
      <geometry>
        <mesh filename="package://meshes\mobile_bracket.stl"/>
      </geometry>
      <material name="mobile_bracket_14_material">
        <color rgba="0.647059 0.647059 0.647059 1"/>
      </material>
    </visual>
    <collision>
      <origin xyz="0.1568 0.000117091 -0.0322436" rpy="1.5708 1.5708 0"/>
      <geometry>
        <mesh filename="package://meshes\mobile_bracket.stl"/>
      </geometry>
    </collision>
    <!-- Part low_tie_4 -->
    <visual>
      <origin xyz="0.0268 0.000117091 -0.0322436" rpy="-1.20056e-15 1.5708 0"/>
      <geometry>
        <mesh filename="package://meshes\low_tie.stl"/>
      </geometry>
      <material name="low_tie_4_material">
        <color rgba="0.282353 0.54902 0.160784 1"/>
      </material>
    </visual>
    <collision>
      <origin xyz="0.0268 0.000117091 -0.0322436" rpy="-1.20056e-15 1.5708 0"/>
      <geometry>
        <mesh filename="package://meshes\low_tie.stl"/>
      </geometry>
    </collision>
    <!-- Part top_tie_4 -->
    <visual>
      <origin xyz="0.0275 2.25514e-17 -0.0305" rpy="-1.20056e-15 1.5708 0"/>
      <geometry>
        <mesh filename="package://meshes\top_tie.stl"/>
      </geometry>
      <material name="top_tie_4_material">
        <color rgba="0.282353 0.54902 0.160784 1"/>
      </material>
    </visual>
    <collision>
      <origin xyz="0.0275 2.25514e-17 -0.0305" rpy="-1.20056e-15 1.5708 0"/>
      <geometry>
        <mesh filename="package://meshes\top_tie.stl"/>
      </geometry>
    </collision>
    <!-- Part servo_wheel_21 -->
    <visual>
      <origin xyz="2.77556e-17 -1.73472e-18 -0.0025" rpy="3.14159 -2.29043e-15 -3.14159"/>
      <geometry>
        <mesh filename="package://meshes\servo_wheel.stl"/>
      </geometry>
      <material name="servo_wheel_21_material">
        <color rgba="0.647059 0.647059 0.647059 1"/>
      </material>
    </visual>
    <collision>
      <origin xyz="2.77556e-17 -1.73472e-18 -0.0025" rpy="3.14159 -2.29043e-15 -3.14159"/>
      <geometry>
        <mesh filename="package://meshes\servo_wheel.stl"/>
      </geometry>
    </collision>
    <!-- Part servo_11 -->
    <visual>
      <origin xyz="0.0175 0.00140442 -0.0305" rpy="3.14159 -2.31474e-15 -3.14159"/>
      <geometry>
        <mesh filename="package://meshes\servo.stl"/>
      </geometry>
      <material name="servo_11_material">
        <color rgba="0.109804 0.109804 0.105882 1"/>
      </material>
    </visual>
    <collision>
      <origin xyz="0.0175 0.00140442 -0.0305" rpy="3.14159 -2.31474e-15 -3.14159"/>
      <geometry>
        <mesh filename="package://meshes\servo.stl"/>
      </geometry>
    </collision>
    <!-- Part fixed_bracket_11 -->
    <visual>
      <origin xyz="0.0575 5.89806e-17 -0.0305" rpy="-1.5708 1.5708 0"/>
      <geometry>
        <mesh filename="package://meshes\fixed_bracket.stl"/>
      </geometry>
      <material name="fixed_bracket_11_material">
        <color rgba="0.647059 0.647059 0.647059 1"/>
      </material>
    </visual>
    <collision>
      <origin xyz="0.0575 5.89806e-17 -0.0305" rpy="-1.5708 1.5708 0"/>
      <geometry>
        <mesh filename="package://meshes\fixed_bracket.stl"/>
      </geometry>
    </collision>
    <!-- Part servo_wheel_22 -->
    <visual>
      <origin xyz="-1.11022e-16 -5.20417e-18 -0.0585" rpy="3.14159 -6.70105e-16 -3.14159"/>
      <geometry>
        <mesh filename="package://meshes\servo_wheel.stl"/>
      </geometry>
      <material name="servo_wheel_22_material">
        <color rgba="0.647059 0.647059 0.647059 1"/>
      </material>
    </visual>
    <collision>
      <origin xyz="-1.11022e-16 -5.20417e-18 -0.0585" rpy="3.14159 -6.70105e-16 -3.14159"/>
      <geometry>
        <mesh filename="package://meshes\servo_wheel.stl"/>
      </geometry>
    </collision>
  </link>
  <!-- Link foot_assembly_4 -->
  <link name="foot_assembly_4">
    <inertial>
      <origin xyz="-0.0719605 -0.00210262 -0.0306706" rpy="0 0 0"/>
      <mass value="0.628062"/>
      <inertia ixx="0.000268406" ixy="-1.55227e-05" ixz="4.14924e-06" iyy="0.0031862" iyz="-2.26544e-07" izz="0.00302315"/>
    </inertial>
    <!-- Part foot_4 -->
    <visual>
      <origin xyz="-0.04425 5.20417e-18 -0.0305" rpy="-8.87469e-31 1.5708 0"/>
      <geometry>
        <mesh filename="package://meshes\foot.stl"/>
      </geometry>
      <material name="foot_4_material">
        <color rgba="0.282353 0.54902 0.160784 1"/>
      </material>
    </visual>
    <collision>
      <origin xyz="-0.04425 5.20417e-18 -0.0305" rpy="-8.87469e-31 1.5708 0"/>
      <geometry>
        <mesh filename="package://meshes\foot.stl"/>
      </geometry>
    </collision>
    <!-- Part ir_sensor_cap_4 -->
    <visual>
      <origin xyz="-0.0442455 6.98571e-05 -0.0305" rpy="4.3291e-16 1.5708 0"/>
      <geometry>
        <mesh filename="package://meshes\ir_sensor_cap.stl"/>
      </geometry>
      <material name="ir_sensor_cap_4_material">
        <color rgba="0.282353 0.54902 0.160784 1"/>
      </material>
    </visual>
    <collision>
      <origin xyz="-0.0442455 6.98571e-05 -0.0305" rpy="4.3291e-16 1.5708 0"/>
      <geometry>
        <mesh filename="package://meshes\ir_sensor_cap.stl"/>
      </geometry>
    </collision>
    <!-- Part rubber_foot_4 -->
    <visual>
      <origin xyz="-0.04375 2.7929e-16 -0.03" rpy="-1.30451e-15 1.5708 0"/>
      <geometry>
        <mesh filename="package://meshes\rubber_foot.stl"/>
      </geometry>
      <material name="rubber_foot_4_material">
        <color rgba="0.262745 0.282353 0.301961 1"/>
      </material>
    </visual>
    <collision>
      <origin xyz="-0.04375 2.7929e-16 -0.03" rpy="-1.30451e-15 1.5708 0"/>
      <geometry>
        <mesh filename="package://meshes\rubber_foot.stl"/>
      </geometry>
    </collision>
    <!-- Part servo_wheel_23 -->
    <visual>
      <origin xyz="5.55112e-17 1.73472e-18 -0.0025" rpy="-3.14159 -6.6826e-17 8.87469e-31"/>
      <geometry>
        <mesh filename="package://meshes\servo_wheel.stl"/>
      </geometry>
      <material name="servo_wheel_23_material">
        <color rgba="0.647059 0.647059 0.647059 1"/>
      </material>
    </visual>
    <collision>
      <origin xyz="5.55112e-17 1.73472e-18 -0.0025" rpy="-3.14159 -6.6826e-17 8.87469e-31"/>
      <geometry>
        <mesh filename="package://meshes\servo_wheel.stl"/>
      </geometry>
    </collision>
    <!-- Part servo_12 -->
    <visual>
      <origin xyz="-0.0175 -0.00140442 -0.0305" rpy="-3.14159 -7.00196e-17 8.87469e-31"/>
      <geometry>
        <mesh filename="package://meshes\servo.stl"/>
      </geometry>
      <material name="servo_12_material">
        <color rgba="0.109804 0.109804 0.105882 1"/>
      </material>
    </visual>
    <collision>
      <origin xyz="-0.0175 -0.00140442 -0.0305" rpy="-3.14159 -7.00196e-17 8.87469e-31"/>
      <geometry>
        <mesh filename="package://meshes\servo.stl"/>
      </geometry>
    </collision>
    <!-- Part fixed_bracket_12 -->
    <visual>
      <origin xyz="-0.0575 5.20417e-18 -0.0305" rpy="1.5708 1.5708 0"/>
      <geometry>
        <mesh filename="package://meshes\fixed_bracket.stl"/>
      </geometry>
      <material name="fixed_bracket_12_material">
        <color rgba="0.647059 0.647059 0.647059 1"/>
      </material>
    </visual>
    <collision>
      <origin xyz="-0.0575 5.20417e-18 -0.0305" rpy="1.5708 1.5708 0"/>
      <geometry>
        <mesh filename="package://meshes\fixed_bracket.stl"/>
      </geometry>
    </collision>
    <!-- Part servo_wheel_24 -->
    <visual>
      <origin xyz="8.88178e-16 0 -0.0585" rpy="-3.14159 -6.48186e-17 8.87469e-31"/>
      <geometry>
        <mesh filename="package://meshes\servo_wheel.stl"/>
      </geometry>
      <material name="servo_wheel_24_material">
        <color rgba="0.647059 0.647059 0.647059 1"/>
      </material>
    </visual>
    <collision>
      <origin xyz="8.88178e-16 0 -0.0585" rpy="-3.14159 -6.48186e-17 8.87469e-31"/>
      <geometry>
        <mesh filename="package://meshes\servo_wheel.stl"/>
      </geometry>
    </collision>
  </link>
  <!-- Joint from ties_assembly_4 to foot_assembly_4 -->
  <joint name="foot_4" type="revolute">
    <origin xyz="0.1918 0.000117091 -0.00186036" rpy="-1.51606e-14 -1.33155e-14 -3.14159"/>
    <parent link="ties_assembly_4"/>
    <child link="foot_assembly_4"/>
    <axis xyz="0 0 1"/>
    <limit effort="10" velocity="10" lower="-2.0944" upper="2.0944"/>
  </joint>
  <!-- Joint from hip_assembly_4 to ties_assembly_4 -->
  <joint name="ties_4" type="revolute">
    <origin xyz="0.0925 -0.0311167 -0.0305" rpy="1.5708 6.85694e-16 -2.44517e-16"/>
    <parent link="hip_assembly_4"/>
    <child link="ties_assembly_4"/>
    <axis xyz="0 0 1"/>
    <limit effort="10" velocity="10" lower="-1.74533" upper="1.74533"/>
  </joint>
  <!-- Joint from base_link to hip_assembly_4 -->
  <joint name="hip_4" type="revolute">
    <origin xyz="-0.132676 -0.0805438 0.0174281" rpy="2.48412e-14 2.47371e-14 -2.70526"/>
    <parent link="base_link"/>
    <child link="hip_assembly_4"/>
    <axis xyz="0 0 1"/>
    <limit effort="10" velocity="10" lower="-1.5708" upper="1.5708"/>
  </joint>
  <!-- Link hip_assembly_5 -->
  <link name="hip_assembly_5">
    <inertial>
      <origin xyz="0.0271153 0.000490209 -0.0317796" rpy="0 0 0"/>
      <mass value="0.38056"/>
      <inertia ixx="0.000187069" ixy="-3.08523e-06" ixz="7.85466e-06" iyy="0.000328441" iyz="1.17914e-06" izz="0.000302664"/>
    </inertial>
    <!-- Part hip_5 -->
    <visual>
      <origin xyz="0.0575 -1.5439e-16 -0.0045" rpy="3.68281e-15 -7.55489e-15 3.14159"/>
      <geometry>
        <mesh filename="package://meshes\hip.stl"/>
      </geometry>
      <material name="hip_5_material">
        <color rgba="0.282353 0.54902 0.160784 1"/>
      </material>
    </visual>
    <collision>
      <origin xyz="0.0575 -1.5439e-16 -0.0045" rpy="3.68281e-15 -7.55489e-15 3.14159"/>
      <geometry>
        <mesh filename="package://meshes\hip.stl"/>
      </geometry>
    </collision>
    <!-- Part mobile_bracket_15 -->
    <visual>
      <origin xyz="0.0575 -2.91434e-16 -0.0305" rpy="-7.61127e-15 -1.9473e-15 -1.5708"/>
      <geometry>
        <mesh filename="package://meshes\mobile_bracket.stl"/>
      </geometry>
      <material name="mobile_bracket_15_material">
        <color rgba="0.647059 0.647059 0.647059 1"/>
      </material>
    </visual>
    <collision>
      <origin xyz="0.0575 -2.91434e-16 -0.0305" rpy="-7.61127e-15 -1.9473e-15 -1.5708"/>
      <geometry>
        <mesh filename="package://meshes\mobile_bracket.stl"/>
      </geometry>
    </collision>
    <!-- Part servo_wheel_25 -->
    <visual>
      <origin xyz="-1.11022e-16 -1.249e-16 -0.0025" rpy="3.14159 -7.61127e-15 3.14159"/>
      <geometry>
        <mesh filename="package://meshes\servo_wheel.stl"/>
      </geometry>
      <material name="servo_wheel_25_material">
        <color rgba="0.647059 0.647059 0.647059 1"/>
      </material>
    </visual>
    <collision>
      <origin xyz="-1.11022e-16 -1.249e-16 -0.0025" rpy="3.14159 -7.61127e-15 3.14159"/>
      <geometry>
        <mesh filename="package://meshes\servo_wheel.stl"/>
      </geometry>
    </collision>
    <!-- Part servo_13 -->
    <visual>
      <origin xyz="0.0175 0.00140442 -0.0305" rpy="-3.14159 -7.61127e-15 3.14159"/>
      <geometry>
        <mesh filename="package://meshes\servo.stl"/>
      </geometry>
      <material name="servo_13_material">
        <color rgba="0.109804 0.109804 0.105882 1"/>
      </material>
    </visual>
    <collision>
      <origin xyz="0.0175 0.00140442 -0.0305" rpy="-3.14159 -7.61127e-15 3.14159"/>
      <geometry>
        <mesh filename="package://meshes\servo.stl"/>
      </geometry>
    </collision>
    <!-- Part fixed_bracket_13 -->
    <visual>
      <origin xyz="0.0575 -2.498e-16 -0.0305" rpy="-1.5708 1.5708 0"/>
      <geometry>
        <mesh filename="package://meshes\fixed_bracket.stl"/>
      </geometry>
      <material name="fixed_bracket_13_material">
        <color rgba="0.647059 0.647059 0.647059 1"/>
      </material>
    </visual>
    <collision>
      <origin xyz="0.0575 -2.498e-16 -0.0305" rpy="-1.5708 1.5708 0"/>
      <geometry>
        <mesh filename="package://meshes\fixed_bracket.stl"/>
      </geometry>
    </collision>
    <!-- Part servo_wheel_26 -->
    <visual>
      <origin xyz="-6.93889e-16 -1.2837e-16 -0.0585" rpy="-3.14159 -7.61127e-15 3.14159"/>
      <geometry>
        <mesh filename="package://meshes\servo_wheel.stl"/>
      </geometry>
      <material name="servo_wheel_26_material">
        <color rgba="0.647059 0.647059 0.647059 1"/>
      </material>
    </visual>
    <collision>
      <origin xyz="-6.93889e-16 -1.2837e-16 -0.0585" rpy="-3.14159 -7.61127e-15 3.14159"/>
      <geometry>
        <mesh filename="package://meshes\servo_wheel.stl"/>
      </geometry>
    </collision>
  </link>
  <!-- Link ties_assembly_5 -->
  <link name="ties_assembly_5">
    <inertial>
      <origin xyz="0.0639313 0.001561 -0.0314406" rpy="0 0 0"/>
      <mass value="0.581468"/>
      <inertia ixx="0.000317042" ixy="-2.4027e-05" ixz="2.78889e-05" iyy="0.00207548" iyz="-4.55023e-07" izz="0.00186094"/>
    </inertial>
    <!-- Part mobile_bracket_16 -->
    <visual>
      <origin xyz="0.1568 0.000117091 -0.0322436" rpy="1.5708 1.5708 0"/>
      <geometry>
        <mesh filename="package://meshes\mobile_bracket.stl"/>
      </geometry>
      <material name="mobile_bracket_16_material">
        <color rgba="0.647059 0.647059 0.647059 1"/>
      </material>
    </visual>
    <collision>
      <origin xyz="0.1568 0.000117091 -0.0322436" rpy="1.5708 1.5708 0"/>
      <geometry>
        <mesh filename="package://meshes\mobile_bracket.stl"/>
      </geometry>
    </collision>
    <!-- Part low_tie_5 -->
    <visual>
      <origin xyz="0.0268 0.000117091 -0.0322436" rpy="3.86877e-16 1.5708 0"/>
      <geometry>
        <mesh filename="package://meshes\low_tie.stl"/>
      </geometry>
      <material name="low_tie_5_material">
        <color rgba="0.282353 0.54902 0.160784 1"/>
      </material>
    </visual>
    <collision>
      <origin xyz="0.0268 0.000117091 -0.0322436" rpy="3.86877e-16 1.5708 0"/>
      <geometry>
        <mesh filename="package://meshes\low_tie.stl"/>
      </geometry>
    </collision>
    <!-- Part top_tie_5 -->
    <visual>
      <origin xyz="0.0275 -9.71445e-17 -0.0305" rpy="3.86877e-16 1.5708 0"/>
      <geometry>
        <mesh filename="package://meshes\top_tie.stl"/>
      </geometry>
      <material name="top_tie_5_material">
        <color rgba="0.282353 0.54902 0.160784 1"/>
      </material>
    </visual>
    <collision>
      <origin xyz="0.0275 -9.71445e-17 -0.0305" rpy="3.86877e-16 1.5708 0"/>
      <geometry>
        <mesh filename="package://meshes\top_tie.stl"/>
      </geometry>
    </collision>
    <!-- Part servo_wheel_27 -->
    <visual>
      <origin xyz="-8.32667e-17 -7.97973e-17 -0.0025" rpy="3.14159 2.46181e-15 3.14159"/>
      <geometry>
        <mesh filename="package://meshes\servo_wheel.stl"/>
      </geometry>
      <material name="servo_wheel_27_material">
        <color rgba="0.647059 0.647059 0.647059 1"/>
      </material>
    </visual>
    <collision>
      <origin xyz="-8.32667e-17 -7.97973e-17 -0.0025" rpy="3.14159 2.46181e-15 3.14159"/>
      <geometry>
        <mesh filename="package://meshes\servo_wheel.stl"/>
      </geometry>
    </collision>
    <!-- Part servo_14 -->
    <visual>
      <origin xyz="0.0175 0.00140442 -0.0305" rpy="3.14159 2.48189e-15 3.14159"/>
      <geometry>
        <mesh filename="package://meshes\servo.stl"/>
      </geometry>
      <material name="servo_14_material">
        <color rgba="0.109804 0.109804 0.105882 1"/>
      </material>
    </visual>
    <collision>
      <origin xyz="0.0175 0.00140442 -0.0305" rpy="3.14159 2.48189e-15 3.14159"/>
      <geometry>
        <mesh filename="package://meshes\servo.stl"/>
      </geometry>
    </collision>
    <!-- Part fixed_bracket_14 -->
    <visual>
      <origin xyz="0.0575 -1.09288e-16 -0.0305" rpy="-1.5708 1.5708 0"/>
      <geometry>
        <mesh filename="package://meshes\fixed_bracket.stl"/>
      </geometry>
      <material name="fixed_bracket_14_material">
        <color rgba="0.647059 0.647059 0.647059 1"/>
      </material>
    </visual>
    <collision>
      <origin xyz="0.0575 -1.09288e-16 -0.0305" rpy="-1.5708 1.5708 0"/>
      <geometry>
        <mesh filename="package://meshes\fixed_bracket.stl"/>
      </geometry>
    </collision>
    <!-- Part servo_wheel_28 -->
    <visual>
      <origin xyz="-1.11022e-16 -8.1532e-17 -0.0585" rpy="-3.14159 2.47248e-15 3.14159"/>
      <geometry>
        <mesh filename="package://meshes\servo_wheel.stl"/>
      </geometry>
      <material name="servo_wheel_28_material">
        <color rgba="0.647059 0.647059 0.647059 1"/>
      </material>
    </visual>
    <collision>
      <origin xyz="-1.11022e-16 -8.1532e-17 -0.0585" rpy="-3.14159 2.47248e-15 3.14159"/>
      <geometry>
        <mesh filename="package://meshes\servo_wheel.stl"/>
      </geometry>
    </collision>
  </link>
  <!-- Link foot_assembly_5 -->
  <link name="foot_assembly_5">
    <inertial>
      <origin xyz="-0.0719605 -0.00210262 -0.0306706" rpy="0 0 0"/>
      <mass value="0.628062"/>
      <inertia ixx="0.000268406" ixy="-1.55227e-05" ixz="4.14924e-06" iyy="0.0031862" iyz="-2.26544e-07" izz="0.00302315"/>
    </inertial>
    <!-- Part foot_5 -->
    <visual>
      <origin xyz="-0.04425 1.45717e-16 -0.0305" rpy="-4.44089e-16 1.5708 0"/>
      <geometry>
        <mesh filename="package://meshes\foot.stl"/>
      </geometry>
      <material name="foot_5_material">
        <color rgba="0.282353 0.54902 0.160784 1"/>
      </material>
    </visual>
    <collision>
      <origin xyz="-0.04425 1.45717e-16 -0.0305" rpy="-4.44089e-16 1.5708 0"/>
      <geometry>
        <mesh filename="package://meshes\foot.stl"/>
      </geometry>
    </collision>
    <!-- Part ir_sensor_cap_5 -->
    <visual>
      <origin xyz="-0.0442455 6.98571e-05 -0.0305" rpy="1.49265e-15 1.5708 0"/>
      <geometry>
        <mesh filename="package://meshes\ir_sensor_cap.stl"/>
      </geometry>
      <material name="ir_sensor_cap_5_material">
        <color rgba="0.282353 0.54902 0.160784 1"/>
      </material>
    </visual>
    <collision>
      <origin xyz="-0.0442455 6.98571e-05 -0.0305" rpy="1.49265e-15 1.5708 0"/>
      <geometry>
        <mesh filename="package://meshes\ir_sensor_cap.stl"/>
      </geometry>
    </collision>
    <!-- Part rubber_foot_5 -->
    <visual>
      <origin xyz="-0.04375 6.69603e-16 -0.03" rpy="-2.05391e-15 1.5708 0"/>
      <geometry>
        <mesh filename="package://meshes\rubber_foot.stl"/>
      </geometry>
      <material name="rubber_foot_5_material">
        <color rgba="0.262745 0.282353 0.301961 1"/>
      </material>
    </visual>
    <collision>
      <origin xyz="-0.04375 6.69603e-16 -0.03" rpy="-2.05391e-15 1.5708 0"/>
      <geometry>
        <mesh filename="package://meshes\rubber_foot.stl"/>
      </geometry>
    </collision>
    <!-- Part servo_wheel_29 -->
    <visual>
      <origin xyz="0 0 -0.0025" rpy="3.14159 4.1793e-18 4.33873e-30"/>
      <geometry>
        <mesh filename="package://meshes\servo_wheel.stl"/>
      </geometry>
      <material name="servo_wheel_29_material">
        <color rgba="0.647059 0.647059 0.647059 1"/>
      </material>
    </visual>
    <collision>
      <origin xyz="0 0 -0.0025" rpy="3.14159 4.1793e-18 4.33873e-30"/>
      <geometry>
        <mesh filename="package://meshes\servo_wheel.stl"/>
      </geometry>
    </collision>
    <!-- Part servo_15 -->
    <visual>
      <origin xyz="-0.0175 -0.00140442 -0.0305" rpy="3.14159 7.38604e-17 1.69605e-29"/>
      <geometry>
        <mesh filename="package://meshes\servo.stl"/>
      </geometry>
      <material name="servo_15_material">
        <color rgba="0.109804 0.109804 0.105882 1"/>
      </material>
    </visual>
    <collision>
      <origin xyz="-0.0175 -0.00140442 -0.0305" rpy="3.14159 7.38604e-17 1.69605e-29"/>
      <geometry>
        <mesh filename="package://meshes\servo.stl"/>
      </geometry>
    </collision>
    <!-- Part fixed_bracket_15 -->
    <visual>
      <origin xyz="-0.0575 6.93889e-18 -0.0305" rpy="1.5708 1.5708 0"/>
      <geometry>
        <mesh filename="package://meshes\fixed_bracket.stl"/>
      </geometry>
      <material name="fixed_bracket_15_material">
        <color rgba="0.647059 0.647059 0.647059 1"/>
      </material>
    </visual>
    <collision>
      <origin xyz="-0.0575 6.93889e-18 -0.0305" rpy="1.5708 1.5708 0"/>
      <geometry>
        <mesh filename="package://meshes\fixed_bracket.stl"/>
      </geometry>
    </collision>
    <!-- Part servo_wheel_30 -->
    <visual>
      <origin xyz="-1.66533e-16 -1.73472e-18 -0.0585" rpy="3.14159 7.38604e-17 1.69605e-29"/>
      <geometry>
        <mesh filename="package://meshes\servo_wheel.stl"/>
      </geometry>
      <material name="servo_wheel_30_material">
        <color rgba="0.647059 0.647059 0.647059 1"/>
      </material>
    </visual>
    <collision>
      <origin xyz="-1.66533e-16 -1.73472e-18 -0.0585" rpy="3.14159 7.38604e-17 1.69605e-29"/>
      <geometry>
        <mesh filename="package://meshes\servo_wheel.stl"/>
      </geometry>
    </collision>
  </link>
  <!-- Joint from ties_assembly_5 to foot_assembly_5 -->
  <joint name="foot_5" type="revolute">
    <origin xyz="0.1918 0.000117091 -0.00186036" rpy="3.30023e-17 1.82639e-15 3.14159"/>
    <parent link="ties_assembly_5"/>
    <child link="foot_assembly_5"/>
    <axis xyz="0 0 1"/>
    <limit effort="10" velocity="10" lower="-2.0944" upper="2.0944"/>
  </joint>
  <!-- Joint from hip_assembly_5 to ties_assembly_5 -->
  <joint name="ties_5" type="revolute">
    <origin xyz="0.0925 -0.0311167 -0.0305" rpy="1.5708 7.61127e-15 1.9026e-16"/>
    <parent link="hip_assembly_5"/>
    <child link="ties_assembly_5"/>
    <axis xyz="0 0 1"/>
    <limit effort="10" velocity="10" lower="-1.74533" upper="1.74533"/>
  </joint>
  <!-- Joint from base_link to hip_assembly_5 -->
  <joint name="hip_5" type="revolute">
    <origin xyz="-0.119426 0.0708948 0.0174281" rpy="-4.50694e-15 3.38573e-14 2.53073"/>
    <parent link="base_link"/>
    <child link="hip_assembly_5"/>
    <axis xyz="0 0 1"/>
    <limit effort="10" velocity="10" lower="-1.5708" upper="1.5708"/>
  </joint>
  <!-- Link hip_assembly_6 -->
  <link name="hip_assembly_6">
    <inertial>
      <origin xyz="0.0271153 0.000490209 -0.0317796" rpy="0 0 0"/>
      <mass value="0.38056"/>
      <inertia ixx="0.000187069" ixy="-3.08523e-06" ixz="7.85466e-06" iyy="0.000328441" iyz="1.17914e-06" izz="0.000302664"/>
    </inertial>
    <!-- Part hip_6 -->
    <visual>
      <origin xyz="0.0575 -2.71484e-16 -0.0045" rpy="2.66188e-15 -1.96349e-15 -3.14159"/>
      <geometry>
        <mesh filename="package://meshes\hip.stl"/>
      </geometry>
      <material name="hip_6_material">
        <color rgba="0.282353 0.54902 0.160784 1"/>
      </material>
    </visual>
    <collision>
      <origin xyz="0.0575 -2.71484e-16 -0.0045" rpy="2.66188e-15 -1.96349e-15 -3.14159"/>
      <geometry>
        <mesh filename="package://meshes\hip.stl"/>
      </geometry>
    </collision>
    <!-- Part mobile_bracket_17 -->
    <visual>
      <origin xyz="0.0575 -9.71445e-17 -0.0305" rpy="-3.18423e-14 7.47715e-14 -1.5708"/>
      <geometry>
        <mesh filename="package://meshes\mobile_bracket.stl"/>
      </geometry>
      <material name="mobile_bracket_17_material">
        <color rgba="0.647059 0.647059 0.647059 1"/>
      </material>
    </visual>
    <collision>
      <origin xyz="0.0575 -9.71445e-17 -0.0305" rpy="-3.18423e-14 7.47715e-14 -1.5708"/>
      <geometry>
        <mesh filename="package://meshes\mobile_bracket.stl"/>
      </geometry>
    </collision>
    <!-- Part servo_wheel_31 -->
    <visual>
      <origin xyz="-8.32667e-17 -7.45931e-17 -0.0025" rpy="-3.14159 -1.99104e-15 3.14159"/>
      <geometry>
        <mesh filename="package://meshes\servo_wheel.stl"/>
      </geometry>
      <material name="servo_wheel_31_material">
        <color rgba="0.647059 0.647059 0.647059 1"/>
      </material>
    </visual>
    <collision>
      <origin xyz="-8.32667e-17 -7.45931e-17 -0.0025" rpy="-3.14159 -1.99104e-15 3.14159"/>
      <geometry>
        <mesh filename="package://meshes\servo_wheel.stl"/>
      </geometry>
    </collision>
    <!-- Part servo_16 -->
    <visual>
      <origin xyz="0.0175 0.00140442 -0.0305" rpy="3.14159 -3.00037e-14 3.14159"/>
      <geometry>
        <mesh filename="package://meshes\servo.stl"/>
      </geometry>
      <material name="servo_16_material">
        <color rgba="0.109804 0.109804 0.105882 1"/>
      </material>
    </visual>
    <collision>
      <origin xyz="0.0175 0.00140442 -0.0305" rpy="3.14159 -3.00037e-14 3.14159"/>
      <geometry>
        <mesh filename="package://meshes\servo.stl"/>
      </geometry>
    </collision>
    <!-- Part fixed_bracket_16 -->
    <visual>
      <origin xyz="0.0575 -9.71445e-17 -0.0305" rpy="-1.5708 1.5708 0"/>
      <geometry>
        <mesh filename="package://meshes\fixed_bracket.stl"/>
      </geometry>
      <material name="fixed_bracket_16_material">
        <color rgba="0.647059 0.647059 0.647059 1"/>
      </material>
    </visual>
    <collision>
      <origin xyz="0.0575 -9.71445e-17 -0.0305" rpy="-1.5708 1.5708 0"/>
      <geometry>
        <mesh filename="package://meshes\fixed_bracket.stl"/>
      </geometry>
    </collision>
    <!-- Part servo_wheel_32 -->
    <visual>
      <origin xyz="1.36002e-15 6.245e-17 -0.0585" rpy="-3.14159 -1.99967e-15 -3.14159"/>
      <geometry>
        <mesh filename="package://meshes\servo_wheel.stl"/>
      </geometry>
      <material name="servo_wheel_32_material">
        <color rgba="0.647059 0.647059 0.647059 1"/>
      </material>
    </visual>
    <collision>
      <origin xyz="1.36002e-15 6.245e-17 -0.0585" rpy="-3.14159 -1.99967e-15 -3.14159"/>
      <geometry>
        <mesh filename="package://meshes\servo_wheel.stl"/>
      </geometry>
    </collision>
  </link>
  <!-- Link ties_assembly_6 -->
  <link name="ties_assembly_6">
    <inertial>
      <origin xyz="0.0639313 0.001561 -0.0314406" rpy="0 0 0"/>
      <mass value="0.581468"/>
      <inertia ixx="0.000317042" ixy="-2.4027e-05" ixz="2.78889e-05" iyy="0.00207548" iyz="-4.55023e-07" izz="0.00186094"/>
    </inertial>
    <!-- Part mobile_bracket_18 -->
    <visual>
      <origin xyz="0.1568 0.000117091 -0.0322436" rpy="1.5708 1.5708 0"/>
      <geometry>
        <mesh filename="package://meshes\mobile_bracket.stl"/>
      </geometry>
      <material name="mobile_bracket_18_material">
        <color rgba="0.647059 0.647059 0.647059 1"/>
      </material>
    </visual>
    <collision>
      <origin xyz="0.1568 0.000117091 -0.0322436" rpy="1.5708 1.5708 0"/>
      <geometry>
        <mesh filename="package://meshes\mobile_bracket.stl"/>
      </geometry>
    </collision>
    <!-- Part low_tie_6 -->
    <visual>
      <origin xyz="0.0268 0.000117091 -0.0322436" rpy="-3.23374e-14 1.5708 0"/>
      <geometry>
        <mesh filename="package://meshes\low_tie.stl"/>
      </geometry>
      <material name="low_tie_6_material">
        <color rgba="0.282353 0.54902 0.160784 1"/>
      </material>
    </visual>
    <collision>
      <origin xyz="0.0268 0.000117091 -0.0322436" rpy="-3.23374e-14 1.5708 0"/>
      <geometry>
        <mesh filename="package://meshes\low_tie.stl"/>
      </geometry>
    </collision>
    <!-- Part top_tie_6 -->
    <visual>
      <origin xyz="0.0275 8.7777e-16 -0.0305" rpy="-3.23374e-14 1.5708 0"/>
      <geometry>
        <mesh filename="package://meshes\top_tie.stl"/>
      </geometry>
      <material name="top_tie_6_material">
        <color rgba="0.282353 0.54902 0.160784 1"/>
      </material>
    </visual>
    <collision>
      <origin xyz="0.0275 8.7777e-16 -0.0305" rpy="-3.23374e-14 1.5708 0"/>
      <geometry>
        <mesh filename="package://meshes\top_tie.stl"/>
      </geometry>
    </collision>
    <!-- Part servo_wheel_33 -->
    <visual>
      <origin xyz="0 -1.73472e-18 -0.0025" rpy="3.14159 -7.54497e-17 -3.14159"/>
      <geometry>
        <mesh filename="package://meshes\servo_wheel.stl"/>
      </geometry>
      <material name="servo_wheel_33_material">
        <color rgba="0.647059 0.647059 0.647059 1"/>
      </material>
    </visual>
    <collision>
      <origin xyz="0 -1.73472e-18 -0.0025" rpy="3.14159 -7.54497e-17 -3.14159"/>
      <geometry>
        <mesh filename="package://meshes\servo_wheel.stl"/>
      </geometry>
    </collision>
    <!-- Part servo_17 -->
    <visual>
      <origin xyz="0.0175 0.00140442 -0.0305" rpy="-3.14159 -8.9707e-17 -3.14159"/>
      <geometry>
        <mesh filename="package://meshes\servo.stl"/>
      </geometry>
      <material name="servo_17_material">
        <color rgba="0.109804 0.109804 0.105882 1"/>
      </material>
    </visual>
    <collision>
      <origin xyz="0.0175 0.00140442 -0.0305" rpy="-3.14159 -8.9707e-17 -3.14159"/>
      <geometry>
        <mesh filename="package://meshes\servo.stl"/>
      </geometry>
    </collision>
    <!-- Part fixed_bracket_17 -->
    <visual>
      <origin xyz="0.0575 1.84922e-15 -0.0305" rpy="-1.5708 1.5708 0"/>
      <geometry>
        <mesh filename="package://meshes\fixed_bracket.stl"/>
      </geometry>
      <material name="fixed_bracket_17_material">
        <color rgba="0.647059 0.647059 0.647059 1"/>
      </material>
    </visual>
    <collision>
      <origin xyz="0.0575 1.84922e-15 -0.0305" rpy="-1.5708 1.5708 0"/>
      <geometry>
        <mesh filename="package://meshes\fixed_bracket.stl"/>
      </geometry>
    </collision>
    <!-- Part servo_wheel_34 -->
    <visual>
      <origin xyz="8.88178e-16 0 -0.0585" rpy="-3.14159 3.4583e-14 -3.14159"/>
      <geometry>
        <mesh filename="package://meshes\servo_wheel.stl"/>
      </geometry>
      <material name="servo_wheel_34_material">
        <color rgba="0.647059 0.647059 0.647059 1"/>
      </material>
    </visual>
    <collision>
      <origin xyz="8.88178e-16 0 -0.0585" rpy="-3.14159 3.4583e-14 -3.14159"/>
      <geometry>
        <mesh filename="package://meshes\servo_wheel.stl"/>
      </geometry>
    </collision>
  </link>
  <!-- Link foot_assembly_6 -->
  <link name="foot_assembly_6">
    <inertial>
      <origin xyz="-0.0719605 -0.00210262 -0.0306706" rpy="0 0 0"/>
      <mass value="0.628062"/>
      <inertia ixx="0.000268406" ixy="-1.55227e-05" ixz="4.14924e-06" iyy="0.0031862" iyz="-2.26544e-07" izz="0.00302315"/>
    </inertial>
    <!-- Part foot_6 -->
    <visual>
      <origin xyz="-0.04425 3.1225e-17 -0.0305" rpy="1.77636e-15 1.5708 0"/>
      <geometry>
        <mesh filename="package://meshes\foot.stl"/>
      </geometry>
      <material name="foot_6_material">
        <color rgba="0.282353 0.54902 0.160784 1"/>
      </material>
    </visual>
    <collision>
      <origin xyz="-0.04425 3.1225e-17 -0.0305" rpy="1.77636e-15 1.5708 0"/>
      <geometry>
        <mesh filename="package://meshes\foot.stl"/>
      </geometry>
    </collision>
    <!-- Part ir_sensor_cap_6 -->
    <visual>
      <origin xyz="-0.0442455 6.98571e-05 -0.0305" rpy="3.5116e-15 1.5708 0"/>
      <geometry>
        <mesh filename="package://meshes\ir_sensor_cap.stl"/>
      </geometry>
      <material name="ir_sensor_cap_6_material">
        <color rgba="0.282353 0.54902 0.160784 1"/>
      </material>
    </visual>
    <collision>
      <origin xyz="-0.0442455 6.98571e-05 -0.0305" rpy="3.5116e-15 1.5708 0"/>
      <geometry>
        <mesh filename="package://meshes\ir_sensor_cap.stl"/>
      </geometry>
    </collision>
    <!-- Part rubber_foot_6 -->
    <visual>
      <origin xyz="-0.04375 1.70697e-15 -0.03" rpy="-6.33599e-15 1.5708 0"/>
      <geometry>
        <mesh filename="package://meshes\rubber_foot.stl"/>
      </geometry>
      <material name="rubber_foot_6_material">
        <color rgba="0.262745 0.282353 0.301961 1"/>
      </material>
    </visual>
    <collision>
      <origin xyz="-0.04375 1.70697e-15 -0.03" rpy="-6.33599e-15 1.5708 0"/>
      <geometry>
        <mesh filename="package://meshes\rubber_foot.stl"/>
      </geometry>
    </collision>
    <!-- Part servo_wheel_35 -->
    <visual>
      <origin xyz="5.55112e-17 0 -0.0025" rpy="-3.14159 1.00961e-18 4.43734e-31"/>
      <geometry>
        <mesh filename="package://meshes\servo_wheel.stl"/>
      </geometry>
      <material name="servo_wheel_35_material">
        <color rgba="0.647059 0.647059 0.647059 1"/>
      </material>
    </visual>
    <collision>
      <origin xyz="5.55112e-17 0 -0.0025" rpy="-3.14159 1.00961e-18 4.43734e-31"/>
      <geometry>
        <mesh filename="package://meshes\servo_wheel.stl"/>
      </geometry>
    </collision>
    <!-- Part servo_18 -->
    <visual>
      <origin xyz="-0.0175 -0.00140442 -0.0305" rpy="3.14159 5.54848e-16 -3.88578e-16"/>
      <geometry>
        <mesh filename="package://meshes\servo.stl"/>
      </geometry>
      <material name="servo_18_material">
        <color rgba="0.109804 0.109804 0.105882 1"/>
      </material>
    </visual>
    <collision>
      <origin xyz="-0.0175 -0.00140442 -0.0305" rpy="3.14159 5.54848e-16 -3.88578e-16"/>
      <geometry>
        <mesh filename="package://meshes\servo.stl"/>
      </geometry>
    </collision>
    <!-- Part fixed_bracket_18 -->
    <visual>
      <origin xyz="-0.0575 5.37764e-17 -0.0305" rpy="1.5708 1.5708 0"/>
      <geometry>
        <mesh filename="package://meshes\fixed_bracket.stl"/>
      </geometry>
      <material name="fixed_bracket_18_material">
        <color rgba="0.647059 0.647059 0.647059 1"/>
      </material>
    </visual>
    <collision>
      <origin xyz="-0.0575 5.37764e-17 -0.0305" rpy="1.5708 1.5708 0"/>
      <geometry>
        <mesh filename="package://meshes\fixed_bracket.stl"/>
      </geometry>
    </collision>
    <!-- Part servo_wheel_36 -->
    <visual>
      <origin xyz="5.55112e-17 2.77556e-17 -0.0585" rpy="-3.14159 1.82205e-15 -3.88578e-16"/>
      <geometry>
        <mesh filename="package://meshes\servo_wheel.stl"/>
      </geometry>
      <material name="servo_wheel_36_material">
        <color rgba="0.647059 0.647059 0.647059 1"/>
      </material>
    </visual>
    <collision>
      <origin xyz="5.55112e-17 2.77556e-17 -0.0585" rpy="-3.14159 1.82205e-15 -3.88578e-16"/>
      <geometry>
        <mesh filename="package://meshes\servo_wheel.stl"/>
      </geometry>
    </collision>
  </link>
  <!-- Joint from ties_assembly_6 to foot_assembly_6 -->
  <joint name="foot_6" type="revolute">
    <origin xyz="0.1918 0.000117091 -0.00186036" rpy="2.27858e-15 -2.06207e-16 -3.14159"/>
    <parent link="ties_assembly_6"/>
    <child link="foot_assembly_6"/>
    <axis xyz="0 0 1"/>
    <limit effort="10" velocity="10" lower="-2.0944" upper="2.0944"/>
  </joint>
  <!-- Joint from hip_assembly_6 to ties_assembly_6 -->
  <joint name="ties_6" type="revolute">
    <origin xyz="0.0925 -0.0311167 -0.0305" rpy="1.5708 3.18423e-14 5.08286e-14"/>
    <parent link="hip_assembly_6"/>
    <child link="ties_assembly_6"/>
    <axis xyz="0 0 1"/>
    <limit effort="10" velocity="10" lower="-1.74533" upper="1.74533"/>
  </joint>
  <!-- Joint from base_link to hip_assembly_6 -->
  <joint name="hip_6" type="revolute">
    <origin xyz="0.0183478 0.13514 0.0166947" rpy="-3.01521e-14 7.87813e-15 1.48353"/>
    <parent link="base_link"/>
    <child link="hip_assembly_6"/>
    <axis xyz="0 0 1"/>
    <limit effort="10" velocity="10" lower="-1.5708" upper="1.5708"/>
  </joint>
</robot>
