<?xml version="1.0" ?>
<!-- Generated using onshape-to-robot -->
<!-- Onshape https://cad.onshape.com/documents/026f9a33ba6a25a983a9d639/w/b83e0182bd0a887a03df3198/e/e49783848224d44e064e4a49 -->
<robot name="C:\Users\gata2\OneDrive\Documents\hexapod\hexapod_py\simulation">
  <!-- Link base_link -->
  <link name="base_link">
    <inertial>
      <origin xyz="0.000110218 0.00373922 -0.0151302" rpy="0 0 0"/>
      <mass value="2.53298"/>
      <inertia ixx="0.0181121" ixy="0.000710932" ixz="-2.18499e-05" iyy="0.0168006" iyz="2.07304e-05" izz="0.0247691"/>
    </inertial>
    <!-- Part mobile_bracket -->
    <visual>
      <origin xyz="0.1066 0.053231 -0.0168925" rpy="1.13446 1.5708 0"/>
      <geometry>
        <mesh filename="package://meshes\mobile_bracket.stl"/>
      </geometry>
      <material name="mobile_bracket_material">
        <color rgba="0.647059 0.647059 0.647059 1"/>
      </material>
    </visual>
    <collision>
      <origin xyz="0.1066 0.053231 -0.0168925" rpy="1.13446 1.5708 0"/>
      <geometry>
        <mesh filename="package://meshes\mobile_bracket.stl"/>
      </geometry>
    </collision>
    <!-- Part ultrasound_sensor -->
    <visual>
      <origin xyz="0.0624927 0.0922459 0.00310749" rpy="8.71922e-15 -3.34841e-14 -0.610865"/>
      <geometry>
        <mesh filename="package://meshes\ultrasound_sensor.stl"/>
      </geometry>
      <material name="ultrasound_sensor_material">
        <color rgba="0.701961 0.701961 0.701961 1"/>
      </material>
    </visual>
    <collision>
      <origin xyz="0.0624927 0.0922459 0.00310749" rpy="8.71922e-15 -3.34841e-14 -0.610865"/>
      <geometry>
        <mesh filename="package://meshes\ultrasound_sensor.stl"/>
      </geometry>
    </collision>
    <!-- Part ultrasound_sensor_2 -->
    <visual>
      <origin xyz="-0.0450964 0.101659 0.00310749" rpy="-3.14159 2.42931e-14 -2.70526"/>
      <geometry>
        <mesh filename="package://meshes\ultrasound_sensor.stl"/>
      </geometry>
      <material name="ultrasound_sensor_2_material">
        <color rgba="0.701961 0.701961 0.701961 1"/>
      </material>
    </visual>
    <collision>
      <origin xyz="-0.0450964 0.101659 0.00310749" rpy="-3.14159 2.42931e-14 -2.70526"/>
      <geometry>
        <mesh filename="package://meshes\ultrasound_sensor.stl"/>
      </geometry>
    </collision>
    <!-- Part mobile_bracket_2 -->
    <visual>
      <origin xyz="0.0964012 -0.0633408 -0.0168925" rpy="2.18166 1.5708 0"/>
      <geometry>
        <mesh filename="package://meshes\mobile_bracket.stl"/>
      </geometry>
      <material name="mobile_bracket_2_material">
        <color rgba="0.647059 0.647059 0.647059 1"/>
      </material>
    </visual>
    <collision>
      <origin xyz="0.0964012 -0.0633408 -0.0168925" rpy="2.18166 1.5708 0"/>
      <geometry>
        <mesh filename="package://meshes\mobile_bracket.stl"/>
      </geometry>
    </collision>
    <!-- Part camera -->
    <visual>
      <origin xyz="-0.042772 0.096674 -0.0288925" rpy="3.14159 -2.43206e-14 0.436332"/>
      <geometry>
        <mesh filename="package://meshes\camera.stl"/>
      </geometry>
      <material name="camera_material">
        <color rgba="0.262745 0.282353 0.301961 1"/>
      </material>
    </visual>
    <collision>
      <origin xyz="-0.042772 0.096674 -0.0288925" rpy="3.14159 -2.43206e-14 0.436332"/>
      <geometry>
        <mesh filename="package://meshes\camera.stl"/>
      </geometry>
    </collision>
    <!-- Part u_sensor_holder -->
    <visual>
      <origin xyz="-0.0450964 0.101659 0.00310749" rpy="-2.46385e-14 -2.42931e-14 0.436332"/>
      <geometry>
        <mesh filename="package://meshes\u_sensor_holder.stl"/>
      </geometry>
      <material name="u_sensor_holder_material">
        <color rgba="0.282353 0.54902 0.160784 1"/>
      </material>
    </visual>
    <collision>
      <origin xyz="-0.0450964 0.101659 0.00310749" rpy="-2.46385e-14 -2.42931e-14 0.436332"/>
      <geometry>
        <mesh filename="package://meshes\u_sensor_holder.stl"/>
      </geometry>
    </collision>
    <!-- Part camera_2 -->
    <visual>
      <origin xyz="0.0438648 -0.0891191 -0.0288925" rpy="-3.14159 2.42931e-14 -2.70526"/>
      <geometry>
        <mesh filename="package://meshes\camera.stl"/>
      </geometry>
      <material name="camera_2_material">
        <color rgba="0.262745 0.282353 0.301961 1"/>
      </material>
    </visual>
    <collision>
      <origin xyz="0.0438648 -0.0891191 -0.0288925" rpy="-3.14159 2.42931e-14 -2.70526"/>
      <geometry>
        <mesh filename="package://meshes\camera.stl"/>
      </geometry>
    </collision>
    <!-- Part bottom_cover -->
    <visual>
      <origin xyz="0.000546408 0.00377743 -0.0518925" rpy="-3.14159 -2.46385e-14 -1.13446"/>
      <geometry>
        <mesh filename="package://meshes\bottom_cover.stl"/>
      </geometry>
      <material name="bottom_cover_material">
        <color rgba="0.282353 0.54902 0.160784 1"/>
      </material>
    </visual>
    <collision>
      <origin xyz="0.000546408 0.00377743 -0.0518925" rpy="-3.14159 -2.46385e-14 -1.13446"/>
      <geometry>
        <mesh filename="package://meshes\bottom_cover.stl"/>
      </geometry>
    </collision>
    <!-- Part left_speaker -->
    <visual>
      <origin xyz="-0.0398634 -0.0539337 0.0185598" rpy="1.5708 0.523599 -0.610865"/>
      <geometry>
        <mesh filename="package://meshes\left_speaker.stl"/>
      </geometry>
      <material name="left_speaker_material">
        <color rgba="0.262745 0.282353 0.301961 1"/>
      </material>
    </visual>
    <collision>
      <origin xyz="-0.0398634 -0.0539337 0.0185598" rpy="1.5708 0.523599 -0.610865"/>
      <geometry>
        <mesh filename="package://meshes\left_speaker.stl"/>
      </geometry>
    </collision>
    <!-- Part body_power -->
    <visual>
      <origin xyz="0.000546408 0.00377743 -0.0168925" rpy="2.46385e-14 2.42931e-14 -2.70526"/>
      <geometry>
        <mesh filename="package://meshes\body_power.stl"/>
      </geometry>
      <material name="body_power_material">
        <color rgba="0.282353 0.54902 0.160784 1"/>
      </material>
    </visual>
    <collision>
      <origin xyz="0.000546408 0.00377743 -0.0168925" rpy="2.46385e-14 2.42931e-14 -2.70526"/>
      <geometry>
        <mesh filename="package://meshes\body_power.stl"/>
      </geometry>
    </collision>
    <!-- Part mobile_bracket_3 -->
    <visual>
      <origin xyz="-0.0096523 -0.112794 -0.0168925" rpy="3.05433 -1.5708 0"/>
      <geometry>
        <mesh filename="package://meshes\mobile_bracket.stl"/>
      </geometry>
      <material name="mobile_bracket_3_material">
        <color rgba="0.647059 0.647059 0.647059 1"/>
      </material>
    </visual>
    <collision>
      <origin xyz="-0.0096523 -0.112794 -0.0168925" rpy="3.05433 -1.5708 0"/>
      <geometry>
        <mesh filename="package://meshes\mobile_bracket.stl"/>
      </geometry>
    </collision>
    <!-- Part cover -->
    <visual>
      <origin xyz="0.000546408 0.00377743 0.0181075" rpy="3.34841e-14 8.71922e-15 -2.18166"/>
      <geometry>
        <mesh filename="package://meshes\cover.stl"/>
      </geometry>
      <material name="cover_material">
        <color rgba="0.282353 0.54902 0.160784 1"/>
      </material>
    </visual>
    <collision>
      <origin xyz="0.000546408 0.00377743 0.0181075" rpy="3.34841e-14 8.71922e-15 -2.18166"/>
      <geometry>
        <mesh filename="package://meshes\cover.stl"/>
      </geometry>
    </collision>
    <!-- Part mobile_bracket_4 -->
    <visual>
      <origin xyz="0.0107451 0.120349 -0.0168925" rpy="0.0872665 1.5708 0"/>
      <geometry>
        <mesh filename="package://meshes\mobile_bracket.stl"/>
      </geometry>
      <material name="mobile_bracket_4_material">
        <color rgba="0.647059 0.647059 0.647059 1"/>
      </material>
    </visual>
    <collision>
      <origin xyz="0.0107451 0.120349 -0.0168925" rpy="0.0872665 1.5708 0"/>
      <geometry>
        <mesh filename="package://meshes\mobile_bracket.stl"/>
      </geometry>
    </collision>
    <!-- Part ultrasound_sensor_3 -->
    <visual>
      <origin xyz="-0.0613998 -0.084691 0.00310749" rpy="-8.71922e-15 3.34841e-14 2.53073"/>
      <geometry>
        <mesh filename="package://meshes\ultrasound_sensor.stl"/>
      </geometry>
      <material name="ultrasound_sensor_3_material">
        <color rgba="0.701961 0.701961 0.701961 1"/>
      </material>
    </visual>
    <collision>
      <origin xyz="-0.0613998 -0.084691 0.00310749" rpy="-8.71922e-15 3.34841e-14 2.53073"/>
      <geometry>
        <mesh filename="package://meshes\ultrasound_sensor.stl"/>
      </geometry>
    </collision>
    <!-- Part mobile_bracket_5 -->
    <visual>
      <origin xyz="-0.105507 -0.0456761 -0.0168925" rpy="2.00713 -1.5708 0"/>
      <geometry>
        <mesh filename="package://meshes\mobile_bracket.stl"/>
      </geometry>
      <material name="mobile_bracket_5_material">
        <color rgba="0.647059 0.647059 0.647059 1"/>
      </material>
    </visual>
    <collision>
      <origin xyz="-0.105507 -0.0456761 -0.0168925" rpy="2.00713 -1.5708 0"/>
      <geometry>
        <mesh filename="package://meshes\mobile_bracket.stl"/>
      </geometry>
    </collision>
    <!-- Part mobile_bracket_6 -->
    <visual>
      <origin xyz="-0.0953084 0.0708957 -0.0168925" rpy="0.959931 -1.5708 0"/>
      <geometry>
        <mesh filename="package://meshes\mobile_bracket.stl"/>
      </geometry>
      <material name="mobile_bracket_6_material">
        <color rgba="0.647059 0.647059 0.647059 1"/>
      </material>
    </visual>
    <collision>
      <origin xyz="-0.0953084 0.0708957 -0.0168925" rpy="0.959931 -1.5708 0"/>
      <geometry>
        <mesh filename="package://meshes\mobile_bracket.stl"/>
      </geometry>
    </collision>
    <!-- Part body_brain -->
    <visual>
      <origin xyz="0.000546408 0.00377743 -0.0168925" rpy="2.46385e-14 2.42931e-14 -2.70526"/>
      <geometry>
        <mesh filename="package://meshes\body_brain.stl"/>
      </geometry>
      <material name="body_brain_material">
        <color rgba="0.282353 0.54902 0.160784 1"/>
      </material>
    </visual>
    <collision>
      <origin xyz="0.000546408 0.00377743 -0.0168925" rpy="2.46385e-14 2.42931e-14 -2.70526"/>
      <geometry>
        <mesh filename="package://meshes\body_brain.stl"/>
      </geometry>
    </collision>
    <!-- Part ultrasound_sensor_4 -->
    <visual>
      <origin xyz="0.108135 -0.00563539 0.00310749" rpy="3.14159 9.19098e-15 1.48353"/>
      <geometry>
        <mesh filename="package://meshes\ultrasound_sensor.stl"/>
      </geometry>
      <material name="ultrasound_sensor_4_material">
        <color rgba="0.701961 0.701961 0.701961 1"/>
      </material>
    </visual>
    <collision>
      <origin xyz="0.108135 -0.00563539 0.00310749" rpy="3.14159 9.19098e-15 1.48353"/>
      <geometry>
        <mesh filename="package://meshes\ultrasound_sensor.stl"/>
      </geometry>
    </collision>
    <!-- Part ultrasound_sensor_5 -->
    <visual>
      <origin xyz="0.0461892 -0.0941038 0.00310749" rpy="3.14159 -2.42931e-14 0.436332"/>
      <geometry>
        <mesh filename="package://meshes\ultrasound_sensor.stl"/>
      </geometry>
      <material name="ultrasound_sensor_5_material">
        <color rgba="0.701961 0.701961 0.701961 1"/>
      </material>
    </visual>
    <collision>
      <origin xyz="0.0461892 -0.0941038 0.00310749" rpy="3.14159 -2.42931e-14 0.436332"/>
      <geometry>
        <mesh filename="package://meshes\ultrasound_sensor.stl"/>
      </geometry>
    </collision>
    <!-- Part left_speaker_2 -->
    <visual>
      <origin xyz="0.0707306 -0.00236289 0.0185598" rpy="1.5708 0.523599 1.48353"/>
      <geometry>
        <mesh filename="package://meshes\left_speaker.stl"/>
      </geometry>
      <material name="left_speaker_2_material">
        <color rgba="0.262745 0.282353 0.301961 1"/>
      </material>
    </visual>
    <collision>
      <origin xyz="0.0707306 -0.00236289 0.0185598" rpy="1.5708 0.523599 1.48353"/>
      <geometry>
        <mesh filename="package://meshes\left_speaker.stl"/>
      </geometry>
    </collision>
    <!-- Part ultrasound_sensor_6 -->
    <visual>
      <origin xyz="-0.107043 0.0131903 0.00310749" rpy="-3.14159 -9.19098e-15 -1.65806"/>
      <geometry>
        <mesh filename="package://meshes\ultrasound_sensor.stl"/>
      </geometry>
      <material name="ultrasound_sensor_6_material">
        <color rgba="0.701961 0.701961 0.701961 1"/>
      </material>
    </visual>
    <collision>
      <origin xyz="-0.107043 0.0131903 0.00310749" rpy="-3.14159 -9.19098e-15 -1.65806"/>
      <geometry>
        <mesh filename="package://meshes\ultrasound_sensor.stl"/>
      </geometry>
    </collision>
  </link>
  <!-- Link hip_assembly -->
  <link name="hip_assembly">
    <inertial>
      <origin xyz="0.0268487 0.000325484 -0.0302141" rpy="0 0 0"/>
      <mass value="0.365356"/>
      <inertia ixx="0.000168136" ixy="-2.8417e-07" ixz="-3.2467e-06" iyy="0.000312332" iyz="9.42575e-07" izz="0.000312341"/>
    </inertial>
    <!-- Part hip -->
    <visual>
      <origin xyz="0.0575 0.0005 -0.0045" rpy="1.25181e-15 -4.80771e-15 -3.14159"/>
      <geometry>
        <mesh filename="package://meshes\hip.stl"/>
      </geometry>
      <material name="hip_material">
        <color rgba="0.282353 0.54902 0.160784 1"/>
      </material>
    </visual>
    <collision>
      <origin xyz="0.0575 0.0005 -0.0045" rpy="1.25181e-15 -4.80771e-15 -3.14159"/>
      <geometry>
        <mesh filename="package://meshes\hip.stl"/>
      </geometry>
    </collision>
    <!-- Part mobile_bracket_7 -->
    <visual>
      <origin xyz="0.0575 1.42984e-13 -0.0305" rpy="-4.45935e-15 -5.30804e-15 -1.5708"/>
      <geometry>
        <mesh filename="package://meshes\mobile_bracket.stl"/>
      </geometry>
      <material name="mobile_bracket_7_material">
        <color rgba="0.647059 0.647059 0.647059 1"/>
      </material>
    </visual>
    <collision>
      <origin xyz="0.0575 1.42984e-13 -0.0305" rpy="-4.45935e-15 -5.30804e-15 -1.5708"/>
      <geometry>
        <mesh filename="package://meshes\mobile_bracket.stl"/>
      </geometry>
    </collision>
    <!-- Part servo_wheel -->
    <visual>
      <origin xyz="-2.77556e-17 2.12504e-17 -0.0025" rpy="-3.14159 -4.73604e-15 -3.14159"/>
      <geometry>
        <mesh filename="package://meshes\servo_wheel.stl"/>
      </geometry>
      <material name="servo_wheel_material">
        <color rgba="0.647059 0.647059 0.647059 1"/>
      </material>
    </visual>
    <collision>
      <origin xyz="-2.77556e-17 2.12504e-17 -0.0025" rpy="-3.14159 -4.73604e-15 -3.14159"/>
      <geometry>
        <mesh filename="package://meshes\servo_wheel.stl"/>
      </geometry>
    </collision>
    <!-- Part servo -->
    <visual>
      <origin xyz="0.0175 0.00140442 -0.0305" rpy="-3.14159 -2.86696e-15 -3.14159"/>
      <geometry>
        <mesh filename="package://meshes\servo.stl"/>
      </geometry>
      <material name="servo_material">
        <color rgba="0.109804 0.109804 0.105882 1"/>
      </material>
    </visual>
    <collision>
      <origin xyz="0.0175 0.00140442 -0.0305" rpy="-3.14159 -2.86696e-15 -3.14159"/>
      <geometry>
        <mesh filename="package://meshes\servo.stl"/>
      </geometry>
    </collision>
    <!-- Part fixed_bracket -->
    <visual>
      <origin xyz="0.0575 1.42984e-13 -0.0305" rpy="-1.5708 1.5708 0"/>
      <geometry>
        <mesh filename="package://meshes\fixed_bracket.stl"/>
      </geometry>
      <material name="fixed_bracket_material">
        <color rgba="0.647059 0.647059 0.647059 1"/>
      </material>
    </visual>
    <collision>
      <origin xyz="0.0575 1.42984e-13 -0.0305" rpy="-1.5708 1.5708 0"/>
      <geometry>
        <mesh filename="package://meshes\fixed_bracket.stl"/>
      </geometry>
    </collision>
    <!-- Part servo_wheel_2 -->
    <visual>
      <origin xyz="-2.77556e-17 3.20924e-17 -0.0585" rpy="-3.14159 -4.94581e-15 -3.14159"/>
      <geometry>
        <mesh filename="package://meshes\servo_wheel.stl"/>
      </geometry>
      <material name="servo_wheel_2_material">
        <color rgba="0.647059 0.647059 0.647059 1"/>
      </material>
    </visual>
    <collision>
      <origin xyz="-2.77556e-17 3.20924e-17 -0.0585" rpy="-3.14159 -4.94581e-15 -3.14159"/>
      <geometry>
        <mesh filename="package://meshes\servo_wheel.stl"/>
      </geometry>
    </collision>
  </link>
  <!-- Link ties_assembly -->
  <link name="ties_assembly">
    <inertial>
      <origin xyz="0.0643598 0.00153088 -0.0309357" rpy="0 0 0"/>
      <mass value="0.589115"/>
      <inertia ixx="0.000320336" ixy="-2.41497e-05" ixz="1.07866e-05" iyy="0.00208685" iyz="2.0947e-07" izz="0.00187002"/>
    </inertial>
    <!-- Part mobile_bracket_8 -->
    <visual>
      <origin xyz="0.1568 0.000210323 -0.0311738" rpy="1.5708 1.5708 0"/>
      <geometry>
        <mesh filename="package://meshes\mobile_bracket.stl"/>
      </geometry>
      <material name="mobile_bracket_8_material">
        <color rgba="0.647059 0.647059 0.647059 1"/>
      </material>
    </visual>
    <collision>
      <origin xyz="0.1568 0.000210323 -0.0311738" rpy="1.5708 1.5708 0"/>
      <geometry>
        <mesh filename="package://meshes\mobile_bracket.stl"/>
      </geometry>
    </collision>
    <!-- Part low_tie -->
    <visual>
      <origin xyz="0.0268 0.000210323 -0.0311738" rpy="-1.90781e-16 1.5708 0"/>
      <geometry>
        <mesh filename="package://meshes\low_tie.stl"/>
      </geometry>
      <material name="low_tie_material">
        <color rgba="0.282353 0.54902 0.160784 1"/>
      </material>
    </visual>
    <collision>
      <origin xyz="0.0268 0.000210323 -0.0311738" rpy="-1.90781e-16 1.5708 0"/>
      <geometry>
        <mesh filename="package://meshes\low_tie.stl"/>
      </geometry>
    </collision>
    <!-- Part top_tie -->
    <visual>
      <origin xyz="0.0275 1.38778e-17 -0.0305" rpy="-1.90781e-16 1.5708 0"/>
      <geometry>
        <mesh filename="package://meshes\top_tie.stl"/>
      </geometry>
      <material name="top_tie_material">
        <color rgba="0.282353 0.54902 0.160784 1"/>
      </material>
    </visual>
    <collision>
      <origin xyz="0.0275 1.38778e-17 -0.0305" rpy="-1.90781e-16 1.5708 0"/>
      <geometry>
        <mesh filename="package://meshes\top_tie.stl"/>
      </geometry>
    </collision>
    <!-- Part servo_wheel_3 -->
    <visual>
      <origin xyz="-5.55112e-17 3.46945e-18 -0.0025" rpy="3.14159 -3.02861e-16 -3.14159"/>
      <geometry>
        <mesh filename="package://meshes\servo_wheel.stl"/>
      </geometry>
      <material name="servo_wheel_3_material">
        <color rgba="0.647059 0.647059 0.647059 1"/>
      </material>
    </visual>
    <collision>
      <origin xyz="-5.55112e-17 3.46945e-18 -0.0025" rpy="3.14159 -3.02861e-16 -3.14159"/>
      <geometry>
        <mesh filename="package://meshes\servo_wheel.stl"/>
      </geometry>
    </collision>
    <!-- Part servo_2 -->
    <visual>
      <origin xyz="0.0175 0.00140442 -0.0305" rpy="3.14159 -2.09141e-16 -3.14159"/>
      <geometry>
        <mesh filename="package://meshes\servo.stl"/>
      </geometry>
      <material name="servo_2_material">
        <color rgba="0.109804 0.109804 0.105882 1"/>
      </material>
    </visual>
    <collision>
      <origin xyz="0.0175 0.00140442 -0.0305" rpy="3.14159 -2.09141e-16 -3.14159"/>
      <geometry>
        <mesh filename="package://meshes\servo.stl"/>
      </geometry>
    </collision>
    <!-- Part fixed_bracket_2 -->
    <visual>
      <origin xyz="0.0575 2.08167e-17 -0.0305" rpy="-1.5708 1.5708 0"/>
      <geometry>
        <mesh filename="package://meshes\fixed_bracket.stl"/>
      </geometry>
      <material name="fixed_bracket_2_material">
        <color rgba="0.647059 0.647059 0.647059 1"/>
      </material>
    </visual>
    <collision>
      <origin xyz="0.0575 2.08167e-17 -0.0305" rpy="-1.5708 1.5708 0"/>
      <geometry>
        <mesh filename="package://meshes\fixed_bracket.stl"/>
      </geometry>
    </collision>
    <!-- Part servo_wheel_4 -->
    <visual>
      <origin xyz="-8.32667e-17 -1.04083e-17 -0.0585" rpy="-3.14159 -5.66514e-16 -3.14159"/>
      <geometry>
        <mesh filename="package://meshes\servo_wheel.stl"/>
      </geometry>
      <material name="servo_wheel_4_material">
        <color rgba="0.647059 0.647059 0.647059 1"/>
      </material>
    </visual>
    <collision>
      <origin xyz="-8.32667e-17 -1.04083e-17 -0.0585" rpy="-3.14159 -5.66514e-16 -3.14159"/>
      <geometry>
        <mesh filename="package://meshes\servo_wheel.stl"/>
      </geometry>
    </collision>
  </link>
  <!-- Link foot_assembly -->
  <link name="foot_assembly">
    <inertial>
      <origin xyz="-0.0724503 -0.00208415 -0.0306672" rpy="0 0 0"/>
      <mass value="0.633745"/>
      <inertia ixx="0.000268495" ixy="-1.4806e-05" ixz="4.28294e-06" iyy="0.00320961" iyz="-2.30165e-07" izz="0.00304658"/>
    </inertial>
    <!-- Part foot -->
    <visual>
      <origin xyz="-0.04425 -2.08167e-17 -0.0305" rpy="-4.71681e-16 1.5708 0"/>
      <geometry>
        <mesh filename="package://meshes\foot.stl"/>
      </geometry>
      <material name="foot_material">
        <color rgba="0.282353 0.54902 0.160784 1"/>
      </material>
    </visual>
    <collision>
      <origin xyz="-0.04425 -2.08167e-17 -0.0305" rpy="-4.71681e-16 1.5708 0"/>
      <geometry>
        <mesh filename="package://meshes\foot.stl"/>
      </geometry>
    </collision>
    <!-- Part ir_sensor_cap -->
    <visual>
      <origin xyz="-0.04425 -1.2039e-15 -0.0305" rpy="6.67378e-15 1.5708 0"/>
      <geometry>
        <mesh filename="package://meshes\ir_sensor_cap.stl"/>
      </geometry>
      <material name="ir_sensor_cap_material">
        <color rgba="0.282353 0.54902 0.160784 1"/>
      </material>
    </visual>
    <collision>
      <origin xyz="-0.04425 -1.2039e-15 -0.0305" rpy="6.67378e-15 1.5708 0"/>
      <geometry>
        <mesh filename="package://meshes\ir_sensor_cap.stl"/>
      </geometry>
    </collision>
    <!-- Part rubber_foot -->
    <visual>
      <origin xyz="-0.04375 -1.73125e-15 -0.03" rpy="7.37908e-15 1.5708 0"/>
      <geometry>
        <mesh filename="package://meshes\rubber_foot.stl"/>
      </geometry>
      <material name="rubber_foot_material">
        <color rgba="0.262745 0.282353 0.301961 1"/>
      </material>
    </visual>
    <collision>
      <origin xyz="-0.04375 -1.73125e-15 -0.03" rpy="7.37908e-15 1.5708 0"/>
      <geometry>
        <mesh filename="package://meshes\rubber_foot.stl"/>
      </geometry>
    </collision>
    <!-- Part servo_wheel_5 -->
    <visual>
      <origin xyz="-5.55112e-17 0 -0.0025" rpy="3.14159 -5.84205e-18 -4.99413e-30"/>
      <geometry>
        <mesh filename="package://meshes\servo_wheel.stl"/>
      </geometry>
      <material name="servo_wheel_5_material">
        <color rgba="0.647059 0.647059 0.647059 1"/>
      </material>
    </visual>
    <collision>
      <origin xyz="-5.55112e-17 0 -0.0025" rpy="3.14159 -5.84205e-18 -4.99413e-30"/>
      <geometry>
        <mesh filename="package://meshes\servo_wheel.stl"/>
      </geometry>
    </collision>
    <!-- Part servo_3 -->
    <visual>
      <origin xyz="-0.0175 -0.00140442 -0.0305" rpy="-3.14159 -7.5462e-17 4.71681e-16"/>
      <geometry>
        <mesh filename="package://meshes\servo.stl"/>
      </geometry>
      <material name="servo_3_material">
        <color rgba="0.109804 0.109804 0.105882 1"/>
      </material>
    </visual>
    <collision>
      <origin xyz="-0.0175 -0.00140442 -0.0305" rpy="-3.14159 -7.5462e-17 4.71681e-16"/>
      <geometry>
        <mesh filename="package://meshes\servo.stl"/>
      </geometry>
    </collision>
    <!-- Part fixed_bracket_3 -->
    <visual>
      <origin xyz="-0.0575 -2.77556e-17 -0.0305" rpy="1.5708 1.5708 0"/>
      <geometry>
        <mesh filename="package://meshes\fixed_bracket.stl"/>
      </geometry>
      <material name="fixed_bracket_3_material">
        <color rgba="0.647059 0.647059 0.647059 1"/>
      </material>
    </visual>
    <collision>
      <origin xyz="-0.0575 -2.77556e-17 -0.0305" rpy="1.5708 1.5708 0"/>
      <geometry>
        <mesh filename="package://meshes\fixed_bracket.stl"/>
      </geometry>
    </collision>
    <!-- Part servo_wheel_6 -->
    <visual>
      <origin xyz="-5.55112e-17 -1.73472e-17 -0.0585" rpy="-3.14159 -2.69494e-16 1.25356e-15"/>
      <geometry>
        <mesh filename="package://meshes\servo_wheel.stl"/>
      </geometry>
      <material name="servo_wheel_6_material">
        <color rgba="0.647059 0.647059 0.647059 1"/>
      </material>
    </visual>
    <collision>
      <origin xyz="-5.55112e-17 -1.73472e-17 -0.0585" rpy="-3.14159 -2.69494e-16 1.25356e-15"/>
      <geometry>
        <mesh filename="package://meshes\servo_wheel.stl"/>
      </geometry>
    </collision>
  </link>
  <!-- Joint from ties_assembly to foot_assembly -->
  <joint name="foot_1" type="revolute">
    <origin xyz="0.1918 0.000210323 -0.000790548" rpy="-1.66622e-14 -3.69666e-15 3.14159"/>
    <parent link="ties_assembly"/>
    <child link="foot_assembly"/>
    <axis xyz="0 0 1"/>
    <limit effort="10" velocity="10" lower="-2.0944" upper="2.0944"/>
  </joint>
  <!-- Joint from hip_assembly to ties_assembly -->
  <joint name="ties_1" type="revolute">
    <origin xyz="0.0925 -0.0311167 -0.0305" rpy="1.5708 4.45935e-15 2.48483e-12"/>
    <parent link="hip_assembly"/>
    <child link="ties_assembly"/>
    <axis xyz="0 0 1"/>
    <limit effort="10" velocity="10" lower="-1.74533" upper="1.74533"/>
  </joint>
  <!-- Joint from base_link to hip_assembly -->
  <joint name="hip_1" type="revolute">
    <origin xyz="0.138321 0.0680226 0.0134908" rpy="-2.3989e-14 -2.8749e-14 0.436332"/>
    <parent link="base_link"/>
    <child link="hip_assembly"/>
    <axis xyz="0 0 1"/>
    <limit effort="10" velocity="10" lower="-1.5708" upper="1.5708"/>
  </joint>
  <!-- Link hip_assembly_2 -->
  <link name="hip_assembly_2">
    <inertial>
      <origin xyz="-0.0268487 -0.000325484 -0.0302141" rpy="0 0 0"/>
      <mass value="0.365356"/>
      <inertia ixx="0.000168136" ixy="-2.8417e-07" ixz="3.2467e-06" iyy="0.000312332" iyz="-9.42575e-07" izz="0.000312341"/>
    </inertial>
    <!-- Part hip_2 -->
    <visual>
      <origin xyz="-0.0575 -0.0005 -0.0045" rpy="-9.81323e-15 4.86997e-15 -1.57814e-16"/>
      <geometry>
        <mesh filename="package://meshes\hip.stl"/>
      </geometry>
      <material name="hip_2_material">
        <color rgba="0.282353 0.54902 0.160784 1"/>
      </material>
    </visual>
    <collision>
      <origin xyz="-0.0575 -0.0005 -0.0045" rpy="-9.81323e-15 4.86997e-15 -1.57814e-16"/>
      <geometry>
        <mesh filename="package://meshes\hip.stl"/>
      </geometry>
    </collision>
    <!-- Part mobile_bracket_9 -->
    <visual>
      <origin xyz="-0.0575 -7.80626e-18 -0.0305" rpy="8.55001e-16 -9.52702e-16 1.5708"/>
      <geometry>
        <mesh filename="package://meshes\mobile_bracket.stl"/>
      </geometry>
      <material name="mobile_bracket_9_material">
        <color rgba="0.647059 0.647059 0.647059 1"/>
      </material>
    </visual>
    <collision>
      <origin xyz="-0.0575 -7.80626e-18 -0.0305" rpy="8.55001e-16 -9.52702e-16 1.5708"/>
      <geometry>
        <mesh filename="package://meshes\mobile_bracket.stl"/>
      </geometry>
    </collision>
    <!-- Part servo_wheel_7 -->
    <visual>
      <origin xyz="2.77556e-17 -6.07153e-18 -0.0025" rpy="3.14159 3.8867e-30 -4.55901e-17"/>
      <geometry>
        <mesh filename="package://meshes\servo_wheel.stl"/>
      </geometry>
      <material name="servo_wheel_7_material">
        <color rgba="0.647059 0.647059 0.647059 1"/>
      </material>
    </visual>
    <collision>
      <origin xyz="2.77556e-17 -6.07153e-18 -0.0025" rpy="3.14159 3.8867e-30 -4.55901e-17"/>
      <geometry>
        <mesh filename="package://meshes\servo_wheel.stl"/>
      </geometry>
    </collision>
    <!-- Part servo_4 -->
    <visual>
      <origin xyz="-0.0175 -0.00140442 -0.0305" rpy="-3.14159 2.56343e-16 -2.07886e-17"/>
      <geometry>
        <mesh filename="package://meshes\servo.stl"/>
      </geometry>
      <material name="servo_4_material">
        <color rgba="0.109804 0.109804 0.105882 1"/>
      </material>
    </visual>
    <collision>
      <origin xyz="-0.0175 -0.00140442 -0.0305" rpy="-3.14159 2.56343e-16 -2.07886e-17"/>
      <geometry>
        <mesh filename="package://meshes\servo.stl"/>
      </geometry>
    </collision>
    <!-- Part fixed_bracket_4 -->
    <visual>
      <origin xyz="-0.0575 -7.80626e-18 -0.0305" rpy="1.5708 1.5708 0"/>
      <geometry>
        <mesh filename="package://meshes\fixed_bracket.stl"/>
      </geometry>
      <material name="fixed_bracket_4_material">
        <color rgba="0.647059 0.647059 0.647059 1"/>
      </material>
    </visual>
    <collision>
      <origin xyz="-0.0575 -7.80626e-18 -0.0305" rpy="1.5708 1.5708 0"/>
      <geometry>
        <mesh filename="package://meshes\fixed_bracket.stl"/>
      </geometry>
    </collision>
    <!-- Part servo_wheel_8 -->
    <visual>
      <origin xyz="0 -1.12757e-17 -0.0585" rpy="-3.14159 6.32414e-17 -2.66968e-17"/>
      <geometry>
        <mesh filename="package://meshes\servo_wheel.stl"/>
      </geometry>
      <material name="servo_wheel_8_material">
        <color rgba="0.647059 0.647059 0.647059 1"/>
      </material>
    </visual>
    <collision>
      <origin xyz="0 -1.12757e-17 -0.0585" rpy="-3.14159 6.32414e-17 -2.66968e-17"/>
      <geometry>
        <mesh filename="package://meshes\servo_wheel.stl"/>
      </geometry>
    </collision>
  </link>
  <!-- Link ties_assembly_2 -->
  <link name="ties_assembly_2">
    <inertial>
      <origin xyz="0.0643598 0.00153088 -0.0309357" rpy="0 0 0"/>
      <mass value="0.589115"/>
      <inertia ixx="0.000320336" ixy="-2.41497e-05" ixz="1.07866e-05" iyy="0.00208685" iyz="2.0947e-07" izz="0.00187002"/>
    </inertial>
    <!-- Part mobile_bracket_10 -->
    <visual>
      <origin xyz="0.1568 0.000210323 -0.0311738" rpy="1.5708 1.5708 0"/>
      <geometry>
        <mesh filename="package://meshes\mobile_bracket.stl"/>
      </geometry>
      <material name="mobile_bracket_10_material">
        <color rgba="0.647059 0.647059 0.647059 1"/>
      </material>
    </visual>
    <collision>
      <origin xyz="0.1568 0.000210323 -0.0311738" rpy="1.5708 1.5708 0"/>
      <geometry>
        <mesh filename="package://meshes\mobile_bracket.stl"/>
      </geometry>
    </collision>
    <!-- Part low_tie_2 -->
    <visual>
      <origin xyz="0.0268 0.000210323 -0.0311738" rpy="-3.71491e-14 1.5708 0"/>
      <geometry>
        <mesh filename="package://meshes\low_tie.stl"/>
      </geometry>
      <material name="low_tie_2_material">
        <color rgba="0.282353 0.54902 0.160784 1"/>
      </material>
    </visual>
    <collision>
      <origin xyz="0.0268 0.000210323 -0.0311738" rpy="-3.71491e-14 1.5708 0"/>
      <geometry>
        <mesh filename="package://meshes\low_tie.stl"/>
      </geometry>
    </collision>
    <!-- Part top_tie_2 -->
    <visual>
      <origin xyz="0.0275 1.02002e-15 -0.0305" rpy="-3.71491e-14 1.5708 0"/>
      <geometry>
        <mesh filename="package://meshes\top_tie.stl"/>
      </geometry>
      <material name="top_tie_2_material">
        <color rgba="0.282353 0.54902 0.160784 1"/>
      </material>
    </visual>
    <collision>
      <origin xyz="0.0275 1.02002e-15 -0.0305" rpy="-3.71491e-14 1.5708 0"/>
      <geometry>
        <mesh filename="package://meshes\top_tie.stl"/>
      </geometry>
    </collision>
    <!-- Part servo_wheel_9 -->
    <visual>
      <origin xyz="0 3.46945e-18 -0.0025" rpy="-3.14159 -6.07909e-15 -3.14159"/>
      <geometry>
        <mesh filename="package://meshes\servo_wheel.stl"/>
      </geometry>
      <material name="servo_wheel_9_material">
        <color rgba="0.647059 0.647059 0.647059 1"/>
      </material>
    </visual>
    <collision>
      <origin xyz="0 3.46945e-18 -0.0025" rpy="-3.14159 -6.07909e-15 -3.14159"/>
      <geometry>
        <mesh filename="package://meshes\servo_wheel.stl"/>
      </geometry>
    </collision>
    <!-- Part servo_5 -->
    <visual>
      <origin xyz="0.0175 0.00140442 -0.0305" rpy="3.14159 -7.09719e-15 -3.14159"/>
      <geometry>
        <mesh filename="package://meshes\servo.stl"/>
      </geometry>
      <material name="servo_5_material">
        <color rgba="0.109804 0.109804 0.105882 1"/>
      </material>
    </visual>
    <collision>
      <origin xyz="0.0175 0.00140442 -0.0305" rpy="3.14159 -7.09719e-15 -3.14159"/>
      <geometry>
        <mesh filename="package://meshes\servo.stl"/>
      </geometry>
    </collision>
    <!-- Part fixed_bracket_5 -->
    <visual>
      <origin xyz="0.0575 2.13371e-15 -0.0305" rpy="-1.5708 1.5708 0"/>
      <geometry>
        <mesh filename="package://meshes\fixed_bracket.stl"/>
      </geometry>
      <material name="fixed_bracket_5_material">
        <color rgba="0.647059 0.647059 0.647059 1"/>
      </material>
    </visual>
    <collision>
      <origin xyz="0.0575 2.13371e-15 -0.0305" rpy="-1.5708 1.5708 0"/>
      <geometry>
        <mesh filename="package://meshes\fixed_bracket.stl"/>
      </geometry>
    </collision>
    <!-- Part servo_wheel_10 -->
    <visual>
      <origin xyz="2.77556e-17 3.46945e-18 -0.0585" rpy="-3.14159 -6.23027e-15 -3.14159"/>
      <geometry>
        <mesh filename="package://meshes\servo_wheel.stl"/>
      </geometry>
      <material name="servo_wheel_10_material">
        <color rgba="0.647059 0.647059 0.647059 1"/>
      </material>
    </visual>
    <collision>
      <origin xyz="2.77556e-17 3.46945e-18 -0.0585" rpy="-3.14159 -6.23027e-15 -3.14159"/>
      <geometry>
        <mesh filename="package://meshes\servo_wheel.stl"/>
      </geometry>
    </collision>
  </link>
  <!-- Link foot_assembly_2 -->
  <link name="foot_assembly_2">
    <inertial>
      <origin xyz="-0.0724503 -0.00208415 -0.0306672" rpy="0 0 0"/>
      <mass value="0.633745"/>
      <inertia ixx="0.000268495" ixy="-1.4806e-05" ixz="4.28294e-06" iyy="0.00320961" iyz="-2.30165e-07" izz="0.00304658"/>
    </inertial>
    <!-- Part foot_2 -->
    <visual>
      <origin xyz="-0.04425 6.93889e-18 -0.0305" rpy="-2.43594e-27 1.5708 0"/>
      <geometry>
        <mesh filename="package://meshes\foot.stl"/>
      </geometry>
      <material name="foot_2_material">
        <color rgba="0.282353 0.54902 0.160784 1"/>
      </material>
    </visual>
    <collision>
      <origin xyz="-0.04425 6.93889e-18 -0.0305" rpy="-2.43594e-27 1.5708 0"/>
      <geometry>
        <mesh filename="package://meshes\foot.stl"/>
      </geometry>
    </collision>
    <!-- Part ir_sensor_cap_2 -->
    <visual>
      <origin xyz="-0.04425 1.25247e-15 -0.0305" rpy="-6.5509e-15 1.5708 0"/>
      <geometry>
        <mesh filename="package://meshes\ir_sensor_cap.stl"/>
      </geometry>
      <material name="ir_sensor_cap_2_material">
        <color rgba="0.282353 0.54902 0.160784 1"/>
      </material>
    </visual>
    <collision>
      <origin xyz="-0.04425 1.25247e-15 -0.0305" rpy="-6.5509e-15 1.5708 0"/>
      <geometry>
        <mesh filename="package://meshes\ir_sensor_cap.stl"/>
      </geometry>
    </collision>
    <!-- Part rubber_foot_2 -->
    <visual>
      <origin xyz="-0.04375 1.66533e-15 -0.03" rpy="-7.87954e-15 1.5708 0"/>
      <geometry>
        <mesh filename="package://meshes\rubber_foot.stl"/>
      </geometry>
      <material name="rubber_foot_2_material">
        <color rgba="0.262745 0.282353 0.301961 1"/>
      </material>
    </visual>
    <collision>
      <origin xyz="-0.04375 1.66533e-15 -0.03" rpy="-7.87954e-15 1.5708 0"/>
      <geometry>
        <mesh filename="package://meshes\rubber_foot.stl"/>
      </geometry>
    </collision>
    <!-- Part servo_wheel_11 -->
    <visual>
      <origin xyz="1.11022e-16 0 -0.0025" rpy="-3.14159 4.41096e-17 -6.37252e-30"/>
      <geometry>
        <mesh filename="package://meshes\servo_wheel.stl"/>
      </geometry>
      <material name="servo_wheel_11_material">
        <color rgba="0.647059 0.647059 0.647059 1"/>
      </material>
    </visual>
    <collision>
      <origin xyz="1.11022e-16 0 -0.0025" rpy="-3.14159 4.41096e-17 -6.37252e-30"/>
      <geometry>
        <mesh filename="package://meshes\servo_wheel.stl"/>
      </geometry>
    </collision>
    <!-- Part servo_6 -->
    <visual>
      <origin xyz="-0.0175 -0.00140442 -0.0305" rpy="3.14159 8.66357e-17 1.1927e-27"/>
      <geometry>
        <mesh filename="package://meshes\servo.stl"/>
      </geometry>
      <material name="servo_6_material">
        <color rgba="0.109804 0.109804 0.105882 1"/>
      </material>
    </visual>
    <collision>
      <origin xyz="-0.0175 -0.00140442 -0.0305" rpy="3.14159 8.66357e-17 1.1927e-27"/>
      <geometry>
        <mesh filename="package://meshes\servo.stl"/>
      </geometry>
    </collision>
    <!-- Part fixed_bracket_6 -->
    <visual>
      <origin xyz="-0.0575 1.04083e-17 -0.0305" rpy="1.5708 1.5708 0"/>
      <geometry>
        <mesh filename="package://meshes\fixed_bracket.stl"/>
      </geometry>
      <material name="fixed_bracket_6_material">
        <color rgba="0.647059 0.647059 0.647059 1"/>
      </material>
    </visual>
    <collision>
      <origin xyz="-0.0575 1.04083e-17 -0.0305" rpy="1.5708 1.5708 0"/>
      <geometry>
        <mesh filename="package://meshes\fixed_bracket.stl"/>
      </geometry>
    </collision>
    <!-- Part servo_wheel_12 -->
    <visual>
      <origin xyz="0 0 -0.0585" rpy="3.14159 -7.49596e-15 1.1927e-27"/>
      <geometry>
        <mesh filename="package://meshes\servo_wheel.stl"/>
      </geometry>
      <material name="servo_wheel_12_material">
        <color rgba="0.647059 0.647059 0.647059 1"/>
      </material>
    </visual>
    <collision>
      <origin xyz="0 0 -0.0585" rpy="3.14159 -7.49596e-15 1.1927e-27"/>
      <geometry>
        <mesh filename="package://meshes\servo_wheel.stl"/>
      </geometry>
    </collision>
  </link>
  <!-- Joint from ties_assembly_2 to foot_assembly_2 -->
  <joint name="foot_2" type="revolute">
    <origin xyz="0.1918 0.000210323 -0.000790548" rpy="2.57504e-15 -5.91728e-15 3.14159"/>
    <parent link="ties_assembly_2"/>
    <child link="foot_assembly_2"/>
    <axis xyz="0 0 1"/>
    <limit effort="10" velocity="10" lower="-2.0944" upper="2.0944"/>
  </joint>
  <!-- Joint from hip_assembly_2 to ties_assembly_2 -->
  <joint name="ties_2" type="revolute">
    <origin xyz="-0.0925 0.0311167 -0.0305" rpy="1.5708 -8.55001e-16 3.14159"/>
    <parent link="hip_assembly_2"/>
    <child link="ties_assembly_2"/>
    <axis xyz="0 0 1"/>
    <limit effort="10" velocity="10" lower="-1.74533" upper="1.74533"/>
  </joint>
  <!-- Joint from base_link to hip_assembly_2 -->
  <joint name="hip_2" type="revolute">
    <origin xyz="0.125071 -0.083416 0.0134908" rpy="-7.92838e-15 3.38805e-14 2.53073"/>
    <parent link="base_link"/>
    <child link="hip_assembly_2"/>
    <axis xyz="0 0 1"/>
    <limit effort="10" velocity="10" lower="-1.5708" upper="1.5708"/>
  </joint>
  <!-- Link hip_assembly_3 -->
  <link name="hip_assembly_3">
    <inertial>
      <origin xyz="0.0268487 0.000325484 -0.0302141" rpy="0 0 0"/>
      <mass value="0.365356"/>
      <inertia ixx="0.000168136" ixy="-2.8417e-07" ixz="-3.2467e-06" iyy="0.000312332" iyz="9.42575e-07" izz="0.000312341"/>
    </inertial>
    <!-- Part hip_3 -->
    <visual>
      <origin xyz="0.0575 0.0005 -0.0045" rpy="-1.99788e-14 -9.22412e-17 -3.14159"/>
      <geometry>
        <mesh filename="package://meshes\hip.stl"/>
      </geometry>
      <material name="hip_3_material">
        <color rgba="0.282353 0.54902 0.160784 1"/>
      </material>
    </visual>
    <collision>
      <origin xyz="0.0575 0.0005 -0.0045" rpy="-1.99788e-14 -9.22412e-17 -3.14159"/>
      <geometry>
        <mesh filename="package://meshes\hip.stl"/>
      </geometry>
    </collision>
    <!-- Part mobile_bracket_11 -->
    <visual>
      <origin xyz="0.0575 1.43814e-13 -0.0305" rpy="-9.22412e-17 2.91099e-14 -1.5708"/>
      <geometry>
        <mesh filename="package://meshes\mobile_bracket.stl"/>
      </geometry>
      <material name="mobile_bracket_11_material">
        <color rgba="0.647059 0.647059 0.647059 1"/>
      </material>
    </visual>
    <collision>
      <origin xyz="0.0575 1.43814e-13 -0.0305" rpy="-9.22412e-17 2.91099e-14 -1.5708"/>
      <geometry>
        <mesh filename="package://meshes\mobile_bracket.stl"/>
      </geometry>
    </collision>
    <!-- Part servo_wheel_13 -->
    <visual>
      <origin xyz="0 -2.43945e-19 -0.0025" rpy="3.14159 -9.22412e-17 -3.14159"/>
      <geometry>
        <mesh filename="package://meshes\servo_wheel.stl"/>
      </geometry>
      <material name="servo_wheel_13_material">
        <color rgba="0.647059 0.647059 0.647059 1"/>
      </material>
    </visual>
    <collision>
      <origin xyz="0 -2.43945e-19 -0.0025" rpy="3.14159 -9.22412e-17 -3.14159"/>
      <geometry>
        <mesh filename="package://meshes\servo_wheel.stl"/>
      </geometry>
    </collision>
    <!-- Part servo_7 -->
    <visual>
      <origin xyz="0.0175 0.00140442 -0.0305" rpy="-3.14159 -9.22412e-17 -3.14159"/>
      <geometry>
        <mesh filename="package://meshes\servo.stl"/>
      </geometry>
      <material name="servo_7_material">
        <color rgba="0.109804 0.109804 0.105882 1"/>
      </material>
    </visual>
    <collision>
      <origin xyz="0.0175 0.00140442 -0.0305" rpy="-3.14159 -9.22412e-17 -3.14159"/>
      <geometry>
        <mesh filename="package://meshes\servo.stl"/>
      </geometry>
    </collision>
    <!-- Part fixed_bracket_7 -->
    <visual>
      <origin xyz="0.0575 1.43814e-13 -0.0305" rpy="-1.5708 1.5708 0"/>
      <geometry>
        <mesh filename="package://meshes\fixed_bracket.stl"/>
      </geometry>
      <material name="fixed_bracket_7_material">
        <color rgba="0.647059 0.647059 0.647059 1"/>
      </material>
    </visual>
    <collision>
      <origin xyz="0.0575 1.43814e-13 -0.0305" rpy="-1.5708 1.5708 0"/>
      <geometry>
        <mesh filename="package://meshes\fixed_bracket.stl"/>
      </geometry>
    </collision>
    <!-- Part servo_wheel_14 -->
    <visual>
      <origin xyz="-1.9984e-15 1.71846e-17 -0.0585" rpy="3.14159 -9.22412e-17 -3.14159"/>
      <geometry>
        <mesh filename="package://meshes\servo_wheel.stl"/>
      </geometry>
      <material name="servo_wheel_14_material">
        <color rgba="0.647059 0.647059 0.647059 1"/>
      </material>
    </visual>
    <collision>
      <origin xyz="-1.9984e-15 1.71846e-17 -0.0585" rpy="3.14159 -9.22412e-17 -3.14159"/>
      <geometry>
        <mesh filename="package://meshes\servo_wheel.stl"/>
      </geometry>
    </collision>
  </link>
  <!-- Link ties_assembly_3 -->
  <link name="ties_assembly_3">
    <inertial>
      <origin xyz="0.0643598 0.00153088 -0.0309357" rpy="0 0 0"/>
      <mass value="0.589115"/>
      <inertia ixx="0.000320336" ixy="-2.41497e-05" ixz="1.07866e-05" iyy="0.00208685" iyz="2.0947e-07" izz="0.00187002"/>
    </inertial>
    <!-- Part mobile_bracket_12 -->
    <visual>
      <origin xyz="0.1568 0.000210323 -0.0311738" rpy="1.5708 1.5708 0"/>
      <geometry>
        <mesh filename="package://meshes\mobile_bracket.stl"/>
      </geometry>
      <material name="mobile_bracket_12_material">
        <color rgba="0.647059 0.647059 0.647059 1"/>
      </material>
    </visual>
    <collision>
      <origin xyz="0.1568 0.000210323 -0.0311738" rpy="1.5708 1.5708 0"/>
      <geometry>
        <mesh filename="package://meshes\mobile_bracket.stl"/>
      </geometry>
    </collision>
    <!-- Part low_tie_3 -->
    <visual>
      <origin xyz="0.0268 0.000210323 -0.0311738" rpy="8.14959e-15 1.5708 0"/>
      <geometry>
        <mesh filename="package://meshes\low_tie.stl"/>
      </geometry>
      <material name="low_tie_3_material">
        <color rgba="0.282353 0.54902 0.160784 1"/>
      </material>
    </visual>
    <collision>
      <origin xyz="0.0268 0.000210323 -0.0311738" rpy="8.14959e-15 1.5708 0"/>
      <geometry>
        <mesh filename="package://meshes\low_tie.stl"/>
      </geometry>
    </collision>
    <!-- Part top_tie_3 -->
    <visual>
      <origin xyz="0.0275 -2.498e-16 -0.0305" rpy="8.14959e-15 1.5708 0"/>
      <geometry>
        <mesh filename="package://meshes\top_tie.stl"/>
      </geometry>
      <material name="top_tie_3_material">
        <color rgba="0.282353 0.54902 0.160784 1"/>
      </material>
    </visual>
    <collision>
      <origin xyz="0.0275 -2.498e-16 -0.0305" rpy="8.14959e-15 1.5708 0"/>
      <geometry>
        <mesh filename="package://meshes\top_tie.stl"/>
      </geometry>
    </collision>
    <!-- Part servo_wheel_15 -->
    <visual>
      <origin xyz="2.77556e-17 -3.46945e-18 -0.0025" rpy="-3.14159 7.2886e-17 3.14159"/>
      <geometry>
        <mesh filename="package://meshes\servo_wheel.stl"/>
      </geometry>
      <material name="servo_wheel_15_material">
        <color rgba="0.647059 0.647059 0.647059 1"/>
      </material>
    </visual>
    <collision>
      <origin xyz="2.77556e-17 -3.46945e-18 -0.0025" rpy="-3.14159 7.2886e-17 3.14159"/>
      <geometry>
        <mesh filename="package://meshes\servo_wheel.stl"/>
      </geometry>
    </collision>
    <!-- Part servo_8 -->
    <visual>
      <origin xyz="0.0175 0.00140442 -0.0305" rpy="-3.14159 -8.01519e-17 3.14159"/>
      <geometry>
        <mesh filename="package://meshes\servo.stl"/>
      </geometry>
      <material name="servo_8_material">
        <color rgba="0.109804 0.109804 0.105882 1"/>
      </material>
    </visual>
    <collision>
      <origin xyz="0.0175 0.00140442 -0.0305" rpy="-3.14159 -8.01519e-17 3.14159"/>
      <geometry>
        <mesh filename="package://meshes\servo.stl"/>
      </geometry>
    </collision>
    <!-- Part fixed_bracket_8 -->
    <visual>
      <origin xyz="0.0575 -4.96131e-16 -0.0305" rpy="-1.5708 1.5708 0"/>
      <geometry>
        <mesh filename="package://meshes\fixed_bracket.stl"/>
      </geometry>
      <material name="fixed_bracket_8_material">
        <color rgba="0.647059 0.647059 0.647059 1"/>
      </material>
    </visual>
    <collision>
      <origin xyz="0.0575 -4.96131e-16 -0.0305" rpy="-1.5708 1.5708 0"/>
      <geometry>
        <mesh filename="package://meshes\fixed_bracket.stl"/>
      </geometry>
    </collision>
    <!-- Part servo_wheel_16 -->
    <visual>
      <origin xyz="2.77556e-17 -3.46945e-18 -0.0585" rpy="-3.14159 -1.20361e-17 3.14159"/>
      <geometry>
        <mesh filename="package://meshes\servo_wheel.stl"/>
      </geometry>
      <material name="servo_wheel_16_material">
        <color rgba="0.647059 0.647059 0.647059 1"/>
      </material>
    </visual>
    <collision>
      <origin xyz="2.77556e-17 -3.46945e-18 -0.0585" rpy="-3.14159 -1.20361e-17 3.14159"/>
      <geometry>
        <mesh filename="package://meshes\servo_wheel.stl"/>
      </geometry>
    </collision>
  </link>
  <!-- Link foot_assembly_3 -->
  <link name="foot_assembly_3">
    <inertial>
      <origin xyz="-0.0724503 -0.00208415 -0.0306672" rpy="0 0 0"/>
      <mass value="0.633745"/>
      <inertia ixx="0.000268495" ixy="-1.4806e-05" ixz="4.28294e-06" iyy="0.00320961" iyz="-2.30165e-07" izz="0.00304658"/>
    </inertial>
    <!-- Part foot_3 -->
    <visual>
      <origin xyz="-0.04425 1.04083e-17 -0.0305" rpy="1.55031e-16 1.5708 0"/>
      <geometry>
        <mesh filename="package://meshes\foot.stl"/>
      </geometry>
      <material name="foot_3_material">
        <color rgba="0.282353 0.54902 0.160784 1"/>
      </material>
    </visual>
    <collision>
      <origin xyz="-0.04425 1.04083e-17 -0.0305" rpy="1.55031e-16 1.5708 0"/>
      <geometry>
        <mesh filename="package://meshes\foot.stl"/>
      </geometry>
    </collision>
    <!-- Part ir_sensor_cap_3 -->
    <visual>
      <origin xyz="-0.04425 2.84842e-15 -0.0305" rpy="-1.49841e-14 1.5708 0"/>
      <geometry>
        <mesh filename="package://meshes\ir_sensor_cap.stl"/>
      </geometry>
      <material name="ir_sensor_cap_3_material">
        <color rgba="0.282353 0.54902 0.160784 1"/>
      </material>
    </visual>
    <collision>
      <origin xyz="-0.04425 2.84842e-15 -0.0305" rpy="-1.49841e-14 1.5708 0"/>
      <geometry>
        <mesh filename="package://meshes\ir_sensor_cap.stl"/>
      </geometry>
    </collision>
    <!-- Part rubber_foot_3 -->
    <visual>
      <origin xyz="-0.04375 3.81639e-16 -0.03" rpy="-1.62907e-15 1.5708 0"/>
      <geometry>
        <mesh filename="package://meshes\rubber_foot.stl"/>
      </geometry>
      <material name="rubber_foot_3_material">
        <color rgba="0.262745 0.282353 0.301961 1"/>
      </material>
    </visual>
    <collision>
      <origin xyz="-0.04375 3.81639e-16 -0.03" rpy="-1.62907e-15 1.5708 0"/>
      <geometry>
        <mesh filename="package://meshes\rubber_foot.stl"/>
      </geometry>
    </collision>
    <!-- Part servo_wheel_17 -->
    <visual>
      <origin xyz="5.55112e-17 0 -0.0025" rpy="-3.14159 1.35612e-17 1.21394e-30"/>
      <geometry>
        <mesh filename="package://meshes\servo_wheel.stl"/>
      </geometry>
      <material name="servo_wheel_17_material">
        <color rgba="0.647059 0.647059 0.647059 1"/>
      </material>
    </visual>
    <collision>
      <origin xyz="5.55112e-17 0 -0.0025" rpy="-3.14159 1.35612e-17 1.21394e-30"/>
      <geometry>
        <mesh filename="package://meshes\servo_wheel.stl"/>
      </geometry>
    </collision>
    <!-- Part servo_9 -->
    <visual>
      <origin xyz="-0.0175 -0.00140442 -0.0305" rpy="-3.14159 1.5433e-15 -2.82897e-30"/>
      <geometry>
        <mesh filename="package://meshes\servo.stl"/>
      </geometry>
      <material name="servo_9_material">
        <color rgba="0.109804 0.109804 0.105882 1"/>
      </material>
    </visual>
    <collision>
      <origin xyz="-0.0175 -0.00140442 -0.0305" rpy="-3.14159 1.5433e-15 -2.82897e-30"/>
      <geometry>
        <mesh filename="package://meshes\servo.stl"/>
      </geometry>
    </collision>
    <!-- Part fixed_bracket_9 -->
    <visual>
      <origin xyz="-0.0575 1.38778e-17 -0.0305" rpy="1.5708 1.5708 0"/>
      <geometry>
        <mesh filename="package://meshes\fixed_bracket.stl"/>
      </geometry>
      <material name="fixed_bracket_9_material">
        <color rgba="0.647059 0.647059 0.647059 1"/>
      </material>
    </visual>
    <collision>
      <origin xyz="-0.0575 1.38778e-17 -0.0305" rpy="1.5708 1.5708 0"/>
      <geometry>
        <mesh filename="package://meshes\fixed_bracket.stl"/>
      </geometry>
    </collision>
    <!-- Part servo_wheel_18 -->
    <visual>
      <origin xyz="0 6.93889e-18 -0.0585" rpy="-3.14159 -2.80722e-17 -2.07665e-17"/>
      <geometry>
        <mesh filename="package://meshes\servo_wheel.stl"/>
      </geometry>
      <material name="servo_wheel_18_material">
        <color rgba="0.647059 0.647059 0.647059 1"/>
      </material>
    </visual>
    <collision>
      <origin xyz="0 6.93889e-18 -0.0585" rpy="-3.14159 -2.80722e-17 -2.07665e-17"/>
      <geometry>
        <mesh filename="package://meshes\servo_wheel.stl"/>
      </geometry>
    </collision>
  </link>
  <!-- Joint from ties_assembly_3 to foot_assembly_3 -->
  <joint name="foot_3" type="revolute">
    <origin xyz="0.1918 0.000210323 -0.000790548" rpy="1.68416e-15 -9.61937e-17 3.14159"/>
    <parent link="ties_assembly_3"/>
    <child link="foot_assembly_3"/>
    <axis xyz="0 0 1"/>
    <limit effort="10" velocity="10" lower="-2.0944" upper="2.0944"/>
  </joint>
  <!-- Joint from hip_assembly_3 to ties_assembly_3 -->
  <joint name="ties_3" type="revolute">
    <origin xyz="0.0925 -0.0311167 -0.0305" rpy="1.5708 9.22412e-17 2.50162e-12"/>
    <parent link="hip_assembly_3"/>
    <child link="ties_assembly_3"/>
    <axis xyz="0 0 1"/>
    <limit effort="10" velocity="10" lower="-1.74533" upper="1.74533"/>
  </joint>
  <!-- Joint from base_link to hip_assembly_3 -->
  <joint name="hip_3" type="revolute">
    <origin xyz="-0.0127028 -0.147661 0.0142242" rpy="3.23352e-14 -8.74693e-15 -1.65806"/>
    <parent link="base_link"/>
    <child link="hip_assembly_3"/>
    <axis xyz="0 0 1"/>
    <limit effort="10" velocity="10" lower="-1.5708" upper="1.5708"/>
  </joint>
  <!-- Link hip_assembly_4 -->
  <link name="hip_assembly_4">
    <inertial>
      <origin xyz="0.0268487 0.000325484 -0.0302141" rpy="0 0 0"/>
      <mass value="0.365356"/>
      <inertia ixx="0.000168136" ixy="-2.8417e-07" ixz="-3.2467e-06" iyy="0.000312332" iyz="9.42575e-07" izz="0.000312341"/>
    </inertial>
    <!-- Part hip_4 -->
    <visual>
      <origin xyz="0.0575 0.0005 -0.0045" rpy="-9.16127e-16 -8.9318e-16 -3.14159"/>
      <geometry>
        <mesh filename="package://meshes\hip.stl"/>
      </geometry>
      <material name="hip_4_material">
        <color rgba="0.282353 0.54902 0.160784 1"/>
      </material>
    </visual>
    <collision>
      <origin xyz="0.0575 0.0005 -0.0045" rpy="-9.16127e-16 -8.9318e-16 -3.14159"/>
      <geometry>
        <mesh filename="package://meshes\hip.stl"/>
      </geometry>
    </collision>
    <!-- Part mobile_bracket_13 -->
    <visual>
      <origin xyz="0.0575 1.43742e-13 -0.0305" rpy="-6.76543e-16 -1.05045e-15 -1.5708"/>
      <geometry>
        <mesh filename="package://meshes\mobile_bracket.stl"/>
      </geometry>
      <material name="mobile_bracket_13_material">
        <color rgba="0.647059 0.647059 0.647059 1"/>
      </material>
    </visual>
    <collision>
      <origin xyz="0.0575 1.43742e-13 -0.0305" rpy="-6.76543e-16 -1.05045e-15 -1.5708"/>
      <geometry>
        <mesh filename="package://meshes\mobile_bracket.stl"/>
      </geometry>
    </collision>
    <!-- Part servo_wheel_19 -->
    <visual>
      <origin xyz="0 -4.33681e-19 -0.0025" rpy="3.14159 -1.78474e-16 -3.14159"/>
      <geometry>
        <mesh filename="package://meshes\servo_wheel.stl"/>
      </geometry>
      <material name="servo_wheel_19_material">
        <color rgba="0.647059 0.647059 0.647059 1"/>
      </material>
    </visual>
    <collision>
      <origin xyz="0 -4.33681e-19 -0.0025" rpy="3.14159 -1.78474e-16 -3.14159"/>
      <geometry>
        <mesh filename="package://meshes\servo_wheel.stl"/>
      </geometry>
    </collision>
    <!-- Part servo_10 -->
    <visual>
      <origin xyz="0.0175 0.00140442 -0.0305" rpy="3.14159 -1.78474e-16 -3.14159"/>
      <geometry>
        <mesh filename="package://meshes\servo.stl"/>
      </geometry>
      <material name="servo_10_material">
        <color rgba="0.109804 0.109804 0.105882 1"/>
      </material>
    </visual>
    <collision>
      <origin xyz="0.0175 0.00140442 -0.0305" rpy="3.14159 -1.78474e-16 -3.14159"/>
      <geometry>
        <mesh filename="package://meshes\servo.stl"/>
      </geometry>
    </collision>
    <!-- Part fixed_bracket_10 -->
    <visual>
      <origin xyz="0.0575 1.43742e-13 -0.0305" rpy="-1.5708 1.5708 0"/>
      <geometry>
        <mesh filename="package://meshes\fixed_bracket.stl"/>
      </geometry>
      <material name="fixed_bracket_10_material">
        <color rgba="0.647059 0.647059 0.647059 1"/>
      </material>
    </visual>
    <collision>
      <origin xyz="0.0575 1.43742e-13 -0.0305" rpy="-1.5708 1.5708 0"/>
      <geometry>
        <mesh filename="package://meshes\fixed_bracket.stl"/>
      </geometry>
    </collision>
    <!-- Part servo_wheel_20 -->
    <visual>
      <origin xyz="0 -9.1073e-18 -0.0585" rpy="3.14159 -1.78474e-16 -3.14159"/>
      <geometry>
        <mesh filename="package://meshes\servo_wheel.stl"/>
      </geometry>
      <material name="servo_wheel_20_material">
        <color rgba="0.647059 0.647059 0.647059 1"/>
      </material>
    </visual>
    <collision>
      <origin xyz="0 -9.1073e-18 -0.0585" rpy="3.14159 -1.78474e-16 -3.14159"/>
      <geometry>
        <mesh filename="package://meshes\servo_wheel.stl"/>
      </geometry>
    </collision>
  </link>
  <!-- Link ties_assembly_4 -->
  <link name="ties_assembly_4">
    <inertial>
      <origin xyz="0.0643598 0.00153088 -0.0309357" rpy="0 0 0"/>
      <mass value="0.589115"/>
      <inertia ixx="0.000320336" ixy="-2.41497e-05" ixz="1.07866e-05" iyy="0.00208685" iyz="2.0947e-07" izz="0.00187002"/>
    </inertial>
    <!-- Part mobile_bracket_14 -->
    <visual>
      <origin xyz="0.1568 0.000210323 -0.0311738" rpy="1.5708 1.5708 0"/>
      <geometry>
        <mesh filename="package://meshes\mobile_bracket.stl"/>
      </geometry>
      <material name="mobile_bracket_14_material">
        <color rgba="0.647059 0.647059 0.647059 1"/>
      </material>
    </visual>
    <collision>
      <origin xyz="0.1568 0.000210323 -0.0311738" rpy="1.5708 1.5708 0"/>
      <geometry>
        <mesh filename="package://meshes\mobile_bracket.stl"/>
      </geometry>
    </collision>
    <!-- Part low_tie_4 -->
    <visual>
      <origin xyz="0.0268 0.000210323 -0.0311738" rpy="-1.07587e-14 1.5708 0"/>
      <geometry>
        <mesh filename="package://meshes\low_tie.stl"/>
      </geometry>
      <material name="low_tie_4_material">
        <color rgba="0.282353 0.54902 0.160784 1"/>
      </material>
    </visual>
    <collision>
      <origin xyz="0.0268 0.000210323 -0.0311738" rpy="-1.07587e-14 1.5708 0"/>
      <geometry>
        <mesh filename="package://meshes\low_tie.stl"/>
      </geometry>
    </collision>
    <!-- Part top_tie_4 -->
    <visual>
      <origin xyz="0.0275 2.91434e-16 -0.0305" rpy="-1.07587e-14 1.5708 0"/>
      <geometry>
        <mesh filename="package://meshes\top_tie.stl"/>
      </geometry>
      <material name="top_tie_4_material">
        <color rgba="0.282353 0.54902 0.160784 1"/>
      </material>
    </visual>
    <collision>
      <origin xyz="0.0275 2.91434e-16 -0.0305" rpy="-1.07587e-14 1.5708 0"/>
      <geometry>
        <mesh filename="package://meshes\top_tie.stl"/>
      </geometry>
    </collision>
    <!-- Part servo_wheel_21 -->
    <visual>
      <origin xyz="-2.77556e-17 0 -0.0025" rpy="3.14159 -1.88765e-14 -3.14159"/>
      <geometry>
        <mesh filename="package://meshes\servo_wheel.stl"/>
      </geometry>
      <material name="servo_wheel_21_material">
        <color rgba="0.647059 0.647059 0.647059 1"/>
      </material>
    </visual>
    <collision>
      <origin xyz="-2.77556e-17 0 -0.0025" rpy="3.14159 -1.88765e-14 -3.14159"/>
      <geometry>
        <mesh filename="package://meshes\servo_wheel.stl"/>
      </geometry>
    </collision>
    <!-- Part servo_11 -->
    <visual>
      <origin xyz="0.0175 0.00140442 -0.0305" rpy="3.14159 -1.89012e-14 -3.14159"/>
      <geometry>
        <mesh filename="package://meshes\servo.stl"/>
      </geometry>
      <material name="servo_11_material">
        <color rgba="0.109804 0.109804 0.105882 1"/>
      </material>
    </visual>
    <collision>
      <origin xyz="0.0175 0.00140442 -0.0305" rpy="3.14159 -1.89012e-14 -3.14159"/>
      <geometry>
        <mesh filename="package://meshes\servo.stl"/>
      </geometry>
    </collision>
    <!-- Part fixed_bracket_11 -->
    <visual>
      <origin xyz="0.0575 6.10623e-16 -0.0305" rpy="-1.5708 1.5708 0"/>
      <geometry>
        <mesh filename="package://meshes\fixed_bracket.stl"/>
      </geometry>
      <material name="fixed_bracket_11_material">
        <color rgba="0.647059 0.647059 0.647059 1"/>
      </material>
    </visual>
    <collision>
      <origin xyz="0.0575 6.10623e-16 -0.0305" rpy="-1.5708 1.5708 0"/>
      <geometry>
        <mesh filename="package://meshes\fixed_bracket.stl"/>
      </geometry>
    </collision>
    <!-- Part servo_wheel_22 -->
    <visual>
      <origin xyz="-1.05471e-15 0 -0.0585" rpy="3.14159 -1.89304e-14 -3.14159"/>
      <geometry>
        <mesh filename="package://meshes\servo_wheel.stl"/>
      </geometry>
      <material name="servo_wheel_22_material">
        <color rgba="0.647059 0.647059 0.647059 1"/>
      </material>
    </visual>
    <collision>
      <origin xyz="-1.05471e-15 0 -0.0585" rpy="3.14159 -1.89304e-14 -3.14159"/>
      <geometry>
        <mesh filename="package://meshes\servo_wheel.stl"/>
      </geometry>
    </collision>
  </link>
  <!-- Link foot_assembly_4 -->
  <link name="foot_assembly_4">
    <inertial>
      <origin xyz="-0.0724503 -0.00208415 -0.0306672" rpy="0 0 0"/>
      <mass value="0.633745"/>
      <inertia ixx="0.000268495" ixy="-1.4806e-05" ixz="4.28294e-06" iyy="0.00320961" iyz="-2.30165e-07" izz="0.00304658"/>
    </inertial>
    <!-- Part foot_4 -->
    <visual>
      <origin xyz="-0.04425 6.93889e-18 -0.0305" rpy="1.8304e-30 1.5708 0"/>
      <geometry>
        <mesh filename="package://meshes\foot.stl"/>
      </geometry>
      <material name="foot_4_material">
        <color rgba="0.282353 0.54902 0.160784 1"/>
      </material>
    </visual>
    <collision>
      <origin xyz="-0.04425 6.93889e-18 -0.0305" rpy="1.8304e-30 1.5708 0"/>
      <geometry>
        <mesh filename="package://meshes\foot.stl"/>
      </geometry>
    </collision>
    <!-- Part ir_sensor_cap_4 -->
    <visual>
      <origin xyz="-0.04425 1.14492e-16 -0.0305" rpy="-2.3615e-16 1.5708 0"/>
      <geometry>
        <mesh filename="package://meshes\ir_sensor_cap.stl"/>
      </geometry>
      <material name="ir_sensor_cap_4_material">
        <color rgba="0.282353 0.54902 0.160784 1"/>
      </material>
    </visual>
    <collision>
      <origin xyz="-0.04425 1.14492e-16 -0.0305" rpy="-2.3615e-16 1.5708 0"/>
      <geometry>
        <mesh filename="package://meshes\ir_sensor_cap.stl"/>
      </geometry>
    </collision>
    <!-- Part rubber_foot_4 -->
    <visual>
      <origin xyz="-0.04375 1.49533e-15 -0.03" rpy="-7.03592e-15 1.5708 0"/>
      <geometry>
        <mesh filename="package://meshes\rubber_foot.stl"/>
      </geometry>
      <material name="rubber_foot_4_material">
        <color rgba="0.262745 0.282353 0.301961 1"/>
      </material>
    </visual>
    <collision>
      <origin xyz="-0.04375 1.49533e-15 -0.03" rpy="-7.03592e-15 1.5708 0"/>
      <geometry>
        <mesh filename="package://meshes\rubber_foot.stl"/>
      </geometry>
    </collision>
    <!-- Part servo_wheel_23 -->
    <visual>
      <origin xyz="-5.55112e-17 0 -0.0025" rpy="-3.14159 5.32981e-17 4.48048e-30"/>
      <geometry>
        <mesh filename="package://meshes\servo_wheel.stl"/>
      </geometry>
      <material name="servo_wheel_23_material">
        <color rgba="0.647059 0.647059 0.647059 1"/>
      </material>
    </visual>
    <collision>
      <origin xyz="-5.55112e-17 0 -0.0025" rpy="-3.14159 5.32981e-17 4.48048e-30"/>
      <geometry>
        <mesh filename="package://meshes\servo_wheel.stl"/>
      </geometry>
    </collision>
    <!-- Part servo_12 -->
    <visual>
      <origin xyz="-0.0175 -0.00140442 -0.0305" rpy="3.14159 2.89927e-17 1.32504e-30"/>
      <geometry>
        <mesh filename="package://meshes\servo.stl"/>
      </geometry>
      <material name="servo_12_material">
        <color rgba="0.109804 0.109804 0.105882 1"/>
      </material>
    </visual>
    <collision>
      <origin xyz="-0.0175 -0.00140442 -0.0305" rpy="3.14159 2.89927e-17 1.32504e-30"/>
      <geometry>
        <mesh filename="package://meshes\servo.stl"/>
      </geometry>
    </collision>
    <!-- Part fixed_bracket_12 -->
    <visual>
      <origin xyz="-0.0575 6.93889e-18 -0.0305" rpy="1.5708 1.5708 0"/>
      <geometry>
        <mesh filename="package://meshes\fixed_bracket.stl"/>
      </geometry>
      <material name="fixed_bracket_12_material">
        <color rgba="0.647059 0.647059 0.647059 1"/>
      </material>
    </visual>
    <collision>
      <origin xyz="-0.0575 6.93889e-18 -0.0305" rpy="1.5708 1.5708 0"/>
      <geometry>
        <mesh filename="package://meshes\fixed_bracket.stl"/>
      </geometry>
    </collision>
    <!-- Part servo_wheel_24 -->
    <visual>
      <origin xyz="-5.55112e-17 0 -0.0585" rpy="-3.14159 4.10941e-17 1.32504e-30"/>
      <geometry>
        <mesh filename="package://meshes\servo_wheel.stl"/>
      </geometry>
      <material name="servo_wheel_24_material">
        <color rgba="0.647059 0.647059 0.647059 1"/>
      </material>
    </visual>
    <collision>
      <origin xyz="-5.55112e-17 0 -0.0585" rpy="-3.14159 4.10941e-17 1.32504e-30"/>
      <geometry>
        <mesh filename="package://meshes\servo_wheel.stl"/>
      </geometry>
    </collision>
  </link>
  <!-- Joint from ties_assembly_4 to foot_assembly_4 -->
  <joint name="foot_4" type="revolute">
    <origin xyz="0.1918 0.000210323 -0.000790548" rpy="-1.34033e-15 3.08383e-16 -3.14159"/>
    <parent link="ties_assembly_4"/>
    <child link="foot_assembly_4"/>
    <axis xyz="0 0 1"/>
    <limit effort="10" velocity="10" lower="-2.0944" upper="2.0944"/>
  </joint>
  <!-- Joint from hip_assembly_4 to ties_assembly_4 -->
  <joint name="ties_4" type="revolute">
    <origin xyz="0.0925 -0.0311167 -0.0305" rpy="1.5708 6.76543e-16 2.49947e-12"/>
    <parent link="hip_assembly_4"/>
    <child link="ties_assembly_4"/>
    <axis xyz="0 0 1"/>
    <limit effort="10" velocity="10" lower="-1.74533" upper="1.74533"/>
  </joint>
  <!-- Joint from base_link to hip_assembly_4 -->
  <joint name="hip_4" type="revolute">
    <origin xyz="-0.137228 -0.0604678 0.0142242" rpy="2.50355e-14 2.47371e-14 -2.70526"/>
    <parent link="base_link"/>
    <child link="hip_assembly_4"/>
    <axis xyz="0 0 1"/>
    <limit effort="10" velocity="10" lower="-1.5708" upper="1.5708"/>
  </joint>
  <!-- Link hip_assembly_5 -->
  <link name="hip_assembly_5">
    <inertial>
      <origin xyz="0.0268487 0.000325484 -0.0302141" rpy="0 0 0"/>
      <mass value="0.365356"/>
      <inertia ixx="0.000168136" ixy="-2.8417e-07" ixz="-3.2467e-06" iyy="0.000312332" iyz="9.42575e-07" izz="0.000312341"/>
    </inertial>
    <!-- Part hip_5 -->
    <visual>
      <origin xyz="0.0575 0.0005 -0.0045" rpy="1.42399e-14 -5.4278e-16 -3.14159"/>
      <geometry>
        <mesh filename="package://meshes\hip.stl"/>
      </geometry>
      <material name="hip_5_material">
        <color rgba="0.282353 0.54902 0.160784 1"/>
      </material>
    </visual>
    <collision>
      <origin xyz="0.0575 0.0005 -0.0045" rpy="1.42399e-14 -5.4278e-16 -3.14159"/>
      <geometry>
        <mesh filename="package://meshes\hip.stl"/>
      </geometry>
    </collision>
    <!-- Part mobile_bracket_15 -->
    <visual>
      <origin xyz="0.0575 1.43449e-13 -0.0305" rpy="-5.4278e-16 -6.10986e-15 -1.5708"/>
      <geometry>
        <mesh filename="package://meshes\mobile_bracket.stl"/>
      </geometry>
      <material name="mobile_bracket_15_material">
        <color rgba="0.647059 0.647059 0.647059 1"/>
      </material>
    </visual>
    <collision>
      <origin xyz="0.0575 1.43449e-13 -0.0305" rpy="-5.4278e-16 -6.10986e-15 -1.5708"/>
      <geometry>
        <mesh filename="package://meshes\mobile_bracket.stl"/>
      </geometry>
    </collision>
    <!-- Part servo_wheel_25 -->
    <visual>
      <origin xyz="-2.77556e-17 1.73472e-18 -0.0025" rpy="-3.14159 -5.4278e-16 -3.14159"/>
      <geometry>
        <mesh filename="package://meshes\servo_wheel.stl"/>
      </geometry>
      <material name="servo_wheel_25_material">
        <color rgba="0.647059 0.647059 0.647059 1"/>
      </material>
    </visual>
    <collision>
      <origin xyz="-2.77556e-17 1.73472e-18 -0.0025" rpy="-3.14159 -5.4278e-16 -3.14159"/>
      <geometry>
        <mesh filename="package://meshes\servo_wheel.stl"/>
      </geometry>
    </collision>
    <!-- Part servo_13 -->
    <visual>
      <origin xyz="0.0175 0.00140442 -0.0305" rpy="-3.14159 -5.4278e-16 -3.14159"/>
      <geometry>
        <mesh filename="package://meshes\servo.stl"/>
      </geometry>
      <material name="servo_13_material">
        <color rgba="0.109804 0.109804 0.105882 1"/>
      </material>
    </visual>
    <collision>
      <origin xyz="0.0175 0.00140442 -0.0305" rpy="-3.14159 -5.4278e-16 -3.14159"/>
      <geometry>
        <mesh filename="package://meshes\servo.stl"/>
      </geometry>
    </collision>
    <!-- Part fixed_bracket_13 -->
    <visual>
      <origin xyz="0.0575 1.43449e-13 -0.0305" rpy="-1.5708 1.5708 0"/>
      <geometry>
        <mesh filename="package://meshes\fixed_bracket.stl"/>
      </geometry>
      <material name="fixed_bracket_13_material">
        <color rgba="0.647059 0.647059 0.647059 1"/>
      </material>
    </visual>
    <collision>
      <origin xyz="0.0575 1.43449e-13 -0.0305" rpy="-1.5708 1.5708 0"/>
      <geometry>
        <mesh filename="package://meshes\fixed_bracket.stl"/>
      </geometry>
    </collision>
    <!-- Part servo_wheel_26 -->
    <visual>
      <origin xyz="-1.94289e-16 -9.54098e-18 -0.0585" rpy="-3.14159 -5.4278e-16 -3.14159"/>
      <geometry>
        <mesh filename="package://meshes\servo_wheel.stl"/>
      </geometry>
      <material name="servo_wheel_26_material">
        <color rgba="0.647059 0.647059 0.647059 1"/>
      </material>
    </visual>
    <collision>
      <origin xyz="-1.94289e-16 -9.54098e-18 -0.0585" rpy="-3.14159 -5.4278e-16 -3.14159"/>
      <geometry>
        <mesh filename="package://meshes\servo_wheel.stl"/>
      </geometry>
    </collision>
  </link>
  <!-- Link ties_assembly_5 -->
  <link name="ties_assembly_5">
    <inertial>
      <origin xyz="0.0643598 0.00153088 -0.0309357" rpy="0 0 0"/>
      <mass value="0.589115"/>
      <inertia ixx="0.000320336" ixy="-2.41497e-05" ixz="1.07866e-05" iyy="0.00208685" iyz="2.0947e-07" izz="0.00187002"/>
    </inertial>
    <!-- Part mobile_bracket_16 -->
    <visual>
      <origin xyz="0.1568 0.000210323 -0.0311738" rpy="1.5708 1.5708 0"/>
      <geometry>
        <mesh filename="package://meshes\mobile_bracket.stl"/>
      </geometry>
      <material name="mobile_bracket_16_material">
        <color rgba="0.647059 0.647059 0.647059 1"/>
      </material>
    </visual>
    <collision>
      <origin xyz="0.1568 0.000210323 -0.0311738" rpy="1.5708 1.5708 0"/>
      <geometry>
        <mesh filename="package://meshes\mobile_bracket.stl"/>
      </geometry>
    </collision>
    <!-- Part low_tie_5 -->
    <visual>
      <origin xyz="0.0268 0.000210323 -0.0311738" rpy="-1.37527e-15 1.5708 0"/>
      <geometry>
        <mesh filename="package://meshes\low_tie.stl"/>
      </geometry>
      <material name="low_tie_5_material">
        <color rgba="0.282353 0.54902 0.160784 1"/>
      </material>
    </visual>
    <collision>
      <origin xyz="0.0268 0.000210323 -0.0311738" rpy="-1.37527e-15 1.5708 0"/>
      <geometry>
        <mesh filename="package://meshes\low_tie.stl"/>
      </geometry>
    </collision>
    <!-- Part top_tie_5 -->
    <visual>
      <origin xyz="0.0275 2.77556e-17 -0.0305" rpy="-1.37527e-15 1.5708 0"/>
      <geometry>
        <mesh filename="package://meshes\top_tie.stl"/>
      </geometry>
      <material name="top_tie_5_material">
        <color rgba="0.282353 0.54902 0.160784 1"/>
      </material>
    </visual>
    <collision>
      <origin xyz="0.0275 2.77556e-17 -0.0305" rpy="-1.37527e-15 1.5708 0"/>
      <geometry>
        <mesh filename="package://meshes\top_tie.stl"/>
      </geometry>
    </collision>
    <!-- Part servo_wheel_27 -->
    <visual>
      <origin xyz="5.55112e-17 -3.46945e-18 -0.0025" rpy="3.14159 8.06031e-14 -3.14159"/>
      <geometry>
        <mesh filename="package://meshes\servo_wheel.stl"/>
      </geometry>
      <material name="servo_wheel_27_material">
        <color rgba="0.647059 0.647059 0.647059 1"/>
      </material>
    </visual>
    <collision>
      <origin xyz="5.55112e-17 -3.46945e-18 -0.0025" rpy="3.14159 8.06031e-14 -3.14159"/>
      <geometry>
        <mesh filename="package://meshes\servo_wheel.stl"/>
      </geometry>
    </collision>
    <!-- Part servo_14 -->
    <visual>
      <origin xyz="0.0175 0.00140442 -0.0305" rpy="3.14159 8.057e-14 -3.14159"/>
      <geometry>
        <mesh filename="package://meshes\servo.stl"/>
      </geometry>
      <material name="servo_14_material">
        <color rgba="0.109804 0.109804 0.105882 1"/>
      </material>
    </visual>
    <collision>
      <origin xyz="0.0175 0.00140442 -0.0305" rpy="3.14159 8.057e-14 -3.14159"/>
      <geometry>
        <mesh filename="package://meshes\servo.stl"/>
      </geometry>
    </collision>
    <!-- Part fixed_bracket_14 -->
    <visual>
      <origin xyz="0.0575 6.93889e-17 -0.0305" rpy="-1.5708 1.5708 0"/>
      <geometry>
        <mesh filename="package://meshes\fixed_bracket.stl"/>
      </geometry>
      <material name="fixed_bracket_14_material">
        <color rgba="0.647059 0.647059 0.647059 1"/>
      </material>
    </visual>
    <collision>
      <origin xyz="0.0575 6.93889e-17 -0.0305" rpy="-1.5708 1.5708 0"/>
      <geometry>
        <mesh filename="package://meshes\fixed_bracket.stl"/>
      </geometry>
    </collision>
    <!-- Part servo_wheel_28 -->
    <visual>
      <origin xyz="4.27436e-15 -6.93889e-18 -0.0585" rpy="3.14159 8.07177e-14 -3.14159"/>
      <geometry>
        <mesh filename="package://meshes\servo_wheel.stl"/>
      </geometry>
      <material name="servo_wheel_28_material">
        <color rgba="0.647059 0.647059 0.647059 1"/>
      </material>
    </visual>
    <collision>
      <origin xyz="4.27436e-15 -6.93889e-18 -0.0585" rpy="3.14159 8.07177e-14 -3.14159"/>
      <geometry>
        <mesh filename="package://meshes\servo_wheel.stl"/>
      </geometry>
    </collision>
  </link>
  <!-- Link foot_assembly_5 -->
  <link name="foot_assembly_5">
    <inertial>
      <origin xyz="-0.0724503 -0.00208415 -0.0306672" rpy="0 0 0"/>
      <mass value="0.633745"/>
      <inertia ixx="0.000268495" ixy="-1.4806e-05" ixz="4.28294e-06" iyy="0.00320961" iyz="-2.30165e-07" izz="0.00304658"/>
    </inertial>
    <!-- Part foot_5 -->
    <visual>
      <origin xyz="-0.04425 1.04083e-17 -0.0305" rpy="-4.1271e-30 1.5708 0"/>
      <geometry>
        <mesh filename="package://meshes\foot.stl"/>
      </geometry>
      <material name="foot_5_material">
        <color rgba="0.282353 0.54902 0.160784 1"/>
      </material>
    </visual>
    <collision>
      <origin xyz="-0.04425 1.04083e-17 -0.0305" rpy="-4.1271e-30 1.5708 0"/>
      <geometry>
        <mesh filename="package://meshes\foot.stl"/>
      </geometry>
    </collision>
    <!-- Part ir_sensor_cap_5 -->
    <visual>
      <origin xyz="-0.04425 -1.97758e-16 -0.0305" rpy="-1.2385e-15 1.5708 0"/>
      <geometry>
        <mesh filename="package://meshes\ir_sensor_cap.stl"/>
      </geometry>
      <material name="ir_sensor_cap_5_material">
        <color rgba="0.282353 0.54902 0.160784 1"/>
      </material>
    </visual>
    <collision>
      <origin xyz="-0.04425 -1.97758e-16 -0.0305" rpy="-1.2385e-15 1.5708 0"/>
      <geometry>
        <mesh filename="package://meshes\ir_sensor_cap.stl"/>
      </geometry>
    </collision>
    <!-- Part rubber_foot_5 -->
    <visual>
      <origin xyz="-0.04375 2.39392e-16 -0.03" rpy="-5.97428e-16 1.5708 0"/>
      <geometry>
        <mesh filename="package://meshes\rubber_foot.stl"/>
      </geometry>
      <material name="rubber_foot_5_material">
        <color rgba="0.262745 0.282353 0.301961 1"/>
      </material>
    </visual>
    <collision>
      <origin xyz="-0.04375 2.39392e-16 -0.03" rpy="-5.97428e-16 1.5708 0"/>
      <geometry>
        <mesh filename="package://meshes\rubber_foot.stl"/>
      </geometry>
    </collision>
    <!-- Part servo_wheel_29 -->
    <visual>
      <origin xyz="1.11022e-16 3.46945e-18 -0.0025" rpy="-3.14159 6.72739e-19 4.1271e-30"/>
      <geometry>
        <mesh filename="package://meshes\servo_wheel.stl"/>
      </geometry>
      <material name="servo_wheel_29_material">
        <color rgba="0.647059 0.647059 0.647059 1"/>
      </material>
    </visual>
    <collision>
      <origin xyz="1.11022e-16 3.46945e-18 -0.0025" rpy="-3.14159 6.72739e-19 4.1271e-30"/>
      <geometry>
        <mesh filename="package://meshes\servo_wheel.stl"/>
      </geometry>
    </collision>
    <!-- Part servo_15 -->
    <visual>
      <origin xyz="-0.0175 -0.00140442 -0.0305" rpy="3.14159 -1.30444e-16 1.0438e-29"/>
      <geometry>
        <mesh filename="package://meshes\servo.stl"/>
      </geometry>
      <material name="servo_15_material">
        <color rgba="0.109804 0.109804 0.105882 1"/>
      </material>
    </visual>
    <collision>
      <origin xyz="-0.0175 -0.00140442 -0.0305" rpy="3.14159 -1.30444e-16 1.0438e-29"/>
      <geometry>
        <mesh filename="package://meshes\servo.stl"/>
      </geometry>
    </collision>
    <!-- Part fixed_bracket_15 -->
    <visual>
      <origin xyz="-0.0575 1.38778e-17 -0.0305" rpy="1.5708 1.5708 0"/>
      <geometry>
        <mesh filename="package://meshes\fixed_bracket.stl"/>
      </geometry>
      <material name="fixed_bracket_15_material">
        <color rgba="0.647059 0.647059 0.647059 1"/>
      </material>
    </visual>
    <collision>
      <origin xyz="-0.0575 1.38778e-17 -0.0305" rpy="1.5708 1.5708 0"/>
      <geometry>
        <mesh filename="package://meshes\fixed_bracket.stl"/>
      </geometry>
    </collision>
    <!-- Part servo_wheel_30 -->
    <visual>
      <origin xyz="-1.83187e-15 6.93889e-18 -0.0585" rpy="3.14159 -5.48546e-17 1.67489e-29"/>
      <geometry>
        <mesh filename="package://meshes\servo_wheel.stl"/>
      </geometry>
      <material name="servo_wheel_30_material">
        <color rgba="0.647059 0.647059 0.647059 1"/>
      </material>
    </visual>
    <collision>
      <origin xyz="-1.83187e-15 6.93889e-18 -0.0585" rpy="3.14159 -5.48546e-17 1.67489e-29"/>
      <geometry>
        <mesh filename="package://meshes\servo_wheel.stl"/>
      </geometry>
    </collision>
  </link>
  <!-- Joint from ties_assembly_5 to foot_assembly_5 -->
  <joint name="foot_5" type="revolute">
    <origin xyz="0.1918 0.000210323 -0.000790548" rpy="3.64523e-14 3.95047e-14 3.14159"/>
    <parent link="ties_assembly_5"/>
    <child link="foot_assembly_5"/>
    <axis xyz="0 0 1"/>
    <limit effort="10" velocity="10" lower="-2.0944" upper="2.0944"/>
  </joint>
  <!-- Joint from hip_assembly_5 to ties_assembly_5 -->
  <joint name="ties_5" type="revolute">
    <origin xyz="0.0925 -0.0311167 -0.0305" rpy="1.5708 5.4278e-16 2.49541e-12"/>
    <parent link="hip_assembly_5"/>
    <child link="ties_assembly_5"/>
    <axis xyz="0 0 1"/>
    <limit effort="10" velocity="10" lower="-1.74533" upper="1.74533"/>
  </joint>
  <!-- Joint from base_link to hip_assembly_5 -->
  <joint name="hip_5" type="revolute">
    <origin xyz="-0.123979 0.0909708 0.0142242" rpy="7.95355e-15 3.42754e-14 2.53073"/>
    <parent link="base_link"/>
    <child link="hip_assembly_5"/>
    <axis xyz="0 0 1"/>
    <limit effort="10" velocity="10" lower="-1.5708" upper="1.5708"/>
  </joint>
  <!-- Link hip_assembly_6 -->
  <link name="hip_assembly_6">
    <inertial>
      <origin xyz="0.0268487 0.000325484 -0.0302141" rpy="0 0 0"/>
      <mass value="0.365356"/>
      <inertia ixx="0.000168136" ixy="-2.8417e-07" ixz="-3.2467e-06" iyy="0.000312332" iyz="9.42575e-07" izz="0.000312341"/>
    </inertial>
    <!-- Part hip_6 -->
    <visual>
      <origin xyz="0.0575 0.0005 -0.0045" rpy="1.10074e-14 -9.78685e-15 -3.14159"/>
      <geometry>
        <mesh filename="package://meshes\hip.stl"/>
      </geometry>
      <material name="hip_6_material">
        <color rgba="0.282353 0.54902 0.160784 1"/>
      </material>
    </visual>
    <collision>
      <origin xyz="0.0575 0.0005 -0.0045" rpy="1.10074e-14 -9.78685e-15 -3.14159"/>
      <geometry>
        <mesh filename="package://meshes\hip.stl"/>
      </geometry>
    </collision>
    <!-- Part mobile_bracket_17 -->
    <visual>
      <origin xyz="0.0575 1.43598e-13 -0.0305" rpy="-7.98949e-15 -1.55507e-14 -1.5708"/>
      <geometry>
        <mesh filename="package://meshes\mobile_bracket.stl"/>
      </geometry>
      <material name="mobile_bracket_17_material">
        <color rgba="0.647059 0.647059 0.647059 1"/>
      </material>
    </visual>
    <collision>
      <origin xyz="0.0575 1.43598e-13 -0.0305" rpy="-7.98949e-15 -1.55507e-14 -1.5708"/>
      <geometry>
        <mesh filename="package://meshes\mobile_bracket.stl"/>
      </geometry>
    </collision>
    <!-- Part servo_wheel_31 -->
    <visual>
      <origin xyz="0 -1.92446e-18 -0.0025" rpy="-3.14159 -9.20409e-15 -3.14159"/>
      <geometry>
        <mesh filename="package://meshes\servo_wheel.stl"/>
      </geometry>
      <material name="servo_wheel_31_material">
        <color rgba="0.647059 0.647059 0.647059 1"/>
      </material>
    </visual>
    <collision>
      <origin xyz="0 -1.92446e-18 -0.0025" rpy="-3.14159 -9.20409e-15 -3.14159"/>
      <geometry>
        <mesh filename="package://meshes\servo_wheel.stl"/>
      </geometry>
    </collision>
    <!-- Part servo_16 -->
    <visual>
      <origin xyz="0.0175 0.00140442 -0.0305" rpy="-3.14159 -8.00272e-15 -3.14159"/>
      <geometry>
        <mesh filename="package://meshes\servo.stl"/>
      </geometry>
      <material name="servo_16_material">
        <color rgba="0.109804 0.109804 0.105882 1"/>
      </material>
    </visual>
    <collision>
      <origin xyz="0.0175 0.00140442 -0.0305" rpy="-3.14159 -8.00272e-15 -3.14159"/>
      <geometry>
        <mesh filename="package://meshes\servo.stl"/>
      </geometry>
    </collision>
    <!-- Part fixed_bracket_16 -->
    <visual>
      <origin xyz="0.0575 1.43598e-13 -0.0305" rpy="-1.5708 1.5708 0"/>
      <geometry>
        <mesh filename="package://meshes\fixed_bracket.stl"/>
      </geometry>
      <material name="fixed_bracket_16_material">
        <color rgba="0.647059 0.647059 0.647059 1"/>
      </material>
    </visual>
    <collision>
      <origin xyz="0.0575 1.43598e-13 -0.0305" rpy="-1.5708 1.5708 0"/>
      <geometry>
        <mesh filename="package://meshes\fixed_bracket.stl"/>
      </geometry>
    </collision>
    <!-- Part servo_wheel_32 -->
    <visual>
      <origin xyz="5.55112e-17 6.88468e-18 -0.0585" rpy="-3.14159 -8.80211e-15 -3.14159"/>
      <geometry>
        <mesh filename="package://meshes\servo_wheel.stl"/>
      </geometry>
      <material name="servo_wheel_32_material">
        <color rgba="0.647059 0.647059 0.647059 1"/>
      </material>
    </visual>
    <collision>
      <origin xyz="5.55112e-17 6.88468e-18 -0.0585" rpy="-3.14159 -8.80211e-15 -3.14159"/>
      <geometry>
        <mesh filename="package://meshes\servo_wheel.stl"/>
      </geometry>
    </collision>
  </link>
  <!-- Link ties_assembly_6 -->
  <link name="ties_assembly_6">
    <inertial>
      <origin xyz="0.0643598 0.00153088 -0.0309357" rpy="0 0 0"/>
      <mass value="0.589115"/>
      <inertia ixx="0.000320336" ixy="-2.41497e-05" ixz="1.07866e-05" iyy="0.00208685" iyz="2.0947e-07" izz="0.00187002"/>
    </inertial>
    <!-- Part mobile_bracket_18 -->
    <visual>
      <origin xyz="0.1568 0.000210323 -0.0311738" rpy="1.5708 1.5708 0"/>
      <geometry>
        <mesh filename="package://meshes\mobile_bracket.stl"/>
      </geometry>
      <material name="mobile_bracket_18_material">
        <color rgba="0.647059 0.647059 0.647059 1"/>
      </material>
    </visual>
    <collision>
      <origin xyz="0.1568 0.000210323 -0.0311738" rpy="1.5708 1.5708 0"/>
      <geometry>
        <mesh filename="package://meshes\mobile_bracket.stl"/>
      </geometry>
    </collision>
    <!-- Part low_tie_6 -->
    <visual>
      <origin xyz="0.0268 0.000210323 -0.0311738" rpy="1.14117e-15 1.5708 0"/>
      <geometry>
        <mesh filename="package://meshes\low_tie.stl"/>
      </geometry>
      <material name="low_tie_6_material">
        <color rgba="0.282353 0.54902 0.160784 1"/>
      </material>
    </visual>
    <collision>
      <origin xyz="0.0268 0.000210323 -0.0311738" rpy="1.14117e-15 1.5708 0"/>
      <geometry>
        <mesh filename="package://meshes\low_tie.stl"/>
      </geometry>
    </collision>
    <!-- Part top_tie_6 -->
    <visual>
      <origin xyz="0.0275 -3.81639e-17 -0.0305" rpy="1.14117e-15 1.5708 0"/>
      <geometry>
        <mesh filename="package://meshes\top_tie.stl"/>
      </geometry>
      <material name="top_tie_6_material">
        <color rgba="0.282353 0.54902 0.160784 1"/>
      </material>
    </visual>
    <collision>
      <origin xyz="0.0275 -3.81639e-17 -0.0305" rpy="1.14117e-15 1.5708 0"/>
      <geometry>
        <mesh filename="package://meshes\top_tie.stl"/>
      </geometry>
    </collision>
    <!-- Part servo_wheel_33 -->
    <visual>
      <origin xyz="2.77556e-17 -3.46945e-18 -0.0025" rpy="-3.14159 -6.82166e-16 3.14159"/>
      <geometry>
        <mesh filename="package://meshes\servo_wheel.stl"/>
      </geometry>
      <material name="servo_wheel_33_material">
        <color rgba="0.647059 0.647059 0.647059 1"/>
      </material>
    </visual>
    <collision>
      <origin xyz="2.77556e-17 -3.46945e-18 -0.0025" rpy="-3.14159 -6.82166e-16 3.14159"/>
      <geometry>
        <mesh filename="package://meshes\servo_wheel.stl"/>
      </geometry>
    </collision>
    <!-- Part servo_17 -->
    <visual>
      <origin xyz="0.0175 0.00140442 -0.0305" rpy="-3.14159 -1.03204e-15 3.14159"/>
      <geometry>
        <mesh filename="package://meshes\servo.stl"/>
      </geometry>
      <material name="servo_17_material">
        <color rgba="0.109804 0.109804 0.105882 1"/>
      </material>
    </visual>
    <collision>
      <origin xyz="0.0175 0.00140442 -0.0305" rpy="-3.14159 -1.03204e-15 3.14159"/>
      <geometry>
        <mesh filename="package://meshes\servo.stl"/>
      </geometry>
    </collision>
    <!-- Part fixed_bracket_17 -->
    <visual>
      <origin xyz="0.0575 -7.28584e-17 -0.0305" rpy="-1.5708 1.5708 0"/>
      <geometry>
        <mesh filename="package://meshes\fixed_bracket.stl"/>
      </geometry>
      <material name="fixed_bracket_17_material">
        <color rgba="0.647059 0.647059 0.647059 1"/>
      </material>
    </visual>
    <collision>
      <origin xyz="0.0575 -7.28584e-17 -0.0305" rpy="-1.5708 1.5708 0"/>
      <geometry>
        <mesh filename="package://meshes\fixed_bracket.stl"/>
      </geometry>
    </collision>
    <!-- Part servo_wheel_34 -->
    <visual>
      <origin xyz="2.77556e-17 3.46945e-18 -0.0585" rpy="-3.14159 -6.65742e-16 3.14159"/>
      <geometry>
        <mesh filename="package://meshes\servo_wheel.stl"/>
      </geometry>
      <material name="servo_wheel_34_material">
        <color rgba="0.647059 0.647059 0.647059 1"/>
      </material>
    </visual>
    <collision>
      <origin xyz="2.77556e-17 3.46945e-18 -0.0585" rpy="-3.14159 -6.65742e-16 3.14159"/>
      <geometry>
        <mesh filename="package://meshes\servo_wheel.stl"/>
      </geometry>
    </collision>
  </link>
  <!-- Link foot_assembly_6 -->
  <link name="foot_assembly_6">
    <inertial>
      <origin xyz="-0.0724503 -0.00208415 -0.0306672" rpy="0 0 0"/>
      <mass value="0.633745"/>
      <inertia ixx="0.000268495" ixy="-1.4806e-05" ixz="4.28294e-06" iyy="0.00320961" iyz="-2.30165e-07" izz="0.00304658"/>
    </inertial>
    <!-- Part foot_6 -->
    <visual>
      <origin xyz="-0.04425 6.93889e-18 -0.0305" rpy="-2.65723e-30 1.5708 0"/>
      <geometry>
        <mesh filename="package://meshes\foot.stl"/>
      </geometry>
      <material name="foot_6_material">
        <color rgba="0.282353 0.54902 0.160784 1"/>
      </material>
    </visual>
    <collision>
      <origin xyz="-0.04425 6.93889e-18 -0.0305" rpy="-2.65723e-30 1.5708 0"/>
      <geometry>
        <mesh filename="package://meshes\foot.stl"/>
      </geometry>
    </collision>
    <!-- Part ir_sensor_cap_6 -->
    <visual>
      <origin xyz="-0.04425 -4.16334e-16 -0.0305" rpy="3.16268e-15 1.5708 0"/>
      <geometry>
        <mesh filename="package://meshes\ir_sensor_cap.stl"/>
      </geometry>
      <material name="ir_sensor_cap_6_material">
        <color rgba="0.282353 0.54902 0.160784 1"/>
      </material>
    </visual>
    <collision>
      <origin xyz="-0.04425 -4.16334e-16 -0.0305" rpy="3.16268e-15 1.5708 0"/>
      <geometry>
        <mesh filename="package://meshes\ir_sensor_cap.stl"/>
      </geometry>
    </collision>
    <!-- Part rubber_foot_6 -->
    <visual>
      <origin xyz="-0.04375 3.60822e-16 -0.03" rpy="-1.61723e-15 1.5708 0"/>
      <geometry>
        <mesh filename="package://meshes\rubber_foot.stl"/>
      </geometry>
      <material name="rubber_foot_6_material">
        <color rgba="0.262745 0.282353 0.301961 1"/>
      </material>
    </visual>
    <collision>
      <origin xyz="-0.04375 3.60822e-16 -0.03" rpy="-1.61723e-15 1.5708 0"/>
      <geometry>
        <mesh filename="package://meshes\rubber_foot.stl"/>
      </geometry>
    </collision>
    <!-- Part servo_wheel_35 -->
    <visual>
      <origin xyz="-5.55112e-17 0 -0.0025" rpy="-3.14159 1.15799e-17 -4.98218e-31"/>
      <geometry>
        <mesh filename="package://meshes\servo_wheel.stl"/>
      </geometry>
      <material name="servo_wheel_35_material">
        <color rgba="0.647059 0.647059 0.647059 1"/>
      </material>
    </visual>
    <collision>
      <origin xyz="-5.55112e-17 0 -0.0025" rpy="-3.14159 1.15799e-17 -4.98218e-31"/>
      <geometry>
        <mesh filename="package://meshes\servo_wheel.stl"/>
      </geometry>
    </collision>
    <!-- Part servo_18 -->
    <visual>
      <origin xyz="-0.0175 -0.00140442 -0.0305" rpy="3.14159 1.60371e-17 -4.98218e-31"/>
      <geometry>
        <mesh filename="package://meshes\servo.stl"/>
      </geometry>
      <material name="servo_18_material">
        <color rgba="0.109804 0.109804 0.105882 1"/>
      </material>
    </visual>
    <collision>
      <origin xyz="-0.0175 -0.00140442 -0.0305" rpy="3.14159 1.60371e-17 -4.98218e-31"/>
      <geometry>
        <mesh filename="package://meshes\servo.stl"/>
      </geometry>
    </collision>
    <!-- Part fixed_bracket_18 -->
    <visual>
      <origin xyz="-0.0575 6.93889e-18 -0.0305" rpy="1.5708 1.5708 0"/>
      <geometry>
        <mesh filename="package://meshes\fixed_bracket.stl"/>
      </geometry>
      <material name="fixed_bracket_18_material">
        <color rgba="0.647059 0.647059 0.647059 1"/>
      </material>
    </visual>
    <collision>
      <origin xyz="-0.0575 6.93889e-18 -0.0305" rpy="1.5708 1.5708 0"/>
      <geometry>
        <mesh filename="package://meshes\fixed_bracket.stl"/>
      </geometry>
    </collision>
    <!-- Part servo_wheel_36 -->
    <visual>
      <origin xyz="1.66533e-16 0 -0.0585" rpy="-3.14159 -7.73986e-15 -2.07594e-30"/>
      <geometry>
        <mesh filename="package://meshes\servo_wheel.stl"/>
      </geometry>
      <material name="servo_wheel_36_material">
        <color rgba="0.647059 0.647059 0.647059 1"/>
      </material>
    </visual>
    <collision>
      <origin xyz="1.66533e-16 0 -0.0585" rpy="-3.14159 -7.73986e-15 -2.07594e-30"/>
      <geometry>
        <mesh filename="package://meshes\servo_wheel.stl"/>
      </geometry>
    </collision>
  </link>
  <!-- Joint from ties_assembly_6 to foot_assembly_6 -->
  <joint name="foot_6" type="revolute">
    <origin xyz="0.1918 0.000210323 -0.000790548" rpy="-1.79782e-15 2.47828e-15 -3.14159"/>
    <parent link="ties_assembly_6"/>
    <child link="foot_assembly_6"/>
    <axis xyz="0 0 1"/>
    <limit effort="10" velocity="10" lower="-2.0944" upper="2.0944"/>
  </joint>
  <!-- Joint from hip_assembly_6 to ties_assembly_6 -->
  <joint name="ties_6" type="revolute">
    <origin xyz="0.0925 -0.0311167 -0.0305" rpy="1.5708 7.98949e-15 2.49698e-12"/>
    <parent link="hip_assembly_6"/>
    <child link="ties_assembly_6"/>
    <axis xyz="0 0 1"/>
    <limit effort="10" velocity="10" lower="-1.74533" upper="1.74533"/>
  </joint>
  <!-- Joint from base_link to hip_assembly_6 -->
  <joint name="hip_6" type="revolute">
    <origin xyz="0.0137956 0.155216 0.0134908" rpy="-1.77288e-14 1.38591e-15 1.48353"/>
    <parent link="base_link"/>
    <child link="hip_assembly_6"/>
    <axis xyz="0 0 1"/>
    <limit effort="10" velocity="10" lower="-1.5708" upper="1.5708"/>
  </joint>
</robot>
