<?xml version="1.0" ?>
<!-- Generated using onshape-to-robot -->
<!-- Onshape https://cad.onshape.com/documents/026f9a33ba6a25a983a9d639/w/b83e0182bd0a887a03df3198/e/e49783848224d44e064e4a49 -->
<sdf version="1.7">
  <model name="simulation">
    <!-- Link base_link -->
    <link name="base_link">
      <inertial>
        <pose>0.00654762 -0.00415149 -0.00150597 0 0 0</pose>
        <mass>2.53676</mass>
        <inertia>
          <ixx>0.0166026</ixx>
          <ixy>0.00018703</ixy>
          <ixz>-2.94423e-05</ixz>
          <iyy>0.0186016</iyy>
          <iyz>-6.25463e-07</iyz>
          <izz>0.0250691</izz>
        </inertia>
      </inertial>
      <pose>0 0 0 0 -0 0</pose>
      <!-- Part mobile_bracket -->
      <visual name="mobile_bracket_visual_mesh_1">
        <pose relative_to="base_link">0.0172411 0.113434 -0.00314611 0.0872665 1.5708 0</pose>
        <geometry>
          <mesh>
            <uri>model://simulation/meshes/mobile_bracket.stl</uri>
          </mesh>
        </geometry>
        <material>
          <ambient>0.647059 0.647059 0.647059 1</ambient>
          <diffuse>0.647059 0.647059 0.647059 1</diffuse>
          <specular>0.1 0.1 0.1 1</specular>
          <emissive>0 0 0 0</emissive>
        </material>
      </visual>
      <collision name="mobile_bracket_collision_mesh_2">
        <pose relative_to="base_link">0.0172411 0.113434 -0.00314611 0.0872665 1.5708 0</pose>
        <geometry>
          <mesh>
            <uri>model://simulation/meshes/mobile_bracket.stl</uri>
          </mesh>
        </geometry>
      </collision>
      <!-- Part ultrasound_sensor -->
      <visual name="ultrasound_sensor_visual_mesh_1">
        <pose relative_to="base_link">-0.0386004 0.0947435 0.0168539 1.29357e-14 -5.29181e-14 0.436332</pose>
        <geometry>
          <mesh>
            <uri>model://simulation/meshes/ultrasound_sensor.stl</uri>
          </mesh>
        </geometry>
        <material>
          <ambient>0.701961 0.701961 0.701961 1</ambient>
          <diffuse>0.701961 0.701961 0.701961 1</diffuse>
          <specular>0.1 0.1 0.1 1</specular>
          <emissive>0 0 0 0</emissive>
        </material>
      </visual>
      <collision name="ultrasound_sensor_collision_mesh_2">
        <pose relative_to="base_link">-0.0386004 0.0947435 0.0168539 1.29357e-14 -5.29181e-14 0.436332</pose>
        <geometry>
          <mesh>
            <uri>model://simulation/meshes/ultrasound_sensor.stl</uri>
          </mesh>
        </geometry>
      </collision>
      <!-- Part ultrasound_sensor_2 -->
      <visual name="ultrasound_sensor_2_visual_mesh_1">
        <pose relative_to="base_link">-0.100547 0.00627507 0.0168539 -3.14159 3.76617e-14 -1.65806</pose>
        <geometry>
          <mesh>
            <uri>model://simulation/meshes/ultrasound_sensor.stl</uri>
          </mesh>
        </geometry>
        <material>
          <ambient>0.701961 0.701961 0.701961 1</ambient>
          <diffuse>0.701961 0.701961 0.701961 1</diffuse>
          <specular>0.1 0.1 0.1 1</specular>
          <emissive>0 0 0 0</emissive>
        </material>
      </visual>
      <collision name="ultrasound_sensor_2_collision_mesh_2">
        <pose relative_to="base_link">-0.100547 0.00627507 0.0168539 -3.14159 3.76617e-14 -1.65806</pose>
        <geometry>
          <mesh>
            <uri>model://simulation/meshes/ultrasound_sensor.stl</uri>
          </mesh>
        </geometry>
      </collision>
      <!-- Part mobile_bracket_2 -->
      <visual name="mobile_bracket_2_visual_mesh_1">
        <pose relative_to="base_link">0.113096 0.0463158 -0.00314611 1.13446 1.5708 0</pose>
        <geometry>
          <mesh>
            <uri>model://simulation/meshes/mobile_bracket.stl</uri>
          </mesh>
        </geometry>
        <material>
          <ambient>0.647059 0.647059 0.647059 1</ambient>
          <diffuse>0.647059 0.647059 0.647059 1</diffuse>
          <specular>0.1 0.1 0.1 1</specular>
          <emissive>0 0 0 0</emissive>
        </material>
      </visual>
      <collision name="mobile_bracket_2_collision_mesh_2">
        <pose relative_to="base_link">0.113096 0.0463158 -0.00314611 1.13446 1.5708 0</pose>
        <geometry>
          <mesh>
            <uri>model://simulation/meshes/mobile_bracket.stl</uri>
          </mesh>
        </geometry>
      </collision>
      <!-- Part camera -->
      <visual name="camera_visual_mesh_1">
        <pose relative_to="base_link">-0.102539 0.00644938 -0.0151461 3.14159 -3.7359e-14 1.48353</pose>
        <geometry>
          <mesh>
            <uri>model://simulation/meshes/camera.stl</uri>
          </mesh>
        </geometry>
        <material>
          <ambient>0.262745 0.282353 0.301961 1</ambient>
          <diffuse>0.262745 0.282353 0.301961 1</diffuse>
          <specular>0.1 0.1 0.1 1</specular>
          <emissive>0 0 0 0</emissive>
        </material>
      </visual>
      <collision name="camera_collision_mesh_2">
        <pose relative_to="base_link">-0.102539 0.00644938 -0.0151461 3.14159 -3.7359e-14 1.48353</pose>
        <geometry>
          <mesh>
            <uri>model://simulation/meshes/camera.stl</uri>
          </mesh>
        </geometry>
      </collision>
      <!-- Part camera_2 -->
      <visual name="camera_2_visual_mesh_1">
        <pose relative_to="base_link">0.116624 -0.0127249 -0.0151461 -3.14159 3.7359e-14 -1.65806</pose>
        <geometry>
          <mesh>
            <uri>model://simulation/meshes/camera.stl</uri>
          </mesh>
        </geometry>
        <material>
          <ambient>0.262745 0.282353 0.301961 1</ambient>
          <diffuse>0.262745 0.282353 0.301961 1</diffuse>
          <specular>0.1 0.1 0.1 1</specular>
          <emissive>0 0 0 0</emissive>
        </material>
      </visual>
      <collision name="camera_2_collision_mesh_2">
        <pose relative_to="base_link">0.116624 -0.0127249 -0.0151461 -3.14159 3.7359e-14 -1.65806</pose>
        <geometry>
          <mesh>
            <uri>model://simulation/meshes/camera.stl</uri>
          </mesh>
        </geometry>
      </collision>
      <!-- Part bottom_cover -->
      <visual name="bottom_cover_visual_mesh_1">
        <pose relative_to="base_link">0.00704236 -0.00313775 -0.0381461 -3.14159 -3.97096e-14 -0.0872665</pose>
        <geometry>
          <mesh>
            <uri>model://simulation/meshes/bottom_cover.stl</uri>
          </mesh>
        </geometry>
        <material>
          <ambient>0.282353 0.54902 0.160784 1</ambient>
          <diffuse>0.282353 0.54902 0.160784 1</diffuse>
          <specular>0.1 0.1 0.1 1</specular>
          <emissive>0 0 0 0</emissive>
        </material>
      </visual>
      <collision name="bottom_cover_collision_mesh_2">
        <pose relative_to="base_link">0.00704236 -0.00313775 -0.0381461 -3.14159 -3.97096e-14 -0.0872665</pose>
        <geometry>
          <mesh>
            <uri>model://simulation/meshes/bottom_cover.stl</uri>
          </mesh>
        </geometry>
      </collision>
      <!-- Part left_speaker -->
      <visual name="left_speaker_visual_mesh_1">
        <pose relative_to="base_link">0.0368168 -0.0669892 0.0323062 1.5708 0.523599 0.436332</pose>
        <geometry>
          <mesh>
            <uri>model://simulation/meshes/left_speaker.stl</uri>
          </mesh>
        </geometry>
        <material>
          <ambient>0.262745 0.282353 0.301961 1</ambient>
          <diffuse>0.262745 0.282353 0.301961 1</diffuse>
          <specular>0.1 0.1 0.1 1</specular>
          <emissive>0 0 0 0</emissive>
        </material>
      </visual>
      <collision name="left_speaker_collision_mesh_2">
        <pose relative_to="base_link">0.0368168 -0.0669892 0.0323062 1.5708 0.523599 0.436332</pose>
        <geometry>
          <mesh>
            <uri>model://simulation/meshes/left_speaker.stl</uri>
          </mesh>
        </geometry>
      </collision>
      <!-- Part body_power -->
      <visual name="body_power_visual_mesh_1">
        <pose relative_to="base_link">0.00704236 -0.00313775 -0.00314611 3.93606e-14 3.76617e-14 -1.65806</pose>
        <geometry>
          <mesh>
            <uri>model://simulation/meshes/body_power.stl</uri>
          </mesh>
        </geometry>
        <material>
          <ambient>0.282353 0.54902 0.160784 1</ambient>
          <diffuse>0.282353 0.54902 0.160784 1</diffuse>
          <specular>0.1 0.1 0.1 1</specular>
          <emissive>0 0 0 0</emissive>
        </material>
      </visual>
      <collision name="body_power_collision_mesh_2">
        <pose relative_to="base_link">0.00704236 -0.00313775 -0.00314611 3.93606e-14 3.76617e-14 -1.65806</pose>
        <geometry>
          <mesh>
            <uri>model://simulation/meshes/body_power.stl</uri>
          </mesh>
        </geometry>
      </collision>
      <!-- Part mobile_bracket_3 -->
      <visual name="mobile_bracket_3_visual_mesh_1">
        <pose relative_to="base_link">0.102897 -0.070256 -0.00314611 -2.18166 -1.5708 0</pose>
        <geometry>
          <mesh>
            <uri>model://simulation/meshes/mobile_bracket.stl</uri>
          </mesh>
        </geometry>
        <material>
          <ambient>0.647059 0.647059 0.647059 1</ambient>
          <diffuse>0.647059 0.647059 0.647059 1</diffuse>
          <specular>0.1 0.1 0.1 1</specular>
          <emissive>0 0 0 0</emissive>
        </material>
      </visual>
      <collision name="mobile_bracket_3_collision_mesh_2">
        <pose relative_to="base_link">0.102897 -0.070256 -0.00314611 -2.18166 -1.5708 0</pose>
        <geometry>
          <mesh>
            <uri>model://simulation/meshes/mobile_bracket.stl</uri>
          </mesh>
        </geometry>
      </collision>
      <!-- Part cover -->
      <visual name="cover_visual_mesh_1">
        <pose relative_to="base_link">0.00704236 -0.00313775 0.0318539 5.29181e-14 1.29357e-14 -1.13446</pose>
        <geometry>
          <mesh>
            <uri>model://simulation/meshes/cover.stl</uri>
          </mesh>
        </geometry>
        <material>
          <ambient>0.282353 0.54902 0.160784 1</ambient>
          <diffuse>0.282353 0.54902 0.160784 1</diffuse>
          <specular>0.1 0.1 0.1 1</specular>
          <emissive>0 0 0 0</emissive>
        </material>
      </visual>
      <collision name="cover_collision_mesh_2">
        <pose relative_to="base_link">0.00704236 -0.00313775 0.0318539 5.29181e-14 1.29357e-14 -1.13446</pose>
        <geometry>
          <mesh>
            <uri>model://simulation/meshes/cover.stl</uri>
          </mesh>
        </geometry>
      </collision>
      <!-- Part mobile_bracket_4 -->
      <visual name="mobile_bracket_4_visual_mesh_1">
        <pose relative_to="base_link">-0.0888124 0.0639805 -0.00314611 -0.959931 1.5708 0</pose>
        <geometry>
          <mesh>
            <uri>model://simulation/meshes/mobile_bracket.stl</uri>
          </mesh>
        </geometry>
        <material>
          <ambient>0.647059 0.647059 0.647059 1</ambient>
          <diffuse>0.647059 0.647059 0.647059 1</diffuse>
          <specular>0.1 0.1 0.1 1</specular>
          <emissive>0 0 0 0</emissive>
        </material>
      </visual>
      <collision name="mobile_bracket_4_collision_mesh_2">
        <pose relative_to="base_link">-0.0888124 0.0639805 -0.00314611 -0.959931 1.5708 0</pose>
        <geometry>
          <mesh>
            <uri>model://simulation/meshes/mobile_bracket.stl</uri>
          </mesh>
        </geometry>
      </collision>
      <!-- Part ultrasound_sensor_3 -->
      <visual name="ultrasound_sensor_3_visual_mesh_1">
        <pose relative_to="base_link">0.0526851 -0.101019 0.0168539 -1.29357e-14 5.29181e-14 -2.70526</pose>
        <geometry>
          <mesh>
            <uri>model://simulation/meshes/ultrasound_sensor.stl</uri>
          </mesh>
        </geometry>
        <material>
          <ambient>0.701961 0.701961 0.701961 1</ambient>
          <diffuse>0.701961 0.701961 0.701961 1</diffuse>
          <specular>0.1 0.1 0.1 1</specular>
          <emissive>0 0 0 0</emissive>
        </material>
      </visual>
      <collision name="ultrasound_sensor_3_collision_mesh_2">
        <pose relative_to="base_link">0.0526851 -0.101019 0.0168539 -1.29357e-14 5.29181e-14 -2.70526</pose>
        <geometry>
          <mesh>
            <uri>model://simulation/meshes/ultrasound_sensor.stl</uri>
          </mesh>
        </geometry>
      </collision>
      <!-- Part mobile_bracket_5 -->
      <visual name="mobile_bracket_5_visual_mesh_1">
        <pose relative_to="base_link">-0.00315634 -0.11971 -0.00314611 3.05433 -1.5708 0</pose>
        <geometry>
          <mesh>
            <uri>model://simulation/meshes/mobile_bracket.stl</uri>
          </mesh>
        </geometry>
        <material>
          <ambient>0.647059 0.647059 0.647059 1</ambient>
          <diffuse>0.647059 0.647059 0.647059 1</diffuse>
          <specular>0.1 0.1 0.1 1</specular>
          <emissive>0 0 0 0</emissive>
        </material>
      </visual>
      <collision name="mobile_bracket_5_collision_mesh_2">
        <pose relative_to="base_link">-0.00315634 -0.11971 -0.00314611 3.05433 -1.5708 0</pose>
        <geometry>
          <mesh>
            <uri>model://simulation/meshes/mobile_bracket.stl</uri>
          </mesh>
        </geometry>
      </collision>
      <!-- Part mobile_bracket_6 -->
      <visual name="mobile_bracket_6_visual_mesh_1">
        <pose relative_to="base_link">-0.0990111 -0.0525913 -0.00314611 2.00713 -1.5708 0</pose>
        <geometry>
          <mesh>
            <uri>model://simulation/meshes/mobile_bracket.stl</uri>
          </mesh>
        </geometry>
        <material>
          <ambient>0.647059 0.647059 0.647059 1</ambient>
          <diffuse>0.647059 0.647059 0.647059 1</diffuse>
          <specular>0.1 0.1 0.1 1</specular>
          <emissive>0 0 0 0</emissive>
        </material>
      </visual>
      <collision name="mobile_bracket_6_collision_mesh_2">
        <pose relative_to="base_link">-0.0990111 -0.0525913 -0.00314611 2.00713 -1.5708 0</pose>
        <geometry>
          <mesh>
            <uri>model://simulation/meshes/mobile_bracket.stl</uri>
          </mesh>
        </geometry>
      </collision>
      <!-- Part body_brain -->
      <visual name="body_brain_visual_mesh_1">
        <pose relative_to="base_link">0.00704236 -0.00313775 -0.00314611 3.97096e-14 3.7359e-14 -1.65806</pose>
        <geometry>
          <mesh>
            <uri>model://simulation/meshes/body_brain.stl</uri>
          </mesh>
        </geometry>
        <material>
          <ambient>0.282353 0.54902 0.160784 1</ambient>
          <diffuse>0.282353 0.54902 0.160784 1</diffuse>
          <specular>0.1 0.1 0.1 1</specular>
          <emissive>0 0 0 0</emissive>
        </material>
      </visual>
      <collision name="body_brain_collision_mesh_2">
        <pose relative_to="base_link">0.00704236 -0.00313775 -0.00314611 3.97096e-14 3.7359e-14 -1.65806</pose>
        <geometry>
          <mesh>
            <uri>model://simulation/meshes/body_brain.stl</uri>
          </mesh>
        </geometry>
      </collision>
      <!-- Part ultrasound_sensor_4 -->
      <visual name="ultrasound_sensor_4_visual_mesh_1">
        <pose relative_to="base_link">0.0689886 0.0853307 0.0168539 3.14159 1.52565e-14 2.53073</pose>
        <geometry>
          <mesh>
            <uri>model://simulation/meshes/ultrasound_sensor.stl</uri>
          </mesh>
        </geometry>
        <material>
          <ambient>0.701961 0.701961 0.701961 1</ambient>
          <diffuse>0.701961 0.701961 0.701961 1</diffuse>
          <specular>0.1 0.1 0.1 1</specular>
          <emissive>0 0 0 0</emissive>
        </material>
      </visual>
      <collision name="ultrasound_sensor_4_collision_mesh_2">
        <pose relative_to="base_link">0.0689886 0.0853307 0.0168539 3.14159 1.52565e-14 2.53073</pose>
        <geometry>
          <mesh>
            <uri>model://simulation/meshes/ultrasound_sensor.stl</uri>
          </mesh>
        </geometry>
      </collision>
      <!-- Part ultrasound_sensor_5 -->
      <visual name="ultrasound_sensor_5_visual_mesh_1">
        <pose relative_to="base_link">0.114631 -0.0125506 0.0168539 3.14159 -3.76617e-14 1.48353</pose>
        <geometry>
          <mesh>
            <uri>model://simulation/meshes/ultrasound_sensor.stl</uri>
          </mesh>
        </geometry>
        <material>
          <ambient>0.701961 0.701961 0.701961 1</ambient>
          <diffuse>0.701961 0.701961 0.701961 1</diffuse>
          <specular>0.1 0.1 0.1 1</specular>
          <emissive>0 0 0 0</emissive>
        </material>
      </visual>
      <collision name="ultrasound_sensor_5_collision_mesh_2">
        <pose relative_to="base_link">0.114631 -0.0125506 0.0168539 3.14159 -3.76617e-14 1.48353</pose>
        <geometry>
          <mesh>
            <uri>model://simulation/meshes/ultrasound_sensor.stl</uri>
          </mesh>
        </geometry>
      </collision>
      <!-- Part left_speaker_2 -->
      <visual name="left_speaker_2_visual_mesh_1">
        <pose relative_to="base_link">0.0474521 0.0545734 0.0323062 1.5708 0.523599 2.53073</pose>
        <geometry>
          <mesh>
            <uri>model://simulation/meshes/left_speaker.stl</uri>
          </mesh>
        </geometry>
        <material>
          <ambient>0.262745 0.282353 0.301961 1</ambient>
          <diffuse>0.262745 0.282353 0.301961 1</diffuse>
          <specular>0.1 0.1 0.1 1</specular>
          <emissive>0 0 0 0</emissive>
        </material>
      </visual>
      <collision name="left_speaker_2_collision_mesh_2">
        <pose relative_to="base_link">0.0474521 0.0545734 0.0323062 1.5708 0.523599 2.53073</pose>
        <geometry>
          <mesh>
            <uri>model://simulation/meshes/left_speaker.stl</uri>
          </mesh>
        </geometry>
      </collision>
      <!-- Part ultrasound_sensor_6 -->
      <visual name="ultrasound_sensor_6_visual_mesh_1">
        <pose relative_to="base_link">-0.0549039 -0.0916062 0.0168539 -3.14159 -1.52565e-14 -0.610865</pose>
        <geometry>
          <mesh>
            <uri>model://simulation/meshes/ultrasound_sensor.stl</uri>
          </mesh>
        </geometry>
        <material>
          <ambient>0.701961 0.701961 0.701961 1</ambient>
          <diffuse>0.701961 0.701961 0.701961 1</diffuse>
          <specular>0.1 0.1 0.1 1</specular>
          <emissive>0 0 0 0</emissive>
        </material>
      </visual>
      <collision name="ultrasound_sensor_6_collision_mesh_2">
        <pose relative_to="base_link">-0.0549039 -0.0916062 0.0168539 -3.14159 -1.52565e-14 -0.610865</pose>
        <geometry>
          <mesh>
            <uri>model://simulation/meshes/ultrasound_sensor.stl</uri>
          </mesh>
        </geometry>
      </collision>
    </link>
    <joint name="base_link_fixed_world" type="fixed">
      <parent>world</parent>
      <child>base_link</child>
    </joint>
    <!-- Link hip_assembly -->
    <link name="hip_assembly">
      <inertial>
        <pose>0.0268487 0.000325484 -0.0302141 0 0 0</pose>
        <mass>0.365356</mass>
        <inertia>
          <ixx>0.000168136</ixx>
          <ixy>-2.8417e-07</ixy>
          <ixz>-3.2467e-06</ixz>
          <iyy>0.000312332</iyy>
          <iyz>9.42575e-07</iyz>
          <izz>0.000312341</izz>
        </inertia>
      </inertial>
      <pose relative_to="hip_1">0 0 0 0 -0 0</pose>
      <!-- Part hip -->
      <visual name="hip_visual_mesh_1">
        <pose relative_to="hip_assembly">0.0575 0.0005 -0.0045 -3.22773e-16 -9.39821e-16 -3.14159</pose>
        <geometry>
          <mesh>
            <uri>model://simulation/meshes/hip.stl</uri>
          </mesh>
        </geometry>
        <material>
          <ambient>0.282353 0.54902 0.160784 1</ambient>
          <diffuse>0.282353 0.54902 0.160784 1</diffuse>
          <specular>0.1 0.1 0.1 1</specular>
          <emissive>0 0 0 0</emissive>
        </material>
      </visual>
      <collision name="hip_collision_mesh_2">
        <pose relative_to="hip_assembly">0.0575 0.0005 -0.0045 -3.22773e-16 -9.39821e-16 -3.14159</pose>
        <geometry>
          <mesh>
            <uri>model://simulation/meshes/hip.stl</uri>
          </mesh>
        </geometry>
      </collision>
      <!-- Part mobile_bracket_7 -->
      <visual name="mobile_bracket_7_visual_mesh_1">
        <pose relative_to="hip_assembly">0.0575 2.84304e-14 -0.0305 -2.34065e-15 -4.32729e-15 -1.5708</pose>
        <geometry>
          <mesh>
            <uri>model://simulation/meshes/mobile_bracket.stl</uri>
          </mesh>
        </geometry>
        <material>
          <ambient>0.647059 0.647059 0.647059 1</ambient>
          <diffuse>0.647059 0.647059 0.647059 1</diffuse>
          <specular>0.1 0.1 0.1 1</specular>
          <emissive>0 0 0 0</emissive>
        </material>
      </visual>
      <collision name="mobile_bracket_7_collision_mesh_2">
        <pose relative_to="hip_assembly">0.0575 2.84304e-14 -0.0305 -2.34065e-15 -4.32729e-15 -1.5708</pose>
        <geometry>
          <mesh>
            <uri>model://simulation/meshes/mobile_bracket.stl</uri>
          </mesh>
        </geometry>
      </collision>
      <!-- Part servo_wheel -->
      <visual name="servo_wheel_visual_mesh_1">
        <pose relative_to="hip_assembly">0 8.67362e-19 -0.0025 3.14159 -9.01655e-16 -3.14159</pose>
        <geometry>
          <mesh>
            <uri>model://simulation/meshes/servo_wheel.stl</uri>
          </mesh>
        </geometry>
        <material>
          <ambient>0.647059 0.647059 0.647059 1</ambient>
          <diffuse>0.647059 0.647059 0.647059 1</diffuse>
          <specular>0.1 0.1 0.1 1</specular>
          <emissive>0 0 0 0</emissive>
        </material>
      </visual>
      <collision name="servo_wheel_collision_mesh_2">
        <pose relative_to="hip_assembly">0 8.67362e-19 -0.0025 3.14159 -9.01655e-16 -3.14159</pose>
        <geometry>
          <mesh>
            <uri>model://simulation/meshes/servo_wheel.stl</uri>
          </mesh>
        </geometry>
      </collision>
      <!-- Part servo -->
      <visual name="servo_visual_mesh_1">
        <pose relative_to="hip_assembly">0.0175 0.00140442 -0.0305 -3.14159 7.27529e-16 -3.14159</pose>
        <geometry>
          <mesh>
            <uri>model://simulation/meshes/servo.stl</uri>
          </mesh>
        </geometry>
        <material>
          <ambient>0.109804 0.109804 0.105882 1</ambient>
          <diffuse>0.109804 0.109804 0.105882 1</diffuse>
          <specular>0.1 0.1 0.1 1</specular>
          <emissive>0 0 0 0</emissive>
        </material>
      </visual>
      <collision name="servo_collision_mesh_2">
        <pose relative_to="hip_assembly">0.0175 0.00140442 -0.0305 -3.14159 7.27529e-16 -3.14159</pose>
        <geometry>
          <mesh>
            <uri>model://simulation/meshes/servo.stl</uri>
          </mesh>
        </geometry>
      </collision>
      <!-- Part fixed_bracket -->
      <visual name="fixed_bracket_visual_mesh_1">
        <pose relative_to="hip_assembly">0.0575 2.84304e-14 -0.0305 -1.5708 1.5708 0</pose>
        <geometry>
          <mesh>
            <uri>model://simulation/meshes/fixed_bracket.stl</uri>
          </mesh>
        </geometry>
        <material>
          <ambient>0.647059 0.647059 0.647059 1</ambient>
          <diffuse>0.647059 0.647059 0.647059 1</diffuse>
          <specular>0.1 0.1 0.1 1</specular>
          <emissive>0 0 0 0</emissive>
        </material>
      </visual>
      <collision name="fixed_bracket_collision_mesh_2">
        <pose relative_to="hip_assembly">0.0575 2.84304e-14 -0.0305 -1.5708 1.5708 0</pose>
        <geometry>
          <mesh>
            <uri>model://simulation/meshes/fixed_bracket.stl</uri>
          </mesh>
        </geometry>
      </collision>
      <!-- Part servo_wheel_2 -->
      <visual name="servo_wheel_2_visual_mesh_1">
        <pose relative_to="hip_assembly">-2.77556e-17 8.67362e-19 -0.0585 -3.14159 -8.74456e-16 -3.14159</pose>
        <geometry>
          <mesh>
            <uri>model://simulation/meshes/servo_wheel.stl</uri>
          </mesh>
        </geometry>
        <material>
          <ambient>0.647059 0.647059 0.647059 1</ambient>
          <diffuse>0.647059 0.647059 0.647059 1</diffuse>
          <specular>0.1 0.1 0.1 1</specular>
          <emissive>0 0 0 0</emissive>
        </material>
      </visual>
      <collision name="servo_wheel_2_collision_mesh_2">
        <pose relative_to="hip_assembly">-2.77556e-17 8.67362e-19 -0.0585 -3.14159 -8.74456e-16 -3.14159</pose>
        <geometry>
          <mesh>
            <uri>model://simulation/meshes/servo_wheel.stl</uri>
          </mesh>
        </geometry>
      </collision>
    </link>
    <!-- Link ties_assembly -->
    <link name="ties_assembly">
      <inertial>
        <pose>0.0643598 0.00153088 -0.0309357 0 0 0</pose>
        <mass>0.589115</mass>
        <inertia>
          <ixx>0.000320336</ixx>
          <ixy>-2.41497e-05</ixy>
          <ixz>1.07866e-05</ixz>
          <iyy>0.00208685</iyy>
          <iyz>2.0947e-07</iyz>
          <izz>0.00187002</izz>
        </inertia>
      </inertial>
      <pose relative_to="ties_1">0 0 0 0 -0 0</pose>
      <!-- Part mobile_bracket_8 -->
      <visual name="mobile_bracket_8_visual_mesh_1">
        <pose relative_to="ties_assembly">0.1568 0.000210323 -0.0311738 1.5708 1.5708 0</pose>
        <geometry>
          <mesh>
            <uri>model://simulation/meshes/mobile_bracket.stl</uri>
          </mesh>
        </geometry>
        <material>
          <ambient>0.647059 0.647059 0.647059 1</ambient>
          <diffuse>0.647059 0.647059 0.647059 1</diffuse>
          <specular>0.1 0.1 0.1 1</specular>
          <emissive>0 0 0 0</emissive>
        </material>
      </visual>
      <collision name="mobile_bracket_8_collision_mesh_2">
        <pose relative_to="ties_assembly">0.1568 0.000210323 -0.0311738 1.5708 1.5708 0</pose>
        <geometry>
          <mesh>
            <uri>model://simulation/meshes/mobile_bracket.stl</uri>
          </mesh>
        </geometry>
      </collision>
      <!-- Part low_tie -->
      <visual name="low_tie_visual_mesh_1">
        <pose relative_to="ties_assembly">0.0268 0.000210323 -0.0311738 -4.80911e-16 1.5708 0</pose>
        <geometry>
          <mesh>
            <uri>model://simulation/meshes/low_tie.stl</uri>
          </mesh>
        </geometry>
        <material>
          <ambient>0.282353 0.54902 0.160784 1</ambient>
          <diffuse>0.282353 0.54902 0.160784 1</diffuse>
          <specular>0.1 0.1 0.1 1</specular>
          <emissive>0 0 0 0</emissive>
        </material>
      </visual>
      <collision name="low_tie_collision_mesh_2">
        <pose relative_to="ties_assembly">0.0268 0.000210323 -0.0311738 -4.80911e-16 1.5708 0</pose>
        <geometry>
          <mesh>
            <uri>model://simulation/meshes/low_tie.stl</uri>
          </mesh>
        </geometry>
      </collision>
      <!-- Part top_tie -->
      <visual name="top_tie_visual_mesh_1">
        <pose relative_to="ties_assembly">0.0275 -2.42861e-17 -0.0305 -4.80911e-16 1.5708 0</pose>
        <geometry>
          <mesh>
            <uri>model://simulation/meshes/top_tie.stl</uri>
          </mesh>
        </geometry>
        <material>
          <ambient>0.282353 0.54902 0.160784 1</ambient>
          <diffuse>0.282353 0.54902 0.160784 1</diffuse>
          <specular>0.1 0.1 0.1 1</specular>
          <emissive>0 0 0 0</emissive>
        </material>
      </visual>
      <collision name="top_tie_collision_mesh_2">
        <pose relative_to="ties_assembly">0.0275 -2.42861e-17 -0.0305 -4.80911e-16 1.5708 0</pose>
        <geometry>
          <mesh>
            <uri>model://simulation/meshes/top_tie.stl</uri>
          </mesh>
        </geometry>
      </collision>
      <!-- Part servo_wheel_3 -->
      <visual name="servo_wheel_3_visual_mesh_1">
        <pose relative_to="ties_assembly">2.77556e-17 -4.33681e-19 -0.0025 3.14159 -1.72342e-15 3.14159</pose>
        <geometry>
          <mesh>
            <uri>model://simulation/meshes/servo_wheel.stl</uri>
          </mesh>
        </geometry>
        <material>
          <ambient>0.647059 0.647059 0.647059 1</ambient>
          <diffuse>0.647059 0.647059 0.647059 1</diffuse>
          <specular>0.1 0.1 0.1 1</specular>
          <emissive>0 0 0 0</emissive>
        </material>
      </visual>
      <collision name="servo_wheel_3_collision_mesh_2">
        <pose relative_to="ties_assembly">2.77556e-17 -4.33681e-19 -0.0025 3.14159 -1.72342e-15 3.14159</pose>
        <geometry>
          <mesh>
            <uri>model://simulation/meshes/servo_wheel.stl</uri>
          </mesh>
        </geometry>
      </collision>
      <!-- Part servo_2 -->
      <visual name="servo_2_visual_mesh_1">
        <pose relative_to="ties_assembly">0.0175 0.00140442 -0.0305 -3.14159 -1.71247e-15 3.14159</pose>
        <geometry>
          <mesh>
            <uri>model://simulation/meshes/servo.stl</uri>
          </mesh>
        </geometry>
        <material>
          <ambient>0.109804 0.109804 0.105882 1</ambient>
          <diffuse>0.109804 0.109804 0.105882 1</diffuse>
          <specular>0.1 0.1 0.1 1</specular>
          <emissive>0 0 0 0</emissive>
        </material>
      </visual>
      <collision name="servo_2_collision_mesh_2">
        <pose relative_to="ties_assembly">0.0175 0.00140442 -0.0305 -3.14159 -1.71247e-15 3.14159</pose>
        <geometry>
          <mesh>
            <uri>model://simulation/meshes/servo.stl</uri>
          </mesh>
        </geometry>
      </collision>
      <!-- Part fixed_bracket_2 -->
      <visual name="fixed_bracket_2_visual_mesh_1">
        <pose relative_to="ties_assembly">0.0575 -1.0842e-17 -0.0305 -1.5708 1.5708 0</pose>
        <geometry>
          <mesh>
            <uri>model://simulation/meshes/fixed_bracket.stl</uri>
          </mesh>
        </geometry>
        <material>
          <ambient>0.647059 0.647059 0.647059 1</ambient>
          <diffuse>0.647059 0.647059 0.647059 1</diffuse>
          <specular>0.1 0.1 0.1 1</specular>
          <emissive>0 0 0 0</emissive>
        </material>
      </visual>
      <collision name="fixed_bracket_2_collision_mesh_2">
        <pose relative_to="ties_assembly">0.0575 -1.0842e-17 -0.0305 -1.5708 1.5708 0</pose>
        <geometry>
          <mesh>
            <uri>model://simulation/meshes/fixed_bracket.stl</uri>
          </mesh>
        </geometry>
      </collision>
      <!-- Part servo_wheel_4 -->
      <visual name="servo_wheel_4_visual_mesh_1">
        <pose relative_to="ties_assembly">-5.55112e-17 -8.67362e-19 -0.0585 3.14159 -1.50558e-15 3.14159</pose>
        <geometry>
          <mesh>
            <uri>model://simulation/meshes/servo_wheel.stl</uri>
          </mesh>
        </geometry>
        <material>
          <ambient>0.647059 0.647059 0.647059 1</ambient>
          <diffuse>0.647059 0.647059 0.647059 1</diffuse>
          <specular>0.1 0.1 0.1 1</specular>
          <emissive>0 0 0 0</emissive>
        </material>
      </visual>
      <collision name="servo_wheel_4_collision_mesh_2">
        <pose relative_to="ties_assembly">-5.55112e-17 -8.67362e-19 -0.0585 3.14159 -1.50558e-15 3.14159</pose>
        <geometry>
          <mesh>
            <uri>model://simulation/meshes/servo_wheel.stl</uri>
          </mesh>
        </geometry>
      </collision>
    </link>
    <!-- Link foot_assembly -->
    <link name="foot_assembly">
      <inertial>
        <pose>-0.0724503 -0.00208415 -0.0306672 0 0 0</pose>
        <mass>0.633745</mass>
        <inertia>
          <ixx>0.000268495</ixx>
          <ixy>-1.4806e-05</ixy>
          <ixz>4.28294e-06</ixz>
          <iyy>0.00320961</iyy>
          <iyz>-2.30165e-07</iyz>
          <izz>0.00304658</izz>
        </inertia>
      </inertial>
      <pose relative_to="foot_1">0 0 0 0 -0 0</pose>
      <!-- Part foot -->
      <visual name="foot_visual_mesh_1">
        <pose relative_to="foot_assembly">-0.04425 7.37257e-18 -0.0305 -1.11022e-16 1.5708 0</pose>
        <geometry>
          <mesh>
            <uri>model://simulation/meshes/foot.stl</uri>
          </mesh>
        </geometry>
        <material>
          <ambient>0.282353 0.54902 0.160784 1</ambient>
          <diffuse>0.282353 0.54902 0.160784 1</diffuse>
          <specular>0.1 0.1 0.1 1</specular>
          <emissive>0 0 0 0</emissive>
        </material>
      </visual>
      <collision name="foot_collision_mesh_2">
        <pose relative_to="foot_assembly">-0.04425 7.37257e-18 -0.0305 -1.11022e-16 1.5708 0</pose>
        <geometry>
          <mesh>
            <uri>model://simulation/meshes/foot.stl</uri>
          </mesh>
        </geometry>
      </collision>
      <!-- Part ir_sensor_cap -->
      <visual name="ir_sensor_cap_visual_mesh_1">
        <pose relative_to="foot_assembly">-0.04425 -2.19876e-16 -0.0305 1.22125e-15 1.5708 0</pose>
        <geometry>
          <mesh>
            <uri>model://simulation/meshes/ir_sensor_cap.stl</uri>
          </mesh>
        </geometry>
        <material>
          <ambient>0.282353 0.54902 0.160784 1</ambient>
          <diffuse>0.282353 0.54902 0.160784 1</diffuse>
          <specular>0.1 0.1 0.1 1</specular>
          <emissive>0 0 0 0</emissive>
        </material>
      </visual>
      <collision name="ir_sensor_cap_collision_mesh_2">
        <pose relative_to="foot_assembly">-0.04425 -2.19876e-16 -0.0305 1.22125e-15 1.5708 0</pose>
        <geometry>
          <mesh>
            <uri>model://simulation/meshes/ir_sensor_cap.stl</uri>
          </mesh>
        </geometry>
      </collision>
      <!-- Part rubber_foot -->
      <visual name="rubber_foot_visual_mesh_1">
        <pose relative_to="foot_assembly">-0.04375 -2.75821e-16 -0.03 1.22346e-15 1.5708 0</pose>
        <geometry>
          <mesh>
            <uri>model://simulation/meshes/rubber_foot.stl</uri>
          </mesh>
        </geometry>
        <material>
          <ambient>0.262745 0.282353 0.301961 1</ambient>
          <diffuse>0.262745 0.282353 0.301961 1</diffuse>
          <specular>0.1 0.1 0.1 1</specular>
          <emissive>0 0 0 0</emissive>
        </material>
      </visual>
      <collision name="rubber_foot_collision_mesh_2">
        <pose relative_to="foot_assembly">-0.04375 -2.75821e-16 -0.03 1.22346e-15 1.5708 0</pose>
        <geometry>
          <mesh>
            <uri>model://simulation/meshes/rubber_foot.stl</uri>
          </mesh>
        </geometry>
      </collision>
      <!-- Part servo_wheel_5 -->
      <visual name="servo_wheel_5_visual_mesh_1">
        <pose relative_to="foot_assembly">0 0 -0.0025 -3.14159 4.18455e-18 4.19082e-31</pose>
        <geometry>
          <mesh>
            <uri>model://simulation/meshes/servo_wheel.stl</uri>
          </mesh>
        </geometry>
        <material>
          <ambient>0.647059 0.647059 0.647059 1</ambient>
          <diffuse>0.647059 0.647059 0.647059 1</diffuse>
          <specular>0.1 0.1 0.1 1</specular>
          <emissive>0 0 0 0</emissive>
        </material>
      </visual>
      <collision name="servo_wheel_5_collision_mesh_2">
        <pose relative_to="foot_assembly">0 0 -0.0025 -3.14159 4.18455e-18 4.19082e-31</pose>
        <geometry>
          <mesh>
            <uri>model://simulation/meshes/servo_wheel.stl</uri>
          </mesh>
        </geometry>
      </collision>
      <!-- Part servo_3 -->
      <visual name="servo_3_visual_mesh_1">
        <pose relative_to="foot_assembly">-0.0175 -0.00140442 -0.0305 3.14159 3.29613e-16 -2.22045e-16</pose>
        <geometry>
          <mesh>
            <uri>model://simulation/meshes/servo.stl</uri>
          </mesh>
        </geometry>
        <material>
          <ambient>0.109804 0.109804 0.105882 1</ambient>
          <diffuse>0.109804 0.109804 0.105882 1</diffuse>
          <specular>0.1 0.1 0.1 1</specular>
          <emissive>0 0 0 0</emissive>
        </material>
      </visual>
      <collision name="servo_3_collision_mesh_2">
        <pose relative_to="foot_assembly">-0.0175 -0.00140442 -0.0305 3.14159 3.29613e-16 -2.22045e-16</pose>
        <geometry>
          <mesh>
            <uri>model://simulation/meshes/servo.stl</uri>
          </mesh>
        </geometry>
      </collision>
      <!-- Part fixed_bracket_3 -->
      <visual name="fixed_bracket_3_visual_mesh_1">
        <pose relative_to="foot_assembly">-0.0575 6.50521e-18 -0.0305 1.5708 1.5708 0</pose>
        <geometry>
          <mesh>
            <uri>model://simulation/meshes/fixed_bracket.stl</uri>
          </mesh>
        </geometry>
        <material>
          <ambient>0.647059 0.647059 0.647059 1</ambient>
          <diffuse>0.647059 0.647059 0.647059 1</diffuse>
          <specular>0.1 0.1 0.1 1</specular>
          <emissive>0 0 0 0</emissive>
        </material>
      </visual>
      <collision name="fixed_bracket_3_collision_mesh_2">
        <pose relative_to="foot_assembly">-0.0575 6.50521e-18 -0.0305 1.5708 1.5708 0</pose>
        <geometry>
          <mesh>
            <uri>model://simulation/meshes/fixed_bracket.stl</uri>
          </mesh>
        </geometry>
      </collision>
      <!-- Part servo_wheel_6 -->
      <visual name="servo_wheel_6_visual_mesh_1">
        <pose relative_to="foot_assembly">1.11022e-16 -1.43115e-17 -0.0585 3.14159 6.47147e-16 -5.55112e-17</pose>
        <geometry>
          <mesh>
            <uri>model://simulation/meshes/servo_wheel.stl</uri>
          </mesh>
        </geometry>
        <material>
          <ambient>0.647059 0.647059 0.647059 1</ambient>
          <diffuse>0.647059 0.647059 0.647059 1</diffuse>
          <specular>0.1 0.1 0.1 1</specular>
          <emissive>0 0 0 0</emissive>
        </material>
      </visual>
      <collision name="servo_wheel_6_collision_mesh_2">
        <pose relative_to="foot_assembly">1.11022e-16 -1.43115e-17 -0.0585 3.14159 6.47147e-16 -5.55112e-17</pose>
        <geometry>
          <mesh>
            <uri>model://simulation/meshes/servo_wheel.stl</uri>
          </mesh>
        </geometry>
      </collision>
    </link>
    <!-- Joint from ties_assembly to foot_assembly -->
    <joint name="foot_1" type="revolute">
      <pose relative_to="ties_assembly">0.1918 0.000210323 -0.000790548 -2.10829e-15 -2.78793e-15 -3.14159</pose>
      <parent>ties_assembly</parent>
      <child>foot_assembly</child>
      <axis>
        <xyz>0 0 1</xyz>
        <limit>
          <effort>10</effort>
          <velocity>10</velocity>
          <lower>-2.0943951023931944</lower>
          <upper>2.094395102393196</upper>
        </limit>
        <dynamics>
          <friction>0.0</friction>
          <damping>0.0</damping>
        </dynamics>
      </axis>
    </joint>
    <!-- Joint from hip_assembly to ties_assembly -->
    <joint name="ties_1" type="revolute">
      <pose relative_to="hip_assembly">0.0925 -0.0311167 -0.0305 1.5708 2.34065e-15 4.95281e-13</pose>
      <parent>hip_assembly</parent>
      <child>ties_assembly</child>
      <axis>
        <xyz>0 0 1</xyz>
        <limit>
          <effort>10</effort>
          <velocity>10</velocity>
          <lower>-1.7453292519943313</lower>
          <upper>1.7453292519943278</upper>
        </limit>
        <dynamics>
          <friction>0.0</friction>
          <damping>0.0</damping>
        </dynamics>
      </axis>
    </joint>
    <!-- Joint from base_link to hip_assembly -->
    <joint name="hip_1" type="revolute">
      <pose relative_to="base_link">0.0202915 0.148301 0.0272372 -3.93428e-14 -3.97183e-14 1.48353</pose>
      <parent>base_link</parent>
      <child>hip_assembly</child>
      <axis>
        <xyz>0 0 1</xyz>
        <limit>
          <effort>10</effort>
          <velocity>10</velocity>
          <lower>-1.5707963267941567</lower>
          <upper>1.5707963267956364</upper>
        </limit>
        <dynamics>
          <friction>0.0</friction>
          <damping>0.0</damping>
        </dynamics>
      </axis>
    </joint>
    <!-- Link hip_assembly_2 -->
    <link name="hip_assembly_2">
      <inertial>
        <pose>-0.0268487 -0.000325484 -0.0302141 0 0 0</pose>
        <mass>0.365356</mass>
        <inertia>
          <ixx>0.000168136</ixx>
          <ixy>-2.8417e-07</ixy>
          <ixz>3.2467e-06</ixz>
          <iyy>0.000312332</iyy>
          <iyz>-9.42575e-07</iyz>
          <izz>0.000312341</izz>
        </inertia>
      </inertial>
      <pose relative_to="hip_2">0 0 0 0 -0 0</pose>
      <!-- Part hip_2 -->
      <visual name="hip_2_visual_mesh_1">
        <pose relative_to="hip_assembly_2">-0.0575 -0.0005 -0.0045 -1.24429e-15 -3.3468e-16 1.35831e-16</pose>
        <geometry>
          <mesh>
            <uri>model://simulation/meshes/hip.stl</uri>
          </mesh>
        </geometry>
        <material>
          <ambient>0.282353 0.54902 0.160784 1</ambient>
          <diffuse>0.282353 0.54902 0.160784 1</diffuse>
          <specular>0.1 0.1 0.1 1</specular>
          <emissive>0 0 0 0</emissive>
        </material>
      </visual>
      <collision name="hip_2_collision_mesh_2">
        <pose relative_to="hip_assembly_2">-0.0575 -0.0005 -0.0045 -1.24429e-15 -3.3468e-16 1.35831e-16</pose>
        <geometry>
          <mesh>
            <uri>model://simulation/meshes/hip.stl</uri>
          </mesh>
        </geometry>
      </collision>
      <!-- Part mobile_bracket_9 -->
      <visual name="mobile_bracket_9_visual_mesh_1">
        <pose relative_to="hip_assembly_2">-0.0575 3.03577e-17 -0.0305 -6.78487e-16 -1.0573e-15 1.5708</pose>
        <geometry>
          <mesh>
            <uri>model://simulation/meshes/mobile_bracket.stl</uri>
          </mesh>
        </geometry>
        <material>
          <ambient>0.647059 0.647059 0.647059 1</ambient>
          <diffuse>0.647059 0.647059 0.647059 1</diffuse>
          <specular>0.1 0.1 0.1 1</specular>
          <emissive>0 0 0 0</emissive>
        </material>
      </visual>
      <collision name="mobile_bracket_9_collision_mesh_2">
        <pose relative_to="hip_assembly_2">-0.0575 3.03577e-17 -0.0305 -6.78487e-16 -1.0573e-15 1.5708</pose>
        <geometry>
          <mesh>
            <uri>model://simulation/meshes/mobile_bracket.stl</uri>
          </mesh>
        </geometry>
      </collision>
      <!-- Part servo_wheel_7 -->
      <visual name="servo_wheel_7_visual_mesh_1">
        <pose relative_to="hip_assembly_2">0 -6.07153e-18 -0.0025 -3.14159 -4.85165e-31 5.14862e-17</pose>
        <geometry>
          <mesh>
            <uri>model://simulation/meshes/servo_wheel.stl</uri>
          </mesh>
        </geometry>
        <material>
          <ambient>0.647059 0.647059 0.647059 1</ambient>
          <diffuse>0.647059 0.647059 0.647059 1</diffuse>
          <specular>0.1 0.1 0.1 1</specular>
          <emissive>0 0 0 0</emissive>
        </material>
      </visual>
      <collision name="servo_wheel_7_collision_mesh_2">
        <pose relative_to="hip_assembly_2">0 -6.07153e-18 -0.0025 -3.14159 -4.85165e-31 5.14862e-17</pose>
        <geometry>
          <mesh>
            <uri>model://simulation/meshes/servo_wheel.stl</uri>
          </mesh>
        </geometry>
      </collision>
      <!-- Part servo_4 -->
      <visual name="servo_4_visual_mesh_1">
        <pose relative_to="hip_assembly_2">-0.0175 -0.00140442 -0.0305 -3.14159 -1.1556e-15 3.58833e-17</pose>
        <geometry>
          <mesh>
            <uri>model://simulation/meshes/servo.stl</uri>
          </mesh>
        </geometry>
        <material>
          <ambient>0.109804 0.109804 0.105882 1</ambient>
          <diffuse>0.109804 0.109804 0.105882 1</diffuse>
          <specular>0.1 0.1 0.1 1</specular>
          <emissive>0 0 0 0</emissive>
        </material>
      </visual>
      <collision name="servo_4_collision_mesh_2">
        <pose relative_to="hip_assembly_2">-0.0175 -0.00140442 -0.0305 -3.14159 -1.1556e-15 3.58833e-17</pose>
        <geometry>
          <mesh>
            <uri>model://simulation/meshes/servo.stl</uri>
          </mesh>
        </geometry>
      </collision>
      <!-- Part fixed_bracket_4 -->
      <visual name="fixed_bracket_4_visual_mesh_1">
        <pose relative_to="hip_assembly_2">-0.0575 3.03577e-17 -0.0305 1.5708 1.5708 0</pose>
        <geometry>
          <mesh>
            <uri>model://simulation/meshes/fixed_bracket.stl</uri>
          </mesh>
        </geometry>
        <material>
          <ambient>0.647059 0.647059 0.647059 1</ambient>
          <diffuse>0.647059 0.647059 0.647059 1</diffuse>
          <specular>0.1 0.1 0.1 1</specular>
          <emissive>0 0 0 0</emissive>
        </material>
      </visual>
      <collision name="fixed_bracket_4_collision_mesh_2">
        <pose relative_to="hip_assembly_2">-0.0575 3.03577e-17 -0.0305 1.5708 1.5708 0</pose>
        <geometry>
          <mesh>
            <uri>model://simulation/meshes/fixed_bracket.stl</uri>
          </mesh>
        </geometry>
      </collision>
      <!-- Part servo_wheel_8 -->
      <visual name="servo_wheel_8_visual_mesh_1">
        <pose relative_to="hip_assembly_2">8.32667e-17 7.89299e-17 -0.0585 -3.14159 -1.04443e-15 1.31303e-16</pose>
        <geometry>
          <mesh>
            <uri>model://simulation/meshes/servo_wheel.stl</uri>
          </mesh>
        </geometry>
        <material>
          <ambient>0.647059 0.647059 0.647059 1</ambient>
          <diffuse>0.647059 0.647059 0.647059 1</diffuse>
          <specular>0.1 0.1 0.1 1</specular>
          <emissive>0 0 0 0</emissive>
        </material>
      </visual>
      <collision name="servo_wheel_8_collision_mesh_2">
        <pose relative_to="hip_assembly_2">8.32667e-17 7.89299e-17 -0.0585 -3.14159 -1.04443e-15 1.31303e-16</pose>
        <geometry>
          <mesh>
            <uri>model://simulation/meshes/servo_wheel.stl</uri>
          </mesh>
        </geometry>
      </collision>
    </link>
    <!-- Link ties_assembly_2 -->
    <link name="ties_assembly_2">
      <inertial>
        <pose>0.0643598 0.00153088 -0.0309357 0 0 0</pose>
        <mass>0.589115</mass>
        <inertia>
          <ixx>0.000320336</ixx>
          <ixy>-2.41497e-05</ixy>
          <ixz>1.07866e-05</ixz>
          <iyy>0.00208685</iyy>
          <iyz>2.0947e-07</iyz>
          <izz>0.00187002</izz>
        </inertia>
      </inertial>
      <pose relative_to="ties_2">0 0 0 0 -0 0</pose>
      <!-- Part mobile_bracket_10 -->
      <visual name="mobile_bracket_10_visual_mesh_1">
        <pose relative_to="ties_assembly_2">0.1568 0.000210323 -0.0311738 1.5708 1.5708 0</pose>
        <geometry>
          <mesh>
            <uri>model://simulation/meshes/mobile_bracket.stl</uri>
          </mesh>
        </geometry>
        <material>
          <ambient>0.647059 0.647059 0.647059 1</ambient>
          <diffuse>0.647059 0.647059 0.647059 1</diffuse>
          <specular>0.1 0.1 0.1 1</specular>
          <emissive>0 0 0 0</emissive>
        </material>
      </visual>
      <collision name="mobile_bracket_10_collision_mesh_2">
        <pose relative_to="ties_assembly_2">0.1568 0.000210323 -0.0311738 1.5708 1.5708 0</pose>
        <geometry>
          <mesh>
            <uri>model://simulation/meshes/mobile_bracket.stl</uri>
          </mesh>
        </geometry>
      </collision>
      <!-- Part low_tie_2 -->
      <visual name="low_tie_2_visual_mesh_1">
        <pose relative_to="ties_assembly_2">0.0268 0.000210323 -0.0311738 -3.26837e-14 1.5708 0</pose>
        <geometry>
          <mesh>
            <uri>model://simulation/meshes/low_tie.stl</uri>
          </mesh>
        </geometry>
        <material>
          <ambient>0.282353 0.54902 0.160784 1</ambient>
          <diffuse>0.282353 0.54902 0.160784 1</diffuse>
          <specular>0.1 0.1 0.1 1</specular>
          <emissive>0 0 0 0</emissive>
        </material>
      </visual>
      <collision name="low_tie_2_collision_mesh_2">
        <pose relative_to="ties_assembly_2">0.0268 0.000210323 -0.0311738 -3.26837e-14 1.5708 0</pose>
        <geometry>
          <mesh>
            <uri>model://simulation/meshes/low_tie.stl</uri>
          </mesh>
        </geometry>
      </collision>
      <!-- Part top_tie_2 -->
      <visual name="top_tie_2_visual_mesh_1">
        <pose relative_to="ties_assembly_2">0.0275 8.91214e-16 -0.0305 -3.26837e-14 1.5708 0</pose>
        <geometry>
          <mesh>
            <uri>model://simulation/meshes/top_tie.stl</uri>
          </mesh>
        </geometry>
        <material>
          <ambient>0.282353 0.54902 0.160784 1</ambient>
          <diffuse>0.282353 0.54902 0.160784 1</diffuse>
          <specular>0.1 0.1 0.1 1</specular>
          <emissive>0 0 0 0</emissive>
        </material>
      </visual>
      <collision name="top_tie_2_collision_mesh_2">
        <pose relative_to="ties_assembly_2">0.0275 8.91214e-16 -0.0305 -3.26837e-14 1.5708 0</pose>
        <geometry>
          <mesh>
            <uri>model://simulation/meshes/top_tie.stl</uri>
          </mesh>
        </geometry>
      </collision>
      <!-- Part servo_wheel_9 -->
      <visual name="servo_wheel_9_visual_mesh_1">
        <pose relative_to="ties_assembly_2">-5.55112e-17 -8.67362e-19 -0.0025 -3.14159 -6.8753e-15 -3.14159</pose>
        <geometry>
          <mesh>
            <uri>model://simulation/meshes/servo_wheel.stl</uri>
          </mesh>
        </geometry>
        <material>
          <ambient>0.647059 0.647059 0.647059 1</ambient>
          <diffuse>0.647059 0.647059 0.647059 1</diffuse>
          <specular>0.1 0.1 0.1 1</specular>
          <emissive>0 0 0 0</emissive>
        </material>
      </visual>
      <collision name="servo_wheel_9_collision_mesh_2">
        <pose relative_to="ties_assembly_2">-5.55112e-17 -8.67362e-19 -0.0025 -3.14159 -6.8753e-15 -3.14159</pose>
        <geometry>
          <mesh>
            <uri>model://simulation/meshes/servo_wheel.stl</uri>
          </mesh>
        </geometry>
      </collision>
      <!-- Part servo_5 -->
      <visual name="servo_5_visual_mesh_1">
        <pose relative_to="ties_assembly_2">0.0175 0.00140442 -0.0305 -3.14159 -6.70706e-15 -3.14159</pose>
        <geometry>
          <mesh>
            <uri>model://simulation/meshes/servo.stl</uri>
          </mesh>
        </geometry>
        <material>
          <ambient>0.109804 0.109804 0.105882 1</ambient>
          <diffuse>0.109804 0.109804 0.105882 1</diffuse>
          <specular>0.1 0.1 0.1 1</specular>
          <emissive>0 0 0 0</emissive>
        </material>
      </visual>
      <collision name="servo_5_collision_mesh_2">
        <pose relative_to="ties_assembly_2">0.0175 0.00140442 -0.0305 -3.14159 -6.70706e-15 -3.14159</pose>
        <geometry>
          <mesh>
            <uri>model://simulation/meshes/servo.stl</uri>
          </mesh>
        </geometry>
      </collision>
      <!-- Part fixed_bracket_5 -->
      <visual name="fixed_bracket_5_visual_mesh_1">
        <pose relative_to="ties_assembly_2">0.0575 1.8709e-15 -0.0305 -1.5708 1.5708 0</pose>
        <geometry>
          <mesh>
            <uri>model://simulation/meshes/fixed_bracket.stl</uri>
          </mesh>
        </geometry>
        <material>
          <ambient>0.647059 0.647059 0.647059 1</ambient>
          <diffuse>0.647059 0.647059 0.647059 1</diffuse>
          <specular>0.1 0.1 0.1 1</specular>
          <emissive>0 0 0 0</emissive>
        </material>
      </visual>
      <collision name="fixed_bracket_5_collision_mesh_2">
        <pose relative_to="ties_assembly_2">0.0575 1.8709e-15 -0.0305 -1.5708 1.5708 0</pose>
        <geometry>
          <mesh>
            <uri>model://simulation/meshes/fixed_bracket.stl</uri>
          </mesh>
        </geometry>
      </collision>
      <!-- Part servo_wheel_10 -->
      <visual name="servo_wheel_10_visual_mesh_1">
        <pose relative_to="ties_assembly_2">-2.77556e-17 -8.67362e-19 -0.0585 -3.14159 -6.98632e-15 -3.14159</pose>
        <geometry>
          <mesh>
            <uri>model://simulation/meshes/servo_wheel.stl</uri>
          </mesh>
        </geometry>
        <material>
          <ambient>0.647059 0.647059 0.647059 1</ambient>
          <diffuse>0.647059 0.647059 0.647059 1</diffuse>
          <specular>0.1 0.1 0.1 1</specular>
          <emissive>0 0 0 0</emissive>
        </material>
      </visual>
      <collision name="servo_wheel_10_collision_mesh_2">
        <pose relative_to="ties_assembly_2">-2.77556e-17 -8.67362e-19 -0.0585 -3.14159 -6.98632e-15 -3.14159</pose>
        <geometry>
          <mesh>
            <uri>model://simulation/meshes/servo_wheel.stl</uri>
          </mesh>
        </geometry>
      </collision>
    </link>
    <!-- Link foot_assembly_2 -->
    <link name="foot_assembly_2">
      <inertial>
        <pose>-0.0724503 -0.00208415 -0.0306672 0 0 0</pose>
        <mass>0.633745</mass>
        <inertia>
          <ixx>0.000268495</ixx>
          <ixy>-1.4806e-05</ixy>
          <ixz>4.28294e-06</ixz>
          <iyy>0.00320961</iyy>
          <iyz>-2.30165e-07</iyz>
          <izz>0.00304658</izz>
        </inertia>
      </inertial>
      <pose relative_to="foot_2">0 0 0 0 -0 0</pose>
      <!-- Part foot_2 -->
      <visual name="foot_2_visual_mesh_1">
        <pose relative_to="foot_assembly_2">-0.04425 6.93889e-18 -0.0305 1.86802e-27 1.5708 0</pose>
        <geometry>
          <mesh>
            <uri>model://simulation/meshes/foot.stl</uri>
          </mesh>
        </geometry>
        <material>
          <ambient>0.282353 0.54902 0.160784 1</ambient>
          <diffuse>0.282353 0.54902 0.160784 1</diffuse>
          <specular>0.1 0.1 0.1 1</specular>
          <emissive>0 0 0 0</emissive>
        </material>
      </visual>
      <collision name="foot_2_collision_mesh_2">
        <pose relative_to="foot_assembly_2">-0.04425 6.93889e-18 -0.0305 1.86802e-27 1.5708 0</pose>
        <geometry>
          <mesh>
            <uri>model://simulation/meshes/foot.stl</uri>
          </mesh>
        </geometry>
      </collision>
      <!-- Part ir_sensor_cap_2 -->
      <visual name="ir_sensor_cap_2_visual_mesh_1">
        <pose relative_to="foot_assembly_2">-0.04425 -2.39392e-16 -0.0305 1.43971e-15 1.5708 0</pose>
        <geometry>
          <mesh>
            <uri>model://simulation/meshes/ir_sensor_cap.stl</uri>
          </mesh>
        </geometry>
        <material>
          <ambient>0.282353 0.54902 0.160784 1</ambient>
          <diffuse>0.282353 0.54902 0.160784 1</diffuse>
          <specular>0.1 0.1 0.1 1</specular>
          <emissive>0 0 0 0</emissive>
        </material>
      </visual>
      <collision name="ir_sensor_cap_2_collision_mesh_2">
        <pose relative_to="foot_assembly_2">-0.04425 -2.39392e-16 -0.0305 1.43971e-15 1.5708 0</pose>
        <geometry>
          <mesh>
            <uri>model://simulation/meshes/ir_sensor_cap.stl</uri>
          </mesh>
        </geometry>
      </collision>
      <!-- Part rubber_foot_2 -->
      <visual name="rubber_foot_2_visual_mesh_1">
        <pose relative_to="foot_assembly_2">-0.04375 7.58942e-17 -0.03 -1.04493e-16 1.5708 0</pose>
        <geometry>
          <mesh>
            <uri>model://simulation/meshes/rubber_foot.stl</uri>
          </mesh>
        </geometry>
        <material>
          <ambient>0.262745 0.282353 0.301961 1</ambient>
          <diffuse>0.262745 0.282353 0.301961 1</diffuse>
          <specular>0.1 0.1 0.1 1</specular>
          <emissive>0 0 0 0</emissive>
        </material>
      </visual>
      <collision name="rubber_foot_2_collision_mesh_2">
        <pose relative_to="foot_assembly_2">-0.04375 7.58942e-17 -0.03 -1.04493e-16 1.5708 0</pose>
        <geometry>
          <mesh>
            <uri>model://simulation/meshes/rubber_foot.stl</uri>
          </mesh>
        </geometry>
      </collision>
      <!-- Part servo_wheel_11 -->
      <visual name="servo_wheel_11_visual_mesh_1">
        <pose relative_to="foot_assembly_2">0 0 -0.0025 -3.14159 -1.96972e-17 0</pose>
        <geometry>
          <mesh>
            <uri>model://simulation/meshes/servo_wheel.stl</uri>
          </mesh>
        </geometry>
        <material>
          <ambient>0.647059 0.647059 0.647059 1</ambient>
          <diffuse>0.647059 0.647059 0.647059 1</diffuse>
          <specular>0.1 0.1 0.1 1</specular>
          <emissive>0 0 0 0</emissive>
        </material>
      </visual>
      <collision name="servo_wheel_11_collision_mesh_2">
        <pose relative_to="foot_assembly_2">0 0 -0.0025 -3.14159 -1.96972e-17 0</pose>
        <geometry>
          <mesh>
            <uri>model://simulation/meshes/servo_wheel.stl</uri>
          </mesh>
        </geometry>
      </collision>
      <!-- Part servo_6 -->
      <visual name="servo_6_visual_mesh_1">
        <pose relative_to="foot_assembly_2">-0.0175 -0.00140442 -0.0305 3.14159 -6.92834e-16 -9.34011e-28</pose>
        <geometry>
          <mesh>
            <uri>model://simulation/meshes/servo.stl</uri>
          </mesh>
        </geometry>
        <material>
          <ambient>0.109804 0.109804 0.105882 1</ambient>
          <diffuse>0.109804 0.109804 0.105882 1</diffuse>
          <specular>0.1 0.1 0.1 1</specular>
          <emissive>0 0 0 0</emissive>
        </material>
      </visual>
      <collision name="servo_6_collision_mesh_2">
        <pose relative_to="foot_assembly_2">-0.0175 -0.00140442 -0.0305 3.14159 -6.92834e-16 -9.34011e-28</pose>
        <geometry>
          <mesh>
            <uri>model://simulation/meshes/servo.stl</uri>
          </mesh>
        </geometry>
      </collision>
      <!-- Part fixed_bracket_6 -->
      <visual name="fixed_bracket_6_visual_mesh_1">
        <pose relative_to="foot_assembly_2">-0.0575 7.80626e-18 -0.0305 1.5708 1.5708 0</pose>
        <geometry>
          <mesh>
            <uri>model://simulation/meshes/fixed_bracket.stl</uri>
          </mesh>
        </geometry>
        <material>
          <ambient>0.647059 0.647059 0.647059 1</ambient>
          <diffuse>0.647059 0.647059 0.647059 1</diffuse>
          <specular>0.1 0.1 0.1 1</specular>
          <emissive>0 0 0 0</emissive>
        </material>
      </visual>
      <collision name="fixed_bracket_6_collision_mesh_2">
        <pose relative_to="foot_assembly_2">-0.0575 7.80626e-18 -0.0305 1.5708 1.5708 0</pose>
        <geometry>
          <mesh>
            <uri>model://simulation/meshes/fixed_bracket.stl</uri>
          </mesh>
        </geometry>
      </collision>
      <!-- Part servo_wheel_12 -->
      <visual name="servo_wheel_12_visual_mesh_1">
        <pose relative_to="foot_assembly_2">0 0 -0.0585 3.14159 -2.54049e-16 -1.76705e-27</pose>
        <geometry>
          <mesh>
            <uri>model://simulation/meshes/servo_wheel.stl</uri>
          </mesh>
        </geometry>
        <material>
          <ambient>0.647059 0.647059 0.647059 1</ambient>
          <diffuse>0.647059 0.647059 0.647059 1</diffuse>
          <specular>0.1 0.1 0.1 1</specular>
          <emissive>0 0 0 0</emissive>
        </material>
      </visual>
      <collision name="servo_wheel_12_collision_mesh_2">
        <pose relative_to="foot_assembly_2">0 0 -0.0585 3.14159 -2.54049e-16 -1.76705e-27</pose>
        <geometry>
          <mesh>
            <uri>model://simulation/meshes/servo_wheel.stl</uri>
          </mesh>
        </geometry>
      </collision>
    </link>
    <!-- Joint from ties_assembly_2 to foot_assembly_2 -->
    <joint name="foot_2" type="revolute">
      <pose relative_to="ties_assembly_2">0.1918 0.000210323 -0.000790548 2.69393e-15 -7.22227e-15 -3.14159</pose>
      <parent>ties_assembly_2</parent>
      <child>foot_assembly_2</child>
      <axis>
        <xyz>0 0 1</xyz>
        <limit>
          <effort>10</effort>
          <velocity>10</velocity>
          <lower>-2.094395102393151</lower>
          <upper>2.0943951023932397</upper>
        </limit>
        <dynamics>
          <friction>0.0</friction>
          <damping>0.0</damping>
        </dynamics>
      </axis>
    </joint>
    <!-- Joint from hip_assembly_2 to ties_assembly_2 -->
    <joint name="ties_2" type="revolute">
      <pose relative_to="hip_assembly_2">-0.0925 0.0311167 -0.0305 1.5708 6.78487e-16 3.14159</pose>
      <parent>hip_assembly_2</parent>
      <child>ties_assembly_2</child>
      <axis>
        <xyz>0 0 1</xyz>
        <limit>
          <effort>10</effort>
          <velocity>10</velocity>
          <lower>-1.7453292519943633</lower>
          <upper>1.7453292519942958</upper>
        </limit>
        <dynamics>
          <friction>0.0</friction>
          <damping>0.0</damping>
        </dynamics>
      </axis>
    </joint>
    <!-- Joint from base_link to hip_assembly_2 -->
    <joint name="hip_2" type="revolute">
      <pose relative_to="base_link">0.144817 0.0611074 0.0272372 -1.42889e-14 5.46584e-14 -2.70526</pose>
      <parent>base_link</parent>
      <child>hip_assembly_2</child>
      <axis>
        <xyz>0 0 1</xyz>
        <limit>
          <effort>10</effort>
          <velocity>10</velocity>
          <lower>-1.5707963267941487</lower>
          <upper>1.5707963267956444</upper>
        </limit>
        <dynamics>
          <friction>0.0</friction>
          <damping>0.0</damping>
        </dynamics>
      </axis>
    </joint>
    <!-- Link hip_assembly_3 -->
    <link name="hip_assembly_3">
      <inertial>
        <pose>-0.0268487 -0.000325484 -0.0302141 0 0 0</pose>
        <mass>0.365356</mass>
        <inertia>
          <ixx>0.000168136</ixx>
          <ixy>-2.8417e-07</ixy>
          <ixz>3.2467e-06</ixz>
          <iyy>0.000312332</iyy>
          <iyz>-9.42575e-07</iyz>
          <izz>0.000312341</izz>
        </inertia>
      </inertial>
      <pose relative_to="hip_3">0 0 0 0 -0 0</pose>
      <!-- Part hip_3 -->
      <visual name="hip_3_visual_mesh_1">
        <pose relative_to="hip_assembly_3">-0.0575 -0.0005 -0.0045 -1.71813e-15 4.91134e-15 -8.80584e-17</pose>
        <geometry>
          <mesh>
            <uri>model://simulation/meshes/hip.stl</uri>
          </mesh>
        </geometry>
        <material>
          <ambient>0.282353 0.54902 0.160784 1</ambient>
          <diffuse>0.282353 0.54902 0.160784 1</diffuse>
          <specular>0.1 0.1 0.1 1</specular>
          <emissive>0 0 0 0</emissive>
        </material>
      </visual>
      <collision name="hip_3_collision_mesh_2">
        <pose relative_to="hip_assembly_3">-0.0575 -0.0005 -0.0045 -1.71813e-15 4.91134e-15 -8.80584e-17</pose>
        <geometry>
          <mesh>
            <uri>model://simulation/meshes/hip.stl</uri>
          </mesh>
        </geometry>
      </collision>
      <!-- Part mobile_bracket_11 -->
      <visual name="mobile_bracket_11_visual_mesh_1">
        <pose relative_to="hip_assembly_3">-0.0575 8.89046e-18 -0.0305 8.44496e-15 9.01927e-15 1.5708</pose>
        <geometry>
          <mesh>
            <uri>model://simulation/meshes/mobile_bracket.stl</uri>
          </mesh>
        </geometry>
        <material>
          <ambient>0.647059 0.647059 0.647059 1</ambient>
          <diffuse>0.647059 0.647059 0.647059 1</diffuse>
          <specular>0.1 0.1 0.1 1</specular>
          <emissive>0 0 0 0</emissive>
        </material>
      </visual>
      <collision name="mobile_bracket_11_collision_mesh_2">
        <pose relative_to="hip_assembly_3">-0.0575 8.89046e-18 -0.0305 8.44496e-15 9.01927e-15 1.5708</pose>
        <geometry>
          <mesh>
            <uri>model://simulation/meshes/mobile_bracket.stl</uri>
          </mesh>
        </geometry>
      </collision>
      <!-- Part servo_wheel_13 -->
      <visual name="servo_wheel_13_visual_mesh_1">
        <pose relative_to="hip_assembly_3">0 2.60209e-18 -0.0025 3.14159 2.67006e-31 -3.2531e-17</pose>
        <geometry>
          <mesh>
            <uri>model://simulation/meshes/servo_wheel.stl</uri>
          </mesh>
        </geometry>
        <material>
          <ambient>0.647059 0.647059 0.647059 1</ambient>
          <diffuse>0.647059 0.647059 0.647059 1</diffuse>
          <specular>0.1 0.1 0.1 1</specular>
          <emissive>0 0 0 0</emissive>
        </material>
      </visual>
      <collision name="servo_wheel_13_collision_mesh_2">
        <pose relative_to="hip_assembly_3">0 2.60209e-18 -0.0025 3.14159 2.67006e-31 -3.2531e-17</pose>
        <geometry>
          <mesh>
            <uri>model://simulation/meshes/servo_wheel.stl</uri>
          </mesh>
        </geometry>
      </collision>
      <!-- Part servo_7 -->
      <visual name="servo_7_visual_mesh_1">
        <pose relative_to="hip_assembly_3">-0.0175 -0.00140442 -0.0305 3.14159 3.55252e-15 -3.37159e-17</pose>
        <geometry>
          <mesh>
            <uri>model://simulation/meshes/servo.stl</uri>
          </mesh>
        </geometry>
        <material>
          <ambient>0.109804 0.109804 0.105882 1</ambient>
          <diffuse>0.109804 0.109804 0.105882 1</diffuse>
          <specular>0.1 0.1 0.1 1</specular>
          <emissive>0 0 0 0</emissive>
        </material>
      </visual>
      <collision name="servo_7_collision_mesh_2">
        <pose relative_to="hip_assembly_3">-0.0175 -0.00140442 -0.0305 3.14159 3.55252e-15 -3.37159e-17</pose>
        <geometry>
          <mesh>
            <uri>model://simulation/meshes/servo.stl</uri>
          </mesh>
        </geometry>
      </collision>
      <!-- Part fixed_bracket_7 -->
      <visual name="fixed_bracket_7_visual_mesh_1">
        <pose relative_to="hip_assembly_3">-0.0575 8.89046e-18 -0.0305 1.5708 1.5708 0</pose>
        <geometry>
          <mesh>
            <uri>model://simulation/meshes/fixed_bracket.stl</uri>
          </mesh>
        </geometry>
        <material>
          <ambient>0.647059 0.647059 0.647059 1</ambient>
          <diffuse>0.647059 0.647059 0.647059 1</diffuse>
          <specular>0.1 0.1 0.1 1</specular>
          <emissive>0 0 0 0</emissive>
        </material>
      </visual>
      <collision name="fixed_bracket_7_collision_mesh_2">
        <pose relative_to="hip_assembly_3">-0.0575 8.89046e-18 -0.0305 1.5708 1.5708 0</pose>
        <geometry>
          <mesh>
            <uri>model://simulation/meshes/fixed_bracket.stl</uri>
          </mesh>
        </geometry>
      </collision>
      <!-- Part servo_wheel_14 -->
      <visual name="servo_wheel_14_visual_mesh_1">
        <pose relative_to="hip_assembly_3">-2.77556e-17 4.33681e-19 -0.0585 3.14159 7.80157e-15 -8.57049e-17</pose>
        <geometry>
          <mesh>
            <uri>model://simulation/meshes/servo_wheel.stl</uri>
          </mesh>
        </geometry>
        <material>
          <ambient>0.647059 0.647059 0.647059 1</ambient>
          <diffuse>0.647059 0.647059 0.647059 1</diffuse>
          <specular>0.1 0.1 0.1 1</specular>
          <emissive>0 0 0 0</emissive>
        </material>
      </visual>
      <collision name="servo_wheel_14_collision_mesh_2">
        <pose relative_to="hip_assembly_3">-2.77556e-17 4.33681e-19 -0.0585 3.14159 7.80157e-15 -8.57049e-17</pose>
        <geometry>
          <mesh>
            <uri>model://simulation/meshes/servo_wheel.stl</uri>
          </mesh>
        </geometry>
      </collision>
    </link>
    <!-- Link ties_assembly_3 -->
    <link name="ties_assembly_3">
      <inertial>
        <pose>0.0643598 0.00153088 -0.0309357 0 0 0</pose>
        <mass>0.589115</mass>
        <inertia>
          <ixx>0.000320336</ixx>
          <ixy>-2.41497e-05</ixy>
          <ixz>1.07866e-05</ixz>
          <iyy>0.00208685</iyy>
          <iyz>2.0947e-07</iyz>
          <izz>0.00187002</izz>
        </inertia>
      </inertial>
      <pose relative_to="ties_3">0 0 0 0 -0 0</pose>
      <!-- Part mobile_bracket_12 -->
      <visual name="mobile_bracket_12_visual_mesh_1">
        <pose relative_to="ties_assembly_3">0.1568 0.000210323 -0.0311738 1.5708 1.5708 0</pose>
        <geometry>
          <mesh>
            <uri>model://simulation/meshes/mobile_bracket.stl</uri>
          </mesh>
        </geometry>
        <material>
          <ambient>0.647059 0.647059 0.647059 1</ambient>
          <diffuse>0.647059 0.647059 0.647059 1</diffuse>
          <specular>0.1 0.1 0.1 1</specular>
          <emissive>0 0 0 0</emissive>
        </material>
      </visual>
      <collision name="mobile_bracket_12_collision_mesh_2">
        <pose relative_to="ties_assembly_3">0.1568 0.000210323 -0.0311738 1.5708 1.5708 0</pose>
        <geometry>
          <mesh>
            <uri>model://simulation/meshes/mobile_bracket.stl</uri>
          </mesh>
        </geometry>
      </collision>
      <!-- Part low_tie_3 -->
      <visual name="low_tie_3_visual_mesh_1">
        <pose relative_to="ties_assembly_3">0.0268 0.000210323 -0.0311738 8.37069e-15 1.5708 0</pose>
        <geometry>
          <mesh>
            <uri>model://simulation/meshes/low_tie.stl</uri>
          </mesh>
        </geometry>
        <material>
          <ambient>0.282353 0.54902 0.160784 1</ambient>
          <diffuse>0.282353 0.54902 0.160784 1</diffuse>
          <specular>0.1 0.1 0.1 1</specular>
          <emissive>0 0 0 0</emissive>
        </material>
      </visual>
      <collision name="low_tie_3_collision_mesh_2">
        <pose relative_to="ties_assembly_3">0.0268 0.000210323 -0.0311738 8.37069e-15 1.5708 0</pose>
        <geometry>
          <mesh>
            <uri>model://simulation/meshes/low_tie.stl</uri>
          </mesh>
        </geometry>
      </collision>
      <!-- Part top_tie_3 -->
      <visual name="top_tie_3_visual_mesh_1">
        <pose relative_to="ties_assembly_3">0.0275 -2.38091e-16 -0.0305 8.37069e-15 1.5708 0</pose>
        <geometry>
          <mesh>
            <uri>model://simulation/meshes/top_tie.stl</uri>
          </mesh>
        </geometry>
        <material>
          <ambient>0.282353 0.54902 0.160784 1</ambient>
          <diffuse>0.282353 0.54902 0.160784 1</diffuse>
          <specular>0.1 0.1 0.1 1</specular>
          <emissive>0 0 0 0</emissive>
        </material>
      </visual>
      <collision name="top_tie_3_collision_mesh_2">
        <pose relative_to="ties_assembly_3">0.0275 -2.38091e-16 -0.0305 8.37069e-15 1.5708 0</pose>
        <geometry>
          <mesh>
            <uri>model://simulation/meshes/top_tie.stl</uri>
          </mesh>
        </geometry>
      </collision>
      <!-- Part servo_wheel_15 -->
      <visual name="servo_wheel_15_visual_mesh_1">
        <pose relative_to="ties_assembly_3">0 -4.33681e-19 -0.0025 3.14159 3.82581e-15 3.14159</pose>
        <geometry>
          <mesh>
            <uri>model://simulation/meshes/servo_wheel.stl</uri>
          </mesh>
        </geometry>
        <material>
          <ambient>0.647059 0.647059 0.647059 1</ambient>
          <diffuse>0.647059 0.647059 0.647059 1</diffuse>
          <specular>0.1 0.1 0.1 1</specular>
          <emissive>0 0 0 0</emissive>
        </material>
      </visual>
      <collision name="servo_wheel_15_collision_mesh_2">
        <pose relative_to="ties_assembly_3">0 -4.33681e-19 -0.0025 3.14159 3.82581e-15 3.14159</pose>
        <geometry>
          <mesh>
            <uri>model://simulation/meshes/servo_wheel.stl</uri>
          </mesh>
        </geometry>
      </collision>
      <!-- Part servo_8 -->
      <visual name="servo_8_visual_mesh_1">
        <pose relative_to="ties_assembly_3">0.0175 0.00140442 -0.0305 3.14159 2.81479e-15 3.14159</pose>
        <geometry>
          <mesh>
            <uri>model://simulation/meshes/servo.stl</uri>
          </mesh>
        </geometry>
        <material>
          <ambient>0.109804 0.109804 0.105882 1</ambient>
          <diffuse>0.109804 0.109804 0.105882 1</diffuse>
          <specular>0.1 0.1 0.1 1</specular>
          <emissive>0 0 0 0</emissive>
        </material>
      </visual>
      <collision name="servo_8_collision_mesh_2">
        <pose relative_to="ties_assembly_3">0.0175 0.00140442 -0.0305 3.14159 2.81479e-15 3.14159</pose>
        <geometry>
          <mesh>
            <uri>model://simulation/meshes/servo.stl</uri>
          </mesh>
        </geometry>
      </collision>
      <!-- Part fixed_bracket_8 -->
      <visual name="fixed_bracket_8_visual_mesh_1">
        <pose relative_to="ties_assembly_3">0.0575 -4.89626e-16 -0.0305 -1.5708 1.5708 0</pose>
        <geometry>
          <mesh>
            <uri>model://simulation/meshes/fixed_bracket.stl</uri>
          </mesh>
        </geometry>
        <material>
          <ambient>0.647059 0.647059 0.647059 1</ambient>
          <diffuse>0.647059 0.647059 0.647059 1</diffuse>
          <specular>0.1 0.1 0.1 1</specular>
          <emissive>0 0 0 0</emissive>
        </material>
      </visual>
      <collision name="fixed_bracket_8_collision_mesh_2">
        <pose relative_to="ties_assembly_3">0.0575 -4.89626e-16 -0.0305 -1.5708 1.5708 0</pose>
        <geometry>
          <mesh>
            <uri>model://simulation/meshes/fixed_bracket.stl</uri>
          </mesh>
        </geometry>
      </collision>
      <!-- Part servo_wheel_16 -->
      <visual name="servo_wheel_16_visual_mesh_1">
        <pose relative_to="ties_assembly_3">0 -8.67362e-19 -0.0585 3.14159 4.80139e-15 3.14159</pose>
        <geometry>
          <mesh>
            <uri>model://simulation/meshes/servo_wheel.stl</uri>
          </mesh>
        </geometry>
        <material>
          <ambient>0.647059 0.647059 0.647059 1</ambient>
          <diffuse>0.647059 0.647059 0.647059 1</diffuse>
          <specular>0.1 0.1 0.1 1</specular>
          <emissive>0 0 0 0</emissive>
        </material>
      </visual>
      <collision name="servo_wheel_16_collision_mesh_2">
        <pose relative_to="ties_assembly_3">0 -8.67362e-19 -0.0585 3.14159 4.80139e-15 3.14159</pose>
        <geometry>
          <mesh>
            <uri>model://simulation/meshes/servo_wheel.stl</uri>
          </mesh>
        </geometry>
      </collision>
    </link>
    <!-- Link foot_assembly_3 -->
    <link name="foot_assembly_3">
      <inertial>
        <pose>-0.0724503 -0.00208415 -0.0306672 0 0 0</pose>
        <mass>0.633745</mass>
        <inertia>
          <ixx>0.000268495</ixx>
          <ixy>-1.4806e-05</ixy>
          <ixz>4.28294e-06</ixz>
          <iyy>0.00320961</iyy>
          <iyz>-2.30165e-07</iyz>
          <izz>0.00304658</izz>
        </inertia>
      </inertial>
      <pose relative_to="foot_3">0 0 0 0 -0 0</pose>
      <!-- Part foot_3 -->
      <visual name="foot_3_visual_mesh_1">
        <pose relative_to="foot_assembly_3">-0.04425 -8.0231e-17 -0.0305 -2.27596e-15 1.5708 0</pose>
        <geometry>
          <mesh>
            <uri>model://simulation/meshes/foot.stl</uri>
          </mesh>
        </geometry>
        <material>
          <ambient>0.282353 0.54902 0.160784 1</ambient>
          <diffuse>0.282353 0.54902 0.160784 1</diffuse>
          <specular>0.1 0.1 0.1 1</specular>
          <emissive>0 0 0 0</emissive>
        </material>
      </visual>
      <collision name="foot_3_collision_mesh_2">
        <pose relative_to="foot_assembly_3">-0.04425 -8.0231e-17 -0.0305 -2.27596e-15 1.5708 0</pose>
        <geometry>
          <mesh>
            <uri>model://simulation/meshes/foot.stl</uri>
          </mesh>
        </geometry>
      </collision>
      <!-- Part ir_sensor_cap_3 -->
      <visual name="ir_sensor_cap_3_visual_mesh_1">
        <pose relative_to="foot_assembly_3">-0.04425 1.56992e-16 -0.0305 -4.44661e-15 1.5708 0</pose>
        <geometry>
          <mesh>
            <uri>model://simulation/meshes/ir_sensor_cap.stl</uri>
          </mesh>
        </geometry>
        <material>
          <ambient>0.282353 0.54902 0.160784 1</ambient>
          <diffuse>0.282353 0.54902 0.160784 1</diffuse>
          <specular>0.1 0.1 0.1 1</specular>
          <emissive>0 0 0 0</emissive>
        </material>
      </visual>
      <collision name="ir_sensor_cap_3_collision_mesh_2">
        <pose relative_to="foot_assembly_3">-0.04425 1.56992e-16 -0.0305 -4.44661e-15 1.5708 0</pose>
        <geometry>
          <mesh>
            <uri>model://simulation/meshes/ir_sensor_cap.stl</uri>
          </mesh>
        </geometry>
      </collision>
      <!-- Part rubber_foot_3 -->
      <visual name="rubber_foot_3_visual_mesh_1">
        <pose relative_to="foot_assembly_3">-0.04375 -3.8294e-16 -0.03 -8.32667e-16 1.5708 0</pose>
        <geometry>
          <mesh>
            <uri>model://simulation/meshes/rubber_foot.stl</uri>
          </mesh>
        </geometry>
        <material>
          <ambient>0.262745 0.282353 0.301961 1</ambient>
          <diffuse>0.262745 0.282353 0.301961 1</diffuse>
          <specular>0.1 0.1 0.1 1</specular>
          <emissive>0 0 0 0</emissive>
        </material>
      </visual>
      <collision name="rubber_foot_3_collision_mesh_2">
        <pose relative_to="foot_assembly_3">-0.04375 -3.8294e-16 -0.03 -8.32667e-16 1.5708 0</pose>
        <geometry>
          <mesh>
            <uri>model://simulation/meshes/rubber_foot.stl</uri>
          </mesh>
        </geometry>
      </collision>
      <!-- Part servo_wheel_17 -->
      <visual name="servo_wheel_17_visual_mesh_1">
        <pose relative_to="foot_assembly_3">5.55112e-17 4.33681e-19 -0.0025 -3.14159 5.39489e-17 2.29263e-30</pose>
        <geometry>
          <mesh>
            <uri>model://simulation/meshes/servo_wheel.stl</uri>
          </mesh>
        </geometry>
        <material>
          <ambient>0.647059 0.647059 0.647059 1</ambient>
          <diffuse>0.647059 0.647059 0.647059 1</diffuse>
          <specular>0.1 0.1 0.1 1</specular>
          <emissive>0 0 0 0</emissive>
        </material>
      </visual>
      <collision name="servo_wheel_17_collision_mesh_2">
        <pose relative_to="foot_assembly_3">5.55112e-17 4.33681e-19 -0.0025 -3.14159 5.39489e-17 2.29263e-30</pose>
        <geometry>
          <mesh>
            <uri>model://simulation/meshes/servo_wheel.stl</uri>
          </mesh>
        </geometry>
      </collision>
      <!-- Part servo_9 -->
      <visual name="servo_9_visual_mesh_1">
        <pose relative_to="foot_assembly_3">-0.0175 -0.00140442 -0.0305 3.14159 -1.83483e-16 1.94289e-15</pose>
        <geometry>
          <mesh>
            <uri>model://simulation/meshes/servo.stl</uri>
          </mesh>
        </geometry>
        <material>
          <ambient>0.109804 0.109804 0.105882 1</ambient>
          <diffuse>0.109804 0.109804 0.105882 1</diffuse>
          <specular>0.1 0.1 0.1 1</specular>
          <emissive>0 0 0 0</emissive>
        </material>
      </visual>
      <collision name="servo_9_collision_mesh_2">
        <pose relative_to="foot_assembly_3">-0.0175 -0.00140442 -0.0305 3.14159 -1.83483e-16 1.94289e-15</pose>
        <geometry>
          <mesh>
            <uri>model://simulation/meshes/servo.stl</uri>
          </mesh>
        </geometry>
      </collision>
      <!-- Part fixed_bracket_9 -->
      <visual name="fixed_bracket_9_visual_mesh_1">
        <pose relative_to="foot_assembly_3">-0.0575 -1.09288e-16 -0.0305 1.5708 1.5708 0</pose>
        <geometry>
          <mesh>
            <uri>model://simulation/meshes/fixed_bracket.stl</uri>
          </mesh>
        </geometry>
        <material>
          <ambient>0.647059 0.647059 0.647059 1</ambient>
          <diffuse>0.647059 0.647059 0.647059 1</diffuse>
          <specular>0.1 0.1 0.1 1</specular>
          <emissive>0 0 0 0</emissive>
        </material>
      </visual>
      <collision name="fixed_bracket_9_collision_mesh_2">
        <pose relative_to="foot_assembly_3">-0.0575 -1.09288e-16 -0.0305 1.5708 1.5708 0</pose>
        <geometry>
          <mesh>
            <uri>model://simulation/meshes/fixed_bracket.stl</uri>
          </mesh>
        </geometry>
      </collision>
      <!-- Part servo_wheel_18 -->
      <visual name="servo_wheel_18_visual_mesh_1">
        <pose relative_to="foot_assembly_3">0 2.29851e-17 -0.0585 3.14159 -2.89054e-15 1.94289e-15</pose>
        <geometry>
          <mesh>
            <uri>model://simulation/meshes/servo_wheel.stl</uri>
          </mesh>
        </geometry>
        <material>
          <ambient>0.647059 0.647059 0.647059 1</ambient>
          <diffuse>0.647059 0.647059 0.647059 1</diffuse>
          <specular>0.1 0.1 0.1 1</specular>
          <emissive>0 0 0 0</emissive>
        </material>
      </visual>
      <collision name="servo_wheel_18_collision_mesh_2">
        <pose relative_to="foot_assembly_3">0 2.29851e-17 -0.0585 3.14159 -2.89054e-15 1.94289e-15</pose>
        <geometry>
          <mesh>
            <uri>model://simulation/meshes/servo_wheel.stl</uri>
          </mesh>
        </geometry>
      </collision>
    </link>
    <!-- Joint from ties_assembly_3 to foot_assembly_3 -->
    <joint name="foot_3" type="revolute">
      <pose relative_to="ties_assembly_3">0.1918 0.000210323 -0.000790548 -3.79287e-15 5.88685e-15 3.14159</pose>
      <parent>ties_assembly_3</parent>
      <child>foot_assembly_3</child>
      <axis>
        <xyz>0 0 1</xyz>
        <limit>
          <effort>10</effort>
          <velocity>10</velocity>
          <lower>-2.09439510239319</lower>
          <upper>2.0943951023932006</upper>
        </limit>
        <dynamics>
          <friction>0.0</friction>
          <damping>0.0</damping>
        </dynamics>
      </axis>
    </joint>
    <!-- Joint from hip_assembly_3 to ties_assembly_3 -->
    <joint name="ties_3" type="revolute">
      <pose relative_to="hip_assembly_3">-0.0925 0.0311167 -0.0305 1.5708 -8.44496e-15 3.14159</pose>
      <parent>hip_assembly_3</parent>
      <child>ties_assembly_3</child>
      <axis>
        <xyz>0 0 1</xyz>
        <limit>
          <effort>10</effort>
          <velocity>10</velocity>
          <lower>-1.7453292519943429</lower>
          <upper>1.7453292519943162</upper>
        </limit>
        <dynamics>
          <friction>0.0</friction>
          <damping>0.0</damping>
        </dynamics>
      </axis>
    </joint>
    <!-- Joint from base_link to hip_assembly_3 -->
    <joint name="hip_3" type="revolute">
      <pose relative_to="base_link">0.131567 -0.0903312 0.0279706 -5.21026e-14 1.54133e-14 2.53073</pose>
      <parent>base_link</parent>
      <child>hip_assembly_3</child>
      <axis>
        <xyz>0 0 1</xyz>
        <limit>
          <effort>10</effort>
          <velocity>10</velocity>
          <lower>-1.570796326794163</lower>
          <upper>1.5707963267956302</upper>
        </limit>
        <dynamics>
          <friction>0.0</friction>
          <damping>0.0</damping>
        </dynamics>
      </axis>
    </joint>
    <!-- Link hip_assembly_4 -->
    <link name="hip_assembly_4">
      <inertial>
        <pose>-0.0268487 -0.000325484 -0.0302141 0 0 0</pose>
        <mass>0.365356</mass>
        <inertia>
          <ixx>0.000168136</ixx>
          <ixy>-2.8417e-07</ixy>
          <ixz>3.2467e-06</ixz>
          <iyy>0.000312332</iyy>
          <iyz>-9.42575e-07</iyz>
          <izz>0.000312341</izz>
        </inertia>
      </inertial>
      <pose relative_to="hip_4">0 0 0 0 -0 0</pose>
      <!-- Part hip_4 -->
      <visual name="hip_4_visual_mesh_1">
        <pose relative_to="hip_assembly_4">-0.0575 -0.0005 -0.0045 -1.39294e-15 -3.74584e-30 -1.95562e-17</pose>
        <geometry>
          <mesh>
            <uri>model://simulation/meshes/hip.stl</uri>
          </mesh>
        </geometry>
        <material>
          <ambient>0.282353 0.54902 0.160784 1</ambient>
          <diffuse>0.282353 0.54902 0.160784 1</diffuse>
          <specular>0.1 0.1 0.1 1</specular>
          <emissive>0 0 0 0</emissive>
        </material>
      </visual>
      <collision name="hip_4_collision_mesh_2">
        <pose relative_to="hip_assembly_4">-0.0575 -0.0005 -0.0045 -1.39294e-15 -3.74584e-30 -1.95562e-17</pose>
        <geometry>
          <mesh>
            <uri>model://simulation/meshes/hip.stl</uri>
          </mesh>
        </geometry>
      </collision>
      <!-- Part mobile_bracket_13 -->
      <visual name="mobile_bracket_13_visual_mesh_1">
        <pose relative_to="hip_assembly_4">-0.0575 -1.38778e-16 -0.0305 1.57073e-16 4.69506e-16 1.5708</pose>
        <geometry>
          <mesh>
            <uri>model://simulation/meshes/mobile_bracket.stl</uri>
          </mesh>
        </geometry>
        <material>
          <ambient>0.647059 0.647059 0.647059 1</ambient>
          <diffuse>0.647059 0.647059 0.647059 1</diffuse>
          <specular>0.1 0.1 0.1 1</specular>
          <emissive>0 0 0 0</emissive>
        </material>
      </visual>
      <collision name="mobile_bracket_13_collision_mesh_2">
        <pose relative_to="hip_assembly_4">-0.0575 -1.38778e-16 -0.0305 1.57073e-16 4.69506e-16 1.5708</pose>
        <geometry>
          <mesh>
            <uri>model://simulation/meshes/mobile_bracket.stl</uri>
          </mesh>
        </geometry>
      </collision>
      <!-- Part servo_wheel_19 -->
      <visual name="servo_wheel_19_visual_mesh_1">
        <pose relative_to="hip_assembly_4">0 2.60209e-18 -0.0025 3.14159 2.56504e-30 -4.56773e-19</pose>
        <geometry>
          <mesh>
            <uri>model://simulation/meshes/servo_wheel.stl</uri>
          </mesh>
        </geometry>
        <material>
          <ambient>0.647059 0.647059 0.647059 1</ambient>
          <diffuse>0.647059 0.647059 0.647059 1</diffuse>
          <specular>0.1 0.1 0.1 1</specular>
          <emissive>0 0 0 0</emissive>
        </material>
      </visual>
      <collision name="servo_wheel_19_collision_mesh_2">
        <pose relative_to="hip_assembly_4">0 2.60209e-18 -0.0025 3.14159 2.56504e-30 -4.56773e-19</pose>
        <geometry>
          <mesh>
            <uri>model://simulation/meshes/servo_wheel.stl</uri>
          </mesh>
        </geometry>
      </collision>
      <!-- Part servo_10 -->
      <visual name="servo_10_visual_mesh_1">
        <pose relative_to="hip_assembly_4">-0.0175 -0.00140442 -0.0305 3.14159 -3.74584e-30 -1.72722e-18</pose>
        <geometry>
          <mesh>
            <uri>model://simulation/meshes/servo.stl</uri>
          </mesh>
        </geometry>
        <material>
          <ambient>0.109804 0.109804 0.105882 1</ambient>
          <diffuse>0.109804 0.109804 0.105882 1</diffuse>
          <specular>0.1 0.1 0.1 1</specular>
          <emissive>0 0 0 0</emissive>
        </material>
      </visual>
      <collision name="servo_10_collision_mesh_2">
        <pose relative_to="hip_assembly_4">-0.0175 -0.00140442 -0.0305 3.14159 -3.74584e-30 -1.72722e-18</pose>
        <geometry>
          <mesh>
            <uri>model://simulation/meshes/servo.stl</uri>
          </mesh>
        </geometry>
      </collision>
      <!-- Part fixed_bracket_10 -->
      <visual name="fixed_bracket_10_visual_mesh_1">
        <pose relative_to="hip_assembly_4">-0.0575 8.67362e-18 -0.0305 1.5708 1.5708 0</pose>
        <geometry>
          <mesh>
            <uri>model://simulation/meshes/fixed_bracket.stl</uri>
          </mesh>
        </geometry>
        <material>
          <ambient>0.647059 0.647059 0.647059 1</ambient>
          <diffuse>0.647059 0.647059 0.647059 1</diffuse>
          <specular>0.1 0.1 0.1 1</specular>
          <emissive>0 0 0 0</emissive>
        </material>
      </visual>
      <collision name="fixed_bracket_10_collision_mesh_2">
        <pose relative_to="hip_assembly_4">-0.0575 8.67362e-18 -0.0305 1.5708 1.5708 0</pose>
        <geometry>
          <mesh>
            <uri>model://simulation/meshes/fixed_bracket.stl</uri>
          </mesh>
        </geometry>
      </collision>
      <!-- Part servo_wheel_20 -->
      <visual name="servo_wheel_20_visual_mesh_1">
        <pose relative_to="hip_assembly_4">1.66533e-16 -2.77556e-17 -0.0585 3.14159 4.31478e-16 5.3696e-16</pose>
        <geometry>
          <mesh>
            <uri>model://simulation/meshes/servo_wheel.stl</uri>
          </mesh>
        </geometry>
        <material>
          <ambient>0.647059 0.647059 0.647059 1</ambient>
          <diffuse>0.647059 0.647059 0.647059 1</diffuse>
          <specular>0.1 0.1 0.1 1</specular>
          <emissive>0 0 0 0</emissive>
        </material>
      </visual>
      <collision name="servo_wheel_20_collision_mesh_2">
        <pose relative_to="hip_assembly_4">1.66533e-16 -2.77556e-17 -0.0585 3.14159 4.31478e-16 5.3696e-16</pose>
        <geometry>
          <mesh>
            <uri>model://simulation/meshes/servo_wheel.stl</uri>
          </mesh>
        </geometry>
      </collision>
    </link>
    <!-- Link ties_assembly_4 -->
    <link name="ties_assembly_4">
      <inertial>
        <pose>0.0643598 0.00153088 -0.0309357 0 0 0</pose>
        <mass>0.589115</mass>
        <inertia>
          <ixx>0.000320336</ixx>
          <ixy>-2.41497e-05</ixy>
          <ixz>1.07866e-05</ixz>
          <iyy>0.00208685</iyy>
          <iyz>2.0947e-07</iyz>
          <izz>0.00187002</izz>
        </inertia>
      </inertial>
      <pose relative_to="ties_4">0 0 0 0 -0 0</pose>
      <!-- Part mobile_bracket_14 -->
      <visual name="mobile_bracket_14_visual_mesh_1">
        <pose relative_to="ties_assembly_4">0.1568 0.000210323 -0.0311738 1.5708 1.5708 0</pose>
        <geometry>
          <mesh>
            <uri>model://simulation/meshes/mobile_bracket.stl</uri>
          </mesh>
        </geometry>
        <material>
          <ambient>0.647059 0.647059 0.647059 1</ambient>
          <diffuse>0.647059 0.647059 0.647059 1</diffuse>
          <specular>0.1 0.1 0.1 1</specular>
          <emissive>0 0 0 0</emissive>
        </material>
      </visual>
      <collision name="mobile_bracket_14_collision_mesh_2">
        <pose relative_to="ties_assembly_4">0.1568 0.000210323 -0.0311738 1.5708 1.5708 0</pose>
        <geometry>
          <mesh>
            <uri>model://simulation/meshes/mobile_bracket.stl</uri>
          </mesh>
        </geometry>
      </collision>
      <!-- Part low_tie_4 -->
      <visual name="low_tie_4_visual_mesh_1">
        <pose relative_to="ties_assembly_4">0.0268 0.000210323 -0.0311738 -1.16307e-17 1.5708 0</pose>
        <geometry>
          <mesh>
            <uri>model://simulation/meshes/low_tie.stl</uri>
          </mesh>
        </geometry>
        <material>
          <ambient>0.282353 0.54902 0.160784 1</ambient>
          <diffuse>0.282353 0.54902 0.160784 1</diffuse>
          <specular>0.1 0.1 0.1 1</specular>
          <emissive>0 0 0 0</emissive>
        </material>
      </visual>
      <collision name="low_tie_4_collision_mesh_2">
        <pose relative_to="ties_assembly_4">0.0268 0.000210323 -0.0311738 -1.16307e-17 1.5708 0</pose>
        <geometry>
          <mesh>
            <uri>model://simulation/meshes/low_tie.stl</uri>
          </mesh>
        </geometry>
      </collision>
      <!-- Part top_tie_4 -->
      <visual name="top_tie_4_visual_mesh_1">
        <pose relative_to="ties_assembly_4">0.0275 -1.47451e-16 -0.0305 -1.16307e-17 1.5708 0</pose>
        <geometry>
          <mesh>
            <uri>model://simulation/meshes/top_tie.stl</uri>
          </mesh>
        </geometry>
        <material>
          <ambient>0.282353 0.54902 0.160784 1</ambient>
          <diffuse>0.282353 0.54902 0.160784 1</diffuse>
          <specular>0.1 0.1 0.1 1</specular>
          <emissive>0 0 0 0</emissive>
        </material>
      </visual>
      <collision name="top_tie_4_collision_mesh_2">
        <pose relative_to="ties_assembly_4">0.0275 -1.47451e-16 -0.0305 -1.16307e-17 1.5708 0</pose>
        <geometry>
          <mesh>
            <uri>model://simulation/meshes/top_tie.stl</uri>
          </mesh>
        </geometry>
      </collision>
      <!-- Part servo_wheel_21 -->
      <visual name="servo_wheel_21_visual_mesh_1">
        <pose relative_to="ties_assembly_4">-3.88578e-16 -1.4138e-16 -0.0025 3.14159 -3.84493e-15 -3.14159</pose>
        <geometry>
          <mesh>
            <uri>model://simulation/meshes/servo_wheel.stl</uri>
          </mesh>
        </geometry>
        <material>
          <ambient>0.647059 0.647059 0.647059 1</ambient>
          <diffuse>0.647059 0.647059 0.647059 1</diffuse>
          <specular>0.1 0.1 0.1 1</specular>
          <emissive>0 0 0 0</emissive>
        </material>
      </visual>
      <collision name="servo_wheel_21_collision_mesh_2">
        <pose relative_to="ties_assembly_4">-3.88578e-16 -1.4138e-16 -0.0025 3.14159 -3.84493e-15 -3.14159</pose>
        <geometry>
          <mesh>
            <uri>model://simulation/meshes/servo_wheel.stl</uri>
          </mesh>
        </geometry>
      </collision>
      <!-- Part servo_11 -->
      <visual name="servo_11_visual_mesh_1">
        <pose relative_to="ties_assembly_4">0.0175 0.00140442 -0.0305 -3.14159 -2.15642e-15 -3.14159</pose>
        <geometry>
          <mesh>
            <uri>model://simulation/meshes/servo.stl</uri>
          </mesh>
        </geometry>
        <material>
          <ambient>0.109804 0.109804 0.105882 1</ambient>
          <diffuse>0.109804 0.109804 0.105882 1</diffuse>
          <specular>0.1 0.1 0.1 1</specular>
          <emissive>0 0 0 0</emissive>
        </material>
      </visual>
      <collision name="servo_11_collision_mesh_2">
        <pose relative_to="ties_assembly_4">0.0175 0.00140442 -0.0305 -3.14159 -2.15642e-15 -3.14159</pose>
        <geometry>
          <mesh>
            <uri>model://simulation/meshes/servo.stl</uri>
          </mesh>
        </geometry>
      </collision>
      <!-- Part fixed_bracket_11 -->
      <visual name="fixed_bracket_11_visual_mesh_1">
        <pose relative_to="ties_assembly_4">0.0575 -3.42608e-17 -0.0305 -1.5708 1.5708 0</pose>
        <geometry>
          <mesh>
            <uri>model://simulation/meshes/fixed_bracket.stl</uri>
          </mesh>
        </geometry>
        <material>
          <ambient>0.647059 0.647059 0.647059 1</ambient>
          <diffuse>0.647059 0.647059 0.647059 1</diffuse>
          <specular>0.1 0.1 0.1 1</specular>
          <emissive>0 0 0 0</emissive>
        </material>
      </visual>
      <collision name="fixed_bracket_11_collision_mesh_2">
        <pose relative_to="ties_assembly_4">0.0575 -3.42608e-17 -0.0305 -1.5708 1.5708 0</pose>
        <geometry>
          <mesh>
            <uri>model://simulation/meshes/fixed_bracket.stl</uri>
          </mesh>
        </geometry>
      </collision>
      <!-- Part servo_wheel_22 -->
      <visual name="servo_wheel_22_visual_mesh_1">
        <pose relative_to="ties_assembly_4">-3.33067e-16 -1.40513e-16 -0.0585 -3.14159 -2.14127e-15 -3.14159</pose>
        <geometry>
          <mesh>
            <uri>model://simulation/meshes/servo_wheel.stl</uri>
          </mesh>
        </geometry>
        <material>
          <ambient>0.647059 0.647059 0.647059 1</ambient>
          <diffuse>0.647059 0.647059 0.647059 1</diffuse>
          <specular>0.1 0.1 0.1 1</specular>
          <emissive>0 0 0 0</emissive>
        </material>
      </visual>
      <collision name="servo_wheel_22_collision_mesh_2">
        <pose relative_to="ties_assembly_4">-3.33067e-16 -1.40513e-16 -0.0585 -3.14159 -2.14127e-15 -3.14159</pose>
        <geometry>
          <mesh>
            <uri>model://simulation/meshes/servo_wheel.stl</uri>
          </mesh>
        </geometry>
      </collision>
    </link>
    <!-- Link foot_assembly_4 -->
    <link name="foot_assembly_4">
      <inertial>
        <pose>-0.0724503 -0.00208415 -0.0306672 0 0 0</pose>
        <mass>0.633745</mass>
        <inertia>
          <ixx>0.000268495</ixx>
          <ixy>-1.4806e-05</ixy>
          <ixz>4.28294e-06</ixz>
          <iyy>0.00320961</iyy>
          <iyz>-2.30165e-07</iyz>
          <izz>0.00304658</izz>
        </inertia>
      </inertial>
      <pose relative_to="foot_4">0 0 0 0 -0 0</pose>
      <!-- Part foot_4 -->
      <visual name="foot_4_visual_mesh_1">
        <pose relative_to="foot_assembly_4">-0.04425 6.50521e-18 -0.0305 1.98251e-28 1.5708 0</pose>
        <geometry>
          <mesh>
            <uri>model://simulation/meshes/foot.stl</uri>
          </mesh>
        </geometry>
        <material>
          <ambient>0.282353 0.54902 0.160784 1</ambient>
          <diffuse>0.282353 0.54902 0.160784 1</diffuse>
          <specular>0.1 0.1 0.1 1</specular>
          <emissive>0 0 0 0</emissive>
        </material>
      </visual>
      <collision name="foot_4_collision_mesh_2">
        <pose relative_to="foot_assembly_4">-0.04425 6.50521e-18 -0.0305 1.98251e-28 1.5708 0</pose>
        <geometry>
          <mesh>
            <uri>model://simulation/meshes/foot.stl</uri>
          </mesh>
        </geometry>
      </collision>
      <!-- Part ir_sensor_cap_4 -->
      <visual name="ir_sensor_cap_4_visual_mesh_1">
        <pose relative_to="foot_assembly_4">-0.04425 -1.04083e-17 -0.0305 8.29418e-17 1.5708 0</pose>
        <geometry>
          <mesh>
            <uri>model://simulation/meshes/ir_sensor_cap.stl</uri>
          </mesh>
        </geometry>
        <material>
          <ambient>0.282353 0.54902 0.160784 1</ambient>
          <diffuse>0.282353 0.54902 0.160784 1</diffuse>
          <specular>0.1 0.1 0.1 1</specular>
          <emissive>0 0 0 0</emissive>
        </material>
      </visual>
      <collision name="ir_sensor_cap_4_collision_mesh_2">
        <pose relative_to="foot_assembly_4">-0.04425 -1.04083e-17 -0.0305 8.29418e-17 1.5708 0</pose>
        <geometry>
          <mesh>
            <uri>model://simulation/meshes/ir_sensor_cap.stl</uri>
          </mesh>
        </geometry>
      </collision>
      <!-- Part rubber_foot_4 -->
      <visual name="rubber_foot_4_visual_mesh_1">
        <pose relative_to="foot_assembly_4">-0.04375 -2.86229e-16 -0.03 4.996e-16 1.5708 0</pose>
        <geometry>
          <mesh>
            <uri>model://simulation/meshes/rubber_foot.stl</uri>
          </mesh>
        </geometry>
        <material>
          <ambient>0.262745 0.282353 0.301961 1</ambient>
          <diffuse>0.262745 0.282353 0.301961 1</diffuse>
          <specular>0.1 0.1 0.1 1</specular>
          <emissive>0 0 0 0</emissive>
        </material>
      </visual>
      <collision name="rubber_foot_4_collision_mesh_2">
        <pose relative_to="foot_assembly_4">-0.04375 -2.86229e-16 -0.03 4.996e-16 1.5708 0</pose>
        <geometry>
          <mesh>
            <uri>model://simulation/meshes/rubber_foot.stl</uri>
          </mesh>
        </geometry>
      </collision>
      <!-- Part servo_wheel_23 -->
      <visual name="servo_wheel_23_visual_mesh_1">
        <pose relative_to="foot_assembly_4">-5.55112e-17 0 -0.0025 -3.14159 -1.50813e-17 3.69779e-30</pose>
        <geometry>
          <mesh>
            <uri>model://simulation/meshes/servo_wheel.stl</uri>
          </mesh>
        </geometry>
        <material>
          <ambient>0.647059 0.647059 0.647059 1</ambient>
          <diffuse>0.647059 0.647059 0.647059 1</diffuse>
          <specular>0.1 0.1 0.1 1</specular>
          <emissive>0 0 0 0</emissive>
        </material>
      </visual>
      <collision name="servo_wheel_23_collision_mesh_2">
        <pose relative_to="foot_assembly_4">-5.55112e-17 0 -0.0025 -3.14159 -1.50813e-17 3.69779e-30</pose>
        <geometry>
          <mesh>
            <uri>model://simulation/meshes/servo_wheel.stl</uri>
          </mesh>
        </geometry>
      </collision>
      <!-- Part servo_12 -->
      <visual name="servo_12_visual_mesh_1">
        <pose relative_to="foot_assembly_4">-0.0175 -0.00140442 -0.0305 -3.14159 4.81166e-14 -2.78567e-29</pose>
        <geometry>
          <mesh>
            <uri>model://simulation/meshes/servo.stl</uri>
          </mesh>
        </geometry>
        <material>
          <ambient>0.109804 0.109804 0.105882 1</ambient>
          <diffuse>0.109804 0.109804 0.105882 1</diffuse>
          <specular>0.1 0.1 0.1 1</specular>
          <emissive>0 0 0 0</emissive>
        </material>
      </visual>
      <collision name="servo_12_collision_mesh_2">
        <pose relative_to="foot_assembly_4">-0.0175 -0.00140442 -0.0305 -3.14159 4.81166e-14 -2.78567e-29</pose>
        <geometry>
          <mesh>
            <uri>model://simulation/meshes/servo.stl</uri>
          </mesh>
        </geometry>
      </collision>
      <!-- Part fixed_bracket_12 -->
      <visual name="fixed_bracket_12_visual_mesh_1">
        <pose relative_to="foot_assembly_4">-0.0575 -1.20563e-16 -0.0305 1.5708 1.5708 0</pose>
        <geometry>
          <mesh>
            <uri>model://simulation/meshes/fixed_bracket.stl</uri>
          </mesh>
        </geometry>
        <material>
          <ambient>0.647059 0.647059 0.647059 1</ambient>
          <diffuse>0.647059 0.647059 0.647059 1</diffuse>
          <specular>0.1 0.1 0.1 1</specular>
          <emissive>0 0 0 0</emissive>
        </material>
      </visual>
      <collision name="fixed_bracket_12_collision_mesh_2">
        <pose relative_to="foot_assembly_4">-0.0575 -1.20563e-16 -0.0305 1.5708 1.5708 0</pose>
        <geometry>
          <mesh>
            <uri>model://simulation/meshes/fixed_bracket.stl</uri>
          </mesh>
        </geometry>
      </collision>
      <!-- Part servo_wheel_24 -->
      <visual name="servo_wheel_24_visual_mesh_1">
        <pose relative_to="foot_assembly_4">-1.11022e-16 4.33681e-19 -0.0585 -3.14159 4.81093e-14 -2.78567e-29</pose>
        <geometry>
          <mesh>
            <uri>model://simulation/meshes/servo_wheel.stl</uri>
          </mesh>
        </geometry>
        <material>
          <ambient>0.647059 0.647059 0.647059 1</ambient>
          <diffuse>0.647059 0.647059 0.647059 1</diffuse>
          <specular>0.1 0.1 0.1 1</specular>
          <emissive>0 0 0 0</emissive>
        </material>
      </visual>
      <collision name="servo_wheel_24_collision_mesh_2">
        <pose relative_to="foot_assembly_4">-1.11022e-16 4.33681e-19 -0.0585 -3.14159 4.81093e-14 -2.78567e-29</pose>
        <geometry>
          <mesh>
            <uri>model://simulation/meshes/servo_wheel.stl</uri>
          </mesh>
        </geometry>
      </collision>
    </link>
    <!-- Joint from ties_assembly_4 to foot_assembly_4 -->
    <joint name="foot_4" type="revolute">
      <pose relative_to="ties_assembly_4">0.1918 0.000210323 -0.000790548 -4.61349e-16 -1.38317e-14 3.14159</pose>
      <parent>ties_assembly_4</parent>
      <child>foot_assembly_4</child>
      <axis>
        <xyz>0 0 1</xyz>
        <limit>
          <effort>10</effort>
          <velocity>10</velocity>
          <lower>-2.0943951023931837</lower>
          <upper>2.094395102393207</upper>
        </limit>
        <dynamics>
          <friction>0.0</friction>
          <damping>0.0</damping>
        </dynamics>
      </axis>
    </joint>
    <!-- Joint from hip_assembly_4 to ties_assembly_4 -->
    <joint name="ties_4" type="revolute">
      <pose relative_to="hip_assembly_4">-0.0925 0.0311167 -0.0305 1.5708 -1.57073e-16 -3.14159</pose>
      <parent>hip_assembly_4</parent>
      <child>ties_assembly_4</child>
      <axis>
        <xyz>0 0 1</xyz>
        <limit>
          <effort>10</effort>
          <velocity>10</velocity>
          <lower>-1.7453292519943313</lower>
          <upper>1.7453292519943278</upper>
        </limit>
        <dynamics>
          <friction>0.0</friction>
          <damping>0.0</damping>
        </dynamics>
      </axis>
    </joint>
    <!-- Joint from base_link to hip_assembly_4 -->
    <joint name="hip_4" type="revolute">
      <pose relative_to="base_link">-0.0062068 -0.154576 0.0279706 -3.9315e-14 -3.78053e-14 1.48353</pose>
      <parent>base_link</parent>
      <child>hip_assembly_4</child>
      <axis>
        <xyz>0 0 1</xyz>
        <limit>
          <effort>10</effort>
          <velocity>10</velocity>
          <lower>-1.5707963267956329</lower>
          <upper>1.5707963267941603</upper>
        </limit>
        <dynamics>
          <friction>0.0</friction>
          <damping>0.0</damping>
        </dynamics>
      </axis>
    </joint>
    <!-- Link hip_assembly_5 -->
    <link name="hip_assembly_5">
      <inertial>
        <pose>0.0268487 0.000325484 -0.0302141 0 0 0</pose>
        <mass>0.365356</mass>
        <inertia>
          <ixx>0.000168136</ixx>
          <ixy>-2.8417e-07</ixy>
          <ixz>-3.2467e-06</ixz>
          <iyy>0.000312332</iyy>
          <iyz>9.42575e-07</iyz>
          <izz>0.000312341</izz>
        </inertia>
      </inertial>
      <pose relative_to="hip_5">0 0 0 0 -0 0</pose>
      <!-- Part hip_5 -->
      <visual name="hip_5_visual_mesh_1">
        <pose relative_to="hip_assembly_5">0.0575 0.0005 -0.0045 -4.7743e-15 5.17634e-17 -3.14159</pose>
        <geometry>
          <mesh>
            <uri>model://simulation/meshes/hip.stl</uri>
          </mesh>
        </geometry>
        <material>
          <ambient>0.282353 0.54902 0.160784 1</ambient>
          <diffuse>0.282353 0.54902 0.160784 1</diffuse>
          <specular>0.1 0.1 0.1 1</specular>
          <emissive>0 0 0 0</emissive>
        </material>
      </visual>
      <collision name="hip_5_collision_mesh_2">
        <pose relative_to="hip_assembly_5">0.0575 0.0005 -0.0045 -4.7743e-15 5.17634e-17 -3.14159</pose>
        <geometry>
          <mesh>
            <uri>model://simulation/meshes/hip.stl</uri>
          </mesh>
        </geometry>
      </collision>
      <!-- Part mobile_bracket_15 -->
      <visual name="mobile_bracket_15_visual_mesh_1">
        <pose relative_to="hip_assembly_5">0.0575 2.86429e-14 -0.0305 5.17634e-17 2.86469e-14 -1.5708</pose>
        <geometry>
          <mesh>
            <uri>model://simulation/meshes/mobile_bracket.stl</uri>
          </mesh>
        </geometry>
        <material>
          <ambient>0.647059 0.647059 0.647059 1</ambient>
          <diffuse>0.647059 0.647059 0.647059 1</diffuse>
          <specular>0.1 0.1 0.1 1</specular>
          <emissive>0 0 0 0</emissive>
        </material>
      </visual>
      <collision name="mobile_bracket_15_collision_mesh_2">
        <pose relative_to="hip_assembly_5">0.0575 2.86429e-14 -0.0305 5.17634e-17 2.86469e-14 -1.5708</pose>
        <geometry>
          <mesh>
            <uri>model://simulation/meshes/mobile_bracket.stl</uri>
          </mesh>
        </geometry>
      </collision>
      <!-- Part servo_wheel_25 -->
      <visual name="servo_wheel_25_visual_mesh_1">
        <pose relative_to="hip_assembly_5">0 1.73472e-18 -0.0025 3.14159 5.17634e-17 -3.14159</pose>
        <geometry>
          <mesh>
            <uri>model://simulation/meshes/servo_wheel.stl</uri>
          </mesh>
        </geometry>
        <material>
          <ambient>0.647059 0.647059 0.647059 1</ambient>
          <diffuse>0.647059 0.647059 0.647059 1</diffuse>
          <specular>0.1 0.1 0.1 1</specular>
          <emissive>0 0 0 0</emissive>
        </material>
      </visual>
      <collision name="servo_wheel_25_collision_mesh_2">
        <pose relative_to="hip_assembly_5">0 1.73472e-18 -0.0025 3.14159 5.17634e-17 -3.14159</pose>
        <geometry>
          <mesh>
            <uri>model://simulation/meshes/servo_wheel.stl</uri>
          </mesh>
        </geometry>
      </collision>
      <!-- Part servo_13 -->
      <visual name="servo_13_visual_mesh_1">
        <pose relative_to="hip_assembly_5">0.0175 0.00140442 -0.0305 3.14159 5.17634e-17 -3.14159</pose>
        <geometry>
          <mesh>
            <uri>model://simulation/meshes/servo.stl</uri>
          </mesh>
        </geometry>
        <material>
          <ambient>0.109804 0.109804 0.105882 1</ambient>
          <diffuse>0.109804 0.109804 0.105882 1</diffuse>
          <specular>0.1 0.1 0.1 1</specular>
          <emissive>0 0 0 0</emissive>
        </material>
      </visual>
      <collision name="servo_13_collision_mesh_2">
        <pose relative_to="hip_assembly_5">0.0175 0.00140442 -0.0305 3.14159 5.17634e-17 -3.14159</pose>
        <geometry>
          <mesh>
            <uri>model://simulation/meshes/servo.stl</uri>
          </mesh>
        </geometry>
      </collision>
      <!-- Part fixed_bracket_13 -->
      <visual name="fixed_bracket_13_visual_mesh_1">
        <pose relative_to="hip_assembly_5">0.0575 2.86429e-14 -0.0305 -1.5708 1.5708 0</pose>
        <geometry>
          <mesh>
            <uri>model://simulation/meshes/fixed_bracket.stl</uri>
          </mesh>
        </geometry>
        <material>
          <ambient>0.647059 0.647059 0.647059 1</ambient>
          <diffuse>0.647059 0.647059 0.647059 1</diffuse>
          <specular>0.1 0.1 0.1 1</specular>
          <emissive>0 0 0 0</emissive>
        </material>
      </visual>
      <collision name="fixed_bracket_13_collision_mesh_2">
        <pose relative_to="hip_assembly_5">0.0575 2.86429e-14 -0.0305 -1.5708 1.5708 0</pose>
        <geometry>
          <mesh>
            <uri>model://simulation/meshes/fixed_bracket.stl</uri>
          </mesh>
        </geometry>
      </collision>
      <!-- Part servo_wheel_26 -->
      <visual name="servo_wheel_26_visual_mesh_1">
        <pose relative_to="hip_assembly_5">0 4.33681e-18 -0.0585 3.14159 5.17634e-17 -3.14159</pose>
        <geometry>
          <mesh>
            <uri>model://simulation/meshes/servo_wheel.stl</uri>
          </mesh>
        </geometry>
        <material>
          <ambient>0.647059 0.647059 0.647059 1</ambient>
          <diffuse>0.647059 0.647059 0.647059 1</diffuse>
          <specular>0.1 0.1 0.1 1</specular>
          <emissive>0 0 0 0</emissive>
        </material>
      </visual>
      <collision name="servo_wheel_26_collision_mesh_2">
        <pose relative_to="hip_assembly_5">0 4.33681e-18 -0.0585 3.14159 5.17634e-17 -3.14159</pose>
        <geometry>
          <mesh>
            <uri>model://simulation/meshes/servo_wheel.stl</uri>
          </mesh>
        </geometry>
      </collision>
    </link>
    <!-- Link ties_assembly_5 -->
    <link name="ties_assembly_5">
      <inertial>
        <pose>0.0643598 0.00153088 -0.0309357 0 0 0</pose>
        <mass>0.589115</mass>
        <inertia>
          <ixx>0.000320336</ixx>
          <ixy>-2.41497e-05</ixy>
          <ixz>1.07866e-05</ixz>
          <iyy>0.00208685</iyy>
          <iyz>2.0947e-07</iyz>
          <izz>0.00187002</izz>
        </inertia>
      </inertial>
      <pose relative_to="ties_5">0 0 0 0 -0 0</pose>
      <!-- Part mobile_bracket_16 -->
      <visual name="mobile_bracket_16_visual_mesh_1">
        <pose relative_to="ties_assembly_5">0.1568 0.000210323 -0.0311738 1.5708 1.5708 0</pose>
        <geometry>
          <mesh>
            <uri>model://simulation/meshes/mobile_bracket.stl</uri>
          </mesh>
        </geometry>
        <material>
          <ambient>0.647059 0.647059 0.647059 1</ambient>
          <diffuse>0.647059 0.647059 0.647059 1</diffuse>
          <specular>0.1 0.1 0.1 1</specular>
          <emissive>0 0 0 0</emissive>
        </material>
      </visual>
      <collision name="mobile_bracket_16_collision_mesh_2">
        <pose relative_to="ties_assembly_5">0.1568 0.000210323 -0.0311738 1.5708 1.5708 0</pose>
        <geometry>
          <mesh>
            <uri>model://simulation/meshes/mobile_bracket.stl</uri>
          </mesh>
        </geometry>
      </collision>
      <!-- Part low_tie_5 -->
      <visual name="low_tie_5_visual_mesh_1">
        <pose relative_to="ties_assembly_5">0.0268 0.000210323 -0.0311738 -2.58324e-14 1.5708 0</pose>
        <geometry>
          <mesh>
            <uri>model://simulation/meshes/low_tie.stl</uri>
          </mesh>
        </geometry>
        <material>
          <ambient>0.282353 0.54902 0.160784 1</ambient>
          <diffuse>0.282353 0.54902 0.160784 1</diffuse>
          <specular>0.1 0.1 0.1 1</specular>
          <emissive>0 0 0 0</emissive>
        </material>
      </visual>
      <collision name="low_tie_5_collision_mesh_2">
        <pose relative_to="ties_assembly_5">0.0268 0.000210323 -0.0311738 -2.58324e-14 1.5708 0</pose>
        <geometry>
          <mesh>
            <uri>model://simulation/meshes/low_tie.stl</uri>
          </mesh>
        </geometry>
      </collision>
      <!-- Part top_tie_5 -->
      <visual name="top_tie_5_visual_mesh_1">
        <pose relative_to="ties_assembly_5">0.0275 6.80445e-16 -0.0305 -2.58324e-14 1.5708 0</pose>
        <geometry>
          <mesh>
            <uri>model://simulation/meshes/top_tie.stl</uri>
          </mesh>
        </geometry>
        <material>
          <ambient>0.282353 0.54902 0.160784 1</ambient>
          <diffuse>0.282353 0.54902 0.160784 1</diffuse>
          <specular>0.1 0.1 0.1 1</specular>
          <emissive>0 0 0 0</emissive>
        </material>
      </visual>
      <collision name="top_tie_5_collision_mesh_2">
        <pose relative_to="ties_assembly_5">0.0275 6.80445e-16 -0.0305 -2.58324e-14 1.5708 0</pose>
        <geometry>
          <mesh>
            <uri>model://simulation/meshes/top_tie.stl</uri>
          </mesh>
        </geometry>
      </collision>
      <!-- Part servo_wheel_27 -->
      <visual name="servo_wheel_27_visual_mesh_1">
        <pose relative_to="ties_assembly_5">-2.77556e-17 -4.33681e-19 -0.0025 -3.14159 -1.64892e-15 -3.14159</pose>
        <geometry>
          <mesh>
            <uri>model://simulation/meshes/servo_wheel.stl</uri>
          </mesh>
        </geometry>
        <material>
          <ambient>0.647059 0.647059 0.647059 1</ambient>
          <diffuse>0.647059 0.647059 0.647059 1</diffuse>
          <specular>0.1 0.1 0.1 1</specular>
          <emissive>0 0 0 0</emissive>
        </material>
      </visual>
      <collision name="servo_wheel_27_collision_mesh_2">
        <pose relative_to="ties_assembly_5">-2.77556e-17 -4.33681e-19 -0.0025 -3.14159 -1.64892e-15 -3.14159</pose>
        <geometry>
          <mesh>
            <uri>model://simulation/meshes/servo_wheel.stl</uri>
          </mesh>
        </geometry>
      </collision>
      <!-- Part servo_14 -->
      <visual name="servo_14_visual_mesh_1">
        <pose relative_to="ties_assembly_5">0.0175 0.00140442 -0.0305 -3.14159 -1.69923e-15 -3.14159</pose>
        <geometry>
          <mesh>
            <uri>model://simulation/meshes/servo.stl</uri>
          </mesh>
        </geometry>
        <material>
          <ambient>0.109804 0.109804 0.105882 1</ambient>
          <diffuse>0.109804 0.109804 0.105882 1</diffuse>
          <specular>0.1 0.1 0.1 1</specular>
          <emissive>0 0 0 0</emissive>
        </material>
      </visual>
      <collision name="servo_14_collision_mesh_2">
        <pose relative_to="ties_assembly_5">0.0175 0.00140442 -0.0305 -3.14159 -1.69923e-15 -3.14159</pose>
        <geometry>
          <mesh>
            <uri>model://simulation/meshes/servo.stl</uri>
          </mesh>
        </geometry>
      </collision>
      <!-- Part fixed_bracket_14 -->
      <visual name="fixed_bracket_14_visual_mesh_1">
        <pose relative_to="ties_assembly_5">0.0575 1.45457e-15 -0.0305 -1.5708 1.5708 0</pose>
        <geometry>
          <mesh>
            <uri>model://simulation/meshes/fixed_bracket.stl</uri>
          </mesh>
        </geometry>
        <material>
          <ambient>0.647059 0.647059 0.647059 1</ambient>
          <diffuse>0.647059 0.647059 0.647059 1</diffuse>
          <specular>0.1 0.1 0.1 1</specular>
          <emissive>0 0 0 0</emissive>
        </material>
      </visual>
      <collision name="fixed_bracket_14_collision_mesh_2">
        <pose relative_to="ties_assembly_5">0.0575 1.45457e-15 -0.0305 -1.5708 1.5708 0</pose>
        <geometry>
          <mesh>
            <uri>model://simulation/meshes/fixed_bracket.stl</uri>
          </mesh>
        </geometry>
      </collision>
      <!-- Part servo_wheel_28 -->
      <visual name="servo_wheel_28_visual_mesh_1">
        <pose relative_to="ties_assembly_5">-1.11022e-16 4.33681e-19 -0.0585 -3.14159 -1.67672e-15 -3.14159</pose>
        <geometry>
          <mesh>
            <uri>model://simulation/meshes/servo_wheel.stl</uri>
          </mesh>
        </geometry>
        <material>
          <ambient>0.647059 0.647059 0.647059 1</ambient>
          <diffuse>0.647059 0.647059 0.647059 1</diffuse>
          <specular>0.1 0.1 0.1 1</specular>
          <emissive>0 0 0 0</emissive>
        </material>
      </visual>
      <collision name="servo_wheel_28_collision_mesh_2">
        <pose relative_to="ties_assembly_5">-1.11022e-16 4.33681e-19 -0.0585 -3.14159 -1.67672e-15 -3.14159</pose>
        <geometry>
          <mesh>
            <uri>model://simulation/meshes/servo_wheel.stl</uri>
          </mesh>
        </geometry>
      </collision>
    </link>
    <!-- Link foot_assembly_5 -->
    <link name="foot_assembly_5">
      <inertial>
        <pose>-0.0724503 -0.00208415 -0.0306672 0 0 0</pose>
        <mass>0.633745</mass>
        <inertia>
          <ixx>0.000268495</ixx>
          <ixy>-1.4806e-05</ixy>
          <ixz>4.28294e-06</ixz>
          <iyy>0.00320961</iyy>
          <iyz>-2.30165e-07</iyz>
          <izz>0.00304658</izz>
        </inertia>
      </inertial>
      <pose relative_to="foot_5">0 0 0 0 -0 0</pose>
      <!-- Part foot_5 -->
      <visual name="foot_5_visual_mesh_1">
        <pose relative_to="foot_assembly_5">-0.04425 5.20417e-18 -0.0305 5.55112e-17 1.5708 0</pose>
        <geometry>
          <mesh>
            <uri>model://simulation/meshes/foot.stl</uri>
          </mesh>
        </geometry>
        <material>
          <ambient>0.282353 0.54902 0.160784 1</ambient>
          <diffuse>0.282353 0.54902 0.160784 1</diffuse>
          <specular>0.1 0.1 0.1 1</specular>
          <emissive>0 0 0 0</emissive>
        </material>
      </visual>
      <collision name="foot_5_collision_mesh_2">
        <pose relative_to="foot_assembly_5">-0.04425 5.20417e-18 -0.0305 5.55112e-17 1.5708 0</pose>
        <geometry>
          <mesh>
            <uri>model://simulation/meshes/foot.stl</uri>
          </mesh>
        </geometry>
      </collision>
      <!-- Part ir_sensor_cap_5 -->
      <visual name="ir_sensor_cap_5_visual_mesh_1">
        <pose relative_to="foot_assembly_5">-0.04425 2.10335e-15 -0.0305 -1.26426e-14 1.5708 0</pose>
        <geometry>
          <mesh>
            <uri>model://simulation/meshes/ir_sensor_cap.stl</uri>
          </mesh>
        </geometry>
        <material>
          <ambient>0.282353 0.54902 0.160784 1</ambient>
          <diffuse>0.282353 0.54902 0.160784 1</diffuse>
          <specular>0.1 0.1 0.1 1</specular>
          <emissive>0 0 0 0</emissive>
        </material>
      </visual>
      <collision name="ir_sensor_cap_5_collision_mesh_2">
        <pose relative_to="foot_assembly_5">-0.04425 2.10335e-15 -0.0305 -1.26426e-14 1.5708 0</pose>
        <geometry>
          <mesh>
            <uri>model://simulation/meshes/ir_sensor_cap.stl</uri>
          </mesh>
        </geometry>
      </collision>
      <!-- Part rubber_foot_5 -->
      <visual name="rubber_foot_5_visual_mesh_1">
        <pose relative_to="foot_assembly_5">-0.04375 2.86967e-15 -0.03 -1.35447e-14 1.5708 0</pose>
        <geometry>
          <mesh>
            <uri>model://simulation/meshes/rubber_foot.stl</uri>
          </mesh>
        </geometry>
        <material>
          <ambient>0.262745 0.282353 0.301961 1</ambient>
          <diffuse>0.262745 0.282353 0.301961 1</diffuse>
          <specular>0.1 0.1 0.1 1</specular>
          <emissive>0 0 0 0</emissive>
        </material>
      </visual>
      <collision name="rubber_foot_5_collision_mesh_2">
        <pose relative_to="foot_assembly_5">-0.04375 2.86967e-15 -0.03 -1.35447e-14 1.5708 0</pose>
        <geometry>
          <mesh>
            <uri>model://simulation/meshes/rubber_foot.stl</uri>
          </mesh>
        </geometry>
      </collision>
      <!-- Part servo_wheel_29 -->
      <visual name="servo_wheel_29_visual_mesh_1">
        <pose relative_to="foot_assembly_5">0 0 -0.0025 3.14159 -5.93214e-17 -3.52522e-30</pose>
        <geometry>
          <mesh>
            <uri>model://simulation/meshes/servo_wheel.stl</uri>
          </mesh>
        </geometry>
        <material>
          <ambient>0.647059 0.647059 0.647059 1</ambient>
          <diffuse>0.647059 0.647059 0.647059 1</diffuse>
          <specular>0.1 0.1 0.1 1</specular>
          <emissive>0 0 0 0</emissive>
        </material>
      </visual>
      <collision name="servo_wheel_29_collision_mesh_2">
        <pose relative_to="foot_assembly_5">0 0 -0.0025 3.14159 -5.93214e-17 -3.52522e-30</pose>
        <geometry>
          <mesh>
            <uri>model://simulation/meshes/servo_wheel.stl</uri>
          </mesh>
        </geometry>
      </collision>
      <!-- Part servo_15 -->
      <visual name="servo_15_visual_mesh_1">
        <pose relative_to="foot_assembly_5">-0.0175 -0.00140442 -0.0305 3.14159 -6.9945e-16 4.44089e-16</pose>
        <geometry>
          <mesh>
            <uri>model://simulation/meshes/servo.stl</uri>
          </mesh>
        </geometry>
        <material>
          <ambient>0.109804 0.109804 0.105882 1</ambient>
          <diffuse>0.109804 0.109804 0.105882 1</diffuse>
          <specular>0.1 0.1 0.1 1</specular>
          <emissive>0 0 0 0</emissive>
        </material>
      </visual>
      <collision name="servo_15_collision_mesh_2">
        <pose relative_to="foot_assembly_5">-0.0175 -0.00140442 -0.0305 3.14159 -6.9945e-16 4.44089e-16</pose>
        <geometry>
          <mesh>
            <uri>model://simulation/meshes/servo.stl</uri>
          </mesh>
        </geometry>
      </collision>
      <!-- Part fixed_bracket_15 -->
      <visual name="fixed_bracket_15_visual_mesh_1">
        <pose relative_to="foot_assembly_5">-0.0575 6.50521e-18 -0.0305 1.5708 1.5708 0</pose>
        <geometry>
          <mesh>
            <uri>model://simulation/meshes/fixed_bracket.stl</uri>
          </mesh>
        </geometry>
        <material>
          <ambient>0.647059 0.647059 0.647059 1</ambient>
          <diffuse>0.647059 0.647059 0.647059 1</diffuse>
          <specular>0.1 0.1 0.1 1</specular>
          <emissive>0 0 0 0</emissive>
        </material>
      </visual>
      <collision name="fixed_bracket_15_collision_mesh_2">
        <pose relative_to="foot_assembly_5">-0.0575 6.50521e-18 -0.0305 1.5708 1.5708 0</pose>
        <geometry>
          <mesh>
            <uri>model://simulation/meshes/fixed_bracket.stl</uri>
          </mesh>
        </geometry>
      </collision>
      <!-- Part servo_wheel_30 -->
      <visual name="servo_wheel_30_visual_mesh_1">
        <pose relative_to="foot_assembly_5">-5.55112e-17 4.38018e-17 -0.0585 3.14159 -7.15053e-16 4.44089e-16</pose>
        <geometry>
          <mesh>
            <uri>model://simulation/meshes/servo_wheel.stl</uri>
          </mesh>
        </geometry>
        <material>
          <ambient>0.647059 0.647059 0.647059 1</ambient>
          <diffuse>0.647059 0.647059 0.647059 1</diffuse>
          <specular>0.1 0.1 0.1 1</specular>
          <emissive>0 0 0 0</emissive>
        </material>
      </visual>
      <collision name="servo_wheel_30_collision_mesh_2">
        <pose relative_to="foot_assembly_5">-5.55112e-17 4.38018e-17 -0.0585 3.14159 -7.15053e-16 4.44089e-16</pose>
        <geometry>
          <mesh>
            <uri>model://simulation/meshes/servo_wheel.stl</uri>
          </mesh>
        </geometry>
      </collision>
    </link>
    <!-- Joint from ties_assembly_5 to foot_assembly_5 -->
    <joint name="foot_5" type="revolute">
      <pose relative_to="ties_assembly_5">0.1918 0.000210323 -0.000790548 3.05282e-15 -8.87362e-16 -3.14159</pose>
      <parent>ties_assembly_5</parent>
      <child>foot_assembly_5</child>
      <axis>
        <xyz>0 0 1</xyz>
        <limit>
          <effort>10</effort>
          <velocity>10</velocity>
          <lower>-2.0943951023931926</lower>
          <upper>2.094395102393198</upper>
        </limit>
        <dynamics>
          <friction>0.0</friction>
          <damping>0.0</damping>
        </dynamics>
      </axis>
    </joint>
    <!-- Joint from hip_assembly_5 to ties_assembly_5 -->
    <joint name="ties_5" type="revolute">
      <pose relative_to="hip_assembly_5">0.0925 -0.0311167 -0.0305 1.5708 -5.17634e-17 4.98829e-13</pose>
      <parent>hip_assembly_5</parent>
      <child>ties_assembly_5</child>
      <axis>
        <xyz>0 0 1</xyz>
        <limit>
          <effort>10</effort>
          <velocity>10</velocity>
          <lower>-1.7453292519943553</lower>
          <upper>1.7453292519943038</upper>
        </limit>
        <dynamics>
          <friction>0.0</friction>
          <damping>0.0</damping>
        </dynamics>
      </axis>
    </joint>
    <!-- Joint from base_link to hip_assembly_5 -->
    <joint name="hip_5" type="revolute">
      <pose relative_to="base_link">-0.130732 -0.0673829 0.0279706 -1.23219e-14 5.33622e-14 -2.70526</pose>
      <parent>base_link</parent>
      <child>hip_assembly_5</child>
      <axis>
        <xyz>0 0 1</xyz>
        <limit>
          <effort>10</effort>
          <velocity>10</velocity>
          <lower>-1.5707963267941523</lower>
          <upper>1.5707963267956409</upper>
        </limit>
        <dynamics>
          <friction>0.0</friction>
          <damping>0.0</damping>
        </dynamics>
      </axis>
    </joint>
    <!-- Link hip_assembly_6 -->
    <link name="hip_assembly_6">
      <inertial>
        <pose>-0.0268487 -0.000325484 -0.0302141 0 0 0</pose>
        <mass>0.365356</mass>
        <inertia>
          <ixx>0.000168136</ixx>
          <ixy>-2.8417e-07</ixy>
          <ixz>3.2467e-06</ixz>
          <iyy>0.000312332</iyy>
          <iyz>-9.42575e-07</iyz>
          <izz>0.000312341</izz>
        </inertia>
      </inertial>
      <pose relative_to="hip_6">0 0 0 0 -0 0</pose>
      <!-- Part hip_6 -->
      <visual name="hip_6_visual_mesh_1">
        <pose relative_to="hip_assembly_6">-0.0575 -0.0005 -0.0045 1.09646e-16 1.6208e-16 -8.34807e-16</pose>
        <geometry>
          <mesh>
            <uri>model://simulation/meshes/hip.stl</uri>
          </mesh>
        </geometry>
        <material>
          <ambient>0.282353 0.54902 0.160784 1</ambient>
          <diffuse>0.282353 0.54902 0.160784 1</diffuse>
          <specular>0.1 0.1 0.1 1</specular>
          <emissive>0 0 0 0</emissive>
        </material>
      </visual>
      <collision name="hip_6_collision_mesh_2">
        <pose relative_to="hip_assembly_6">-0.0575 -0.0005 -0.0045 1.09646e-16 1.6208e-16 -8.34807e-16</pose>
        <geometry>
          <mesh>
            <uri>model://simulation/meshes/hip.stl</uri>
          </mesh>
        </geometry>
      </collision>
      <!-- Part mobile_bracket_17 -->
      <visual name="mobile_bracket_17_visual_mesh_1">
        <pose relative_to="hip_assembly_6">-0.0575 5.5728e-17 -0.0305 1.6208e-16 -3.94756e-14 1.5708</pose>
        <geometry>
          <mesh>
            <uri>model://simulation/meshes/mobile_bracket.stl</uri>
          </mesh>
        </geometry>
        <material>
          <ambient>0.647059 0.647059 0.647059 1</ambient>
          <diffuse>0.647059 0.647059 0.647059 1</diffuse>
          <specular>0.1 0.1 0.1 1</specular>
          <emissive>0 0 0 0</emissive>
        </material>
      </visual>
      <collision name="mobile_bracket_17_collision_mesh_2">
        <pose relative_to="hip_assembly_6">-0.0575 5.5728e-17 -0.0305 1.6208e-16 -3.94756e-14 1.5708</pose>
        <geometry>
          <mesh>
            <uri>model://simulation/meshes/mobile_bracket.stl</uri>
          </mesh>
        </geometry>
      </collision>
      <!-- Part servo_wheel_31 -->
      <visual name="servo_wheel_31_visual_mesh_1">
        <pose relative_to="hip_assembly_6">-2.77556e-17 3.25261e-18 -0.0025 -3.14159 -5.20433e-30 1.19819e-17</pose>
        <geometry>
          <mesh>
            <uri>model://simulation/meshes/servo_wheel.stl</uri>
          </mesh>
        </geometry>
        <material>
          <ambient>0.647059 0.647059 0.647059 1</ambient>
          <diffuse>0.647059 0.647059 0.647059 1</diffuse>
          <specular>0.1 0.1 0.1 1</specular>
          <emissive>0 0 0 0</emissive>
        </material>
      </visual>
      <collision name="servo_wheel_31_collision_mesh_2">
        <pose relative_to="hip_assembly_6">-2.77556e-17 3.25261e-18 -0.0025 -3.14159 -5.20433e-30 1.19819e-17</pose>
        <geometry>
          <mesh>
            <uri>model://simulation/meshes/servo_wheel.stl</uri>
          </mesh>
        </geometry>
      </collision>
      <!-- Part servo_16 -->
      <visual name="servo_16_visual_mesh_1">
        <pose relative_to="hip_assembly_6">-0.0175 -0.00140442 -0.0305 3.14159 1.6208e-16 -8.34839e-16</pose>
        <geometry>
          <mesh>
            <uri>model://simulation/meshes/servo.stl</uri>
          </mesh>
        </geometry>
        <material>
          <ambient>0.109804 0.109804 0.105882 1</ambient>
          <diffuse>0.109804 0.109804 0.105882 1</diffuse>
          <specular>0.1 0.1 0.1 1</specular>
          <emissive>0 0 0 0</emissive>
        </material>
      </visual>
      <collision name="servo_16_collision_mesh_2">
        <pose relative_to="hip_assembly_6">-0.0175 -0.00140442 -0.0305 3.14159 1.6208e-16 -8.34839e-16</pose>
        <geometry>
          <mesh>
            <uri>model://simulation/meshes/servo.stl</uri>
          </mesh>
        </geometry>
      </collision>
      <!-- Part fixed_bracket_16 -->
      <visual name="fixed_bracket_16_visual_mesh_1">
        <pose relative_to="hip_assembly_6">-0.0575 5.5728e-17 -0.0305 1.5708 1.5708 0</pose>
        <geometry>
          <mesh>
            <uri>model://simulation/meshes/fixed_bracket.stl</uri>
          </mesh>
        </geometry>
        <material>
          <ambient>0.647059 0.647059 0.647059 1</ambient>
          <diffuse>0.647059 0.647059 0.647059 1</diffuse>
          <specular>0.1 0.1 0.1 1</specular>
          <emissive>0 0 0 0</emissive>
        </material>
      </visual>
      <collision name="fixed_bracket_16_collision_mesh_2">
        <pose relative_to="hip_assembly_6">-0.0575 5.5728e-17 -0.0305 1.5708 1.5708 0</pose>
        <geometry>
          <mesh>
            <uri>model://simulation/meshes/fixed_bracket.stl</uri>
          </mesh>
        </geometry>
      </collision>
      <!-- Part servo_wheel_32 -->
      <visual name="servo_wheel_32_visual_mesh_1">
        <pose relative_to="hip_assembly_6">0 -1.73472e-18 -0.0585 -3.14159 4.5549e-28 -4.04969e-16</pose>
        <geometry>
          <mesh>
            <uri>model://simulation/meshes/servo_wheel.stl</uri>
          </mesh>
        </geometry>
        <material>
          <ambient>0.647059 0.647059 0.647059 1</ambient>
          <diffuse>0.647059 0.647059 0.647059 1</diffuse>
          <specular>0.1 0.1 0.1 1</specular>
          <emissive>0 0 0 0</emissive>
        </material>
      </visual>
      <collision name="servo_wheel_32_collision_mesh_2">
        <pose relative_to="hip_assembly_6">0 -1.73472e-18 -0.0585 -3.14159 4.5549e-28 -4.04969e-16</pose>
        <geometry>
          <mesh>
            <uri>model://simulation/meshes/servo_wheel.stl</uri>
          </mesh>
        </geometry>
      </collision>
    </link>
    <!-- Link ties_assembly_6 -->
    <link name="ties_assembly_6">
      <inertial>
        <pose>0.0643598 0.00153088 -0.0309357 0 0 0</pose>
        <mass>0.589115</mass>
        <inertia>
          <ixx>0.000320336</ixx>
          <ixy>-2.41497e-05</ixy>
          <ixz>1.07866e-05</ixz>
          <iyy>0.00208685</iyy>
          <iyz>2.0947e-07</iyz>
          <izz>0.00187002</izz>
        </inertia>
      </inertial>
      <pose relative_to="ties_6">0 0 0 0 -0 0</pose>
      <!-- Part mobile_bracket_18 -->
      <visual name="mobile_bracket_18_visual_mesh_1">
        <pose relative_to="ties_assembly_6">0.1568 0.000210323 -0.0311738 1.5708 1.5708 0</pose>
        <geometry>
          <mesh>
            <uri>model://simulation/meshes/mobile_bracket.stl</uri>
          </mesh>
        </geometry>
        <material>
          <ambient>0.647059 0.647059 0.647059 1</ambient>
          <diffuse>0.647059 0.647059 0.647059 1</diffuse>
          <specular>0.1 0.1 0.1 1</specular>
          <emissive>0 0 0 0</emissive>
        </material>
      </visual>
      <collision name="mobile_bracket_18_collision_mesh_2">
        <pose relative_to="ties_assembly_6">0.1568 0.000210323 -0.0311738 1.5708 1.5708 0</pose>
        <geometry>
          <mesh>
            <uri>model://simulation/meshes/mobile_bracket.stl</uri>
          </mesh>
        </geometry>
      </collision>
      <!-- Part low_tie_6 -->
      <visual name="low_tie_6_visual_mesh_1">
        <pose relative_to="ties_assembly_6">0.0268 0.000210323 -0.0311738 6.08252e-16 1.5708 0</pose>
        <geometry>
          <mesh>
            <uri>model://simulation/meshes/low_tie.stl</uri>
          </mesh>
        </geometry>
        <material>
          <ambient>0.282353 0.54902 0.160784 1</ambient>
          <diffuse>0.282353 0.54902 0.160784 1</diffuse>
          <specular>0.1 0.1 0.1 1</specular>
          <emissive>0 0 0 0</emissive>
        </material>
      </visual>
      <collision name="low_tie_6_collision_mesh_2">
        <pose relative_to="ties_assembly_6">0.0268 0.000210323 -0.0311738 6.08252e-16 1.5708 0</pose>
        <geometry>
          <mesh>
            <uri>model://simulation/meshes/low_tie.stl</uri>
          </mesh>
        </geometry>
      </collision>
      <!-- Part top_tie_6 -->
      <visual name="top_tie_6_visual_mesh_1">
        <pose relative_to="ties_assembly_6">0.0275 -2.21177e-17 -0.0305 6.08252e-16 1.5708 0</pose>
        <geometry>
          <mesh>
            <uri>model://simulation/meshes/top_tie.stl</uri>
          </mesh>
        </geometry>
        <material>
          <ambient>0.282353 0.54902 0.160784 1</ambient>
          <diffuse>0.282353 0.54902 0.160784 1</diffuse>
          <specular>0.1 0.1 0.1 1</specular>
          <emissive>0 0 0 0</emissive>
        </material>
      </visual>
      <collision name="top_tie_6_collision_mesh_2">
        <pose relative_to="ties_assembly_6">0.0275 -2.21177e-17 -0.0305 6.08252e-16 1.5708 0</pose>
        <geometry>
          <mesh>
            <uri>model://simulation/meshes/top_tie.stl</uri>
          </mesh>
        </geometry>
      </collision>
      <!-- Part servo_wheel_33 -->
      <visual name="servo_wheel_33_visual_mesh_1">
        <pose relative_to="ties_assembly_6">0 -4.33681e-19 -0.0025 -3.14159 -1.17685e-14 3.14159</pose>
        <geometry>
          <mesh>
            <uri>model://simulation/meshes/servo_wheel.stl</uri>
          </mesh>
        </geometry>
        <material>
          <ambient>0.647059 0.647059 0.647059 1</ambient>
          <diffuse>0.647059 0.647059 0.647059 1</diffuse>
          <specular>0.1 0.1 0.1 1</specular>
          <emissive>0 0 0 0</emissive>
        </material>
      </visual>
      <collision name="servo_wheel_33_collision_mesh_2">
        <pose relative_to="ties_assembly_6">0 -4.33681e-19 -0.0025 -3.14159 -1.17685e-14 3.14159</pose>
        <geometry>
          <mesh>
            <uri>model://simulation/meshes/servo_wheel.stl</uri>
          </mesh>
        </geometry>
      </collision>
      <!-- Part servo_17 -->
      <visual name="servo_17_visual_mesh_1">
        <pose relative_to="ties_assembly_6">0.0175 0.00140442 -0.0305 3.14159 -1.17744e-14 3.14159</pose>
        <geometry>
          <mesh>
            <uri>model://simulation/meshes/servo.stl</uri>
          </mesh>
        </geometry>
        <material>
          <ambient>0.109804 0.109804 0.105882 1</ambient>
          <diffuse>0.109804 0.109804 0.105882 1</diffuse>
          <specular>0.1 0.1 0.1 1</specular>
          <emissive>0 0 0 0</emissive>
        </material>
      </visual>
      <collision name="servo_17_collision_mesh_2">
        <pose relative_to="ties_assembly_6">0.0175 0.00140442 -0.0305 3.14159 -1.17744e-14 3.14159</pose>
        <geometry>
          <mesh>
            <uri>model://simulation/meshes/servo.stl</uri>
          </mesh>
        </geometry>
      </collision>
      <!-- Part fixed_bracket_17 -->
      <visual name="fixed_bracket_17_visual_mesh_1">
        <pose relative_to="ties_assembly_6">0.0575 -4.0766e-17 -0.0305 -1.5708 1.5708 0</pose>
        <geometry>
          <mesh>
            <uri>model://simulation/meshes/fixed_bracket.stl</uri>
          </mesh>
        </geometry>
        <material>
          <ambient>0.647059 0.647059 0.647059 1</ambient>
          <diffuse>0.647059 0.647059 0.647059 1</diffuse>
          <specular>0.1 0.1 0.1 1</specular>
          <emissive>0 0 0 0</emissive>
        </material>
      </visual>
      <collision name="fixed_bracket_17_collision_mesh_2">
        <pose relative_to="ties_assembly_6">0.0575 -4.0766e-17 -0.0305 -1.5708 1.5708 0</pose>
        <geometry>
          <mesh>
            <uri>model://simulation/meshes/fixed_bracket.stl</uri>
          </mesh>
        </geometry>
      </collision>
      <!-- Part servo_wheel_34 -->
      <visual name="servo_wheel_34_visual_mesh_1">
        <pose relative_to="ties_assembly_6">-7.21645e-16 2.60209e-18 -0.0585 3.14159 -1.18157e-14 3.14159</pose>
        <geometry>
          <mesh>
            <uri>model://simulation/meshes/servo_wheel.stl</uri>
          </mesh>
        </geometry>
        <material>
          <ambient>0.647059 0.647059 0.647059 1</ambient>
          <diffuse>0.647059 0.647059 0.647059 1</diffuse>
          <specular>0.1 0.1 0.1 1</specular>
          <emissive>0 0 0 0</emissive>
        </material>
      </visual>
      <collision name="servo_wheel_34_collision_mesh_2">
        <pose relative_to="ties_assembly_6">-7.21645e-16 2.60209e-18 -0.0585 3.14159 -1.18157e-14 3.14159</pose>
        <geometry>
          <mesh>
            <uri>model://simulation/meshes/servo_wheel.stl</uri>
          </mesh>
        </geometry>
      </collision>
    </link>
    <!-- Link foot_assembly_6 -->
    <link name="foot_assembly_6">
      <inertial>
        <pose>-0.0724503 -0.00208415 -0.0306672 0 0 0</pose>
        <mass>0.633745</mass>
        <inertia>
          <ixx>0.000268495</ixx>
          <ixy>-1.4806e-05</ixy>
          <ixz>4.28294e-06</ixz>
          <iyy>0.00320961</iyy>
          <iyz>-2.30165e-07</iyz>
          <izz>0.00304658</izz>
        </inertia>
      </inertial>
      <pose relative_to="foot_6">0 0 0 0 -0 0</pose>
      <!-- Part foot_6 -->
      <visual name="foot_6_visual_mesh_1">
        <pose relative_to="foot_assembly_6">-0.04425 6.93889e-18 -0.0305 -1.57772e-29 1.5708 0</pose>
        <geometry>
          <mesh>
            <uri>model://simulation/meshes/foot.stl</uri>
          </mesh>
        </geometry>
        <material>
          <ambient>0.282353 0.54902 0.160784 1</ambient>
          <diffuse>0.282353 0.54902 0.160784 1</diffuse>
          <specular>0.1 0.1 0.1 1</specular>
          <emissive>0 0 0 0</emissive>
        </material>
      </visual>
      <collision name="foot_6_collision_mesh_2">
        <pose relative_to="foot_assembly_6">-0.04425 6.93889e-18 -0.0305 -1.57772e-29 1.5708 0</pose>
        <geometry>
          <mesh>
            <uri>model://simulation/meshes/foot.stl</uri>
          </mesh>
        </geometry>
      </collision>
      <!-- Part ir_sensor_cap_6 -->
      <visual name="ir_sensor_cap_6_visual_mesh_1">
        <pose relative_to="foot_assembly_6">-0.04425 -8.26596e-16 -0.0305 4.57824e-15 1.5708 0</pose>
        <geometry>
          <mesh>
            <uri>model://simulation/meshes/ir_sensor_cap.stl</uri>
          </mesh>
        </geometry>
        <material>
          <ambient>0.282353 0.54902 0.160784 1</ambient>
          <diffuse>0.282353 0.54902 0.160784 1</diffuse>
          <specular>0.1 0.1 0.1 1</specular>
          <emissive>0 0 0 0</emissive>
        </material>
      </visual>
      <collision name="ir_sensor_cap_6_collision_mesh_2">
        <pose relative_to="foot_assembly_6">-0.04425 -8.26596e-16 -0.0305 4.57824e-15 1.5708 0</pose>
        <geometry>
          <mesh>
            <uri>model://simulation/meshes/ir_sensor_cap.stl</uri>
          </mesh>
        </geometry>
      </collision>
      <!-- Part rubber_foot_6 -->
      <visual name="rubber_foot_6_visual_mesh_1">
        <pose relative_to="foot_assembly_6">-0.04375 -8.90781e-16 -0.03 4.23423e-15 1.5708 0</pose>
        <geometry>
          <mesh>
            <uri>model://simulation/meshes/rubber_foot.stl</uri>
          </mesh>
        </geometry>
        <material>
          <ambient>0.262745 0.282353 0.301961 1</ambient>
          <diffuse>0.262745 0.282353 0.301961 1</diffuse>
          <specular>0.1 0.1 0.1 1</specular>
          <emissive>0 0 0 0</emissive>
        </material>
      </visual>
      <collision name="rubber_foot_6_collision_mesh_2">
        <pose relative_to="foot_assembly_6">-0.04375 -8.90781e-16 -0.03 4.23423e-15 1.5708 0</pose>
        <geometry>
          <mesh>
            <uri>model://simulation/meshes/rubber_foot.stl</uri>
          </mesh>
        </geometry>
      </collision>
      <!-- Part servo_wheel_35 -->
      <visual name="servo_wheel_35_visual_mesh_1">
        <pose relative_to="foot_assembly_6">-1.11022e-16 0 -0.0025 3.14159 -3.19561e-17 1.10441e-29</pose>
        <geometry>
          <mesh>
            <uri>model://simulation/meshes/servo_wheel.stl</uri>
          </mesh>
        </geometry>
        <material>
          <ambient>0.647059 0.647059 0.647059 1</ambient>
          <diffuse>0.647059 0.647059 0.647059 1</diffuse>
          <specular>0.1 0.1 0.1 1</specular>
          <emissive>0 0 0 0</emissive>
        </material>
      </visual>
      <collision name="servo_wheel_35_collision_mesh_2">
        <pose relative_to="foot_assembly_6">-1.11022e-16 0 -0.0025 3.14159 -3.19561e-17 1.10441e-29</pose>
        <geometry>
          <mesh>
            <uri>model://simulation/meshes/servo_wheel.stl</uri>
          </mesh>
        </geometry>
      </collision>
      <!-- Part servo_18 -->
      <visual name="servo_18_visual_mesh_1">
        <pose relative_to="foot_assembly_6">-0.0175 -0.00140442 -0.0305 -3.14159 4.83565e-17 1.57772e-30</pose>
        <geometry>
          <mesh>
            <uri>model://simulation/meshes/servo.stl</uri>
          </mesh>
        </geometry>
        <material>
          <ambient>0.109804 0.109804 0.105882 1</ambient>
          <diffuse>0.109804 0.109804 0.105882 1</diffuse>
          <specular>0.1 0.1 0.1 1</specular>
          <emissive>0 0 0 0</emissive>
        </material>
      </visual>
      <collision name="servo_18_collision_mesh_2">
        <pose relative_to="foot_assembly_6">-0.0175 -0.00140442 -0.0305 -3.14159 4.83565e-17 1.57772e-30</pose>
        <geometry>
          <mesh>
            <uri>model://simulation/meshes/servo.stl</uri>
          </mesh>
        </geometry>
      </collision>
      <!-- Part fixed_bracket_18 -->
      <visual name="fixed_bracket_18_visual_mesh_1">
        <pose relative_to="foot_assembly_6">-0.0575 7.80626e-18 -0.0305 1.5708 1.5708 0</pose>
        <geometry>
          <mesh>
            <uri>model://simulation/meshes/fixed_bracket.stl</uri>
          </mesh>
        </geometry>
        <material>
          <ambient>0.647059 0.647059 0.647059 1</ambient>
          <diffuse>0.647059 0.647059 0.647059 1</diffuse>
          <specular>0.1 0.1 0.1 1</specular>
          <emissive>0 0 0 0</emissive>
        </material>
      </visual>
      <collision name="fixed_bracket_18_collision_mesh_2">
        <pose relative_to="foot_assembly_6">-0.0575 7.80626e-18 -0.0305 1.5708 1.5708 0</pose>
        <geometry>
          <mesh>
            <uri>model://simulation/meshes/fixed_bracket.stl</uri>
          </mesh>
        </geometry>
      </collision>
      <!-- Part servo_wheel_36 -->
      <visual name="servo_wheel_36_visual_mesh_1">
        <pose relative_to="foot_assembly_6">-1.66533e-16 0 -0.0585 3.14159 6.48962e-17 -1.57772e-30</pose>
        <geometry>
          <mesh>
            <uri>model://simulation/meshes/servo_wheel.stl</uri>
          </mesh>
        </geometry>
        <material>
          <ambient>0.647059 0.647059 0.647059 1</ambient>
          <diffuse>0.647059 0.647059 0.647059 1</diffuse>
          <specular>0.1 0.1 0.1 1</specular>
          <emissive>0 0 0 0</emissive>
        </material>
      </visual>
      <collision name="servo_wheel_36_collision_mesh_2">
        <pose relative_to="foot_assembly_6">-1.66533e-16 0 -0.0585 3.14159 6.48962e-17 -1.57772e-30</pose>
        <geometry>
          <mesh>
            <uri>model://simulation/meshes/servo_wheel.stl</uri>
          </mesh>
        </geometry>
      </collision>
    </link>
    <!-- Joint from ties_assembly_6 to foot_assembly_6 -->
    <joint name="foot_6" type="revolute">
      <pose relative_to="ties_assembly_6">0.1918 0.000210323 -0.000790548 1.60664e-16 -3.19561e-17 -3.14159</pose>
      <parent>ties_assembly_6</parent>
      <child>foot_assembly_6</child>
      <axis>
        <xyz>0 0 1</xyz>
        <limit>
          <effort>10</effort>
          <velocity>10</velocity>
          <lower>-2.09439510239318</lower>
          <upper>2.0943951023932104</upper>
        </limit>
        <dynamics>
          <friction>0.0</friction>
          <damping>0.0</damping>
        </dynamics>
      </axis>
    </joint>
    <!-- Joint from hip_assembly_6 to ties_assembly_6 -->
    <joint name="ties_6" type="revolute">
      <pose relative_to="hip_assembly_6">-0.0925 0.0311167 -0.0305 1.5708 -1.6208e-16 3.14159</pose>
      <parent>hip_assembly_6</parent>
      <child>ties_assembly_6</child>
      <axis>
        <xyz>0 0 1</xyz>
        <limit>
          <effort>10</effort>
          <velocity>10</velocity>
          <lower>-1.7453292519943437</lower>
          <upper>1.7453292519943153</upper>
        </limit>
        <dynamics>
          <friction>0.0</friction>
          <damping>0.0</damping>
        </dynamics>
      </axis>
    </joint>
    <!-- Joint from base_link to hip_assembly_6 -->
    <joint name="hip_6" type="revolute">
      <pose relative_to="base_link">-0.117483 0.0840557 0.0272372 5.19838e-14 -1.50414e-14 -0.610865</pose>
      <parent>base_link</parent>
      <child>hip_assembly_6</child>
      <axis>
        <xyz>0 0 1</xyz>
        <limit>
          <effort>10</effort>
          <velocity>10</velocity>
          <lower>-1.5707963267941594</lower>
          <upper>1.5707963267956337</upper>
        </limit>
        <dynamics>
          <friction>0.0</friction>
          <damping>0.0</damping>
        </dynamics>
      </axis>
    </joint>
  </model>
</sdf>
