<?xml version="1.0" ?>
<!-- Generated using onshape-to-robot -->
<!-- Onshape https://cad.onshape.com/documents/026f9a33ba6a25a983a9d639/w/b83e0182bd0a887a03df3198/e/e49783848224d44e064e4a49 -->
<robot name="hexapod_description">
  <!-- Link base_link -->
  <link name="base_link">
    <inertial>
      <origin xyz="0.00531951 -0.00413089 -0.000427637" rpy="0 0 0"/>
      <mass value="2.26596"/>
      <inertia ixx="0.0152472" ixy="6.11534e-05" ixz="-0.000168484" iyy="0.015875" iyz="8.77712e-06" izz="0.0214935"/>
    </inertial>
    <!-- Part mobile_bracket -->
    <visual>
      <origin xyz="0.0172411 0.113434 -0.00314611" rpy="0.0872665 1.5708 0"/>
      <geometry>
        <mesh filename="package://hexapod_description/meshes/mobile_bracket.stl"/>
      </geometry>
      <material name="mobile_bracket_material">
        <color rgba="0.647059 0.647059 0.647059 1"/>
      </material>
    </visual>
    <collision>
      <origin xyz="0.0172411 0.113434 -0.00314611" rpy="0.0872665 1.5708 0"/>
      <geometry>
        <mesh filename="package://hexapod_description/meshes/mobile_bracket.stl"/>
      </geometry>
    </collision>
    <!-- Part ultrasound_sensor -->
    <visual>
      <origin xyz="-0.0386004 0.0947435 0.0198539" rpy="1.29357e-14 -5.29181e-14 0.436332"/>
      <geometry>
        <mesh filename="package://hexapod_description/meshes/ultrasound_sensor.stl"/>
      </geometry>
      <material name="ultrasound_sensor_material">
        <color rgba="0.701961 0.701961 0.701961 1"/>
      </material>
    </visual>
    <collision>
      <origin xyz="-0.0386004 0.0947435 0.0198539" rpy="1.29357e-14 -5.29181e-14 0.436332"/>
      <geometry>
        <mesh filename="package://hexapod_description/meshes/ultrasound_sensor.stl"/>
      </geometry>
    </collision>
    <!-- Part ultrasound_sensor_2 -->
    <visual>
      <origin xyz="-0.100547 0.00627507 0.0198539" rpy="-3.14159 3.76617e-14 -1.65806"/>
      <geometry>
        <mesh filename="package://hexapod_description/meshes/ultrasound_sensor.stl"/>
      </geometry>
      <material name="ultrasound_sensor_2_material">
        <color rgba="0.701961 0.701961 0.701961 1"/>
      </material>
    </visual>
    <collision>
      <origin xyz="-0.100547 0.00627507 0.0198539" rpy="-3.14159 3.76617e-14 -1.65806"/>
      <geometry>
        <mesh filename="package://hexapod_description/meshes/ultrasound_sensor.stl"/>
      </geometry>
    </collision>
    <!-- Part mobile_bracket_2 -->
    <visual>
      <origin xyz="0.113096 0.0463158 -0.00314611" rpy="1.13446 1.5708 0"/>
      <geometry>
        <mesh filename="package://hexapod_description/meshes/mobile_bracket.stl"/>
      </geometry>
      <material name="mobile_bracket_2_material">
        <color rgba="0.647059 0.647059 0.647059 1"/>
      </material>
    </visual>
    <collision>
      <origin xyz="0.113096 0.0463158 -0.00314611" rpy="1.13446 1.5708 0"/>
      <geometry>
        <mesh filename="package://hexapod_description/meshes/mobile_bracket.stl"/>
      </geometry>
    </collision>
    <!-- Part camera -->
    <visual>
      <origin xyz="-0.102539 0.00644938 -0.0151461" rpy="3.14159 -3.7359e-14 1.48353"/>
      <geometry>
        <mesh filename="package://hexapod_description/meshes/camera.stl"/>
      </geometry>
      <material name="camera_material">
        <color rgba="0.262745 0.282353 0.301961 1"/>
      </material>
    </visual>
    <collision>
      <origin xyz="-0.102539 0.00644938 -0.0151461" rpy="3.14159 -3.7359e-14 1.48353"/>
      <geometry>
        <mesh filename="package://hexapod_description/meshes/camera.stl"/>
      </geometry>
    </collision>
    <!-- Part camera_2 -->
    <visual>
      <origin xyz="0.116624 -0.0127249 -0.0151461" rpy="-3.14159 3.7359e-14 -1.65806"/>
      <geometry>
        <mesh filename="package://hexapod_description/meshes/camera.stl"/>
      </geometry>
      <material name="camera_2_material">
        <color rgba="0.262745 0.282353 0.301961 1"/>
      </material>
    </visual>
    <collision>
      <origin xyz="0.116624 -0.0127249 -0.0151461" rpy="-3.14159 3.7359e-14 -1.65806"/>
      <geometry>
        <mesh filename="package://hexapod_description/meshes/camera.stl"/>
      </geometry>
    </collision>
    <!-- Part bottom_cover -->
    <visual>
      <origin xyz="0.00704236 -0.00313775 -0.0381461" rpy="-3.14159 -3.97096e-14 -0.0872665"/>
      <geometry>
        <mesh filename="package://hexapod_description/meshes/bottom_cover.stl"/>
      </geometry>
      <material name="bottom_cover_material">
        <color rgba="0.282353 0.54902 0.160784 1"/>
      </material>
    </visual>
    <collision>
      <origin xyz="0.00704236 -0.00313775 -0.0381461" rpy="-3.14159 -3.97096e-14 -0.0872665"/>
      <geometry>
        <mesh filename="package://hexapod_description/meshes/bottom_cover.stl"/>
      </geometry>
    </collision>
    <!-- Part left_speaker -->
    <visual>
      <origin xyz="0.0368168 -0.0669892 0.0323062" rpy="1.5708 0.523599 0.436332"/>
      <geometry>
        <mesh filename="package://hexapod_description/meshes/left_speaker.stl"/>
      </geometry>
      <material name="left_speaker_material">
        <color rgba="0.262745 0.282353 0.301961 1"/>
      </material>
    </visual>
    <collision>
      <origin xyz="0.0368168 -0.0669892 0.0323062" rpy="1.5708 0.523599 0.436332"/>
      <geometry>
        <mesh filename="package://hexapod_description/meshes/left_speaker.stl"/>
      </geometry>
    </collision>
    <!-- Part body_power -->
    <visual>
      <origin xyz="0.00704236 -0.00313775 -0.00314611" rpy="3.93606e-14 3.76617e-14 -1.65806"/>
      <geometry>
        <mesh filename="package://hexapod_description/meshes/body_power.stl"/>
      </geometry>
      <material name="body_power_material">
        <color rgba="0.282353 0.54902 0.160784 1"/>
      </material>
    </visual>
    <collision>
      <origin xyz="0.00704236 -0.00313775 -0.00314611" rpy="3.93606e-14 3.76617e-14 -1.65806"/>
      <geometry>
        <mesh filename="package://hexapod_description/meshes/body_power.stl"/>
      </geometry>
    </collision>
    <!-- Part mobile_bracket_3 -->
    <visual>
      <origin xyz="0.102897 -0.070256 -0.00314611" rpy="-2.18166 -1.5708 0"/>
      <geometry>
        <mesh filename="package://hexapod_description/meshes/mobile_bracket.stl"/>
      </geometry>
      <material name="mobile_bracket_3_material">
        <color rgba="0.647059 0.647059 0.647059 1"/>
      </material>
    </visual>
    <collision>
      <origin xyz="0.102897 -0.070256 -0.00314611" rpy="-2.18166 -1.5708 0"/>
      <geometry>
        <mesh filename="package://hexapod_description/meshes/mobile_bracket.stl"/>
      </geometry>
    </collision>
    <!-- Part cover -->
    <visual>
      <origin xyz="0.00704236 -0.00313775 0.0318539" rpy="5.29181e-14 1.29357e-14 -1.13446"/>
      <geometry>
        <mesh filename="package://hexapod_description/meshes/cover.stl"/>
      </geometry>
      <material name="cover_material">
        <color rgba="0.282353 0.54902 0.160784 1"/>
      </material>
    </visual>
    <collision>
      <origin xyz="0.00704236 -0.00313775 0.0318539" rpy="5.29181e-14 1.29357e-14 -1.13446"/>
      <geometry>
        <mesh filename="package://hexapod_description/meshes/cover.stl"/>
      </geometry>
    </collision>
    <!-- Part mobile_bracket_4 -->
    <visual>
      <origin xyz="-0.0888124 0.0639805 -0.00314611" rpy="-0.959931 1.5708 0"/>
      <geometry>
        <mesh filename="package://hexapod_description/meshes/mobile_bracket.stl"/>
      </geometry>
      <material name="mobile_bracket_4_material">
        <color rgba="0.647059 0.647059 0.647059 1"/>
      </material>
    </visual>
    <collision>
      <origin xyz="-0.0888124 0.0639805 -0.00314611" rpy="-0.959931 1.5708 0"/>
      <geometry>
        <mesh filename="package://hexapod_description/meshes/mobile_bracket.stl"/>
      </geometry>
    </collision>
    <!-- Part ultrasound_sensor_3 -->
    <visual>
      <origin xyz="0.0526851 -0.101019 0.0198539" rpy="-1.29357e-14 5.29181e-14 -2.70526"/>
      <geometry>
        <mesh filename="package://hexapod_description/meshes/ultrasound_sensor.stl"/>
      </geometry>
      <material name="ultrasound_sensor_3_material">
        <color rgba="0.701961 0.701961 0.701961 1"/>
      </material>
    </visual>
    <collision>
      <origin xyz="0.0526851 -0.101019 0.0198539" rpy="-1.29357e-14 5.29181e-14 -2.70526"/>
      <geometry>
        <mesh filename="package://hexapod_description/meshes/ultrasound_sensor.stl"/>
      </geometry>
    </collision>
    <!-- Part mobile_bracket_5 -->
    <visual>
      <origin xyz="-0.00315634 -0.11971 -0.00314611" rpy="3.05433 -1.5708 0"/>
      <geometry>
        <mesh filename="package://hexapod_description/meshes/mobile_bracket.stl"/>
      </geometry>
      <material name="mobile_bracket_5_material">
        <color rgba="0.647059 0.647059 0.647059 1"/>
      </material>
    </visual>
    <collision>
      <origin xyz="-0.00315634 -0.11971 -0.00314611" rpy="3.05433 -1.5708 0"/>
      <geometry>
        <mesh filename="package://hexapod_description/meshes/mobile_bracket.stl"/>
      </geometry>
    </collision>
    <!-- Part mobile_bracket_6 -->
    <visual>
      <origin xyz="-0.0990111 -0.0525913 -0.00314611" rpy="2.00713 -1.5708 0"/>
      <geometry>
        <mesh filename="package://hexapod_description/meshes/mobile_bracket.stl"/>
      </geometry>
      <material name="mobile_bracket_6_material">
        <color rgba="0.647059 0.647059 0.647059 1"/>
      </material>
    </visual>
    <collision>
      <origin xyz="-0.0990111 -0.0525913 -0.00314611" rpy="2.00713 -1.5708 0"/>
      <geometry>
        <mesh filename="package://hexapod_description/meshes/mobile_bracket.stl"/>
      </geometry>
    </collision>
    <!-- Part body_brain -->
    <visual>
      <origin xyz="0.00704236 -0.00313775 -0.00314611" rpy="3.97096e-14 3.7359e-14 -1.65806"/>
      <geometry>
        <mesh filename="package://hexapod_description/meshes/body_brain.stl"/>
      </geometry>
      <material name="body_brain_material">
        <color rgba="0.282353 0.54902 0.160784 1"/>
      </material>
    </visual>
    <collision>
      <origin xyz="0.00704236 -0.00313775 -0.00314611" rpy="3.97096e-14 3.7359e-14 -1.65806"/>
      <geometry>
        <mesh filename="package://hexapod_description/meshes/body_brain.stl"/>
      </geometry>
    </collision>
    <!-- Part ultrasound_sensor_4 -->
    <visual>
      <origin xyz="0.0689886 0.0853307 0.0198539" rpy="3.14159 1.52565e-14 2.53073"/>
      <geometry>
        <mesh filename="package://hexapod_description/meshes/ultrasound_sensor.stl"/>
      </geometry>
      <material name="ultrasound_sensor_4_material">
        <color rgba="0.701961 0.701961 0.701961 1"/>
      </material>
    </visual>
    <collision>
      <origin xyz="0.0689886 0.0853307 0.0198539" rpy="3.14159 1.52565e-14 2.53073"/>
      <geometry>
        <mesh filename="package://hexapod_description/meshes/ultrasound_sensor.stl"/>
      </geometry>
    </collision>
    <!-- Part ultrasound_sensor_5 -->
    <visual>
      <origin xyz="0.114631 -0.0125506 0.0198539" rpy="3.14159 -3.76617e-14 1.48353"/>
      <geometry>
        <mesh filename="package://hexapod_description/meshes/ultrasound_sensor.stl"/>
      </geometry>
      <material name="ultrasound_sensor_5_material">
        <color rgba="0.701961 0.701961 0.701961 1"/>
      </material>
    </visual>
    <collision>
      <origin xyz="0.114631 -0.0125506 0.0198539" rpy="3.14159 -3.76617e-14 1.48353"/>
      <geometry>
        <mesh filename="package://hexapod_description/meshes/ultrasound_sensor.stl"/>
      </geometry>
    </collision>
    <!-- Part left_speaker_2 -->
    <visual>
      <origin xyz="0.0474521 0.0545734 0.0323062" rpy="1.5708 0.523599 2.53073"/>
      <geometry>
        <mesh filename="package://hexapod_description/meshes/left_speaker.stl"/>
      </geometry>
      <material name="left_speaker_2_material">
        <color rgba="0.262745 0.282353 0.301961 1"/>
      </material>
    </visual>
    <collision>
      <origin xyz="0.0474521 0.0545734 0.0323062" rpy="1.5708 0.523599 2.53073"/>
      <geometry>
        <mesh filename="package://hexapod_description/meshes/left_speaker.stl"/>
      </geometry>
    </collision>
    <!-- Part ultrasound_sensor_6 -->
    <visual>
      <origin xyz="-0.0549039 -0.0916062 0.0198539" rpy="-3.14159 -1.52565e-14 -0.610865"/>
      <geometry>
        <mesh filename="package://hexapod_description/meshes/ultrasound_sensor.stl"/>
      </geometry>
      <material name="ultrasound_sensor_6_material">
        <color rgba="0.701961 0.701961 0.701961 1"/>
      </material>
    </visual>
    <collision>
      <origin xyz="-0.0549039 -0.0916062 0.0198539" rpy="-3.14159 -1.52565e-14 -0.610865"/>
      <geometry>
        <mesh filename="package://hexapod_description/meshes/ultrasound_sensor.stl"/>
      </geometry>
    </collision>
  </link>
  <!-- Link hip_assembly -->
  <link name="hip_assembly">
    <inertial>
      <origin xyz="0.0268487 0.000325484 -0.0302141" rpy="0 0 0"/>
      <mass value="0.365356"/>
      <inertia ixx="0.000168136" ixy="-2.8417e-07" ixz="-3.2467e-06" iyy="0.000312332" iyz="9.42575e-07" izz="0.000312341"/>
    </inertial>
    <!-- Part hip -->
    <visual>
      <origin xyz="0.0575 0.0005 -0.0045" rpy="-3.5793e-17 -3.2709e-15 -3.14159"/>
      <geometry>
        <mesh filename="package://hexapod_description/meshes/hip.stl"/>
      </geometry>
      <material name="hip_material">
        <color rgba="0.282353 0.54902 0.160784 1"/>
      </material>
    </visual>
    <collision>
      <origin xyz="0.0575 0.0005 -0.0045" rpy="-3.5793e-17 -3.2709e-15 -3.14159"/>
      <geometry>
        <mesh filename="package://hexapod_description/meshes/hip.stl"/>
      </geometry>
    </collision>
    <!-- Part mobile_bracket_7 -->
    <visual>
      <origin xyz="0.0575 -8.67362e-19 -0.0305" rpy="-3.25123e-15 -2.14293e-16 -1.5708"/>
      <geometry>
        <mesh filename="package://hexapod_description/meshes/mobile_bracket.stl"/>
      </geometry>
      <material name="mobile_bracket_7_material">
        <color rgba="0.647059 0.647059 0.647059 1"/>
      </material>
    </visual>
    <collision>
      <origin xyz="0.0575 -8.67362e-19 -0.0305" rpy="-3.25123e-15 -2.14293e-16 -1.5708"/>
      <geometry>
        <mesh filename="package://hexapod_description/meshes/mobile_bracket.stl"/>
      </geometry>
    </collision>
    <!-- Part servo_wheel -->
    <visual>
      <origin xyz="2.77556e-17 2.60209e-18 -0.0025" rpy="3.14159 -3.2709e-15 -3.14159"/>
      <geometry>
        <mesh filename="package://hexapod_description/meshes/servo_wheel.stl"/>
      </geometry>
      <material name="servo_wheel_material">
        <color rgba="0.647059 0.647059 0.647059 1"/>
      </material>
    </visual>
    <collision>
      <origin xyz="2.77556e-17 2.60209e-18 -0.0025" rpy="3.14159 -3.2709e-15 -3.14159"/>
      <geometry>
        <mesh filename="package://hexapod_description/meshes/servo_wheel.stl"/>
      </geometry>
    </collision>
    <!-- Part servo -->
    <visual>
      <origin xyz="0.0175 0.00140442 -0.0305" rpy="3.14159 -3.2709e-15 -3.14159"/>
      <geometry>
        <mesh filename="package://hexapod_description/meshes/servo.stl"/>
      </geometry>
      <material name="servo_material">
        <color rgba="0.109804 0.109804 0.105882 1"/>
      </material>
    </visual>
    <collision>
      <origin xyz="0.0175 0.00140442 -0.0305" rpy="3.14159 -3.2709e-15 -3.14159"/>
      <geometry>
        <mesh filename="package://hexapod_description/meshes/servo.stl"/>
      </geometry>
    </collision>
    <!-- Part fixed_bracket -->
    <visual>
      <origin xyz="0.0575 -8.67362e-19 -0.0305" rpy="-1.5708 1.5708 0"/>
      <geometry>
        <mesh filename="package://hexapod_description/meshes/fixed_bracket.stl"/>
      </geometry>
      <material name="fixed_bracket_material">
        <color rgba="0.647059 0.647059 0.647059 1"/>
      </material>
    </visual>
    <collision>
      <origin xyz="0.0575 -8.67362e-19 -0.0305" rpy="-1.5708 1.5708 0"/>
      <geometry>
        <mesh filename="package://hexapod_description/meshes/fixed_bracket.stl"/>
      </geometry>
    </collision>
    <!-- Part servo_wheel_2 -->
    <visual>
      <origin xyz="-5.55112e-17 5.20417e-18 -0.0585" rpy="3.14159 -3.2709e-15 -3.14159"/>
      <geometry>
        <mesh filename="package://hexapod_description/meshes/servo_wheel.stl"/>
      </geometry>
      <material name="servo_wheel_2_material">
        <color rgba="0.647059 0.647059 0.647059 1"/>
      </material>
    </visual>
    <collision>
      <origin xyz="-5.55112e-17 5.20417e-18 -0.0585" rpy="3.14159 -3.2709e-15 -3.14159"/>
      <geometry>
        <mesh filename="package://hexapod_description/meshes/servo_wheel.stl"/>
      </geometry>
    </collision>
  </link>
  <!-- Link ties_assembly -->
  <link name="ties_assembly">
    <inertial>
      <origin xyz="0.0549718 0.0335057 -0.0309357" rpy="0 0 0"/>
      <mass value="0.589115"/>
      <inertia ixx="0.000782879" ixy="-0.000776998" ixz="9.2367e-06" iyy="0.00162431" iyz="5.57469e-06" izz="0.00187002"/>
    </inertial>
    <!-- Part mobile_bracket_8 -->
    <visual>
      <origin xyz="0.135688 0.0785821 -0.0311738" rpy="1.0472 1.5708 0"/>
      <geometry>
        <mesh filename="package://hexapod_description/meshes/mobile_bracket.stl"/>
      </geometry>
      <material name="mobile_bracket_8_material">
        <color rgba="0.647059 0.647059 0.647059 1"/>
      </material>
    </visual>
    <collision>
      <origin xyz="0.135688 0.0785821 -0.0311738" rpy="1.0472 1.5708 0"/>
      <geometry>
        <mesh filename="package://hexapod_description/meshes/mobile_bracket.stl"/>
      </geometry>
    </collision>
    <!-- Part low_tie -->
    <visual>
      <origin xyz="0.0231043 0.0135821 -0.0311738" rpy="-0.523599 1.5708 0"/>
      <geometry>
        <mesh filename="package://hexapod_description/meshes/low_tie.stl"/>
      </geometry>
      <material name="low_tie_material">
        <color rgba="0.282353 0.54902 0.160784 1"/>
      </material>
    </visual>
    <collision>
      <origin xyz="0.0231043 0.0135821 -0.0311738" rpy="-0.523599 1.5708 0"/>
      <geometry>
        <mesh filename="package://hexapod_description/meshes/low_tie.stl"/>
      </geometry>
    </collision>
    <!-- Part top_tie -->
    <visual>
      <origin xyz="0.0238157 0.01375 -0.0305" rpy="-0.523599 1.5708 0"/>
      <geometry>
        <mesh filename="package://hexapod_description/meshes/top_tie.stl"/>
      </geometry>
      <material name="top_tie_material">
        <color rgba="0.282353 0.54902 0.160784 1"/>
      </material>
    </visual>
    <collision>
      <origin xyz="0.0238157 0.01375 -0.0305" rpy="-0.523599 1.5708 0"/>
      <geometry>
        <mesh filename="package://hexapod_description/meshes/top_tie.stl"/>
      </geometry>
    </collision>
    <!-- Part servo_wheel_3 -->
    <visual>
      <origin xyz="0 0 -0.0025" rpy="-3.14159 -1.07536e-14 -2.61799"/>
      <geometry>
        <mesh filename="package://hexapod_description/meshes/servo_wheel.stl"/>
      </geometry>
      <material name="servo_wheel_3_material">
        <color rgba="0.647059 0.647059 0.647059 1"/>
      </material>
    </visual>
    <collision>
      <origin xyz="0 0 -0.0025" rpy="-3.14159 -1.07536e-14 -2.61799"/>
      <geometry>
        <mesh filename="package://hexapod_description/meshes/servo_wheel.stl"/>
      </geometry>
    </collision>
    <!-- Part servo_2 -->
    <visual>
      <origin xyz="0.0144532 0.00996626 -0.0305" rpy="-3.14159 -1.07578e-14 -2.61799"/>
      <geometry>
        <mesh filename="package://hexapod_description/meshes/servo.stl"/>
      </geometry>
      <material name="servo_2_material">
        <color rgba="0.109804 0.109804 0.105882 1"/>
      </material>
    </visual>
    <collision>
      <origin xyz="0.0144532 0.00996626 -0.0305" rpy="-3.14159 -1.07578e-14 -2.61799"/>
      <geometry>
        <mesh filename="package://hexapod_description/meshes/servo.stl"/>
      </geometry>
    </collision>
    <!-- Part fixed_bracket_2 -->
    <visual>
      <origin xyz="0.0497965 0.02875 -0.0305" rpy="-2.0944 1.5708 0"/>
      <geometry>
        <mesh filename="package://hexapod_description/meshes/fixed_bracket.stl"/>
      </geometry>
      <material name="fixed_bracket_2_material">
        <color rgba="0.647059 0.647059 0.647059 1"/>
      </material>
    </visual>
    <collision>
      <origin xyz="0.0497965 0.02875 -0.0305" rpy="-2.0944 1.5708 0"/>
      <geometry>
        <mesh filename="package://hexapod_description/meshes/fixed_bracket.stl"/>
      </geometry>
    </collision>
    <!-- Part servo_wheel_4 -->
    <visual>
      <origin xyz="-3.88578e-16 -2.42861e-16 -0.0585" rpy="3.14159 -1.06389e-14 -2.61799"/>
      <geometry>
        <mesh filename="package://hexapod_description/meshes/servo_wheel.stl"/>
      </geometry>
      <material name="servo_wheel_4_material">
        <color rgba="0.647059 0.647059 0.647059 1"/>
      </material>
    </visual>
    <collision>
      <origin xyz="-3.88578e-16 -2.42861e-16 -0.0585" rpy="3.14159 -1.06389e-14 -2.61799"/>
      <geometry>
        <mesh filename="package://hexapod_description/meshes/servo_wheel.stl"/>
      </geometry>
    </collision>
  </link>
  <!-- Link foot_assembly -->
  <link name="foot_assembly">
    <inertial>
      <origin xyz="-0.0724503 -0.00208415 -0.0306672" rpy="0 0 0"/>
      <mass value="0.633745"/>
      <inertia ixx="0.000268495" ixy="-1.4806e-05" ixz="4.28294e-06" iyy="0.00320961" iyz="-2.30165e-07" izz="0.00304658"/>
    </inertial>
    <!-- Part foot -->
    <visual>
      <origin xyz="-0.04425 -5.55112e-17 -0.0305" rpy="8.65203e-17 1.5708 0"/>
      <geometry>
        <mesh filename="package://hexapod_description/meshes/foot.stl"/>
      </geometry>
      <material name="foot_material">
        <color rgba="0.282353 0.54902 0.160784 1"/>
      </material>
    </visual>
    <collision>
      <origin xyz="-0.04425 -5.55112e-17 -0.0305" rpy="8.65203e-17 1.5708 0"/>
      <geometry>
        <mesh filename="package://hexapod_description/meshes/foot.stl"/>
      </geometry>
    </collision>
    <!-- Part ir_sensor_cap -->
    <visual>
      <origin xyz="-0.04425 1.11022e-16 -0.0305" rpy="-5.10534e-16 1.5708 0"/>
      <geometry>
        <mesh filename="package://hexapod_description/meshes/ir_sensor_cap.stl"/>
      </geometry>
      <material name="ir_sensor_cap_material">
        <color rgba="0.282353 0.54902 0.160784 1"/>
      </material>
    </visual>
    <collision>
      <origin xyz="-0.04425 1.11022e-16 -0.0305" rpy="-5.10534e-16 1.5708 0"/>
      <geometry>
        <mesh filename="package://hexapod_description/meshes/ir_sensor_cap.stl"/>
      </geometry>
    </collision>
    <!-- Part rubber_foot -->
    <visual>
      <origin xyz="-0.04375 5.55112e-17 -0.03" rpy="-3.4853e-16 1.5708 0"/>
      <geometry>
        <mesh filename="package://hexapod_description/meshes/rubber_foot.stl"/>
      </geometry>
      <material name="rubber_foot_material">
        <color rgba="0.262745 0.282353 0.301961 1"/>
      </material>
    </visual>
    <collision>
      <origin xyz="-0.04375 5.55112e-17 -0.03" rpy="-3.4853e-16 1.5708 0"/>
      <geometry>
        <mesh filename="package://hexapod_description/meshes/rubber_foot.stl"/>
      </geometry>
    </collision>
    <!-- Part servo_wheel_5 -->
    <visual>
      <origin xyz="-3.46945e-17 0 -0.0025" rpy="-3.14159 -4.38496e-18 2.50406e-17"/>
      <geometry>
        <mesh filename="package://hexapod_description/meshes/servo_wheel.stl"/>
      </geometry>
      <material name="servo_wheel_5_material">
        <color rgba="0.647059 0.647059 0.647059 1"/>
      </material>
    </visual>
    <collision>
      <origin xyz="-3.46945e-17 0 -0.0025" rpy="-3.14159 -4.38496e-18 2.50406e-17"/>
      <geometry>
        <mesh filename="package://hexapod_description/meshes/servo_wheel.stl"/>
      </geometry>
    </collision>
    <!-- Part servo_3 -->
    <visual>
      <origin xyz="-0.0175 -0.00140442 -0.0305" rpy="3.14159 -3.68514e-18 -3.9689e-17"/>
      <geometry>
        <mesh filename="package://hexapod_description/meshes/servo.stl"/>
      </geometry>
      <material name="servo_3_material">
        <color rgba="0.109804 0.109804 0.105882 1"/>
      </material>
    </visual>
    <collision>
      <origin xyz="-0.0175 -0.00140442 -0.0305" rpy="3.14159 -3.68514e-18 -3.9689e-17"/>
      <geometry>
        <mesh filename="package://hexapod_description/meshes/servo.stl"/>
      </geometry>
    </collision>
    <!-- Part fixed_bracket_3 -->
    <visual>
      <origin xyz="-0.0575 0 -0.0305" rpy="1.5708 1.5708 0"/>
      <geometry>
        <mesh filename="package://hexapod_description/meshes/fixed_bracket.stl"/>
      </geometry>
      <material name="fixed_bracket_3_material">
        <color rgba="0.647059 0.647059 0.647059 1"/>
      </material>
    </visual>
    <collision>
      <origin xyz="-0.0575 0 -0.0305" rpy="1.5708 1.5708 0"/>
      <geometry>
        <mesh filename="package://hexapod_description/meshes/fixed_bracket.stl"/>
      </geometry>
    </collision>
    <!-- Part servo_wheel_6 -->
    <visual>
      <origin xyz="-6.31439e-16 -5.55112e-17 -0.0585" rpy="-3.14159 -1.84192e-16 -1.34699e-17"/>
      <geometry>
        <mesh filename="package://hexapod_description/meshes/servo_wheel.stl"/>
      </geometry>
      <material name="servo_wheel_6_material">
        <color rgba="0.647059 0.647059 0.647059 1"/>
      </material>
    </visual>
    <collision>
      <origin xyz="-6.31439e-16 -5.55112e-17 -0.0585" rpy="-3.14159 -1.84192e-16 -1.34699e-17"/>
      <geometry>
        <mesh filename="package://hexapod_description/meshes/servo_wheel.stl"/>
      </geometry>
    </collision>
  </link>
  <!-- Joint from ties_assembly to foot_assembly -->
  <joint name="foot_1" type="revolute">
    <origin xyz="0.165999 0.0960821 -0.000790548" rpy="1.05854e-17 1.13313e-14 1.91986"/>
    <parent link="ties_assembly"/>
    <child link="foot_assembly"/>
    <axis xyz="0 0 1"/>
    <limit effort="10" velocity="10" lower="-0.349066" upper="3.83972"/>
  </joint>
  <!-- Joint from hip_assembly to ties_assembly -->
  <joint name="ties_1" type="revolute">
    <origin xyz="0.0925 -0.0311167 -0.0305" rpy="1.5708 3.25123e-15 3.22165e-16"/>
    <parent link="hip_assembly"/>
    <child link="ties_assembly"/>
    <axis xyz="0 0 1"/>
    <limit effort="10" velocity="10" lower="-2.26893" upper="1.22173"/>
  </joint>
  <!-- Joint from base_link to hip_assembly -->
  <joint name="hip_1" type="revolute">
    <origin xyz="0.0202915 0.148301 0.0272372" rpy="-3.93428e-14 -3.97183e-14 1.48353"/>
    <parent link="base_link"/>
    <child link="hip_assembly"/>
    <axis xyz="0 0 1"/>
    <limit effort="10" velocity="10" lower="-1.5708" upper="1.5708"/>
  </joint>
  <!-- Link hip_assembly_2 -->
  <link name="hip_assembly_2">
    <inertial>
      <origin xyz="-0.0268487 -0.000325484 -0.0302141" rpy="0 0 0"/>
      <mass value="0.365356"/>
      <inertia ixx="0.000168136" ixy="-2.8417e-07" ixz="3.2467e-06" iyy="0.000312332" iyz="-9.42575e-07" izz="0.000312341"/>
    </inertial>
    <!-- Part hip_2 -->
    <visual>
      <origin xyz="-0.0575 -0.0005 -0.0045" rpy="1.05049e-16 -1.89327e-29 -2.47243e-16"/>
      <geometry>
        <mesh filename="package://hexapod_description/meshes/hip.stl"/>
      </geometry>
      <material name="hip_2_material">
        <color rgba="0.282353 0.54902 0.160784 1"/>
      </material>
    </visual>
    <collision>
      <origin xyz="-0.0575 -0.0005 -0.0045" rpy="1.05049e-16 -1.89327e-29 -2.47243e-16"/>
      <geometry>
        <mesh filename="package://hexapod_description/meshes/hip.stl"/>
      </geometry>
    </collision>
    <!-- Part mobile_bracket_9 -->
    <visual>
      <origin xyz="-0.0575 2.68882e-17 -0.0305" rpy="-3.50154e-15 -5.7739e-15 1.5708"/>
      <geometry>
        <mesh filename="package://hexapod_description/meshes/mobile_bracket.stl"/>
      </geometry>
      <material name="mobile_bracket_9_material">
        <color rgba="0.647059 0.647059 0.647059 1"/>
      </material>
    </visual>
    <collision>
      <origin xyz="-0.0575 2.68882e-17 -0.0305" rpy="-3.50154e-15 -5.7739e-15 1.5708"/>
      <geometry>
        <mesh filename="package://hexapod_description/meshes/mobile_bracket.stl"/>
      </geometry>
    </collision>
    <!-- Part servo_wheel_7 -->
    <visual>
      <origin xyz="0 -8.67362e-19 -0.0025" rpy="3.14159 -6.31089e-30 -8.9275e-19"/>
      <geometry>
        <mesh filename="package://hexapod_description/meshes/servo_wheel.stl"/>
      </geometry>
      <material name="servo_wheel_7_material">
        <color rgba="0.647059 0.647059 0.647059 1"/>
      </material>
    </visual>
    <collision>
      <origin xyz="0 -8.67362e-19 -0.0025" rpy="3.14159 -6.31089e-30 -8.9275e-19"/>
      <geometry>
        <mesh filename="package://hexapod_description/meshes/servo_wheel.stl"/>
      </geometry>
    </collision>
    <!-- Part servo_4 -->
    <visual>
      <origin xyz="-0.0175 -0.00140442 -0.0305" rpy="-3.14159 -2.52435e-29 -3.79069e-16"/>
      <geometry>
        <mesh filename="package://hexapod_description/meshes/servo.stl"/>
      </geometry>
      <material name="servo_4_material">
        <color rgba="0.109804 0.109804 0.105882 1"/>
      </material>
    </visual>
    <collision>
      <origin xyz="-0.0175 -0.00140442 -0.0305" rpy="-3.14159 -2.52435e-29 -3.79069e-16"/>
      <geometry>
        <mesh filename="package://hexapod_description/meshes/servo.stl"/>
      </geometry>
    </collision>
    <!-- Part fixed_bracket_4 -->
    <visual>
      <origin xyz="-0.0575 2.68882e-17 -0.0305" rpy="1.5708 1.5708 0"/>
      <geometry>
        <mesh filename="package://hexapod_description/meshes/fixed_bracket.stl"/>
      </geometry>
      <material name="fixed_bracket_4_material">
        <color rgba="0.647059 0.647059 0.647059 1"/>
      </material>
    </visual>
    <collision>
      <origin xyz="-0.0575 2.68882e-17 -0.0305" rpy="1.5708 1.5708 0"/>
      <geometry>
        <mesh filename="package://hexapod_description/meshes/fixed_bracket.stl"/>
      </geometry>
    </collision>
    <!-- Part servo_wheel_8 -->
    <visual>
      <origin xyz="-8.32667e-17 3.46945e-17 -0.0585" rpy="-3.14159 -3.78653e-29 -4.44982e-16"/>
      <geometry>
        <mesh filename="package://hexapod_description/meshes/servo_wheel.stl"/>
      </geometry>
      <material name="servo_wheel_8_material">
        <color rgba="0.647059 0.647059 0.647059 1"/>
      </material>
    </visual>
    <collision>
      <origin xyz="-8.32667e-17 3.46945e-17 -0.0585" rpy="-3.14159 -3.78653e-29 -4.44982e-16"/>
      <geometry>
        <mesh filename="package://hexapod_description/meshes/servo_wheel.stl"/>
      </geometry>
    </collision>
  </link>
  <!-- Link ties_assembly_2 -->
  <link name="ties_assembly_2">
    <inertial>
      <origin xyz="0.0549718 0.0335057 -0.0309357" rpy="0 0 0"/>
      <mass value="0.589115"/>
      <inertia ixx="0.000782879" ixy="-0.000776998" ixz="9.2367e-06" iyy="0.00162431" iyz="5.57469e-06" izz="0.00187002"/>
    </inertial>
    <!-- Part mobile_bracket_10 -->
    <visual>
      <origin xyz="0.135688 0.0785821 -0.0311738" rpy="1.0472 1.5708 0"/>
      <geometry>
        <mesh filename="package://hexapod_description/meshes/mobile_bracket.stl"/>
      </geometry>
      <material name="mobile_bracket_10_material">
        <color rgba="0.647059 0.647059 0.647059 1"/>
      </material>
    </visual>
    <collision>
      <origin xyz="0.135688 0.0785821 -0.0311738" rpy="1.0472 1.5708 0"/>
      <geometry>
        <mesh filename="package://hexapod_description/meshes/mobile_bracket.stl"/>
      </geometry>
    </collision>
    <!-- Part low_tie_2 -->
    <visual>
      <origin xyz="0.0231043 0.0135821 -0.0311738" rpy="-0.523599 1.5708 0"/>
      <geometry>
        <mesh filename="package://hexapod_description/meshes/low_tie.stl"/>
      </geometry>
      <material name="low_tie_2_material">
        <color rgba="0.282353 0.54902 0.160784 1"/>
      </material>
    </visual>
    <collision>
      <origin xyz="0.0231043 0.0135821 -0.0311738" rpy="-0.523599 1.5708 0"/>
      <geometry>
        <mesh filename="package://hexapod_description/meshes/low_tie.stl"/>
      </geometry>
    </collision>
    <!-- Part top_tie_2 -->
    <visual>
      <origin xyz="0.0238157 0.01375 -0.0305" rpy="-0.523599 1.5708 0"/>
      <geometry>
        <mesh filename="package://hexapod_description/meshes/top_tie.stl"/>
      </geometry>
      <material name="top_tie_2_material">
        <color rgba="0.282353 0.54902 0.160784 1"/>
      </material>
    </visual>
    <collision>
      <origin xyz="0.0238157 0.01375 -0.0305" rpy="-0.523599 1.5708 0"/>
      <geometry>
        <mesh filename="package://hexapod_description/meshes/top_tie.stl"/>
      </geometry>
    </collision>
    <!-- Part servo_wheel_9 -->
    <visual>
      <origin xyz="-5.55112e-17 0 -0.0025" rpy="3.14159 -1.03168e-15 -2.61799"/>
      <geometry>
        <mesh filename="package://hexapod_description/meshes/servo_wheel.stl"/>
      </geometry>
      <material name="servo_wheel_9_material">
        <color rgba="0.647059 0.647059 0.647059 1"/>
      </material>
    </visual>
    <collision>
      <origin xyz="-5.55112e-17 0 -0.0025" rpy="3.14159 -1.03168e-15 -2.61799"/>
      <geometry>
        <mesh filename="package://hexapod_description/meshes/servo_wheel.stl"/>
      </geometry>
    </collision>
    <!-- Part servo_5 -->
    <visual>
      <origin xyz="0.0144532 0.00996626 -0.0305" rpy="-3.14159 -3.50198e-15 -2.61799"/>
      <geometry>
        <mesh filename="package://hexapod_description/meshes/servo.stl"/>
      </geometry>
      <material name="servo_5_material">
        <color rgba="0.109804 0.109804 0.105882 1"/>
      </material>
    </visual>
    <collision>
      <origin xyz="0.0144532 0.00996626 -0.0305" rpy="-3.14159 -3.50198e-15 -2.61799"/>
      <geometry>
        <mesh filename="package://hexapod_description/meshes/servo.stl"/>
      </geometry>
    </collision>
    <!-- Part fixed_bracket_5 -->
    <visual>
      <origin xyz="0.0497965 0.02875 -0.0305" rpy="-2.0944 1.5708 0"/>
      <geometry>
        <mesh filename="package://hexapod_description/meshes/fixed_bracket.stl"/>
      </geometry>
      <material name="fixed_bracket_5_material">
        <color rgba="0.647059 0.647059 0.647059 1"/>
      </material>
    </visual>
    <collision>
      <origin xyz="0.0497965 0.02875 -0.0305" rpy="-2.0944 1.5708 0"/>
      <geometry>
        <mesh filename="package://hexapod_description/meshes/fixed_bracket.stl"/>
      </geometry>
    </collision>
    <!-- Part servo_wheel_10 -->
    <visual>
      <origin xyz="-5.55112e-17 1.21864e-16 -0.0585" rpy="3.14159 1.38491e-15 -2.61799"/>
      <geometry>
        <mesh filename="package://hexapod_description/meshes/servo_wheel.stl"/>
      </geometry>
      <material name="servo_wheel_10_material">
        <color rgba="0.647059 0.647059 0.647059 1"/>
      </material>
    </visual>
    <collision>
      <origin xyz="-5.55112e-17 1.21864e-16 -0.0585" rpy="3.14159 1.38491e-15 -2.61799"/>
      <geometry>
        <mesh filename="package://hexapod_description/meshes/servo_wheel.stl"/>
      </geometry>
    </collision>
  </link>
  <!-- Link foot_assembly_2 -->
  <link name="foot_assembly_2">
    <inertial>
      <origin xyz="-0.0724503 -0.00208415 -0.0306672" rpy="0 0 0"/>
      <mass value="0.633745"/>
      <inertia ixx="0.000268495" ixy="-1.4806e-05" ixz="4.28294e-06" iyy="0.00320961" iyz="-2.30165e-07" izz="0.00304658"/>
    </inertial>
    <!-- Part foot_2 -->
    <visual>
      <origin xyz="-0.04425 0 -0.0305" rpy="-1.91543e-17 1.5708 0"/>
      <geometry>
        <mesh filename="package://hexapod_description/meshes/foot.stl"/>
      </geometry>
      <material name="foot_2_material">
        <color rgba="0.282353 0.54902 0.160784 1"/>
      </material>
    </visual>
    <collision>
      <origin xyz="-0.04425 0 -0.0305" rpy="-1.91543e-17 1.5708 0"/>
      <geometry>
        <mesh filename="package://hexapod_description/meshes/foot.stl"/>
      </geometry>
    </collision>
    <!-- Part ir_sensor_cap_2 -->
    <visual>
      <origin xyz="-0.04425 5.55112e-17 -0.0305" rpy="1.00727e-16 1.5708 0"/>
      <geometry>
        <mesh filename="package://hexapod_description/meshes/ir_sensor_cap.stl"/>
      </geometry>
      <material name="ir_sensor_cap_2_material">
        <color rgba="0.282353 0.54902 0.160784 1"/>
      </material>
    </visual>
    <collision>
      <origin xyz="-0.04425 5.55112e-17 -0.0305" rpy="1.00727e-16 1.5708 0"/>
      <geometry>
        <mesh filename="package://hexapod_description/meshes/ir_sensor_cap.stl"/>
      </geometry>
    </collision>
    <!-- Part rubber_foot_2 -->
    <visual>
      <origin xyz="-0.04375 -1.11022e-16 -0.03" rpy="7.92901e-16 1.5708 0"/>
      <geometry>
        <mesh filename="package://hexapod_description/meshes/rubber_foot.stl"/>
      </geometry>
      <material name="rubber_foot_2_material">
        <color rgba="0.262745 0.282353 0.301961 1"/>
      </material>
    </visual>
    <collision>
      <origin xyz="-0.04375 -1.11022e-16 -0.03" rpy="7.92901e-16 1.5708 0"/>
      <geometry>
        <mesh filename="package://hexapod_description/meshes/rubber_foot.stl"/>
      </geometry>
    </collision>
    <!-- Part servo_wheel_11 -->
    <visual>
      <origin xyz="3.46945e-17 0 -0.0025" rpy="3.14159 -3.41361e-18 -1.41083e-17"/>
      <geometry>
        <mesh filename="package://hexapod_description/meshes/servo_wheel.stl"/>
      </geometry>
      <material name="servo_wheel_11_material">
        <color rgba="0.647059 0.647059 0.647059 1"/>
      </material>
    </visual>
    <collision>
      <origin xyz="3.46945e-17 0 -0.0025" rpy="3.14159 -3.41361e-18 -1.41083e-17"/>
      <geometry>
        <mesh filename="package://hexapod_description/meshes/servo_wheel.stl"/>
      </geometry>
    </collision>
    <!-- Part servo_6 -->
    <visual>
      <origin xyz="-0.0175 -0.00140442 -0.0305" rpy="-3.14159 9.48615e-18 -4.81095e-17"/>
      <geometry>
        <mesh filename="package://hexapod_description/meshes/servo.stl"/>
      </geometry>
      <material name="servo_6_material">
        <color rgba="0.109804 0.109804 0.105882 1"/>
      </material>
    </visual>
    <collision>
      <origin xyz="-0.0175 -0.00140442 -0.0305" rpy="-3.14159 9.48615e-18 -4.81095e-17"/>
      <geometry>
        <mesh filename="package://hexapod_description/meshes/servo.stl"/>
      </geometry>
    </collision>
    <!-- Part fixed_bracket_6 -->
    <visual>
      <origin xyz="-0.0575 -5.55112e-17 -0.0305" rpy="1.5708 1.5708 0"/>
      <geometry>
        <mesh filename="package://hexapod_description/meshes/fixed_bracket.stl"/>
      </geometry>
      <material name="fixed_bracket_6_material">
        <color rgba="0.647059 0.647059 0.647059 1"/>
      </material>
    </visual>
    <collision>
      <origin xyz="-0.0575 -5.55112e-17 -0.0305" rpy="1.5708 1.5708 0"/>
      <geometry>
        <mesh filename="package://hexapod_description/meshes/fixed_bracket.stl"/>
      </geometry>
    </collision>
    <!-- Part servo_wheel_12 -->
    <visual>
      <origin xyz="-2.98372e-16 0 -0.0585" rpy="-3.14159 1.91167e-15 4.86746e-18"/>
      <geometry>
        <mesh filename="package://hexapod_description/meshes/servo_wheel.stl"/>
      </geometry>
      <material name="servo_wheel_12_material">
        <color rgba="0.647059 0.647059 0.647059 1"/>
      </material>
    </visual>
    <collision>
      <origin xyz="-2.98372e-16 0 -0.0585" rpy="-3.14159 1.91167e-15 4.86746e-18"/>
      <geometry>
        <mesh filename="package://hexapod_description/meshes/servo_wheel.stl"/>
      </geometry>
    </collision>
  </link>
  <!-- Joint from ties_assembly_2 to foot_assembly_2 -->
  <joint name="foot_2" type="revolute">
    <origin xyz="0.165999 0.0960821 -0.000790548" rpy="-1.18413e-16 1.60207e-15 1.91986"/>
    <parent link="ties_assembly_2"/>
    <child link="foot_assembly_2"/>
    <axis xyz="0 0 1"/>
    <limit effort="10" velocity="10" lower="-0.349066" upper="3.83972"/>
  </joint>
  <!-- Joint from hip_assembly_2 to ties_assembly_2 -->
  <joint name="ties_2" type="revolute">
    <origin xyz="-0.0925 0.0311167 -0.0305" rpy="1.5708 3.50154e-15 3.14159"/>
    <parent link="hip_assembly_2"/>
    <child link="ties_assembly_2"/>
    <axis xyz="0 0 1"/>
    <limit effort="10" velocity="10" lower="-2.26893" upper="1.22173"/>
  </joint>
  <!-- Joint from base_link to hip_assembly_2 -->
  <joint name="hip_2" type="revolute">
    <origin xyz="0.144817 0.0611074 0.0272372" rpy="-1.39309e-14 5.38714e-14 -2.70526"/>
    <parent link="base_link"/>
    <child link="hip_assembly_2"/>
    <axis xyz="0 0 1"/>
    <limit effort="10" velocity="10" lower="-1.5708" upper="1.5708"/>
  </joint>
  <!-- Link hip_assembly_3 -->
  <link name="hip_assembly_3">
    <inertial>
      <origin xyz="-0.0268487 -0.000325484 -0.0302141" rpy="0 0 0"/>
      <mass value="0.365356"/>
      <inertia ixx="0.000168136" ixy="-2.8417e-07" ixz="3.2467e-06" iyy="0.000312332" iyz="-9.42575e-07" izz="0.000312341"/>
    </inertial>
    <!-- Part hip_3 -->
    <visual>
      <origin xyz="-0.0575 -0.0005 -0.0045" rpy="3.04166e-16 -8.3994e-16 9.29433e-16"/>
      <geometry>
        <mesh filename="package://hexapod_description/meshes/hip.stl"/>
      </geometry>
      <material name="hip_3_material">
        <color rgba="0.282353 0.54902 0.160784 1"/>
      </material>
    </visual>
    <collision>
      <origin xyz="-0.0575 -0.0005 -0.0045" rpy="3.04166e-16 -8.3994e-16 9.29433e-16"/>
      <geometry>
        <mesh filename="package://hexapod_description/meshes/hip.stl"/>
      </geometry>
    </collision>
    <!-- Part mobile_bracket_11 -->
    <visual>
      <origin xyz="-0.0575 -2.01662e-17 -0.0305" rpy="8.53508e-17 -1.30826e-17 1.5708"/>
      <geometry>
        <mesh filename="package://hexapod_description/meshes/mobile_bracket.stl"/>
      </geometry>
      <material name="mobile_bracket_11_material">
        <color rgba="0.647059 0.647059 0.647059 1"/>
      </material>
    </visual>
    <collision>
      <origin xyz="-0.0575 -2.01662e-17 -0.0305" rpy="8.53508e-17 -1.30826e-17 1.5708"/>
      <geometry>
        <mesh filename="package://hexapod_description/meshes/mobile_bracket.stl"/>
      </geometry>
    </collision>
    <!-- Part servo_wheel_13 -->
    <visual>
      <origin xyz="0 -4.55365e-18 -0.0025" rpy="3.14159 2.62092e-30 7.0779e-17"/>
      <geometry>
        <mesh filename="package://hexapod_description/meshes/servo_wheel.stl"/>
      </geometry>
      <material name="servo_wheel_13_material">
        <color rgba="0.647059 0.647059 0.647059 1"/>
      </material>
    </visual>
    <collision>
      <origin xyz="0 -4.55365e-18 -0.0025" rpy="3.14159 2.62092e-30 7.0779e-17"/>
      <geometry>
        <mesh filename="package://hexapod_description/meshes/servo_wheel.stl"/>
      </geometry>
    </collision>
    <!-- Part servo_7 -->
    <visual>
      <origin xyz="-0.0175 -0.00140442 -0.0305" rpy="3.14159 5.77636e-30 6.60557e-17"/>
      <geometry>
        <mesh filename="package://hexapod_description/meshes/servo.stl"/>
      </geometry>
      <material name="servo_7_material">
        <color rgba="0.109804 0.109804 0.105882 1"/>
      </material>
    </visual>
    <collision>
      <origin xyz="-0.0175 -0.00140442 -0.0305" rpy="3.14159 5.77636e-30 6.60557e-17"/>
      <geometry>
        <mesh filename="package://hexapod_description/meshes/servo.stl"/>
      </geometry>
    </collision>
    <!-- Part fixed_bracket_7 -->
    <visual>
      <origin xyz="-0.0575 -2.01662e-17 -0.0305" rpy="1.5708 1.5708 0"/>
      <geometry>
        <mesh filename="package://hexapod_description/meshes/fixed_bracket.stl"/>
      </geometry>
      <material name="fixed_bracket_7_material">
        <color rgba="0.647059 0.647059 0.647059 1"/>
      </material>
    </visual>
    <collision>
      <origin xyz="-0.0575 -2.01662e-17 -0.0305" rpy="1.5708 1.5708 0"/>
      <geometry>
        <mesh filename="package://hexapod_description/meshes/fixed_bracket.stl"/>
      </geometry>
    </collision>
    <!-- Part servo_wheel_14 -->
    <visual>
      <origin xyz="-5.55112e-17 -2.81893e-17 -0.0585" rpy="-3.14159 1.54695e-16 8.61339e-17"/>
      <geometry>
        <mesh filename="package://hexapod_description/meshes/servo_wheel.stl"/>
      </geometry>
      <material name="servo_wheel_14_material">
        <color rgba="0.647059 0.647059 0.647059 1"/>
      </material>
    </visual>
    <collision>
      <origin xyz="-5.55112e-17 -2.81893e-17 -0.0585" rpy="-3.14159 1.54695e-16 8.61339e-17"/>
      <geometry>
        <mesh filename="package://hexapod_description/meshes/servo_wheel.stl"/>
      </geometry>
    </collision>
  </link>
  <!-- Link ties_assembly_3 -->
  <link name="ties_assembly_3">
    <inertial>
      <origin xyz="0.0549718 0.0335057 -0.0309357" rpy="0 0 0"/>
      <mass value="0.589115"/>
      <inertia ixx="0.000782879" ixy="-0.000776998" ixz="9.2367e-06" iyy="0.00162431" iyz="5.57469e-06" izz="0.00187002"/>
    </inertial>
    <!-- Part mobile_bracket_12 -->
    <visual>
      <origin xyz="0.135688 0.0785821 -0.0311738" rpy="1.0472 1.5708 0"/>
      <geometry>
        <mesh filename="package://hexapod_description/meshes/mobile_bracket.stl"/>
      </geometry>
      <material name="mobile_bracket_12_material">
        <color rgba="0.647059 0.647059 0.647059 1"/>
      </material>
    </visual>
    <collision>
      <origin xyz="0.135688 0.0785821 -0.0311738" rpy="1.0472 1.5708 0"/>
      <geometry>
        <mesh filename="package://hexapod_description/meshes/mobile_bracket.stl"/>
      </geometry>
    </collision>
    <!-- Part low_tie_3 -->
    <visual>
      <origin xyz="0.0231043 0.0135821 -0.0311738" rpy="-0.523599 1.5708 0"/>
      <geometry>
        <mesh filename="package://hexapod_description/meshes/low_tie.stl"/>
      </geometry>
      <material name="low_tie_3_material">
        <color rgba="0.282353 0.54902 0.160784 1"/>
      </material>
    </visual>
    <collision>
      <origin xyz="0.0231043 0.0135821 -0.0311738" rpy="-0.523599 1.5708 0"/>
      <geometry>
        <mesh filename="package://hexapod_description/meshes/low_tie.stl"/>
      </geometry>
    </collision>
    <!-- Part top_tie_3 -->
    <visual>
      <origin xyz="0.0238157 0.01375 -0.0305" rpy="-0.523599 1.5708 0"/>
      <geometry>
        <mesh filename="package://hexapod_description/meshes/top_tie.stl"/>
      </geometry>
      <material name="top_tie_3_material">
        <color rgba="0.282353 0.54902 0.160784 1"/>
      </material>
    </visual>
    <collision>
      <origin xyz="0.0238157 0.01375 -0.0305" rpy="-0.523599 1.5708 0"/>
      <geometry>
        <mesh filename="package://hexapod_description/meshes/top_tie.stl"/>
      </geometry>
    </collision>
    <!-- Part servo_wheel_15 -->
    <visual>
      <origin xyz="-5.55112e-17 4.33681e-19 -0.0025" rpy="3.14159 6.86081e-16 -2.61799"/>
      <geometry>
        <mesh filename="package://hexapod_description/meshes/servo_wheel.stl"/>
      </geometry>
      <material name="servo_wheel_15_material">
        <color rgba="0.647059 0.647059 0.647059 1"/>
      </material>
    </visual>
    <collision>
      <origin xyz="-5.55112e-17 4.33681e-19 -0.0025" rpy="3.14159 6.86081e-16 -2.61799"/>
      <geometry>
        <mesh filename="package://hexapod_description/meshes/servo_wheel.stl"/>
      </geometry>
    </collision>
    <!-- Part servo_8 -->
    <visual>
      <origin xyz="0.0144532 0.00996626 -0.0305" rpy="-3.14159 1.34159e-14 -2.61799"/>
      <geometry>
        <mesh filename="package://hexapod_description/meshes/servo.stl"/>
      </geometry>
      <material name="servo_8_material">
        <color rgba="0.109804 0.109804 0.105882 1"/>
      </material>
    </visual>
    <collision>
      <origin xyz="0.0144532 0.00996626 -0.0305" rpy="-3.14159 1.34159e-14 -2.61799"/>
      <geometry>
        <mesh filename="package://hexapod_description/meshes/servo.stl"/>
      </geometry>
    </collision>
    <!-- Part fixed_bracket_8 -->
    <visual>
      <origin xyz="0.0497965 0.02875 -0.0305" rpy="-2.0944 1.5708 0"/>
      <geometry>
        <mesh filename="package://hexapod_description/meshes/fixed_bracket.stl"/>
      </geometry>
      <material name="fixed_bracket_8_material">
        <color rgba="0.647059 0.647059 0.647059 1"/>
      </material>
    </visual>
    <collision>
      <origin xyz="0.0497965 0.02875 -0.0305" rpy="-2.0944 1.5708 0"/>
      <geometry>
        <mesh filename="package://hexapod_description/meshes/fixed_bracket.stl"/>
      </geometry>
    </collision>
    <!-- Part servo_wheel_16 -->
    <visual>
      <origin xyz="-5.55112e-17 1.30104e-17 -0.0585" rpy="-3.14159 1.60882e-14 -2.61799"/>
      <geometry>
        <mesh filename="package://hexapod_description/meshes/servo_wheel.stl"/>
      </geometry>
      <material name="servo_wheel_16_material">
        <color rgba="0.647059 0.647059 0.647059 1"/>
      </material>
    </visual>
    <collision>
      <origin xyz="-5.55112e-17 1.30104e-17 -0.0585" rpy="-3.14159 1.60882e-14 -2.61799"/>
      <geometry>
        <mesh filename="package://hexapod_description/meshes/servo_wheel.stl"/>
      </geometry>
    </collision>
  </link>
  <!-- Link foot_assembly_3 -->
  <link name="foot_assembly_3">
    <inertial>
      <origin xyz="-0.0724503 -0.00208415 -0.0306672" rpy="0 0 0"/>
      <mass value="0.633745"/>
      <inertia ixx="0.000268495" ixy="-1.4806e-05" ixz="4.28294e-06" iyy="0.00320961" iyz="-2.30165e-07" izz="0.00304658"/>
    </inertial>
    <!-- Part foot_3 -->
    <visual>
      <origin xyz="-0.04425 1.66533e-16 -0.0305" rpy="1.32822e-16 1.5708 0"/>
      <geometry>
        <mesh filename="package://hexapod_description/meshes/foot.stl"/>
      </geometry>
      <material name="foot_3_material">
        <color rgba="0.282353 0.54902 0.160784 1"/>
      </material>
    </visual>
    <collision>
      <origin xyz="-0.04425 1.66533e-16 -0.0305" rpy="1.32822e-16 1.5708 0"/>
      <geometry>
        <mesh filename="package://hexapod_description/meshes/foot.stl"/>
      </geometry>
    </collision>
    <!-- Part ir_sensor_cap_3 -->
    <visual>
      <origin xyz="-0.04425 -1.05471e-15 -0.0305" rpy="7.16486e-15 1.5708 0"/>
      <geometry>
        <mesh filename="package://hexapod_description/meshes/ir_sensor_cap.stl"/>
      </geometry>
      <material name="ir_sensor_cap_3_material">
        <color rgba="0.282353 0.54902 0.160784 1"/>
      </material>
    </visual>
    <collision>
      <origin xyz="-0.04425 -1.05471e-15 -0.0305" rpy="7.16486e-15 1.5708 0"/>
      <geometry>
        <mesh filename="package://hexapod_description/meshes/ir_sensor_cap.stl"/>
      </geometry>
    </collision>
    <!-- Part rubber_foot_3 -->
    <visual>
      <origin xyz="-0.04375 -2.33147e-15 -0.03" rpy="1.07884e-14 1.5708 0"/>
      <geometry>
        <mesh filename="package://hexapod_description/meshes/rubber_foot.stl"/>
      </geometry>
      <material name="rubber_foot_3_material">
        <color rgba="0.262745 0.282353 0.301961 1"/>
      </material>
    </visual>
    <collision>
      <origin xyz="-0.04375 -2.33147e-15 -0.03" rpy="1.07884e-14 1.5708 0"/>
      <geometry>
        <mesh filename="package://hexapod_description/meshes/rubber_foot.stl"/>
      </geometry>
    </collision>
    <!-- Part servo_wheel_17 -->
    <visual>
      <origin xyz="6.93889e-18 0 -0.0025" rpy="-3.14159 -2.05429e-17 -9.73839e-17"/>
      <geometry>
        <mesh filename="package://hexapod_description/meshes/servo_wheel.stl"/>
      </geometry>
      <material name="servo_wheel_17_material">
        <color rgba="0.647059 0.647059 0.647059 1"/>
      </material>
    </visual>
    <collision>
      <origin xyz="6.93889e-18 0 -0.0025" rpy="-3.14159 -2.05429e-17 -9.73839e-17"/>
      <geometry>
        <mesh filename="package://hexapod_description/meshes/servo_wheel.stl"/>
      </geometry>
    </collision>
    <!-- Part servo_9 -->
    <visual>
      <origin xyz="-0.0175 -0.00140442 -0.0305" rpy="-3.14159 1.77245e-14 -2.16009e-16"/>
      <geometry>
        <mesh filename="package://hexapod_description/meshes/servo.stl"/>
      </geometry>
      <material name="servo_9_material">
        <color rgba="0.109804 0.109804 0.105882 1"/>
      </material>
    </visual>
    <collision>
      <origin xyz="-0.0175 -0.00140442 -0.0305" rpy="-3.14159 1.77245e-14 -2.16009e-16"/>
      <geometry>
        <mesh filename="package://hexapod_description/meshes/servo.stl"/>
      </geometry>
    </collision>
    <!-- Part fixed_bracket_9 -->
    <visual>
      <origin xyz="-0.0575 1.11022e-16 -0.0305" rpy="1.5708 1.5708 0"/>
      <geometry>
        <mesh filename="package://hexapod_description/meshes/fixed_bracket.stl"/>
      </geometry>
      <material name="fixed_bracket_9_material">
        <color rgba="0.647059 0.647059 0.647059 1"/>
      </material>
    </visual>
    <collision>
      <origin xyz="-0.0575 1.11022e-16 -0.0305" rpy="1.5708 1.5708 0"/>
      <geometry>
        <mesh filename="package://hexapod_description/meshes/fixed_bracket.stl"/>
      </geometry>
    </collision>
    <!-- Part servo_wheel_18 -->
    <visual>
      <origin xyz="-5.55112e-17 -5.55112e-17 -0.0585" rpy="3.14159 1.77008e-14 -1.41501e-16"/>
      <geometry>
        <mesh filename="package://hexapod_description/meshes/servo_wheel.stl"/>
      </geometry>
      <material name="servo_wheel_18_material">
        <color rgba="0.647059 0.647059 0.647059 1"/>
      </material>
    </visual>
    <collision>
      <origin xyz="-5.55112e-17 -5.55112e-17 -0.0585" rpy="3.14159 1.77008e-14 -1.41501e-16"/>
      <geometry>
        <mesh filename="package://hexapod_description/meshes/servo_wheel.stl"/>
      </geometry>
    </collision>
  </link>
  <!-- Joint from ties_assembly_3 to foot_assembly_3 -->
  <joint name="foot_3" type="revolute">
    <origin xyz="0.165999 0.0960821 -0.000790548" rpy="-2.99398e-16 -1.37685e-16 1.91986"/>
    <parent link="ties_assembly_3"/>
    <child link="foot_assembly_3"/>
    <axis xyz="0 0 1"/>
    <limit effort="10" velocity="10" lower="-0.349066" upper="3.83972"/>
  </joint>
  <!-- Joint from hip_assembly_3 to ties_assembly_3 -->
  <joint name="ties_3" type="revolute">
    <origin xyz="-0.0925 0.0311167 -0.0305" rpy="1.5708 -8.53508e-17 -3.14159"/>
    <parent link="hip_assembly_3"/>
    <child link="ties_assembly_3"/>
    <axis xyz="0 0 1"/>
    <limit effort="10" velocity="10" lower="-2.26893" upper="1.22173"/>
  </joint>
  <!-- Joint from base_link to hip_assembly_3 -->
  <joint name="hip_3" type="revolute">
    <origin xyz="0.131567 -0.0903312 0.0279706" rpy="-5.21664e-14 1.54145e-14 2.53073"/>
    <parent link="base_link"/>
    <child link="hip_assembly_3"/>
    <axis xyz="0 0 1"/>
    <limit effort="10" velocity="10" lower="-1.5708" upper="1.5708"/>
  </joint>
  <!-- Link hip_assembly_4 -->
  <link name="hip_assembly_4">
    <inertial>
      <origin xyz="-0.0268487 -0.000325484 -0.0302141" rpy="0 0 0"/>
      <mass value="0.365356"/>
      <inertia ixx="0.000168136" ixy="-2.8417e-07" ixz="3.2467e-06" iyy="0.000312332" iyz="-9.42575e-07" izz="0.000312341"/>
    </inertial>
    <!-- Part hip_4 -->
    <visual>
      <origin xyz="-0.0575 -0.0005 -0.0045" rpy="2.06741e-15 1.97865e-15 -4.13872e-16"/>
      <geometry>
        <mesh filename="package://hexapod_description/meshes/hip.stl"/>
      </geometry>
      <material name="hip_4_material">
        <color rgba="0.282353 0.54902 0.160784 1"/>
      </material>
    </visual>
    <collision>
      <origin xyz="-0.0575 -0.0005 -0.0045" rpy="2.06741e-15 1.97865e-15 -4.13872e-16"/>
      <geometry>
        <mesh filename="package://hexapod_description/meshes/hip.stl"/>
      </geometry>
    </collision>
    <!-- Part mobile_bracket_13 -->
    <visual>
      <origin xyz="-0.0575 5.20417e-18 -0.0305" rpy="1.87979e-15 4.53065e-16 1.5708"/>
      <geometry>
        <mesh filename="package://hexapod_description/meshes/mobile_bracket.stl"/>
      </geometry>
      <material name="mobile_bracket_13_material">
        <color rgba="0.647059 0.647059 0.647059 1"/>
      </material>
    </visual>
    <collision>
      <origin xyz="-0.0575 5.20417e-18 -0.0305" rpy="1.87979e-15 4.53065e-16 1.5708"/>
      <geometry>
        <mesh filename="package://hexapod_description/meshes/mobile_bracket.stl"/>
      </geometry>
    </collision>
    <!-- Part servo_wheel_19 -->
    <visual>
      <origin xyz="0 8.67362e-19 -0.0025" rpy="3.14159 4.33975e-30 2.4618e-18"/>
      <geometry>
        <mesh filename="package://hexapod_description/meshes/servo_wheel.stl"/>
      </geometry>
      <material name="servo_wheel_19_material">
        <color rgba="0.647059 0.647059 0.647059 1"/>
      </material>
    </visual>
    <collision>
      <origin xyz="0 8.67362e-19 -0.0025" rpy="3.14159 4.33975e-30 2.4618e-18"/>
      <geometry>
        <mesh filename="package://hexapod_description/meshes/servo_wheel.stl"/>
      </geometry>
    </collision>
    <!-- Part servo_10 -->
    <visual>
      <origin xyz="-0.0175 -0.00140442 -0.0305" rpy="-3.14159 -1.97114e-30 1.67218e-17"/>
      <geometry>
        <mesh filename="package://hexapod_description/meshes/servo.stl"/>
      </geometry>
      <material name="servo_10_material">
        <color rgba="0.109804 0.109804 0.105882 1"/>
      </material>
    </visual>
    <collision>
      <origin xyz="-0.0175 -0.00140442 -0.0305" rpy="-3.14159 -1.97114e-30 1.67218e-17"/>
      <geometry>
        <mesh filename="package://hexapod_description/meshes/servo.stl"/>
      </geometry>
    </collision>
    <!-- Part fixed_bracket_10 -->
    <visual>
      <origin xyz="-0.0575 5.20417e-18 -0.0305" rpy="1.5708 1.5708 0"/>
      <geometry>
        <mesh filename="package://hexapod_description/meshes/fixed_bracket.stl"/>
      </geometry>
      <material name="fixed_bracket_10_material">
        <color rgba="0.647059 0.647059 0.647059 1"/>
      </material>
    </visual>
    <collision>
      <origin xyz="-0.0575 5.20417e-18 -0.0305" rpy="1.5708 1.5708 0"/>
      <geometry>
        <mesh filename="package://hexapod_description/meshes/fixed_bracket.stl"/>
      </geometry>
    </collision>
    <!-- Part servo_wheel_20 -->
    <visual>
      <origin xyz="0 0 -0.0585" rpy="-3.14159 1.87979e-15 1.25202e-17"/>
      <geometry>
        <mesh filename="package://hexapod_description/meshes/servo_wheel.stl"/>
      </geometry>
      <material name="servo_wheel_20_material">
        <color rgba="0.647059 0.647059 0.647059 1"/>
      </material>
    </visual>
    <collision>
      <origin xyz="0 0 -0.0585" rpy="-3.14159 1.87979e-15 1.25202e-17"/>
      <geometry>
        <mesh filename="package://hexapod_description/meshes/servo_wheel.stl"/>
      </geometry>
    </collision>
  </link>
  <!-- Link ties_assembly_4 -->
  <link name="ties_assembly_4">
    <inertial>
      <origin xyz="0.0549718 0.0335057 -0.0309357" rpy="0 0 0"/>
      <mass value="0.589115"/>
      <inertia ixx="0.000782879" ixy="-0.000776998" ixz="9.2367e-06" iyy="0.00162431" iyz="5.57469e-06" izz="0.00187002"/>
    </inertial>
    <!-- Part mobile_bracket_14 -->
    <visual>
      <origin xyz="0.135688 0.0785821 -0.0311738" rpy="1.0472 1.5708 0"/>
      <geometry>
        <mesh filename="package://hexapod_description/meshes/mobile_bracket.stl"/>
      </geometry>
      <material name="mobile_bracket_14_material">
        <color rgba="0.647059 0.647059 0.647059 1"/>
      </material>
    </visual>
    <collision>
      <origin xyz="0.135688 0.0785821 -0.0311738" rpy="1.0472 1.5708 0"/>
      <geometry>
        <mesh filename="package://hexapod_description/meshes/mobile_bracket.stl"/>
      </geometry>
    </collision>
    <!-- Part low_tie_4 -->
    <visual>
      <origin xyz="0.0231043 0.0135821 -0.0311738" rpy="-0.523599 1.5708 0"/>
      <geometry>
        <mesh filename="package://hexapod_description/meshes/low_tie.stl"/>
      </geometry>
      <material name="low_tie_4_material">
        <color rgba="0.282353 0.54902 0.160784 1"/>
      </material>
    </visual>
    <collision>
      <origin xyz="0.0231043 0.0135821 -0.0311738" rpy="-0.523599 1.5708 0"/>
      <geometry>
        <mesh filename="package://hexapod_description/meshes/low_tie.stl"/>
      </geometry>
    </collision>
    <!-- Part top_tie_4 -->
    <visual>
      <origin xyz="0.0238157 0.01375 -0.0305" rpy="-0.523599 1.5708 0"/>
      <geometry>
        <mesh filename="package://hexapod_description/meshes/top_tie.stl"/>
      </geometry>
      <material name="top_tie_4_material">
        <color rgba="0.282353 0.54902 0.160784 1"/>
      </material>
    </visual>
    <collision>
      <origin xyz="0.0238157 0.01375 -0.0305" rpy="-0.523599 1.5708 0"/>
      <geometry>
        <mesh filename="package://hexapod_description/meshes/top_tie.stl"/>
      </geometry>
    </collision>
    <!-- Part servo_wheel_21 -->
    <visual>
      <origin xyz="0 -2.1684e-18 -0.0025" rpy="3.14159 -2.9101e-15 -2.61799"/>
      <geometry>
        <mesh filename="package://hexapod_description/meshes/servo_wheel.stl"/>
      </geometry>
      <material name="servo_wheel_21_material">
        <color rgba="0.647059 0.647059 0.647059 1"/>
      </material>
    </visual>
    <collision>
      <origin xyz="0 -2.1684e-18 -0.0025" rpy="3.14159 -2.9101e-15 -2.61799"/>
      <geometry>
        <mesh filename="package://hexapod_description/meshes/servo_wheel.stl"/>
      </geometry>
    </collision>
    <!-- Part servo_11 -->
    <visual>
      <origin xyz="0.0144532 0.00996626 -0.0305" rpy="3.14159 -6.25631e-15 -2.61799"/>
      <geometry>
        <mesh filename="package://hexapod_description/meshes/servo.stl"/>
      </geometry>
      <material name="servo_11_material">
        <color rgba="0.109804 0.109804 0.105882 1"/>
      </material>
    </visual>
    <collision>
      <origin xyz="0.0144532 0.00996626 -0.0305" rpy="3.14159 -6.25631e-15 -2.61799"/>
      <geometry>
        <mesh filename="package://hexapod_description/meshes/servo.stl"/>
      </geometry>
    </collision>
    <!-- Part fixed_bracket_11 -->
    <visual>
      <origin xyz="0.0497965 0.02875 -0.0305" rpy="-2.0944 1.5708 0"/>
      <geometry>
        <mesh filename="package://hexapod_description/meshes/fixed_bracket.stl"/>
      </geometry>
      <material name="fixed_bracket_11_material">
        <color rgba="0.647059 0.647059 0.647059 1"/>
      </material>
    </visual>
    <collision>
      <origin xyz="0.0497965 0.02875 -0.0305" rpy="-2.0944 1.5708 0"/>
      <geometry>
        <mesh filename="package://hexapod_description/meshes/fixed_bracket.stl"/>
      </geometry>
    </collision>
    <!-- Part servo_wheel_22 -->
    <visual>
      <origin xyz="-8.32667e-17 -5.33427e-17 -0.0585" rpy="-3.14159 -6.25096e-15 -2.61799"/>
      <geometry>
        <mesh filename="package://hexapod_description/meshes/servo_wheel.stl"/>
      </geometry>
      <material name="servo_wheel_22_material">
        <color rgba="0.647059 0.647059 0.647059 1"/>
      </material>
    </visual>
    <collision>
      <origin xyz="-8.32667e-17 -5.33427e-17 -0.0585" rpy="-3.14159 -6.25096e-15 -2.61799"/>
      <geometry>
        <mesh filename="package://hexapod_description/meshes/servo_wheel.stl"/>
      </geometry>
    </collision>
  </link>
  <!-- Link foot_assembly_4 -->
  <link name="foot_assembly_4">
    <inertial>
      <origin xyz="-0.0724503 -0.00208415 -0.0306672" rpy="0 0 0"/>
      <mass value="0.633745"/>
      <inertia ixx="0.000268495" ixy="-1.4806e-05" ixz="4.28294e-06" iyy="0.00320961" iyz="-2.30165e-07" izz="0.00304658"/>
    </inertial>
    <!-- Part foot_4 -->
    <visual>
      <origin xyz="-0.04425 0 -0.0305" rpy="4.264e-17 1.5708 0"/>
      <geometry>
        <mesh filename="package://hexapod_description/meshes/foot.stl"/>
      </geometry>
      <material name="foot_4_material">
        <color rgba="0.282353 0.54902 0.160784 1"/>
      </material>
    </visual>
    <collision>
      <origin xyz="-0.04425 0 -0.0305" rpy="4.264e-17 1.5708 0"/>
      <geometry>
        <mesh filename="package://hexapod_description/meshes/foot.stl"/>
      </geometry>
    </collision>
    <!-- Part ir_sensor_cap_4 -->
    <visual>
      <origin xyz="-0.04425 1.11022e-16 -0.0305" rpy="4.66809e-18 1.5708 0"/>
      <geometry>
        <mesh filename="package://hexapod_description/meshes/ir_sensor_cap.stl"/>
      </geometry>
      <material name="ir_sensor_cap_4_material">
        <color rgba="0.282353 0.54902 0.160784 1"/>
      </material>
    </visual>
    <collision>
      <origin xyz="-0.04425 1.11022e-16 -0.0305" rpy="4.66809e-18 1.5708 0"/>
      <geometry>
        <mesh filename="package://hexapod_description/meshes/ir_sensor_cap.stl"/>
      </geometry>
    </collision>
    <!-- Part rubber_foot_4 -->
    <visual>
      <origin xyz="-0.04375 1.9984e-15 -0.03" rpy="-8.86065e-15 1.5708 0"/>
      <geometry>
        <mesh filename="package://hexapod_description/meshes/rubber_foot.stl"/>
      </geometry>
      <material name="rubber_foot_4_material">
        <color rgba="0.262745 0.282353 0.301961 1"/>
      </material>
    </visual>
    <collision>
      <origin xyz="-0.04375 1.9984e-15 -0.03" rpy="-8.86065e-15 1.5708 0"/>
      <geometry>
        <mesh filename="package://hexapod_description/meshes/rubber_foot.stl"/>
      </geometry>
    </collision>
    <!-- Part servo_wheel_23 -->
    <visual>
      <origin xyz="4.16334e-17 0 -0.0025" rpy="3.14159 -2.57829e-18 3.04105e-17"/>
      <geometry>
        <mesh filename="package://hexapod_description/meshes/servo_wheel.stl"/>
      </geometry>
      <material name="servo_wheel_23_material">
        <color rgba="0.647059 0.647059 0.647059 1"/>
      </material>
    </visual>
    <collision>
      <origin xyz="4.16334e-17 0 -0.0025" rpy="3.14159 -2.57829e-18 3.04105e-17"/>
      <geometry>
        <mesh filename="package://hexapod_description/meshes/servo_wheel.stl"/>
      </geometry>
    </collision>
    <!-- Part servo_12 -->
    <visual>
      <origin xyz="-0.0175 -0.00140442 -0.0305" rpy="-3.14159 1.1312e-15 1.06354e-16"/>
      <geometry>
        <mesh filename="package://hexapod_description/meshes/servo.stl"/>
      </geometry>
      <material name="servo_12_material">
        <color rgba="0.109804 0.109804 0.105882 1"/>
      </material>
    </visual>
    <collision>
      <origin xyz="-0.0175 -0.00140442 -0.0305" rpy="-3.14159 1.1312e-15 1.06354e-16"/>
      <geometry>
        <mesh filename="package://hexapod_description/meshes/servo.stl"/>
      </geometry>
    </collision>
    <!-- Part fixed_bracket_12 -->
    <visual>
      <origin xyz="-0.0575 0 -0.0305" rpy="1.5708 1.5708 0"/>
      <geometry>
        <mesh filename="package://hexapod_description/meshes/fixed_bracket.stl"/>
      </geometry>
      <material name="fixed_bracket_12_material">
        <color rgba="0.647059 0.647059 0.647059 1"/>
      </material>
    </visual>
    <collision>
      <origin xyz="-0.0575 0 -0.0305" rpy="1.5708 1.5708 0"/>
      <geometry>
        <mesh filename="package://hexapod_description/meshes/fixed_bracket.stl"/>
      </geometry>
    </collision>
    <!-- Part servo_wheel_24 -->
    <visual>
      <origin xyz="6.93889e-18 -5.55112e-17 -0.0585" rpy="-3.14159 1.13403e-15 8.30283e-17"/>
      <geometry>
        <mesh filename="package://hexapod_description/meshes/servo_wheel.stl"/>
      </geometry>
      <material name="servo_wheel_24_material">
        <color rgba="0.647059 0.647059 0.647059 1"/>
      </material>
    </visual>
    <collision>
      <origin xyz="6.93889e-18 -5.55112e-17 -0.0585" rpy="-3.14159 1.13403e-15 8.30283e-17"/>
      <geometry>
        <mesh filename="package://hexapod_description/meshes/servo_wheel.stl"/>
      </geometry>
    </collision>
  </link>
  <!-- Joint from ties_assembly_4 to foot_assembly_4 -->
  <joint name="foot_4" type="revolute">
    <origin xyz="0.165999 0.0960821 -0.000790548" rpy="1.4637e-15 1.68038e-16 1.91986"/>
    <parent link="ties_assembly_4"/>
    <child link="foot_assembly_4"/>
    <axis xyz="0 0 1"/>
    <limit effort="10" velocity="10" lower="-0.349066" upper="3.83972"/>
  </joint>
  <!-- Joint from hip_assembly_4 to ties_assembly_4 -->
  <joint name="ties_4" type="revolute">
    <origin xyz="-0.0925 0.0311167 -0.0305" rpy="1.5708 -1.87979e-15 -3.14159"/>
    <parent link="hip_assembly_4"/>
    <child link="ties_assembly_4"/>
    <axis xyz="0 0 1"/>
    <limit effort="10" velocity="10" lower="-2.26893" upper="1.22173"/>
  </joint>
  <!-- Joint from base_link to hip_assembly_4 -->
  <joint name="hip_4" type="revolute">
    <origin xyz="-0.0062068 -0.154576 0.0279706" rpy="-3.88964e-14 -3.72989e-14 1.48353"/>
    <parent link="base_link"/>
    <child link="hip_assembly_4"/>
    <axis xyz="0 0 1"/>
    <limit effort="10" velocity="10" lower="-1.5708" upper="1.5708"/>
  </joint>
  <!-- Link hip_assembly_5 -->
  <link name="hip_assembly_5">
    <inertial>
      <origin xyz="0.0268487 0.000325484 -0.0302141" rpy="0 0 0"/>
      <mass value="0.365356"/>
      <inertia ixx="0.000168136" ixy="-2.8417e-07" ixz="-3.2467e-06" iyy="0.000312332" iyz="9.42575e-07" izz="0.000312341"/>
    </inertial>
    <!-- Part hip_5 -->
    <visual>
      <origin xyz="0.0575 0.0005 -0.0045" rpy="1.13633e-15 -2.88289e-16 -3.14159"/>
      <geometry>
        <mesh filename="package://hexapod_description/meshes/hip.stl"/>
      </geometry>
      <material name="hip_5_material">
        <color rgba="0.282353 0.54902 0.160784 1"/>
      </material>
    </visual>
    <collision>
      <origin xyz="0.0575 0.0005 -0.0045" rpy="1.13633e-15 -2.88289e-16 -3.14159"/>
      <geometry>
        <mesh filename="package://hexapod_description/meshes/hip.stl"/>
      </geometry>
    </collision>
    <!-- Part mobile_bracket_15 -->
    <visual>
      <origin xyz="0.0575 -5.46438e-17 -0.0305" rpy="-2.88289e-16 -5.02371e-15 -1.5708"/>
      <geometry>
        <mesh filename="package://hexapod_description/meshes/mobile_bracket.stl"/>
      </geometry>
      <material name="mobile_bracket_15_material">
        <color rgba="0.647059 0.647059 0.647059 1"/>
      </material>
    </visual>
    <collision>
      <origin xyz="0.0575 -5.46438e-17 -0.0305" rpy="-2.88289e-16 -5.02371e-15 -1.5708"/>
      <geometry>
        <mesh filename="package://hexapod_description/meshes/mobile_bracket.stl"/>
      </geometry>
    </collision>
    <!-- Part servo_wheel_25 -->
    <visual>
      <origin xyz="5.55112e-17 -7.80626e-18 -0.0025" rpy="-3.14159 -2.88289e-16 3.14159"/>
      <geometry>
        <mesh filename="package://hexapod_description/meshes/servo_wheel.stl"/>
      </geometry>
      <material name="servo_wheel_25_material">
        <color rgba="0.647059 0.647059 0.647059 1"/>
      </material>
    </visual>
    <collision>
      <origin xyz="5.55112e-17 -7.80626e-18 -0.0025" rpy="-3.14159 -2.88289e-16 3.14159"/>
      <geometry>
        <mesh filename="package://hexapod_description/meshes/servo_wheel.stl"/>
      </geometry>
    </collision>
    <!-- Part servo_13 -->
    <visual>
      <origin xyz="0.0175 0.00140442 -0.0305" rpy="-3.14159 -2.88289e-16 -3.14159"/>
      <geometry>
        <mesh filename="package://hexapod_description/meshes/servo.stl"/>
      </geometry>
      <material name="servo_13_material">
        <color rgba="0.109804 0.109804 0.105882 1"/>
      </material>
    </visual>
    <collision>
      <origin xyz="0.0175 0.00140442 -0.0305" rpy="-3.14159 -2.88289e-16 -3.14159"/>
      <geometry>
        <mesh filename="package://hexapod_description/meshes/servo.stl"/>
      </geometry>
    </collision>
    <!-- Part fixed_bracket_13 -->
    <visual>
      <origin xyz="0.0575 -5.46438e-17 -0.0305" rpy="-1.5708 1.5708 0"/>
      <geometry>
        <mesh filename="package://hexapod_description/meshes/fixed_bracket.stl"/>
      </geometry>
      <material name="fixed_bracket_13_material">
        <color rgba="0.647059 0.647059 0.647059 1"/>
      </material>
    </visual>
    <collision>
      <origin xyz="0.0575 -5.46438e-17 -0.0305" rpy="-1.5708 1.5708 0"/>
      <geometry>
        <mesh filename="package://hexapod_description/meshes/fixed_bracket.stl"/>
      </geometry>
    </collision>
    <!-- Part servo_wheel_26 -->
    <visual>
      <origin xyz="5.55112e-17 -6.93889e-17 -0.0585" rpy="-3.14159 -2.88289e-16 -3.14159"/>
      <geometry>
        <mesh filename="package://hexapod_description/meshes/servo_wheel.stl"/>
      </geometry>
      <material name="servo_wheel_26_material">
        <color rgba="0.647059 0.647059 0.647059 1"/>
      </material>
    </visual>
    <collision>
      <origin xyz="5.55112e-17 -6.93889e-17 -0.0585" rpy="-3.14159 -2.88289e-16 -3.14159"/>
      <geometry>
        <mesh filename="package://hexapod_description/meshes/servo_wheel.stl"/>
      </geometry>
    </collision>
  </link>
  <!-- Link ties_assembly_5 -->
  <link name="ties_assembly_5">
    <inertial>
      <origin xyz="0.0549718 0.0335057 -0.0309357" rpy="0 0 0"/>
      <mass value="0.589115"/>
      <inertia ixx="0.000782879" ixy="-0.000776998" ixz="9.2367e-06" iyy="0.00162431" iyz="5.57469e-06" izz="0.00187002"/>
    </inertial>
    <!-- Part mobile_bracket_16 -->
    <visual>
      <origin xyz="0.135688 0.0785821 -0.0311738" rpy="1.0472 1.5708 0"/>
      <geometry>
        <mesh filename="package://hexapod_description/meshes/mobile_bracket.stl"/>
      </geometry>
      <material name="mobile_bracket_16_material">
        <color rgba="0.647059 0.647059 0.647059 1"/>
      </material>
    </visual>
    <collision>
      <origin xyz="0.135688 0.0785821 -0.0311738" rpy="1.0472 1.5708 0"/>
      <geometry>
        <mesh filename="package://hexapod_description/meshes/mobile_bracket.stl"/>
      </geometry>
    </collision>
    <!-- Part low_tie_5 -->
    <visual>
      <origin xyz="0.0231043 0.0135821 -0.0311738" rpy="-0.523599 1.5708 0"/>
      <geometry>
        <mesh filename="package://hexapod_description/meshes/low_tie.stl"/>
      </geometry>
      <material name="low_tie_5_material">
        <color rgba="0.282353 0.54902 0.160784 1"/>
      </material>
    </visual>
    <collision>
      <origin xyz="0.0231043 0.0135821 -0.0311738" rpy="-0.523599 1.5708 0"/>
      <geometry>
        <mesh filename="package://hexapod_description/meshes/low_tie.stl"/>
      </geometry>
    </collision>
    <!-- Part top_tie_5 -->
    <visual>
      <origin xyz="0.0238157 0.01375 -0.0305" rpy="-0.523599 1.5708 0"/>
      <geometry>
        <mesh filename="package://hexapod_description/meshes/top_tie.stl"/>
      </geometry>
      <material name="top_tie_5_material">
        <color rgba="0.282353 0.54902 0.160784 1"/>
      </material>
    </visual>
    <collision>
      <origin xyz="0.0238157 0.01375 -0.0305" rpy="-0.523599 1.5708 0"/>
      <geometry>
        <mesh filename="package://hexapod_description/meshes/top_tie.stl"/>
      </geometry>
    </collision>
    <!-- Part servo_wheel_27 -->
    <visual>
      <origin xyz="0 1.9082e-17 -0.0025" rpy="3.14159 5.404e-15 -2.61799"/>
      <geometry>
        <mesh filename="package://hexapod_description/meshes/servo_wheel.stl"/>
      </geometry>
      <material name="servo_wheel_27_material">
        <color rgba="0.647059 0.647059 0.647059 1"/>
      </material>
    </visual>
    <collision>
      <origin xyz="0 1.9082e-17 -0.0025" rpy="3.14159 5.404e-15 -2.61799"/>
      <geometry>
        <mesh filename="package://hexapod_description/meshes/servo_wheel.stl"/>
      </geometry>
    </collision>
    <!-- Part servo_14 -->
    <visual>
      <origin xyz="0.0144532 0.00996626 -0.0305" rpy="3.14159 4.56824e-15 -2.61799"/>
      <geometry>
        <mesh filename="package://hexapod_description/meshes/servo.stl"/>
      </geometry>
      <material name="servo_14_material">
        <color rgba="0.109804 0.109804 0.105882 1"/>
      </material>
    </visual>
    <collision>
      <origin xyz="0.0144532 0.00996626 -0.0305" rpy="3.14159 4.56824e-15 -2.61799"/>
      <geometry>
        <mesh filename="package://hexapod_description/meshes/servo.stl"/>
      </geometry>
    </collision>
    <!-- Part fixed_bracket_14 -->
    <visual>
      <origin xyz="0.0497965 0.02875 -0.0305" rpy="-2.0944 1.5708 0"/>
      <geometry>
        <mesh filename="package://hexapod_description/meshes/fixed_bracket.stl"/>
      </geometry>
      <material name="fixed_bracket_14_material">
        <color rgba="0.647059 0.647059 0.647059 1"/>
      </material>
    </visual>
    <collision>
      <origin xyz="0.0497965 0.02875 -0.0305" rpy="-2.0944 1.5708 0"/>
      <geometry>
        <mesh filename="package://hexapod_description/meshes/fixed_bracket.stl"/>
      </geometry>
    </collision>
    <!-- Part servo_wheel_28 -->
    <visual>
      <origin xyz="-5.55112e-17 1.19696e-16 -0.0585" rpy="3.14159 2.71135e-15 -2.61799"/>
      <geometry>
        <mesh filename="package://hexapod_description/meshes/servo_wheel.stl"/>
      </geometry>
      <material name="servo_wheel_28_material">
        <color rgba="0.647059 0.647059 0.647059 1"/>
      </material>
    </visual>
    <collision>
      <origin xyz="-5.55112e-17 1.19696e-16 -0.0585" rpy="3.14159 2.71135e-15 -2.61799"/>
      <geometry>
        <mesh filename="package://hexapod_description/meshes/servo_wheel.stl"/>
      </geometry>
    </collision>
  </link>
  <!-- Link foot_assembly_5 -->
  <link name="foot_assembly_5">
    <inertial>
      <origin xyz="-0.0724503 -0.00208415 -0.0306672" rpy="0 0 0"/>
      <mass value="0.633745"/>
      <inertia ixx="0.000268495" ixy="-1.4806e-05" ixz="4.28294e-06" iyy="0.00320961" iyz="-2.30165e-07" izz="0.00304658"/>
    </inertial>
    <!-- Part foot_5 -->
    <visual>
      <origin xyz="-0.04425 -5.55112e-17 -0.0305" rpy="-6.03496e-16 1.5708 0"/>
      <geometry>
        <mesh filename="package://hexapod_description/meshes/foot.stl"/>
      </geometry>
      <material name="foot_5_material">
        <color rgba="0.282353 0.54902 0.160784 1"/>
      </material>
    </visual>
    <collision>
      <origin xyz="-0.04425 -5.55112e-17 -0.0305" rpy="-6.03496e-16 1.5708 0"/>
      <geometry>
        <mesh filename="package://hexapod_description/meshes/foot.stl"/>
      </geometry>
    </collision>
    <!-- Part ir_sensor_cap_5 -->
    <visual>
      <origin xyz="-0.04425 -1.66533e-16 -0.0305" rpy="3.07469e-16 1.5708 0"/>
      <geometry>
        <mesh filename="package://hexapod_description/meshes/ir_sensor_cap.stl"/>
      </geometry>
      <material name="ir_sensor_cap_5_material">
        <color rgba="0.282353 0.54902 0.160784 1"/>
      </material>
    </visual>
    <collision>
      <origin xyz="-0.04425 -1.66533e-16 -0.0305" rpy="3.07469e-16 1.5708 0"/>
      <geometry>
        <mesh filename="package://hexapod_description/meshes/ir_sensor_cap.stl"/>
      </geometry>
    </collision>
    <!-- Part rubber_foot_5 -->
    <visual>
      <origin xyz="-0.04375 1.66533e-16 -0.03" rpy="-1.82546e-15 1.5708 0"/>
      <geometry>
        <mesh filename="package://hexapod_description/meshes/rubber_foot.stl"/>
      </geometry>
      <material name="rubber_foot_5_material">
        <color rgba="0.262745 0.282353 0.301961 1"/>
      </material>
    </visual>
    <collision>
      <origin xyz="-0.04375 1.66533e-16 -0.03" rpy="-1.82546e-15 1.5708 0"/>
      <geometry>
        <mesh filename="package://hexapod_description/meshes/rubber_foot.stl"/>
      </geometry>
    </collision>
    <!-- Part servo_wheel_29 -->
    <visual>
      <origin xyz="-1.38778e-17 -5.55112e-17 -0.0025" rpy="-3.14159 -1.51171e-17 4.36756e-17"/>
      <geometry>
        <mesh filename="package://hexapod_description/meshes/servo_wheel.stl"/>
      </geometry>
      <material name="servo_wheel_29_material">
        <color rgba="0.647059 0.647059 0.647059 1"/>
      </material>
    </visual>
    <collision>
      <origin xyz="-1.38778e-17 -5.55112e-17 -0.0025" rpy="-3.14159 -1.51171e-17 4.36756e-17"/>
      <geometry>
        <mesh filename="package://hexapod_description/meshes/servo_wheel.stl"/>
      </geometry>
    </collision>
    <!-- Part servo_15 -->
    <visual>
      <origin xyz="-0.0175 -0.00140442 -0.0305" rpy="-3.14159 6.33714e-16 4.93372e-16"/>
      <geometry>
        <mesh filename="package://hexapod_description/meshes/servo.stl"/>
      </geometry>
      <material name="servo_15_material">
        <color rgba="0.109804 0.109804 0.105882 1"/>
      </material>
    </visual>
    <collision>
      <origin xyz="-0.0175 -0.00140442 -0.0305" rpy="-3.14159 6.33714e-16 4.93372e-16"/>
      <geometry>
        <mesh filename="package://hexapod_description/meshes/servo.stl"/>
      </geometry>
    </collision>
    <!-- Part fixed_bracket_15 -->
    <visual>
      <origin xyz="-0.0575 -1.11022e-16 -0.0305" rpy="1.5708 1.5708 0"/>
      <geometry>
        <mesh filename="package://hexapod_description/meshes/fixed_bracket.stl"/>
      </geometry>
      <material name="fixed_bracket_15_material">
        <color rgba="0.647059 0.647059 0.647059 1"/>
      </material>
    </visual>
    <collision>
      <origin xyz="-0.0575 -1.11022e-16 -0.0305" rpy="1.5708 1.5708 0"/>
      <geometry>
        <mesh filename="package://hexapod_description/meshes/fixed_bracket.stl"/>
      </geometry>
    </collision>
    <!-- Part servo_wheel_30 -->
    <visual>
      <origin xyz="2.08167e-17 -1.11022e-16 -0.0585" rpy="-3.14159 6.34667e-16 5.21766e-16"/>
      <geometry>
        <mesh filename="package://hexapod_description/meshes/servo_wheel.stl"/>
      </geometry>
      <material name="servo_wheel_30_material">
        <color rgba="0.647059 0.647059 0.647059 1"/>
      </material>
    </visual>
    <collision>
      <origin xyz="2.08167e-17 -1.11022e-16 -0.0585" rpy="-3.14159 6.34667e-16 5.21766e-16"/>
      <geometry>
        <mesh filename="package://hexapod_description/meshes/servo_wheel.stl"/>
      </geometry>
    </collision>
  </link>
  <!-- Joint from ties_assembly_5 to foot_assembly_5 -->
  <joint name="foot_5" type="revolute">
    <origin xyz="0.165999 0.0960821 -0.000790548" rpy="-3.9985e-15 -5.62892e-15 1.91986"/>
    <parent link="ties_assembly_5"/>
    <child link="foot_assembly_5"/>
    <axis xyz="0 0 1"/>
    <limit effort="10" velocity="10" lower="-0.349066" upper="3.83972"/>
  </joint>
  <!-- Joint from hip_assembly_5 to ties_assembly_5 -->
  <joint name="ties_5" type="revolute">
    <origin xyz="0.0925 -0.0311167 -0.0305" rpy="1.5708 2.88289e-16 1.53604e-15"/>
    <parent link="hip_assembly_5"/>
    <child link="ties_assembly_5"/>
    <axis xyz="0 0 1"/>
    <limit effort="10" velocity="10" lower="-2.26893" upper="1.22173"/>
  </joint>
  <!-- Joint from base_link to hip_assembly_5 -->
  <joint name="hip_5" type="revolute">
    <origin xyz="-0.130732 -0.0673829 0.0279706" rpy="-1.23219e-14 5.33622e-14 -2.70526"/>
    <parent link="base_link"/>
    <child link="hip_assembly_5"/>
    <axis xyz="0 0 1"/>
    <limit effort="10" velocity="10" lower="-1.5708" upper="1.5708"/>
  </joint>
  <!-- Link hip_assembly_6 -->
  <link name="hip_assembly_6">
    <inertial>
      <origin xyz="-0.0268487 -0.000325484 -0.0302141" rpy="0 0 0"/>
      <mass value="0.365356"/>
      <inertia ixx="0.000168136" ixy="-2.8417e-07" ixz="3.2467e-06" iyy="0.000312332" iyz="-9.42575e-07" izz="0.000312341"/>
    </inertial>
    <!-- Part hip_6 -->
    <visual>
      <origin xyz="-0.0575 -0.0005 -0.0045" rpy="1.73648e-16 -1.50931e-16 -3.8329e-16"/>
      <geometry>
        <mesh filename="package://hexapod_description/meshes/hip.stl"/>
      </geometry>
      <material name="hip_6_material">
        <color rgba="0.282353 0.54902 0.160784 1"/>
      </material>
    </visual>
    <collision>
      <origin xyz="-0.0575 -0.0005 -0.0045" rpy="1.73648e-16 -1.50931e-16 -3.8329e-16"/>
      <geometry>
        <mesh filename="package://hexapod_description/meshes/hip.stl"/>
      </geometry>
    </collision>
    <!-- Part mobile_bracket_17 -->
    <visual>
      <origin xyz="-0.0575 1.4962e-17 -0.0305" rpy="-1.00974e-28 -9.94783e-15 1.5708"/>
      <geometry>
        <mesh filename="package://hexapod_description/meshes/mobile_bracket.stl"/>
      </geometry>
      <material name="mobile_bracket_17_material">
        <color rgba="0.647059 0.647059 0.647059 1"/>
      </material>
    </visual>
    <collision>
      <origin xyz="-0.0575 1.4962e-17 -0.0305" rpy="-1.00974e-28 -9.94783e-15 1.5708"/>
      <geometry>
        <mesh filename="package://hexapod_description/meshes/mobile_bracket.stl"/>
      </geometry>
    </collision>
    <!-- Part servo_wheel_31 -->
    <visual>
      <origin xyz="0 7.58942e-18 -0.0025" rpy="3.14159 -9.46633e-30 -2.89926e-17"/>
      <geometry>
        <mesh filename="package://hexapod_description/meshes/servo_wheel.stl"/>
      </geometry>
      <material name="servo_wheel_31_material">
        <color rgba="0.647059 0.647059 0.647059 1"/>
      </material>
    </visual>
    <collision>
      <origin xyz="0 7.58942e-18 -0.0025" rpy="3.14159 -9.46633e-30 -2.89926e-17"/>
      <geometry>
        <mesh filename="package://hexapod_description/meshes/servo_wheel.stl"/>
      </geometry>
    </collision>
    <!-- Part servo_16 -->
    <visual>
      <origin xyz="-0.0175 -0.00140442 -0.0305" rpy="-3.14159 2.52435e-29 -3.49008e-17"/>
      <geometry>
        <mesh filename="package://hexapod_description/meshes/servo.stl"/>
      </geometry>
      <material name="servo_16_material">
        <color rgba="0.109804 0.109804 0.105882 1"/>
      </material>
    </visual>
    <collision>
      <origin xyz="-0.0175 -0.00140442 -0.0305" rpy="-3.14159 2.52435e-29 -3.49008e-17"/>
      <geometry>
        <mesh filename="package://hexapod_description/meshes/servo.stl"/>
      </geometry>
    </collision>
    <!-- Part fixed_bracket_16 -->
    <visual>
      <origin xyz="-0.0575 1.4962e-17 -0.0305" rpy="1.5708 1.5708 0"/>
      <geometry>
        <mesh filename="package://hexapod_description/meshes/fixed_bracket.stl"/>
      </geometry>
      <material name="fixed_bracket_16_material">
        <color rgba="0.647059 0.647059 0.647059 1"/>
      </material>
    </visual>
    <collision>
      <origin xyz="-0.0575 1.4962e-17 -0.0305" rpy="1.5708 1.5708 0"/>
      <geometry>
        <mesh filename="package://hexapod_description/meshes/fixed_bracket.stl"/>
      </geometry>
    </collision>
    <!-- Part servo_wheel_32 -->
    <visual>
      <origin xyz="2.77556e-17 -9.75782e-18 -0.0585" rpy="-3.14159 6.31089e-29 -1.47108e-16"/>
      <geometry>
        <mesh filename="package://hexapod_description/meshes/servo_wheel.stl"/>
      </geometry>
      <material name="servo_wheel_32_material">
        <color rgba="0.647059 0.647059 0.647059 1"/>
      </material>
    </visual>
    <collision>
      <origin xyz="2.77556e-17 -9.75782e-18 -0.0585" rpy="-3.14159 6.31089e-29 -1.47108e-16"/>
      <geometry>
        <mesh filename="package://hexapod_description/meshes/servo_wheel.stl"/>
      </geometry>
    </collision>
  </link>
  <!-- Link ties_assembly_6 -->
  <link name="ties_assembly_6">
    <inertial>
      <origin xyz="0.0549718 0.0335057 -0.0309357" rpy="0 0 0"/>
      <mass value="0.589115"/>
      <inertia ixx="0.000782879" ixy="-0.000776998" ixz="9.2367e-06" iyy="0.00162431" iyz="5.57469e-06" izz="0.00187002"/>
    </inertial>
    <!-- Part mobile_bracket_18 -->
    <visual>
      <origin xyz="0.135688 0.0785821 -0.0311738" rpy="1.0472 1.5708 0"/>
      <geometry>
        <mesh filename="package://hexapod_description/meshes/mobile_bracket.stl"/>
      </geometry>
      <material name="mobile_bracket_18_material">
        <color rgba="0.647059 0.647059 0.647059 1"/>
      </material>
    </visual>
    <collision>
      <origin xyz="0.135688 0.0785821 -0.0311738" rpy="1.0472 1.5708 0"/>
      <geometry>
        <mesh filename="package://hexapod_description/meshes/mobile_bracket.stl"/>
      </geometry>
    </collision>
    <!-- Part low_tie_6 -->
    <visual>
      <origin xyz="0.0231043 0.0135821 -0.0311738" rpy="-0.523599 1.5708 0"/>
      <geometry>
        <mesh filename="package://hexapod_description/meshes/low_tie.stl"/>
      </geometry>
      <material name="low_tie_6_material">
        <color rgba="0.282353 0.54902 0.160784 1"/>
      </material>
    </visual>
    <collision>
      <origin xyz="0.0231043 0.0135821 -0.0311738" rpy="-0.523599 1.5708 0"/>
      <geometry>
        <mesh filename="package://hexapod_description/meshes/low_tie.stl"/>
      </geometry>
    </collision>
    <!-- Part top_tie_6 -->
    <visual>
      <origin xyz="0.0238157 0.01375 -0.0305" rpy="-0.523599 1.5708 0"/>
      <geometry>
        <mesh filename="package://hexapod_description/meshes/top_tie.stl"/>
      </geometry>
      <material name="top_tie_6_material">
        <color rgba="0.282353 0.54902 0.160784 1"/>
      </material>
    </visual>
    <collision>
      <origin xyz="0.0238157 0.01375 -0.0305" rpy="-0.523599 1.5708 0"/>
      <geometry>
        <mesh filename="package://hexapod_description/meshes/top_tie.stl"/>
      </geometry>
    </collision>
    <!-- Part servo_wheel_33 -->
    <visual>
      <origin xyz="-2.77556e-17 -1.30104e-18 -0.0025" rpy="-3.14159 -6.6442e-16 -2.61799"/>
      <geometry>
        <mesh filename="package://hexapod_description/meshes/servo_wheel.stl"/>
      </geometry>
      <material name="servo_wheel_33_material">
        <color rgba="0.647059 0.647059 0.647059 1"/>
      </material>
    </visual>
    <collision>
      <origin xyz="-2.77556e-17 -1.30104e-18 -0.0025" rpy="-3.14159 -6.6442e-16 -2.61799"/>
      <geometry>
        <mesh filename="package://hexapod_description/meshes/servo_wheel.stl"/>
      </geometry>
    </collision>
    <!-- Part servo_17 -->
    <visual>
      <origin xyz="0.0144532 0.00996626 -0.0305" rpy="3.14159 -7.72448e-16 -2.61799"/>
      <geometry>
        <mesh filename="package://hexapod_description/meshes/servo.stl"/>
      </geometry>
      <material name="servo_17_material">
        <color rgba="0.109804 0.109804 0.105882 1"/>
      </material>
    </visual>
    <collision>
      <origin xyz="0.0144532 0.00996626 -0.0305" rpy="3.14159 -7.72448e-16 -2.61799"/>
      <geometry>
        <mesh filename="package://hexapod_description/meshes/servo.stl"/>
      </geometry>
    </collision>
    <!-- Part fixed_bracket_17 -->
    <visual>
      <origin xyz="0.0497965 0.02875 -0.0305" rpy="-2.0944 1.5708 0"/>
      <geometry>
        <mesh filename="package://hexapod_description/meshes/fixed_bracket.stl"/>
      </geometry>
      <material name="fixed_bracket_17_material">
        <color rgba="0.647059 0.647059 0.647059 1"/>
      </material>
    </visual>
    <collision>
      <origin xyz="0.0497965 0.02875 -0.0305" rpy="-2.0944 1.5708 0"/>
      <geometry>
        <mesh filename="package://hexapod_description/meshes/fixed_bracket.stl"/>
      </geometry>
    </collision>
    <!-- Part servo_wheel_34 -->
    <visual>
      <origin xyz="-1.22125e-15 -7.02997e-16 -0.0585" rpy="3.14159 -6.08909e-16 -2.61799"/>
      <geometry>
        <mesh filename="package://hexapod_description/meshes/servo_wheel.stl"/>
      </geometry>
      <material name="servo_wheel_34_material">
        <color rgba="0.647059 0.647059 0.647059 1"/>
      </material>
    </visual>
    <collision>
      <origin xyz="-1.22125e-15 -7.02997e-16 -0.0585" rpy="3.14159 -6.08909e-16 -2.61799"/>
      <geometry>
        <mesh filename="package://hexapod_description/meshes/servo_wheel.stl"/>
      </geometry>
    </collision>
  </link>
  <!-- Link foot_assembly_6 -->
  <link name="foot_assembly_6">
    <inertial>
      <origin xyz="-0.0724503 -0.00208415 -0.0306672" rpy="0 0 0"/>
      <mass value="0.633745"/>
      <inertia ixx="0.000268495" ixy="-1.4806e-05" ixz="4.28294e-06" iyy="0.00320961" iyz="-2.30165e-07" izz="0.00304658"/>
    </inertial>
    <!-- Part foot_6 -->
    <visual>
      <origin xyz="-0.04425 -1.11022e-16 -0.0305" rpy="3.91202e-17 1.5708 0"/>
      <geometry>
        <mesh filename="package://hexapod_description/meshes/foot.stl"/>
      </geometry>
      <material name="foot_6_material">
        <color rgba="0.282353 0.54902 0.160784 1"/>
      </material>
    </visual>
    <collision>
      <origin xyz="-0.04425 -1.11022e-16 -0.0305" rpy="3.91202e-17 1.5708 0"/>
      <geometry>
        <mesh filename="package://hexapod_description/meshes/foot.stl"/>
      </geometry>
    </collision>
    <!-- Part ir_sensor_cap_6 -->
    <visual>
      <origin xyz="-0.04425 -4.55191e-15 -0.0305" rpy="1.9598e-14 1.5708 0"/>
      <geometry>
        <mesh filename="package://hexapod_description/meshes/ir_sensor_cap.stl"/>
      </geometry>
      <material name="ir_sensor_cap_6_material">
        <color rgba="0.282353 0.54902 0.160784 1"/>
      </material>
    </visual>
    <collision>
      <origin xyz="-0.04425 -4.55191e-15 -0.0305" rpy="1.9598e-14 1.5708 0"/>
      <geometry>
        <mesh filename="package://hexapod_description/meshes/ir_sensor_cap.stl"/>
      </geometry>
    </collision>
    <!-- Part rubber_foot_6 -->
    <visual>
      <origin xyz="-0.04375 -5.55112e-17 -0.03" rpy="2.96423e-16 1.5708 0"/>
      <geometry>
        <mesh filename="package://hexapod_description/meshes/rubber_foot.stl"/>
      </geometry>
      <material name="rubber_foot_6_material">
        <color rgba="0.262745 0.282353 0.301961 1"/>
      </material>
    </visual>
    <collision>
      <origin xyz="-0.04375 -5.55112e-17 -0.03" rpy="2.96423e-16 1.5708 0"/>
      <geometry>
        <mesh filename="package://hexapod_description/meshes/rubber_foot.stl"/>
      </geometry>
    </collision>
    <!-- Part servo_wheel_35 -->
    <visual>
      <origin xyz="-6.93889e-18 0 -0.0025" rpy="3.14159 1.0086e-17 2.12798e-17"/>
      <geometry>
        <mesh filename="package://hexapod_description/meshes/servo_wheel.stl"/>
      </geometry>
      <material name="servo_wheel_35_material">
        <color rgba="0.647059 0.647059 0.647059 1"/>
      </material>
    </visual>
    <collision>
      <origin xyz="-6.93889e-18 0 -0.0025" rpy="3.14159 1.0086e-17 2.12798e-17"/>
      <geometry>
        <mesh filename="package://hexapod_description/meshes/servo_wheel.stl"/>
      </geometry>
    </collision>
    <!-- Part servo_18 -->
    <visual>
      <origin xyz="-0.0175 -0.00140442 -0.0305" rpy="3.14159 -1.61656e-15 6.89209e-16"/>
      <geometry>
        <mesh filename="package://hexapod_description/meshes/servo.stl"/>
      </geometry>
      <material name="servo_18_material">
        <color rgba="0.109804 0.109804 0.105882 1"/>
      </material>
    </visual>
    <collision>
      <origin xyz="-0.0175 -0.00140442 -0.0305" rpy="3.14159 -1.61656e-15 6.89209e-16"/>
      <geometry>
        <mesh filename="package://hexapod_description/meshes/servo.stl"/>
      </geometry>
    </collision>
    <!-- Part fixed_bracket_18 -->
    <visual>
      <origin xyz="-0.0575 0 -0.0305" rpy="1.5708 1.5708 0"/>
      <geometry>
        <mesh filename="package://hexapod_description/meshes/fixed_bracket.stl"/>
      </geometry>
      <material name="fixed_bracket_18_material">
        <color rgba="0.647059 0.647059 0.647059 1"/>
      </material>
    </visual>
    <collision>
      <origin xyz="-0.0575 0 -0.0305" rpy="1.5708 1.5708 0"/>
      <geometry>
        <mesh filename="package://hexapod_description/meshes/fixed_bracket.stl"/>
      </geometry>
    </collision>
    <!-- Part servo_wheel_36 -->
    <visual>
      <origin xyz="-2.08167e-16 -5.55112e-17 -0.0585" rpy="3.14159 -9.71686e-16 1.02445e-15"/>
      <geometry>
        <mesh filename="package://hexapod_description/meshes/servo_wheel.stl"/>
      </geometry>
      <material name="servo_wheel_36_material">
        <color rgba="0.647059 0.647059 0.647059 1"/>
      </material>
    </visual>
    <collision>
      <origin xyz="-2.08167e-16 -5.55112e-17 -0.0585" rpy="3.14159 -9.71686e-16 1.02445e-15"/>
      <geometry>
        <mesh filename="package://hexapod_description/meshes/servo_wheel.stl"/>
      </geometry>
    </collision>
  </link>
  <!-- Joint from ties_assembly_6 to foot_assembly_6 -->
  <joint name="foot_6" type="revolute">
    <origin xyz="0.165999 0.0960821 -0.000790548" rpy="-6.52802e-17 -1.18702e-16 1.91986"/>
    <parent link="ties_assembly_6"/>
    <child link="foot_assembly_6"/>
    <axis xyz="0 0 1"/>
    <limit effort="10" velocity="10" lower="-0.349066" upper="3.83972"/>
  </joint>
  <!-- Joint from hip_assembly_6 to ties_assembly_6 -->
  <joint name="ties_6" type="revolute">
    <origin xyz="-0.0925 0.0311167 -0.0305" rpy="1.5708 1.0413e-28 3.14159"/>
    <parent link="hip_assembly_6"/>
    <child link="ties_assembly_6"/>
    <axis xyz="0 0 1"/>
    <limit effort="10" velocity="10" lower="-2.26893" upper="1.22173"/>
  </joint>
  <!-- Joint from base_link to hip_assembly_6 -->
  <joint name="hip_6" type="revolute">
    <origin xyz="-0.117483 0.0840557 0.0272372" rpy="5.19508e-14 -1.48406e-14 -0.610865"/>
    <parent link="base_link"/>
    <child link="hip_assembly_6"/>
    <axis xyz="0 0 1"/>
    <limit effort="10" velocity="10" lower="-1.5708" upper="1.5708"/>
  </joint>
</robot>
