<?xml version="1.0" ?>
<!-- Generated using onshape-to-robot -->
<!-- Onshape https://cad.onshape.com/documents/026f9a33ba6a25a983a9d639/w/b83e0182bd0a887a03df3198/e/e49783848224d44e064e4a49 -->
<robot name="hexapod_description">
  <!-- Link base_link -->
  <link name="base_link">
    <inertial>
      <origin xyz="-0.588958 -0.50583 0.355198" rpy="0 0 0"/>
      <mass value="2.24777"/>
      <inertia ixx="0.0169759" ixy="2.42972e-05" ixz="-0.000206283" iyy="0.0170231" iyz="-1.262e-05" izz="0.0239802"/>
    </inertial>
    <!-- Part mobile_bracket -->
    <visual>
      <origin xyz="-0.576789 -0.382643 0.356409" rpy="0.0872665 1.5708 0"/>
      <geometry>
        <mesh filename="package://hexapod_description/meshes/mobile_bracket.stl"/>
      </geometry>
      <material name="mobile_bracket_material">
        <color rgba="0.647059 0.647059 0.647059 1"/>
      </material>
    </visual>
    <collision>
      <origin xyz="-0.576789 -0.382643 0.356409" rpy="0.0872665 1.5708 0"/>
      <geometry>
        <mesh filename="package://hexapod_description/meshes/mobile_bracket.stl"/>
      </geometry>
    </collision>
    <!-- Part mobile_bracket_2 -->
    <visual>
      <origin xyz="-0.688075 -0.434537 0.356409" rpy="-0.959931 1.5708 0"/>
      <geometry>
        <mesh filename="package://hexapod_description/meshes/mobile_bracket.stl"/>
      </geometry>
      <material name="mobile_bracket_2_material">
        <color rgba="0.647059 0.647059 0.647059 1"/>
      </material>
    </visual>
    <collision>
      <origin xyz="-0.688075 -0.434537 0.356409" rpy="-0.959931 1.5708 0"/>
      <geometry>
        <mesh filename="package://hexapod_description/meshes/mobile_bracket.stl"/>
      </geometry>
    </collision>
    <!-- Part bottom_cover -->
    <visual>
      <origin xyz="-0.587491 -0.504966 0.321409" rpy="-3.14159 -3.97096e-14 -0.0872665"/>
      <geometry>
        <mesh filename="package://hexapod_description/meshes/bottom_cover.stl"/>
      </geometry>
      <material name="bottom_cover_material">
        <color rgba="0.282353 0.54902 0.160784 1"/>
      </material>
    </visual>
    <collision>
      <origin xyz="-0.587491 -0.504966 0.321409" rpy="-3.14159 -3.97096e-14 -0.0872665"/>
      <geometry>
        <mesh filename="package://hexapod_description/meshes/bottom_cover.stl"/>
      </geometry>
    </collision>
    <!-- Part mobile_bracket_3 -->
    <visual>
      <origin xyz="-0.698777 -0.55686 0.356409" rpy="2.00713 -1.5708 0"/>
      <geometry>
        <mesh filename="package://hexapod_description/meshes/mobile_bracket.stl"/>
      </geometry>
      <material name="mobile_bracket_3_material">
        <color rgba="0.647059 0.647059 0.647059 1"/>
      </material>
    </visual>
    <collision>
      <origin xyz="-0.698777 -0.55686 0.356409" rpy="2.00713 -1.5708 0"/>
      <geometry>
        <mesh filename="package://hexapod_description/meshes/mobile_bracket.stl"/>
      </geometry>
    </collision>
    <!-- Part cover -->
    <visual>
      <origin xyz="-0.587491 -0.504966 0.391409" rpy="1.571e-14 5.22087e-14 -2.18166"/>
      <geometry>
        <mesh filename="package://hexapod_description/meshes/cover.stl"/>
      </geometry>
      <material name="cover_material">
        <color rgba="0.282353 0.54902 0.160784 1"/>
      </material>
    </visual>
    <collision>
      <origin xyz="-0.587491 -0.504966 0.391409" rpy="1.571e-14 5.22087e-14 -2.18166"/>
      <geometry>
        <mesh filename="package://hexapod_description/meshes/cover.stl"/>
      </geometry>
    </collision>
    <!-- Part mobile_bracket_4 -->
    <visual>
      <origin xyz="-0.476205 -0.453073 0.356409" rpy="1.13446 1.5708 0"/>
      <geometry>
        <mesh filename="package://hexapod_description/meshes/mobile_bracket.stl"/>
      </geometry>
      <material name="mobile_bracket_4_material">
        <color rgba="0.647059 0.647059 0.647059 1"/>
      </material>
    </visual>
    <collision>
      <origin xyz="-0.476205 -0.453073 0.356409" rpy="1.13446 1.5708 0"/>
      <geometry>
        <mesh filename="package://hexapod_description/meshes/mobile_bracket.stl"/>
      </geometry>
    </collision>
    <!-- Part mobile_bracket_5 -->
    <visual>
      <origin xyz="-0.598193 -0.62729 0.356409" rpy="3.05433 -1.5708 0"/>
      <geometry>
        <mesh filename="package://hexapod_description/meshes/mobile_bracket.stl"/>
      </geometry>
      <material name="mobile_bracket_5_material">
        <color rgba="0.647059 0.647059 0.647059 1"/>
      </material>
    </visual>
    <collision>
      <origin xyz="-0.598193 -0.62729 0.356409" rpy="3.05433 -1.5708 0"/>
      <geometry>
        <mesh filename="package://hexapod_description/meshes/mobile_bracket.stl"/>
      </geometry>
    </collision>
    <!-- Part mobile_bracket_6 -->
    <visual>
      <origin xyz="-0.486907 -0.575396 0.356409" rpy="-2.18166 -1.5708 0"/>
      <geometry>
        <mesh filename="package://hexapod_description/meshes/mobile_bracket.stl"/>
      </geometry>
      <material name="mobile_bracket_6_material">
        <color rgba="0.647059 0.647059 0.647059 1"/>
      </material>
    </visual>
    <collision>
      <origin xyz="-0.486907 -0.575396 0.356409" rpy="-2.18166 -1.5708 0"/>
      <geometry>
        <mesh filename="package://hexapod_description/meshes/mobile_bracket.stl"/>
      </geometry>
    </collision>
    <!-- Part body -->
    <visual>
      <origin xyz="-0.587491 -0.504966 0.356409" rpy="-3.14159 3.7359e-14 -1.65806"/>
      <geometry>
        <mesh filename="package://hexapod_description/meshes/body.stl"/>
      </geometry>
      <material name="body_material">
        <color rgba="0.282353 0.54902 0.160784 1"/>
      </material>
    </visual>
    <collision>
      <origin xyz="-0.587491 -0.504966 0.356409" rpy="-3.14159 3.7359e-14 -1.65806"/>
      <geometry>
        <mesh filename="package://hexapod_description/meshes/body.stl"/>
      </geometry>
    </collision>
  </link>
  <!-- Link hip_assembly -->
  <link name="hip_assembly">
    <inertial>
      <origin xyz="0.0268487 0.000325484 -0.0302141" rpy="0 0 0"/>
      <mass value="0.365356"/>
      <inertia ixx="0.000168136" ixy="-2.8417e-07" ixz="-3.2467e-06" iyy="0.000312332" iyz="9.42575e-07" izz="0.000312341"/>
    </inertial>
    <!-- Part hip -->
    <visual>
      <origin xyz="0.0575 0.0005 -0.0045" rpy="6.85426e-16 -4.86762e-16 -3.14159"/>
      <geometry>
        <mesh filename="package://hexapod_description/meshes/hip.stl"/>
      </geometry>
      <material name="hip_material">
        <color rgba="0.282353 0.54902 0.160784 1"/>
      </material>
    </visual>
    <collision>
      <origin xyz="0.0575 0.0005 -0.0045" rpy="6.85426e-16 -4.86762e-16 -3.14159"/>
      <geometry>
        <mesh filename="package://hexapod_description/meshes/hip.stl"/>
      </geometry>
    </collision>
    <!-- Part mobile_bracket_7 -->
    <visual>
      <origin xyz="0.0575 -1.11022e-16 -0.0305" rpy="-7.28949e-15 -5.6326e-15 -1.5708"/>
      <geometry>
        <mesh filename="package://hexapod_description/meshes/mobile_bracket.stl"/>
      </geometry>
      <material name="mobile_bracket_7_material">
        <color rgba="0.647059 0.647059 0.647059 1"/>
      </material>
    </visual>
    <collision>
      <origin xyz="0.0575 -1.11022e-16 -0.0305" rpy="-7.28949e-15 -5.6326e-15 -1.5708"/>
      <geometry>
        <mesh filename="package://hexapod_description/meshes/mobile_bracket.stl"/>
      </geometry>
    </collision>
    <!-- Part servo_wheel -->
    <visual>
      <origin xyz="5.55112e-17 1.11022e-16 -0.0025" rpy="-3.14159 -1.16706e-15 3.14159"/>
      <geometry>
        <mesh filename="package://hexapod_description/meshes/servo_wheel.stl"/>
      </geometry>
      <material name="servo_wheel_material">
        <color rgba="0.647059 0.647059 0.647059 1"/>
      </material>
    </visual>
    <collision>
      <origin xyz="5.55112e-17 1.11022e-16 -0.0025" rpy="-3.14159 -1.16706e-15 3.14159"/>
      <geometry>
        <mesh filename="package://hexapod_description/meshes/servo_wheel.stl"/>
      </geometry>
    </collision>
    <!-- Part servo -->
    <visual>
      <origin xyz="0.0175 0.00140442 -0.0305" rpy="-3.14159 -2.19766e-16 -3.14159"/>
      <geometry>
        <mesh filename="package://hexapod_description/meshes/servo.stl"/>
      </geometry>
      <material name="servo_material">
        <color rgba="0.109804 0.109804 0.105882 1"/>
      </material>
    </visual>
    <collision>
      <origin xyz="0.0175 0.00140442 -0.0305" rpy="-3.14159 -2.19766e-16 -3.14159"/>
      <geometry>
        <mesh filename="package://hexapod_description/meshes/servo.stl"/>
      </geometry>
    </collision>
    <!-- Part fixed_bracket -->
    <visual>
      <origin xyz="0.0575 -1.11022e-16 -0.0305" rpy="-1.5708 1.5708 0"/>
      <geometry>
        <mesh filename="package://hexapod_description/meshes/fixed_bracket.stl"/>
      </geometry>
      <material name="fixed_bracket_material">
        <color rgba="0.647059 0.647059 0.647059 1"/>
      </material>
    </visual>
    <collision>
      <origin xyz="0.0575 -1.11022e-16 -0.0305" rpy="-1.5708 1.5708 0"/>
      <geometry>
        <mesh filename="package://hexapod_description/meshes/fixed_bracket.stl"/>
      </geometry>
    </collision>
    <!-- Part servo_wheel_2 -->
    <visual>
      <origin xyz="0 1.11022e-16 -0.0585" rpy="-3.14159 -1.16706e-15 -3.14159"/>
      <geometry>
        <mesh filename="package://hexapod_description/meshes/servo_wheel.stl"/>
      </geometry>
      <material name="servo_wheel_2_material">
        <color rgba="0.647059 0.647059 0.647059 1"/>
      </material>
    </visual>
    <collision>
      <origin xyz="0 1.11022e-16 -0.0585" rpy="-3.14159 -1.16706e-15 -3.14159"/>
      <geometry>
        <mesh filename="package://hexapod_description/meshes/servo_wheel.stl"/>
      </geometry>
    </collision>
  </link>
  <!-- Link ties_assembly -->
  <link name="ties_assembly">
    <inertial>
      <origin xyz="0.0549718 0.0335057 -0.0309357" rpy="0 0 0"/>
      <mass value="0.589115"/>
      <inertia ixx="0.000782879" ixy="-0.000776998" ixz="9.2367e-06" iyy="0.00162431" iyz="5.57469e-06" izz="0.00187002"/>
    </inertial>
    <!-- Part mobile_bracket_8 -->
    <visual>
      <origin xyz="0.135688 0.0785821 -0.0311738" rpy="1.0472 1.5708 0"/>
      <geometry>
        <mesh filename="package://hexapod_description/meshes/mobile_bracket.stl"/>
      </geometry>
      <material name="mobile_bracket_8_material">
        <color rgba="0.647059 0.647059 0.647059 1"/>
      </material>
    </visual>
    <collision>
      <origin xyz="0.135688 0.0785821 -0.0311738" rpy="1.0472 1.5708 0"/>
      <geometry>
        <mesh filename="package://hexapod_description/meshes/mobile_bracket.stl"/>
      </geometry>
    </collision>
    <!-- Part low_tie -->
    <visual>
      <origin xyz="0.0231043 0.0135821 -0.0311738" rpy="-0.523599 1.5708 0"/>
      <geometry>
        <mesh filename="package://hexapod_description/meshes/low_tie.stl"/>
      </geometry>
      <material name="low_tie_material">
        <color rgba="0.282353 0.54902 0.160784 1"/>
      </material>
    </visual>
    <collision>
      <origin xyz="0.0231043 0.0135821 -0.0311738" rpy="-0.523599 1.5708 0"/>
      <geometry>
        <mesh filename="package://hexapod_description/meshes/low_tie.stl"/>
      </geometry>
    </collision>
    <!-- Part top_tie -->
    <visual>
      <origin xyz="0.0238157 0.01375 -0.0305" rpy="-0.523599 1.5708 0"/>
      <geometry>
        <mesh filename="package://hexapod_description/meshes/top_tie.stl"/>
      </geometry>
      <material name="top_tie_material">
        <color rgba="0.282353 0.54902 0.160784 1"/>
      </material>
    </visual>
    <collision>
      <origin xyz="0.0238157 0.01375 -0.0305" rpy="-0.523599 1.5708 0"/>
      <geometry>
        <mesh filename="package://hexapod_description/meshes/top_tie.stl"/>
      </geometry>
    </collision>
    <!-- Part servo_wheel_3 -->
    <visual>
      <origin xyz="1.11022e-16 5.55112e-17 -0.0025" rpy="-3.14159 -2.23646e-16 -2.61799"/>
      <geometry>
        <mesh filename="package://hexapod_description/meshes/servo_wheel.stl"/>
      </geometry>
      <material name="servo_wheel_3_material">
        <color rgba="0.647059 0.647059 0.647059 1"/>
      </material>
    </visual>
    <collision>
      <origin xyz="1.11022e-16 5.55112e-17 -0.0025" rpy="-3.14159 -2.23646e-16 -2.61799"/>
      <geometry>
        <mesh filename="package://hexapod_description/meshes/servo_wheel.stl"/>
      </geometry>
    </collision>
    <!-- Part servo_2 -->
    <visual>
      <origin xyz="0.0144532 0.00996626 -0.0305" rpy="3.14159 -2.2339e-16 -2.61799"/>
      <geometry>
        <mesh filename="package://hexapod_description/meshes/servo.stl"/>
      </geometry>
      <material name="servo_2_material">
        <color rgba="0.109804 0.109804 0.105882 1"/>
      </material>
    </visual>
    <collision>
      <origin xyz="0.0144532 0.00996626 -0.0305" rpy="3.14159 -2.2339e-16 -2.61799"/>
      <geometry>
        <mesh filename="package://hexapod_description/meshes/servo.stl"/>
      </geometry>
    </collision>
    <!-- Part fixed_bracket_2 -->
    <visual>
      <origin xyz="0.0497965 0.02875 -0.0305" rpy="-2.0944 1.5708 0"/>
      <geometry>
        <mesh filename="package://hexapod_description/meshes/fixed_bracket.stl"/>
      </geometry>
      <material name="fixed_bracket_2_material">
        <color rgba="0.647059 0.647059 0.647059 1"/>
      </material>
    </visual>
    <collision>
      <origin xyz="0.0497965 0.02875 -0.0305" rpy="-2.0944 1.5708 0"/>
      <geometry>
        <mesh filename="package://hexapod_description/meshes/fixed_bracket.stl"/>
      </geometry>
    </collision>
    <!-- Part servo_wheel_4 -->
    <visual>
      <origin xyz="-1.11022e-15 -7.21645e-16 -0.0585" rpy="-3.14159 -2.85252e-14 -2.61799"/>
      <geometry>
        <mesh filename="package://hexapod_description/meshes/servo_wheel.stl"/>
      </geometry>
      <material name="servo_wheel_4_material">
        <color rgba="0.647059 0.647059 0.647059 1"/>
      </material>
    </visual>
    <collision>
      <origin xyz="-1.11022e-15 -7.21645e-16 -0.0585" rpy="-3.14159 -2.85252e-14 -2.61799"/>
      <geometry>
        <mesh filename="package://hexapod_description/meshes/servo_wheel.stl"/>
      </geometry>
    </collision>
  </link>
  <!-- Link foot_assembly -->
  <link name="foot_assembly">
    <inertial>
      <origin xyz="-0.0724503 -0.00208415 -0.0306672" rpy="0 0 0"/>
      <mass value="0.633745"/>
      <inertia ixx="0.000268495" ixy="-1.4806e-05" ixz="4.28294e-06" iyy="0.00320961" iyz="-2.30165e-07" izz="0.00304658"/>
    </inertial>
    <!-- Part foot -->
    <visual>
      <origin xyz="-0.04425 -5.89806e-17 -0.0305" rpy="-3.12558e-17 1.5708 0"/>
      <geometry>
        <mesh filename="package://hexapod_description/meshes/foot.stl"/>
      </geometry>
      <material name="foot_material">
        <color rgba="0.282353 0.54902 0.160784 1"/>
      </material>
    </visual>
    <collision>
      <origin xyz="-0.04425 -5.89806e-17 -0.0305" rpy="-3.12558e-17 1.5708 0"/>
      <geometry>
        <mesh filename="package://hexapod_description/meshes/foot.stl"/>
      </geometry>
    </collision>
    <!-- Part ir_sensor_cap -->
    <visual>
      <origin xyz="-0.04425 3.81639e-17 -0.0305" rpy="-7.51938e-17 1.5708 0"/>
      <geometry>
        <mesh filename="package://hexapod_description/meshes/ir_sensor_cap.stl"/>
      </geometry>
      <material name="ir_sensor_cap_material">
        <color rgba="0.282353 0.54902 0.160784 1"/>
      </material>
    </visual>
    <collision>
      <origin xyz="-0.04425 3.81639e-17 -0.0305" rpy="-7.51938e-17 1.5708 0"/>
      <geometry>
        <mesh filename="package://hexapod_description/meshes/ir_sensor_cap.stl"/>
      </geometry>
    </collision>
    <!-- Part rubber_foot -->
    <visual>
      <origin xyz="-0.04375 1.61052e-14 -0.03" rpy="-7.6652e-14 1.5708 0"/>
      <geometry>
        <mesh filename="package://hexapod_description/meshes/rubber_foot.stl"/>
      </geometry>
      <material name="rubber_foot_material">
        <color rgba="0.262745 0.282353 0.301961 1"/>
      </material>
    </visual>
    <collision>
      <origin xyz="-0.04375 1.61052e-14 -0.03" rpy="-7.6652e-14 1.5708 0"/>
      <geometry>
        <mesh filename="package://hexapod_description/meshes/rubber_foot.stl"/>
      </geometry>
    </collision>
    <!-- Part servo_wheel_5 -->
    <visual>
      <origin xyz="0 2.08167e-17 -0.0025" rpy="-3.14159 1.32541e-18 -3.00419e-17"/>
      <geometry>
        <mesh filename="package://hexapod_description/meshes/servo_wheel.stl"/>
      </geometry>
      <material name="servo_wheel_5_material">
        <color rgba="0.647059 0.647059 0.647059 1"/>
      </material>
    </visual>
    <collision>
      <origin xyz="0 2.08167e-17 -0.0025" rpy="-3.14159 1.32541e-18 -3.00419e-17"/>
      <geometry>
        <mesh filename="package://hexapod_description/meshes/servo_wheel.stl"/>
      </geometry>
    </collision>
    <!-- Part servo_3 -->
    <visual>
      <origin xyz="-0.0175 -0.00140442 -0.0305" rpy="3.14159 -1.50748e-18 -6.71605e-18"/>
      <geometry>
        <mesh filename="package://hexapod_description/meshes/servo.stl"/>
      </geometry>
      <material name="servo_3_material">
        <color rgba="0.109804 0.109804 0.105882 1"/>
      </material>
    </visual>
    <collision>
      <origin xyz="-0.0175 -0.00140442 -0.0305" rpy="3.14159 -1.50748e-18 -6.71605e-18"/>
      <geometry>
        <mesh filename="package://hexapod_description/meshes/servo.stl"/>
      </geometry>
    </collision>
    <!-- Part fixed_bracket_3 -->
    <visual>
      <origin xyz="-0.0575 -5.89806e-17 -0.0305" rpy="1.5708 1.5708 0"/>
      <geometry>
        <mesh filename="package://hexapod_description/meshes/fixed_bracket.stl"/>
      </geometry>
      <material name="fixed_bracket_3_material">
        <color rgba="0.647059 0.647059 0.647059 1"/>
      </material>
    </visual>
    <collision>
      <origin xyz="-0.0575 -5.89806e-17 -0.0305" rpy="1.5708 1.5708 0"/>
      <geometry>
        <mesh filename="package://hexapod_description/meshes/fixed_bracket.stl"/>
      </geometry>
    </collision>
    <!-- Part servo_wheel_6 -->
    <visual>
      <origin xyz="-5.55112e-17 3.46945e-18 -0.0585" rpy="3.14159 -5.21805e-17 -2.42553e-17"/>
      <geometry>
        <mesh filename="package://hexapod_description/meshes/servo_wheel.stl"/>
      </geometry>
      <material name="servo_wheel_6_material">
        <color rgba="0.647059 0.647059 0.647059 1"/>
      </material>
    </visual>
    <collision>
      <origin xyz="-5.55112e-17 3.46945e-18 -0.0585" rpy="3.14159 -5.21805e-17 -2.42553e-17"/>
      <geometry>
        <mesh filename="package://hexapod_description/meshes/servo_wheel.stl"/>
      </geometry>
    </collision>
  </link>
  <!-- Joint from ties_assembly to foot_assembly -->
  <joint name="foot_1" type="revolute">
    <origin xyz="0.165999 0.0960821 -0.000790548" rpy="2.04167e-16 7.25873e-16 1.91986"/>
    <parent link="ties_assembly"/>
    <child link="foot_assembly"/>
    <axis xyz="0 0 1"/>
    <limit effort="10" velocity="10" lower="-0.349066" upper="3.83972"/>
  </joint>
  <!-- Joint from hip_assembly to ties_assembly -->
  <joint name="ties_1" type="revolute">
    <origin xyz="0.0925 -0.0311167 -0.0305" rpy="1.5708 7.28949e-15 7.80449e-15"/>
    <parent link="hip_assembly"/>
    <child link="ties_assembly"/>
    <axis xyz="0 0 1"/>
    <limit effort="10" velocity="10" lower="-2.26893" upper="1.22173"/>
  </joint>
  <!-- Joint from base_link to hip_assembly -->
  <joint name="hip_1" type="revolute">
    <origin xyz="-0.573739 -0.347776 0.386792" rpy="-3.98192e-14 -3.78648e-14 1.48353"/>
    <parent link="base_link"/>
    <child link="hip_assembly"/>
    <axis xyz="0 0 1"/>
    <limit effort="10" velocity="10" lower="-1.5708" upper="1.5708"/>
  </joint>
  <!-- Link hip_assembly_2 -->
  <link name="hip_assembly_2">
    <inertial>
      <origin xyz="-0.0268487 -0.000325484 -0.0302141" rpy="0 0 0"/>
      <mass value="0.365356"/>
      <inertia ixx="0.000168136" ixy="-2.8417e-07" ixz="3.2467e-06" iyy="0.000312332" iyz="-9.42575e-07" izz="0.000312341"/>
    </inertial>
    <!-- Part hip_2 -->
    <visual>
      <origin xyz="-0.0575 -0.0005 -0.0045" rpy="-1.80502e-16 2.7401e-29 1.23512e-16"/>
      <geometry>
        <mesh filename="package://hexapod_description/meshes/hip.stl"/>
      </geometry>
      <material name="hip_2_material">
        <color rgba="0.282353 0.54902 0.160784 1"/>
      </material>
    </visual>
    <collision>
      <origin xyz="-0.0575 -0.0005 -0.0045" rpy="-1.80502e-16 2.7401e-29 1.23512e-16"/>
      <geometry>
        <mesh filename="package://hexapod_description/meshes/hip.stl"/>
      </geometry>
    </collision>
    <!-- Part mobile_bracket_9 -->
    <visual>
      <origin xyz="-0.0575 -2.22045e-16 -0.0305" rpy="1.20123e-27 -5.50704e-17 1.5708"/>
      <geometry>
        <mesh filename="package://hexapod_description/meshes/mobile_bracket.stl"/>
      </geometry>
      <material name="mobile_bracket_9_material">
        <color rgba="0.647059 0.647059 0.647059 1"/>
      </material>
    </visual>
    <collision>
      <origin xyz="-0.0575 -2.22045e-16 -0.0305" rpy="1.20123e-27 -5.50704e-17 1.5708"/>
      <geometry>
        <mesh filename="package://hexapod_description/meshes/mobile_bracket.stl"/>
      </geometry>
    </collision>
    <!-- Part servo_wheel_7 -->
    <visual>
      <origin xyz="-1.66533e-16 0 -0.0025" rpy="3.14159 2.1575e-30 3.25683e-17"/>
      <geometry>
        <mesh filename="package://hexapod_description/meshes/servo_wheel.stl"/>
      </geometry>
      <material name="servo_wheel_7_material">
        <color rgba="0.647059 0.647059 0.647059 1"/>
      </material>
    </visual>
    <collision>
      <origin xyz="-1.66533e-16 0 -0.0025" rpy="3.14159 2.1575e-30 3.25683e-17"/>
      <geometry>
        <mesh filename="package://hexapod_description/meshes/servo_wheel.stl"/>
      </geometry>
    </collision>
    <!-- Part servo_4 -->
    <visual>
      <origin xyz="-0.0175 -0.00140442 -0.0305" rpy="3.14159 6.21109e-29 2.69968e-16"/>
      <geometry>
        <mesh filename="package://hexapod_description/meshes/servo.stl"/>
      </geometry>
      <material name="servo_4_material">
        <color rgba="0.109804 0.109804 0.105882 1"/>
      </material>
    </visual>
    <collision>
      <origin xyz="-0.0175 -0.00140442 -0.0305" rpy="3.14159 6.21109e-29 2.69968e-16"/>
      <geometry>
        <mesh filename="package://hexapod_description/meshes/servo.stl"/>
      </geometry>
    </collision>
    <!-- Part fixed_bracket_4 -->
    <visual>
      <origin xyz="-0.0575 1.11022e-16 -0.0305" rpy="1.5708 1.5708 0"/>
      <geometry>
        <mesh filename="package://hexapod_description/meshes/fixed_bracket.stl"/>
      </geometry>
      <material name="fixed_bracket_4_material">
        <color rgba="0.647059 0.647059 0.647059 1"/>
      </material>
    </visual>
    <collision>
      <origin xyz="-0.0575 1.11022e-16 -0.0305" rpy="1.5708 1.5708 0"/>
      <geometry>
        <mesh filename="package://hexapod_description/meshes/fixed_bracket.stl"/>
      </geometry>
    </collision>
    <!-- Part servo_wheel_8 -->
    <visual>
      <origin xyz="-1.11022e-16 1.11022e-16 -0.0585" rpy="3.14159 1.47793e-29 3.10124e-16"/>
      <geometry>
        <mesh filename="package://hexapod_description/meshes/servo_wheel.stl"/>
      </geometry>
      <material name="servo_wheel_8_material">
        <color rgba="0.647059 0.647059 0.647059 1"/>
      </material>
    </visual>
    <collision>
      <origin xyz="-1.11022e-16 1.11022e-16 -0.0585" rpy="3.14159 1.47793e-29 3.10124e-16"/>
      <geometry>
        <mesh filename="package://hexapod_description/meshes/servo_wheel.stl"/>
      </geometry>
    </collision>
  </link>
  <!-- Link ties_assembly_2 -->
  <link name="ties_assembly_2">
    <inertial>
      <origin xyz="0.0549718 0.0335057 -0.0309357" rpy="0 0 0"/>
      <mass value="0.589115"/>
      <inertia ixx="0.000782879" ixy="-0.000776998" ixz="9.2367e-06" iyy="0.00162431" iyz="5.57469e-06" izz="0.00187002"/>
    </inertial>
    <!-- Part mobile_bracket_10 -->
    <visual>
      <origin xyz="0.135688 0.0785821 -0.0311738" rpy="1.0472 1.5708 0"/>
      <geometry>
        <mesh filename="package://hexapod_description/meshes/mobile_bracket.stl"/>
      </geometry>
      <material name="mobile_bracket_10_material">
        <color rgba="0.647059 0.647059 0.647059 1"/>
      </material>
    </visual>
    <collision>
      <origin xyz="0.135688 0.0785821 -0.0311738" rpy="1.0472 1.5708 0"/>
      <geometry>
        <mesh filename="package://hexapod_description/meshes/mobile_bracket.stl"/>
      </geometry>
    </collision>
    <!-- Part low_tie_2 -->
    <visual>
      <origin xyz="0.0231043 0.0135821 -0.0311738" rpy="-0.523599 1.5708 0"/>
      <geometry>
        <mesh filename="package://hexapod_description/meshes/low_tie.stl"/>
      </geometry>
      <material name="low_tie_2_material">
        <color rgba="0.282353 0.54902 0.160784 1"/>
      </material>
    </visual>
    <collision>
      <origin xyz="0.0231043 0.0135821 -0.0311738" rpy="-0.523599 1.5708 0"/>
      <geometry>
        <mesh filename="package://hexapod_description/meshes/low_tie.stl"/>
      </geometry>
    </collision>
    <!-- Part top_tie_2 -->
    <visual>
      <origin xyz="0.0238157 0.01375 -0.0305" rpy="-0.523599 1.5708 0"/>
      <geometry>
        <mesh filename="package://hexapod_description/meshes/top_tie.stl"/>
      </geometry>
      <material name="top_tie_2_material">
        <color rgba="0.282353 0.54902 0.160784 1"/>
      </material>
    </visual>
    <collision>
      <origin xyz="0.0238157 0.01375 -0.0305" rpy="-0.523599 1.5708 0"/>
      <geometry>
        <mesh filename="package://hexapod_description/meshes/top_tie.stl"/>
      </geometry>
    </collision>
    <!-- Part servo_wheel_9 -->
    <visual>
      <origin xyz="-1.44329e-15 1.66533e-16 -0.0025" rpy="-3.14159 1.01795e-14 -2.61799"/>
      <geometry>
        <mesh filename="package://hexapod_description/meshes/servo_wheel.stl"/>
      </geometry>
      <material name="servo_wheel_9_material">
        <color rgba="0.647059 0.647059 0.647059 1"/>
      </material>
    </visual>
    <collision>
      <origin xyz="-1.44329e-15 1.66533e-16 -0.0025" rpy="-3.14159 1.01795e-14 -2.61799"/>
      <geometry>
        <mesh filename="package://hexapod_description/meshes/servo_wheel.stl"/>
      </geometry>
    </collision>
    <!-- Part servo_5 -->
    <visual>
      <origin xyz="0.0144532 0.00996626 -0.0305" rpy="-3.14159 1.01493e-14 -2.61799"/>
      <geometry>
        <mesh filename="package://hexapod_description/meshes/servo.stl"/>
      </geometry>
      <material name="servo_5_material">
        <color rgba="0.109804 0.109804 0.105882 1"/>
      </material>
    </visual>
    <collision>
      <origin xyz="0.0144532 0.00996626 -0.0305" rpy="-3.14159 1.01493e-14 -2.61799"/>
      <geometry>
        <mesh filename="package://hexapod_description/meshes/servo.stl"/>
      </geometry>
    </collision>
    <!-- Part fixed_bracket_5 -->
    <visual>
      <origin xyz="0.0497965 0.02875 -0.0305" rpy="-2.0944 1.5708 0"/>
      <geometry>
        <mesh filename="package://hexapod_description/meshes/fixed_bracket.stl"/>
      </geometry>
      <material name="fixed_bracket_5_material">
        <color rgba="0.647059 0.647059 0.647059 1"/>
      </material>
    </visual>
    <collision>
      <origin xyz="0.0497965 0.02875 -0.0305" rpy="-2.0944 1.5708 0"/>
      <geometry>
        <mesh filename="package://hexapod_description/meshes/fixed_bracket.stl"/>
      </geometry>
    </collision>
    <!-- Part servo_wheel_10 -->
    <visual>
      <origin xyz="-9.99201e-16 3.88578e-16 -0.0585" rpy="-3.14159 1.0806e-14 -2.61799"/>
      <geometry>
        <mesh filename="package://hexapod_description/meshes/servo_wheel.stl"/>
      </geometry>
      <material name="servo_wheel_10_material">
        <color rgba="0.647059 0.647059 0.647059 1"/>
      </material>
    </visual>
    <collision>
      <origin xyz="-9.99201e-16 3.88578e-16 -0.0585" rpy="-3.14159 1.0806e-14 -2.61799"/>
      <geometry>
        <mesh filename="package://hexapod_description/meshes/servo_wheel.stl"/>
      </geometry>
    </collision>
  </link>
  <!-- Link foot_assembly_2 -->
  <link name="foot_assembly_2">
    <inertial>
      <origin xyz="-0.0724503 -0.00208415 -0.0306672" rpy="0 0 0"/>
      <mass value="0.633745"/>
      <inertia ixx="0.000268495" ixy="-1.4806e-05" ixz="4.28294e-06" iyy="0.00320961" iyz="-2.30165e-07" izz="0.00304658"/>
    </inertial>
    <!-- Part foot_2 -->
    <visual>
      <origin xyz="-0.04425 2.22045e-16 -0.0305" rpy="-8.29462e-17 1.5708 0"/>
      <geometry>
        <mesh filename="package://hexapod_description/meshes/foot.stl"/>
      </geometry>
      <material name="foot_2_material">
        <color rgba="0.282353 0.54902 0.160784 1"/>
      </material>
    </visual>
    <collision>
      <origin xyz="-0.04425 2.22045e-16 -0.0305" rpy="-8.29462e-17 1.5708 0"/>
      <geometry>
        <mesh filename="package://hexapod_description/meshes/foot.stl"/>
      </geometry>
    </collision>
    <!-- Part ir_sensor_cap_2 -->
    <visual>
      <origin xyz="-0.04425 1.11022e-16 -0.0305" rpy="-2.74351e-17 1.5708 0"/>
      <geometry>
        <mesh filename="package://hexapod_description/meshes/ir_sensor_cap.stl"/>
      </geometry>
      <material name="ir_sensor_cap_2_material">
        <color rgba="0.282353 0.54902 0.160784 1"/>
      </material>
    </visual>
    <collision>
      <origin xyz="-0.04425 1.11022e-16 -0.0305" rpy="-2.74351e-17 1.5708 0"/>
      <geometry>
        <mesh filename="package://hexapod_description/meshes/ir_sensor_cap.stl"/>
      </geometry>
    </collision>
    <!-- Part rubber_foot_2 -->
    <visual>
      <origin xyz="-0.04375 2.22045e-16 -0.03" rpy="-4.49744e-17 1.5708 0"/>
      <geometry>
        <mesh filename="package://hexapod_description/meshes/rubber_foot.stl"/>
      </geometry>
      <material name="rubber_foot_2_material">
        <color rgba="0.262745 0.282353 0.301961 1"/>
      </material>
    </visual>
    <collision>
      <origin xyz="-0.04375 2.22045e-16 -0.03" rpy="-4.49744e-17 1.5708 0"/>
      <geometry>
        <mesh filename="package://hexapod_description/meshes/rubber_foot.stl"/>
      </geometry>
    </collision>
    <!-- Part servo_wheel_11 -->
    <visual>
      <origin xyz="5.55112e-17 2.22045e-16 -0.0025" rpy="-3.14159 8.00934e-18 2.74351e-17"/>
      <geometry>
        <mesh filename="package://hexapod_description/meshes/servo_wheel.stl"/>
      </geometry>
      <material name="servo_wheel_11_material">
        <color rgba="0.647059 0.647059 0.647059 1"/>
      </material>
    </visual>
    <collision>
      <origin xyz="5.55112e-17 2.22045e-16 -0.0025" rpy="-3.14159 8.00934e-18 2.74351e-17"/>
      <geometry>
        <mesh filename="package://hexapod_description/meshes/servo_wheel.stl"/>
      </geometry>
    </collision>
    <!-- Part servo_6 -->
    <visual>
      <origin xyz="-0.0175 -0.00140442 -0.0305" rpy="3.14159 8.00934e-18 2.74351e-17"/>
      <geometry>
        <mesh filename="package://hexapod_description/meshes/servo.stl"/>
      </geometry>
      <material name="servo_6_material">
        <color rgba="0.109804 0.109804 0.105882 1"/>
      </material>
    </visual>
    <collision>
      <origin xyz="-0.0175 -0.00140442 -0.0305" rpy="3.14159 8.00934e-18 2.74351e-17"/>
      <geometry>
        <mesh filename="package://hexapod_description/meshes/servo.stl"/>
      </geometry>
    </collision>
    <!-- Part fixed_bracket_6 -->
    <visual>
      <origin xyz="-0.0575 2.22045e-16 -0.0305" rpy="1.5708 1.5708 0"/>
      <geometry>
        <mesh filename="package://hexapod_description/meshes/fixed_bracket.stl"/>
      </geometry>
      <material name="fixed_bracket_6_material">
        <color rgba="0.647059 0.647059 0.647059 1"/>
      </material>
    </visual>
    <collision>
      <origin xyz="-0.0575 2.22045e-16 -0.0305" rpy="1.5708 1.5708 0"/>
      <geometry>
        <mesh filename="package://hexapod_description/meshes/fixed_bracket.stl"/>
      </geometry>
    </collision>
    <!-- Part servo_wheel_12 -->
    <visual>
      <origin xyz="-2.77556e-17 3.33067e-16 -0.0585" rpy="-3.14159 6.61784e-17 1.55997e-16"/>
      <geometry>
        <mesh filename="package://hexapod_description/meshes/servo_wheel.stl"/>
      </geometry>
      <material name="servo_wheel_12_material">
        <color rgba="0.647059 0.647059 0.647059 1"/>
      </material>
    </visual>
    <collision>
      <origin xyz="-2.77556e-17 3.33067e-16 -0.0585" rpy="-3.14159 6.61784e-17 1.55997e-16"/>
      <geometry>
        <mesh filename="package://hexapod_description/meshes/servo_wheel.stl"/>
      </geometry>
    </collision>
  </link>
  <!-- Joint from ties_assembly_2 to foot_assembly_2 -->
  <joint name="foot_2" type="revolute">
    <origin xyz="0.165999 0.0960821 -0.000790548" rpy="1.74534e-16 -7.20665e-17 1.91986"/>
    <parent link="ties_assembly_2"/>
    <child link="foot_assembly_2"/>
    <axis xyz="0 0 1"/>
    <limit effort="10" velocity="10" lower="-0.349066" upper="3.83972"/>
  </joint>
  <!-- Joint from hip_assembly_2 to ties_assembly_2 -->
  <joint name="ties_2" type="revolute">
    <origin xyz="-0.0925 0.0311167 -0.0305" rpy="1.5708 -1.19807e-27 -3.14159"/>
    <parent link="hip_assembly_2"/>
    <child link="ties_assembly_2"/>
    <axis xyz="0 0 1"/>
    <limit effort="10" velocity="10" lower="-2.26893" upper="1.22173"/>
  </joint>
  <!-- Joint from base_link to hip_assembly_2 -->
  <joint name="hip_2" type="revolute">
    <origin xyz="-0.716746 -0.414461 0.386792" rpy="5.13858e-14 -1.55159e-14 -0.610865"/>
    <parent link="base_link"/>
    <child link="hip_assembly_2"/>
    <axis xyz="0 0 1"/>
    <limit effort="10" velocity="10" lower="-1.5708" upper="1.5708"/>
  </joint>
  <!-- Link hip_assembly_3 -->
  <link name="hip_assembly_3">
    <inertial>
      <origin xyz="-0.0268487 -0.000325484 -0.0302141" rpy="0 0 0"/>
      <mass value="0.365356"/>
      <inertia ixx="0.000168136" ixy="-2.8417e-07" ixz="3.2467e-06" iyy="0.000312332" iyz="-9.42575e-07" izz="0.000312341"/>
    </inertial>
    <!-- Part hip_3 -->
    <visual>
      <origin xyz="-0.0575 -0.0005 -0.0045" rpy="-7.17961e-15 -1.63347e-15 -1.44093e-16"/>
      <geometry>
        <mesh filename="package://hexapod_description/meshes/hip.stl"/>
      </geometry>
      <material name="hip_3_material">
        <color rgba="0.282353 0.54902 0.160784 1"/>
      </material>
    </visual>
    <collision>
      <origin xyz="-0.0575 -0.0005 -0.0045" rpy="-7.17961e-15 -1.63347e-15 -1.44093e-16"/>
      <geometry>
        <mesh filename="package://hexapod_description/meshes/hip.stl"/>
      </geometry>
    </collision>
    <!-- Part mobile_bracket_11 -->
    <visual>
      <origin xyz="-0.0575 -1.38778e-16 -0.0305" rpy="6.31089e-30 5.5948e-14 1.5708"/>
      <geometry>
        <mesh filename="package://hexapod_description/meshes/mobile_bracket.stl"/>
      </geometry>
      <material name="mobile_bracket_11_material">
        <color rgba="0.647059 0.647059 0.647059 1"/>
      </material>
    </visual>
    <collision>
      <origin xyz="-0.0575 -1.38778e-16 -0.0305" rpy="6.31089e-30 5.5948e-14 1.5708"/>
      <geometry>
        <mesh filename="package://hexapod_description/meshes/mobile_bracket.stl"/>
      </geometry>
    </collision>
    <!-- Part servo_wheel_13 -->
    <visual>
      <origin xyz="1.11022e-16 5.55112e-17 -0.0025" rpy="-3.14159 1.26218e-29 -7.31844e-17"/>
      <geometry>
        <mesh filename="package://hexapod_description/meshes/servo_wheel.stl"/>
      </geometry>
      <material name="servo_wheel_13_material">
        <color rgba="0.647059 0.647059 0.647059 1"/>
      </material>
    </visual>
    <collision>
      <origin xyz="1.11022e-16 5.55112e-17 -0.0025" rpy="-3.14159 1.26218e-29 -7.31844e-17"/>
      <geometry>
        <mesh filename="package://hexapod_description/meshes/servo_wheel.stl"/>
      </geometry>
    </collision>
    <!-- Part servo_7 -->
    <visual>
      <origin xyz="-0.0175 -0.00140442 -0.0305" rpy="3.14159 6.12323e-17 -1.94156e-15"/>
      <geometry>
        <mesh filename="package://hexapod_description/meshes/servo.stl"/>
      </geometry>
      <material name="servo_7_material">
        <color rgba="0.109804 0.109804 0.105882 1"/>
      </material>
    </visual>
    <collision>
      <origin xyz="-0.0175 -0.00140442 -0.0305" rpy="3.14159 6.12323e-17 -1.94156e-15"/>
      <geometry>
        <mesh filename="package://hexapod_description/meshes/servo.stl"/>
      </geometry>
    </collision>
    <!-- Part fixed_bracket_7 -->
    <visual>
      <origin xyz="-0.0575 -1.38778e-16 -0.0305" rpy="1.5708 1.5708 0"/>
      <geometry>
        <mesh filename="package://hexapod_description/meshes/fixed_bracket.stl"/>
      </geometry>
      <material name="fixed_bracket_7_material">
        <color rgba="0.647059 0.647059 0.647059 1"/>
      </material>
    </visual>
    <collision>
      <origin xyz="-0.0575 -1.38778e-16 -0.0305" rpy="1.5708 1.5708 0"/>
      <geometry>
        <mesh filename="package://hexapod_description/meshes/fixed_bracket.stl"/>
      </geometry>
    </collision>
    <!-- Part servo_wheel_14 -->
    <visual>
      <origin xyz="0 2.498e-16 -0.0585" rpy="3.14159 6.12323e-17 -1.83744e-15"/>
      <geometry>
        <mesh filename="package://hexapod_description/meshes/servo_wheel.stl"/>
      </geometry>
      <material name="servo_wheel_14_material">
        <color rgba="0.647059 0.647059 0.647059 1"/>
      </material>
    </visual>
    <collision>
      <origin xyz="0 2.498e-16 -0.0585" rpy="3.14159 6.12323e-17 -1.83744e-15"/>
      <geometry>
        <mesh filename="package://hexapod_description/meshes/servo_wheel.stl"/>
      </geometry>
    </collision>
  </link>
  <!-- Link ties_assembly_3 -->
  <link name="ties_assembly_3">
    <inertial>
      <origin xyz="0.0549718 0.0335057 -0.0309357" rpy="0 0 0"/>
      <mass value="0.589115"/>
      <inertia ixx="0.000782879" ixy="-0.000776998" ixz="9.2367e-06" iyy="0.00162431" iyz="5.57469e-06" izz="0.00187002"/>
    </inertial>
    <!-- Part mobile_bracket_12 -->
    <visual>
      <origin xyz="0.135688 0.0785821 -0.0311738" rpy="1.0472 1.5708 0"/>
      <geometry>
        <mesh filename="package://hexapod_description/meshes/mobile_bracket.stl"/>
      </geometry>
      <material name="mobile_bracket_12_material">
        <color rgba="0.647059 0.647059 0.647059 1"/>
      </material>
    </visual>
    <collision>
      <origin xyz="0.135688 0.0785821 -0.0311738" rpy="1.0472 1.5708 0"/>
      <geometry>
        <mesh filename="package://hexapod_description/meshes/mobile_bracket.stl"/>
      </geometry>
    </collision>
    <!-- Part low_tie_3 -->
    <visual>
      <origin xyz="0.0231043 0.0135821 -0.0311738" rpy="-0.523599 1.5708 0"/>
      <geometry>
        <mesh filename="package://hexapod_description/meshes/low_tie.stl"/>
      </geometry>
      <material name="low_tie_3_material">
        <color rgba="0.282353 0.54902 0.160784 1"/>
      </material>
    </visual>
    <collision>
      <origin xyz="0.0231043 0.0135821 -0.0311738" rpy="-0.523599 1.5708 0"/>
      <geometry>
        <mesh filename="package://hexapod_description/meshes/low_tie.stl"/>
      </geometry>
    </collision>
    <!-- Part top_tie_3 -->
    <visual>
      <origin xyz="0.0238157 0.01375 -0.0305" rpy="-0.523599 1.5708 0"/>
      <geometry>
        <mesh filename="package://hexapod_description/meshes/top_tie.stl"/>
      </geometry>
      <material name="top_tie_3_material">
        <color rgba="0.282353 0.54902 0.160784 1"/>
      </material>
    </visual>
    <collision>
      <origin xyz="0.0238157 0.01375 -0.0305" rpy="-0.523599 1.5708 0"/>
      <geometry>
        <mesh filename="package://hexapod_description/meshes/top_tie.stl"/>
      </geometry>
    </collision>
    <!-- Part servo_wheel_15 -->
    <visual>
      <origin xyz="-2.22045e-16 -1.66533e-16 -0.0025" rpy="3.14159 -4.69348e-16 -2.61799"/>
      <geometry>
        <mesh filename="package://hexapod_description/meshes/servo_wheel.stl"/>
      </geometry>
      <material name="servo_wheel_15_material">
        <color rgba="0.647059 0.647059 0.647059 1"/>
      </material>
    </visual>
    <collision>
      <origin xyz="-2.22045e-16 -1.66533e-16 -0.0025" rpy="3.14159 -4.69348e-16 -2.61799"/>
      <geometry>
        <mesh filename="package://hexapod_description/meshes/servo_wheel.stl"/>
      </geometry>
    </collision>
    <!-- Part servo_8 -->
    <visual>
      <origin xyz="0.0144532 0.00996626 -0.0305" rpy="3.14159 -1.44984e-16 -2.61799"/>
      <geometry>
        <mesh filename="package://hexapod_description/meshes/servo.stl"/>
      </geometry>
      <material name="servo_8_material">
        <color rgba="0.109804 0.109804 0.105882 1"/>
      </material>
    </visual>
    <collision>
      <origin xyz="0.0144532 0.00996626 -0.0305" rpy="3.14159 -1.44984e-16 -2.61799"/>
      <geometry>
        <mesh filename="package://hexapod_description/meshes/servo.stl"/>
      </geometry>
    </collision>
    <!-- Part fixed_bracket_8 -->
    <visual>
      <origin xyz="0.0497965 0.02875 -0.0305" rpy="-2.0944 1.5708 0"/>
      <geometry>
        <mesh filename="package://hexapod_description/meshes/fixed_bracket.stl"/>
      </geometry>
      <material name="fixed_bracket_8_material">
        <color rgba="0.647059 0.647059 0.647059 1"/>
      </material>
    </visual>
    <collision>
      <origin xyz="0.0497965 0.02875 -0.0305" rpy="-2.0944 1.5708 0"/>
      <geometry>
        <mesh filename="package://hexapod_description/meshes/fixed_bracket.stl"/>
      </geometry>
    </collision>
    <!-- Part servo_wheel_16 -->
    <visual>
      <origin xyz="2.22045e-16 -3.33067e-16 -0.0585" rpy="3.14159 4.06543e-17 -2.61799"/>
      <geometry>
        <mesh filename="package://hexapod_description/meshes/servo_wheel.stl"/>
      </geometry>
      <material name="servo_wheel_16_material">
        <color rgba="0.647059 0.647059 0.647059 1"/>
      </material>
    </visual>
    <collision>
      <origin xyz="2.22045e-16 -3.33067e-16 -0.0585" rpy="3.14159 4.06543e-17 -2.61799"/>
      <geometry>
        <mesh filename="package://hexapod_description/meshes/servo_wheel.stl"/>
      </geometry>
    </collision>
  </link>
  <!-- Link foot_assembly_3 -->
  <link name="foot_assembly_3">
    <inertial>
      <origin xyz="-0.0724503 -0.00208415 -0.0306672" rpy="0 0 0"/>
      <mass value="0.633745"/>
      <inertia ixx="0.000268495" ixy="-1.4806e-05" ixz="4.28294e-06" iyy="0.00320961" iyz="-2.30165e-07" izz="0.00304658"/>
    </inertial>
    <!-- Part foot_3 -->
    <visual>
      <origin xyz="-0.04425 0 -0.0305" rpy="1.67473e-16 1.5708 0"/>
      <geometry>
        <mesh filename="package://hexapod_description/meshes/foot.stl"/>
      </geometry>
      <material name="foot_3_material">
        <color rgba="0.282353 0.54902 0.160784 1"/>
      </material>
    </visual>
    <collision>
      <origin xyz="-0.04425 0 -0.0305" rpy="1.67473e-16 1.5708 0"/>
      <geometry>
        <mesh filename="package://hexapod_description/meshes/foot.stl"/>
      </geometry>
    </collision>
    <!-- Part ir_sensor_cap_3 -->
    <visual>
      <origin xyz="-0.04425 -3.77476e-15 -0.0305" rpy="2.12212e-14 1.5708 0"/>
      <geometry>
        <mesh filename="package://hexapod_description/meshes/ir_sensor_cap.stl"/>
      </geometry>
      <material name="ir_sensor_cap_3_material">
        <color rgba="0.282353 0.54902 0.160784 1"/>
      </material>
    </visual>
    <collision>
      <origin xyz="-0.04425 -3.77476e-15 -0.0305" rpy="2.12212e-14 1.5708 0"/>
      <geometry>
        <mesh filename="package://hexapod_description/meshes/ir_sensor_cap.stl"/>
      </geometry>
    </collision>
    <!-- Part rubber_foot_3 -->
    <visual>
      <origin xyz="-0.04375 -4.21885e-15 -0.03" rpy="1.96991e-14 1.5708 0"/>
      <geometry>
        <mesh filename="package://hexapod_description/meshes/rubber_foot.stl"/>
      </geometry>
      <material name="rubber_foot_3_material">
        <color rgba="0.262745 0.282353 0.301961 1"/>
      </material>
    </visual>
    <collision>
      <origin xyz="-0.04375 -4.21885e-15 -0.03" rpy="1.96991e-14 1.5708 0"/>
      <geometry>
        <mesh filename="package://hexapod_description/meshes/rubber_foot.stl"/>
      </geometry>
    </collision>
    <!-- Part servo_wheel_17 -->
    <visual>
      <origin xyz="-2.42861e-17 -2.22045e-16 -0.0025" rpy="-3.14159 2.06853e-17 9.73618e-18"/>
      <geometry>
        <mesh filename="package://hexapod_description/meshes/servo_wheel.stl"/>
      </geometry>
      <material name="servo_wheel_17_material">
        <color rgba="0.647059 0.647059 0.647059 1"/>
      </material>
    </visual>
    <collision>
      <origin xyz="-2.42861e-17 -2.22045e-16 -0.0025" rpy="-3.14159 2.06853e-17 9.73618e-18"/>
      <geometry>
        <mesh filename="package://hexapod_description/meshes/servo_wheel.stl"/>
      </geometry>
    </collision>
    <!-- Part servo_9 -->
    <visual>
      <origin xyz="-0.0175 -0.00140442 -0.0305" rpy="3.14159 -4.32956e-16 -1.88983e-16"/>
      <geometry>
        <mesh filename="package://hexapod_description/meshes/servo.stl"/>
      </geometry>
      <material name="servo_9_material">
        <color rgba="0.109804 0.109804 0.105882 1"/>
      </material>
    </visual>
    <collision>
      <origin xyz="-0.0175 -0.00140442 -0.0305" rpy="3.14159 -4.32956e-16 -1.88983e-16"/>
      <geometry>
        <mesh filename="package://hexapod_description/meshes/servo.stl"/>
      </geometry>
    </collision>
    <!-- Part fixed_bracket_9 -->
    <visual>
      <origin xyz="-0.0575 0 -0.0305" rpy="1.5708 1.5708 0"/>
      <geometry>
        <mesh filename="package://hexapod_description/meshes/fixed_bracket.stl"/>
      </geometry>
      <material name="fixed_bracket_9_material">
        <color rgba="0.647059 0.647059 0.647059 1"/>
      </material>
    </visual>
    <collision>
      <origin xyz="-0.0575 0 -0.0305" rpy="1.5708 1.5708 0"/>
      <geometry>
        <mesh filename="package://hexapod_description/meshes/fixed_bracket.stl"/>
      </geometry>
    </collision>
    <!-- Part servo_wheel_18 -->
    <visual>
      <origin xyz="-5.89806e-17 2.22045e-16 -0.0585" rpy="-3.14159 -4.46757e-16 -2.8029e-16"/>
      <geometry>
        <mesh filename="package://hexapod_description/meshes/servo_wheel.stl"/>
      </geometry>
      <material name="servo_wheel_18_material">
        <color rgba="0.647059 0.647059 0.647059 1"/>
      </material>
    </visual>
    <collision>
      <origin xyz="-5.89806e-17 2.22045e-16 -0.0585" rpy="-3.14159 -4.46757e-16 -2.8029e-16"/>
      <geometry>
        <mesh filename="package://hexapod_description/meshes/servo_wheel.stl"/>
      </geometry>
    </collision>
  </link>
  <!-- Joint from ties_assembly_3 to foot_assembly_3 -->
  <joint name="foot_3" type="revolute">
    <origin xyz="0.165999 0.0960821 -0.000790548" rpy="1.44039e-15 7.27652e-16 1.91986"/>
    <parent link="ties_assembly_3"/>
    <child link="foot_assembly_3"/>
    <axis xyz="0 0 1"/>
    <limit effort="10" velocity="10" lower="-0.349066" upper="3.83972"/>
  </joint>
  <!-- Joint from hip_assembly_3 to ties_assembly_3 -->
  <joint name="ties_3" type="revolute">
    <origin xyz="-0.0925 0.0311167 -0.0305" rpy="1.5708 -3.15544e-29 -3.14159"/>
    <parent link="hip_assembly_3"/>
    <child link="ties_assembly_3"/>
    <axis xyz="0 0 1"/>
    <limit effort="10" velocity="10" lower="-2.26893" upper="1.22173"/>
  </joint>
  <!-- Joint from base_link to hip_assembly_3 -->
  <joint name="hip_3" type="revolute">
    <origin xyz="-0.730498 -0.571652 0.387526" rpy="1.1508e-14 -5.35395e-14 0.436332"/>
    <parent link="base_link"/>
    <child link="hip_assembly_3"/>
    <axis xyz="0 0 1"/>
    <limit effort="10" velocity="10" lower="-1.5708" upper="1.5708"/>
  </joint>
  <!-- Link hip_assembly_4 -->
  <link name="hip_assembly_4">
    <inertial>
      <origin xyz="-0.0268487 -0.000325484 -0.0302141" rpy="0 0 0"/>
      <mass value="0.365356"/>
      <inertia ixx="0.000168136" ixy="-2.8417e-07" ixz="3.2467e-06" iyy="0.000312332" iyz="-9.42575e-07" izz="0.000312341"/>
    </inertial>
    <!-- Part hip_4 -->
    <visual>
      <origin xyz="-0.0575 -0.0005 -0.0045" rpy="-6.57173e-16 1.50582e-16 5.5187e-16"/>
      <geometry>
        <mesh filename="package://hexapod_description/meshes/hip.stl"/>
      </geometry>
      <material name="hip_4_material">
        <color rgba="0.282353 0.54902 0.160784 1"/>
      </material>
    </visual>
    <collision>
      <origin xyz="-0.0575 -0.0005 -0.0045" rpy="-6.57173e-16 1.50582e-16 5.5187e-16"/>
      <geometry>
        <mesh filename="package://hexapod_description/meshes/hip.stl"/>
      </geometry>
    </collision>
    <!-- Part mobile_bracket_13 -->
    <visual>
      <origin xyz="-0.0575 1.11022e-16 -0.0305" rpy="3.33266e-16 1.95667e-16 1.5708"/>
      <geometry>
        <mesh filename="package://hexapod_description/meshes/mobile_bracket.stl"/>
      </geometry>
      <material name="mobile_bracket_13_material">
        <color rgba="0.647059 0.647059 0.647059 1"/>
      </material>
    </visual>
    <collision>
      <origin xyz="-0.0575 1.11022e-16 -0.0305" rpy="3.33266e-16 1.95667e-16 1.5708"/>
      <geometry>
        <mesh filename="package://hexapod_description/meshes/mobile_bracket.stl"/>
      </geometry>
    </collision>
    <!-- Part servo_wheel_19 -->
    <visual>
      <origin xyz="0 0 -0.0025" rpy="3.14159 -6.69997e-30 8.0896e-18"/>
      <geometry>
        <mesh filename="package://hexapod_description/meshes/servo_wheel.stl"/>
      </geometry>
      <material name="servo_wheel_19_material">
        <color rgba="0.647059 0.647059 0.647059 1"/>
      </material>
    </visual>
    <collision>
      <origin xyz="0 0 -0.0025" rpy="3.14159 -6.69997e-30 8.0896e-18"/>
      <geometry>
        <mesh filename="package://hexapod_description/meshes/servo_wheel.stl"/>
      </geometry>
    </collision>
    <!-- Part servo_10 -->
    <visual>
      <origin xyz="-0.0175 -0.00140442 -0.0305" rpy="3.14159 2.3496e-16 9.78762e-16"/>
      <geometry>
        <mesh filename="package://hexapod_description/meshes/servo.stl"/>
      </geometry>
      <material name="servo_10_material">
        <color rgba="0.109804 0.109804 0.105882 1"/>
      </material>
    </visual>
    <collision>
      <origin xyz="-0.0175 -0.00140442 -0.0305" rpy="3.14159 2.3496e-16 9.78762e-16"/>
      <geometry>
        <mesh filename="package://hexapod_description/meshes/servo.stl"/>
      </geometry>
    </collision>
    <!-- Part fixed_bracket_10 -->
    <visual>
      <origin xyz="-0.0575 1.11022e-16 -0.0305" rpy="1.5708 1.5708 0"/>
      <geometry>
        <mesh filename="package://hexapod_description/meshes/fixed_bracket.stl"/>
      </geometry>
      <material name="fixed_bracket_10_material">
        <color rgba="0.647059 0.647059 0.647059 1"/>
      </material>
    </visual>
    <collision>
      <origin xyz="-0.0575 1.11022e-16 -0.0305" rpy="1.5708 1.5708 0"/>
      <geometry>
        <mesh filename="package://hexapod_description/meshes/fixed_bracket.stl"/>
      </geometry>
    </collision>
    <!-- Part servo_wheel_20 -->
    <visual>
      <origin xyz="0 0 -0.0585" rpy="3.14159 3.02703e-16 1.31833e-15"/>
      <geometry>
        <mesh filename="package://hexapod_description/meshes/servo_wheel.stl"/>
      </geometry>
      <material name="servo_wheel_20_material">
        <color rgba="0.647059 0.647059 0.647059 1"/>
      </material>
    </visual>
    <collision>
      <origin xyz="0 0 -0.0585" rpy="3.14159 3.02703e-16 1.31833e-15"/>
      <geometry>
        <mesh filename="package://hexapod_description/meshes/servo_wheel.stl"/>
      </geometry>
    </collision>
  </link>
  <!-- Link ties_assembly_4 -->
  <link name="ties_assembly_4">
    <inertial>
      <origin xyz="0.0549718 0.0335057 -0.0309357" rpy="0 0 0"/>
      <mass value="0.589115"/>
      <inertia ixx="0.000782879" ixy="-0.000776998" ixz="9.2367e-06" iyy="0.00162431" iyz="5.57469e-06" izz="0.00187002"/>
    </inertial>
    <!-- Part mobile_bracket_14 -->
    <visual>
      <origin xyz="0.135688 0.0785821 -0.0311738" rpy="1.0472 1.5708 0"/>
      <geometry>
        <mesh filename="package://hexapod_description/meshes/mobile_bracket.stl"/>
      </geometry>
      <material name="mobile_bracket_14_material">
        <color rgba="0.647059 0.647059 0.647059 1"/>
      </material>
    </visual>
    <collision>
      <origin xyz="0.135688 0.0785821 -0.0311738" rpy="1.0472 1.5708 0"/>
      <geometry>
        <mesh filename="package://hexapod_description/meshes/mobile_bracket.stl"/>
      </geometry>
    </collision>
    <!-- Part low_tie_4 -->
    <visual>
      <origin xyz="0.0231043 0.0135821 -0.0311738" rpy="-0.523599 1.5708 0"/>
      <geometry>
        <mesh filename="package://hexapod_description/meshes/low_tie.stl"/>
      </geometry>
      <material name="low_tie_4_material">
        <color rgba="0.282353 0.54902 0.160784 1"/>
      </material>
    </visual>
    <collision>
      <origin xyz="0.0231043 0.0135821 -0.0311738" rpy="-0.523599 1.5708 0"/>
      <geometry>
        <mesh filename="package://hexapod_description/meshes/low_tie.stl"/>
      </geometry>
    </collision>
    <!-- Part top_tie_4 -->
    <visual>
      <origin xyz="0.0238157 0.01375 -0.0305" rpy="-0.523599 1.5708 0"/>
      <geometry>
        <mesh filename="package://hexapod_description/meshes/top_tie.stl"/>
      </geometry>
      <material name="top_tie_4_material">
        <color rgba="0.282353 0.54902 0.160784 1"/>
      </material>
    </visual>
    <collision>
      <origin xyz="0.0238157 0.01375 -0.0305" rpy="-0.523599 1.5708 0"/>
      <geometry>
        <mesh filename="package://hexapod_description/meshes/top_tie.stl"/>
      </geometry>
    </collision>
    <!-- Part servo_wheel_21 -->
    <visual>
      <origin xyz="1.11022e-16 0 -0.0025" rpy="3.14159 3.75396e-16 -2.61799"/>
      <geometry>
        <mesh filename="package://hexapod_description/meshes/servo_wheel.stl"/>
      </geometry>
      <material name="servo_wheel_21_material">
        <color rgba="0.647059 0.647059 0.647059 1"/>
      </material>
    </visual>
    <collision>
      <origin xyz="1.11022e-16 0 -0.0025" rpy="3.14159 3.75396e-16 -2.61799"/>
      <geometry>
        <mesh filename="package://hexapod_description/meshes/servo_wheel.stl"/>
      </geometry>
    </collision>
    <!-- Part servo_11 -->
    <visual>
      <origin xyz="0.0144532 0.00996626 -0.0305" rpy="3.14159 8.39626e-17 -2.61799"/>
      <geometry>
        <mesh filename="package://hexapod_description/meshes/servo.stl"/>
      </geometry>
      <material name="servo_11_material">
        <color rgba="0.109804 0.109804 0.105882 1"/>
      </material>
    </visual>
    <collision>
      <origin xyz="0.0144532 0.00996626 -0.0305" rpy="3.14159 8.39626e-17 -2.61799"/>
      <geometry>
        <mesh filename="package://hexapod_description/meshes/servo.stl"/>
      </geometry>
    </collision>
    <!-- Part fixed_bracket_11 -->
    <visual>
      <origin xyz="0.0497965 0.02875 -0.0305" rpy="-2.0944 1.5708 0"/>
      <geometry>
        <mesh filename="package://hexapod_description/meshes/fixed_bracket.stl"/>
      </geometry>
      <material name="fixed_bracket_11_material">
        <color rgba="0.647059 0.647059 0.647059 1"/>
      </material>
    </visual>
    <collision>
      <origin xyz="0.0497965 0.02875 -0.0305" rpy="-2.0944 1.5708 0"/>
      <geometry>
        <mesh filename="package://hexapod_description/meshes/fixed_bracket.stl"/>
      </geometry>
    </collision>
    <!-- Part servo_wheel_22 -->
    <visual>
      <origin xyz="1.11022e-16 5.55112e-17 -0.0585" rpy="-3.14159 3.0015e-16 -2.61799"/>
      <geometry>
        <mesh filename="package://hexapod_description/meshes/servo_wheel.stl"/>
      </geometry>
      <material name="servo_wheel_22_material">
        <color rgba="0.647059 0.647059 0.647059 1"/>
      </material>
    </visual>
    <collision>
      <origin xyz="1.11022e-16 5.55112e-17 -0.0585" rpy="-3.14159 3.0015e-16 -2.61799"/>
      <geometry>
        <mesh filename="package://hexapod_description/meshes/servo_wheel.stl"/>
      </geometry>
    </collision>
  </link>
  <!-- Link foot_assembly_4 -->
  <link name="foot_assembly_4">
    <inertial>
      <origin xyz="-0.0724503 -0.00208415 -0.0306672" rpy="0 0 0"/>
      <mass value="0.633745"/>
      <inertia ixx="0.000268495" ixy="-1.4806e-05" ixz="4.28294e-06" iyy="0.00320961" iyz="-2.30165e-07" izz="0.00304658"/>
    </inertial>
    <!-- Part foot_4 -->
    <visual>
      <origin xyz="-0.04425 -2.22045e-16 -0.0305" rpy="2.35311e-16 1.5708 0"/>
      <geometry>
        <mesh filename="package://hexapod_description/meshes/foot.stl"/>
      </geometry>
      <material name="foot_4_material">
        <color rgba="0.282353 0.54902 0.160784 1"/>
      </material>
    </visual>
    <collision>
      <origin xyz="-0.04425 -2.22045e-16 -0.0305" rpy="2.35311e-16 1.5708 0"/>
      <geometry>
        <mesh filename="package://hexapod_description/meshes/foot.stl"/>
      </geometry>
    </collision>
    <!-- Part ir_sensor_cap_4 -->
    <visual>
      <origin xyz="-0.04425 -2.22045e-16 -0.0305" rpy="1.70464e-15 1.5708 0"/>
      <geometry>
        <mesh filename="package://hexapod_description/meshes/ir_sensor_cap.stl"/>
      </geometry>
      <material name="ir_sensor_cap_4_material">
        <color rgba="0.282353 0.54902 0.160784 1"/>
      </material>
    </visual>
    <collision>
      <origin xyz="-0.04425 -2.22045e-16 -0.0305" rpy="1.70464e-15 1.5708 0"/>
      <geometry>
        <mesh filename="package://hexapod_description/meshes/ir_sensor_cap.stl"/>
      </geometry>
    </collision>
    <!-- Part rubber_foot_4 -->
    <visual>
      <origin xyz="-0.04375 2.22045e-16 -0.03" rpy="-1.66075e-15 1.5708 0"/>
      <geometry>
        <mesh filename="package://hexapod_description/meshes/rubber_foot.stl"/>
      </geometry>
      <material name="rubber_foot_4_material">
        <color rgba="0.262745 0.282353 0.301961 1"/>
      </material>
    </visual>
    <collision>
      <origin xyz="-0.04375 2.22045e-16 -0.03" rpy="-1.66075e-15 1.5708 0"/>
      <geometry>
        <mesh filename="package://hexapod_description/meshes/rubber_foot.stl"/>
      </geometry>
    </collision>
    <!-- Part servo_wheel_23 -->
    <visual>
      <origin xyz="0 0 -0.0025" rpy="3.14159 1.96172e-18 -1.09463e-16"/>
      <geometry>
        <mesh filename="package://hexapod_description/meshes/servo_wheel.stl"/>
      </geometry>
      <material name="servo_wheel_23_material">
        <color rgba="0.647059 0.647059 0.647059 1"/>
      </material>
    </visual>
    <collision>
      <origin xyz="0 0 -0.0025" rpy="3.14159 1.96172e-18 -1.09463e-16"/>
      <geometry>
        <mesh filename="package://hexapod_description/meshes/servo_wheel.stl"/>
      </geometry>
    </collision>
    <!-- Part servo_12 -->
    <visual>
      <origin xyz="-0.0175 -0.00140442 -0.0305" rpy="3.14159 -1.32307e-14 -2.40379e-16"/>
      <geometry>
        <mesh filename="package://hexapod_description/meshes/servo.stl"/>
      </geometry>
      <material name="servo_12_material">
        <color rgba="0.109804 0.109804 0.105882 1"/>
      </material>
    </visual>
    <collision>
      <origin xyz="-0.0175 -0.00140442 -0.0305" rpy="3.14159 -1.32307e-14 -2.40379e-16"/>
      <geometry>
        <mesh filename="package://hexapod_description/meshes/servo.stl"/>
      </geometry>
    </collision>
    <!-- Part fixed_bracket_12 -->
    <visual>
      <origin xyz="-0.0575 -2.22045e-16 -0.0305" rpy="1.5708 1.5708 0"/>
      <geometry>
        <mesh filename="package://hexapod_description/meshes/fixed_bracket.stl"/>
      </geometry>
      <material name="fixed_bracket_12_material">
        <color rgba="0.647059 0.647059 0.647059 1"/>
      </material>
    </visual>
    <collision>
      <origin xyz="-0.0575 -2.22045e-16 -0.0305" rpy="1.5708 1.5708 0"/>
      <geometry>
        <mesh filename="package://hexapod_description/meshes/fixed_bracket.stl"/>
      </geometry>
    </collision>
    <!-- Part servo_wheel_24 -->
    <visual>
      <origin xyz="-8.32667e-17 -2.22045e-16 -0.0585" rpy="3.14159 -1.32362e-14 -1.3225e-16"/>
      <geometry>
        <mesh filename="package://hexapod_description/meshes/servo_wheel.stl"/>
      </geometry>
      <material name="servo_wheel_24_material">
        <color rgba="0.647059 0.647059 0.647059 1"/>
      </material>
    </visual>
    <collision>
      <origin xyz="-8.32667e-17 -2.22045e-16 -0.0585" rpy="3.14159 -1.32362e-14 -1.3225e-16"/>
      <geometry>
        <mesh filename="package://hexapod_description/meshes/servo_wheel.stl"/>
      </geometry>
    </collision>
  </link>
  <!-- Joint from ties_assembly_4 to foot_assembly_4 -->
  <joint name="foot_4" type="revolute">
    <origin xyz="0.165999 0.0960821 -0.000790548" rpy="-6.20588e-15 -8.9332e-15 1.91986"/>
    <parent link="ties_assembly_4"/>
    <child link="foot_assembly_4"/>
    <axis xyz="0 0 1"/>
    <limit effort="10" velocity="10" lower="-0.349066" upper="3.83972"/>
  </joint>
  <!-- Joint from hip_assembly_4 to ties_assembly_4 -->
  <joint name="ties_4" type="revolute">
    <origin xyz="-0.0925 0.0311167 -0.0305" rpy="1.5708 -3.33266e-16 -3.14159"/>
    <parent link="hip_assembly_4"/>
    <child link="ties_assembly_4"/>
    <axis xyz="0 0 1"/>
    <limit effort="10" velocity="10" lower="-2.26893" upper="1.22173"/>
  </joint>
  <!-- Joint from base_link to hip_assembly_4 -->
  <joint name="hip_4" type="revolute">
    <origin xyz="-0.601244 -0.662156 0.387526" rpy="-4.00013e-14 -3.73115e-14 1.48353"/>
    <parent link="base_link"/>
    <child link="hip_assembly_4"/>
    <axis xyz="0 0 1"/>
    <limit effort="10" velocity="10" lower="-1.5708" upper="1.5708"/>
  </joint>
  <!-- Link hip_assembly_5 -->
  <link name="hip_assembly_5">
    <inertial>
      <origin xyz="0.0268487 0.000325484 -0.0302141" rpy="0 0 0"/>
      <mass value="0.365356"/>
      <inertia ixx="0.000168136" ixy="-2.8417e-07" ixz="-3.2467e-06" iyy="0.000312332" iyz="9.42575e-07" izz="0.000312341"/>
    </inertial>
    <!-- Part hip_5 -->
    <visual>
      <origin xyz="0.0575 0.0005 -0.0045" rpy="-4.00617e-16 4.99454e-16 -3.14159"/>
      <geometry>
        <mesh filename="package://hexapod_description/meshes/hip.stl"/>
      </geometry>
      <material name="hip_5_material">
        <color rgba="0.282353 0.54902 0.160784 1"/>
      </material>
    </visual>
    <collision>
      <origin xyz="0.0575 0.0005 -0.0045" rpy="-4.00617e-16 4.99454e-16 -3.14159"/>
      <geometry>
        <mesh filename="package://hexapod_description/meshes/hip.stl"/>
      </geometry>
    </collision>
    <!-- Part mobile_bracket_15 -->
    <visual>
      <origin xyz="0.0575 1.11022e-16 -0.0305" rpy="7.65103e-16 2.54331e-16 -1.5708"/>
      <geometry>
        <mesh filename="package://hexapod_description/meshes/mobile_bracket.stl"/>
      </geometry>
      <material name="mobile_bracket_15_material">
        <color rgba="0.647059 0.647059 0.647059 1"/>
      </material>
    </visual>
    <collision>
      <origin xyz="0.0575 1.11022e-16 -0.0305" rpy="7.65103e-16 2.54331e-16 -1.5708"/>
      <geometry>
        <mesh filename="package://hexapod_description/meshes/mobile_bracket.stl"/>
      </geometry>
    </collision>
    <!-- Part servo_wheel_25 -->
    <visual>
      <origin xyz="0 2.22045e-16 -0.0025" rpy="-3.14159 5.59458e-14 -3.14159"/>
      <geometry>
        <mesh filename="package://hexapod_description/meshes/servo_wheel.stl"/>
      </geometry>
      <material name="servo_wheel_25_material">
        <color rgba="0.647059 0.647059 0.647059 1"/>
      </material>
    </visual>
    <collision>
      <origin xyz="0 2.22045e-16 -0.0025" rpy="-3.14159 5.59458e-14 -3.14159"/>
      <geometry>
        <mesh filename="package://hexapod_description/meshes/servo_wheel.stl"/>
      </geometry>
    </collision>
    <!-- Part servo_13 -->
    <visual>
      <origin xyz="0.0175 0.00140442 -0.0305" rpy="-3.14159 5.75594e-14 -3.14159"/>
      <geometry>
        <mesh filename="package://hexapod_description/meshes/servo.stl"/>
      </geometry>
      <material name="servo_13_material">
        <color rgba="0.109804 0.109804 0.105882 1"/>
      </material>
    </visual>
    <collision>
      <origin xyz="0.0175 0.00140442 -0.0305" rpy="-3.14159 5.75594e-14 -3.14159"/>
      <geometry>
        <mesh filename="package://hexapod_description/meshes/servo.stl"/>
      </geometry>
    </collision>
    <!-- Part fixed_bracket_13 -->
    <visual>
      <origin xyz="0.0575 1.11022e-16 -0.0305" rpy="-1.5708 1.5708 0"/>
      <geometry>
        <mesh filename="package://hexapod_description/meshes/fixed_bracket.stl"/>
      </geometry>
      <material name="fixed_bracket_13_material">
        <color rgba="0.647059 0.647059 0.647059 1"/>
      </material>
    </visual>
    <collision>
      <origin xyz="0.0575 1.11022e-16 -0.0305" rpy="-1.5708 1.5708 0"/>
      <geometry>
        <mesh filename="package://hexapod_description/meshes/fixed_bracket.stl"/>
      </geometry>
    </collision>
    <!-- Part servo_wheel_26 -->
    <visual>
      <origin xyz="2.08167e-17 3.33067e-16 -0.0585" rpy="3.14159 5.36659e-16 -3.14159"/>
      <geometry>
        <mesh filename="package://hexapod_description/meshes/servo_wheel.stl"/>
      </geometry>
      <material name="servo_wheel_26_material">
        <color rgba="0.647059 0.647059 0.647059 1"/>
      </material>
    </visual>
    <collision>
      <origin xyz="2.08167e-17 3.33067e-16 -0.0585" rpy="3.14159 5.36659e-16 -3.14159"/>
      <geometry>
        <mesh filename="package://hexapod_description/meshes/servo_wheel.stl"/>
      </geometry>
    </collision>
  </link>
  <!-- Link ties_assembly_5 -->
  <link name="ties_assembly_5">
    <inertial>
      <origin xyz="0.0549718 0.0335057 -0.0309357" rpy="0 0 0"/>
      <mass value="0.589115"/>
      <inertia ixx="0.000782879" ixy="-0.000776998" ixz="9.2367e-06" iyy="0.00162431" iyz="5.57469e-06" izz="0.00187002"/>
    </inertial>
    <!-- Part mobile_bracket_16 -->
    <visual>
      <origin xyz="0.135688 0.0785821 -0.0311738" rpy="1.0472 1.5708 0"/>
      <geometry>
        <mesh filename="package://hexapod_description/meshes/mobile_bracket.stl"/>
      </geometry>
      <material name="mobile_bracket_16_material">
        <color rgba="0.647059 0.647059 0.647059 1"/>
      </material>
    </visual>
    <collision>
      <origin xyz="0.135688 0.0785821 -0.0311738" rpy="1.0472 1.5708 0"/>
      <geometry>
        <mesh filename="package://hexapod_description/meshes/mobile_bracket.stl"/>
      </geometry>
    </collision>
    <!-- Part low_tie_5 -->
    <visual>
      <origin xyz="0.0231043 0.0135821 -0.0311738" rpy="-0.523599 1.5708 0"/>
      <geometry>
        <mesh filename="package://hexapod_description/meshes/low_tie.stl"/>
      </geometry>
      <material name="low_tie_5_material">
        <color rgba="0.282353 0.54902 0.160784 1"/>
      </material>
    </visual>
    <collision>
      <origin xyz="0.0231043 0.0135821 -0.0311738" rpy="-0.523599 1.5708 0"/>
      <geometry>
        <mesh filename="package://hexapod_description/meshes/low_tie.stl"/>
      </geometry>
    </collision>
    <!-- Part top_tie_5 -->
    <visual>
      <origin xyz="0.0238157 0.01375 -0.0305" rpy="-0.523599 1.5708 0"/>
      <geometry>
        <mesh filename="package://hexapod_description/meshes/top_tie.stl"/>
      </geometry>
      <material name="top_tie_5_material">
        <color rgba="0.282353 0.54902 0.160784 1"/>
      </material>
    </visual>
    <collision>
      <origin xyz="0.0238157 0.01375 -0.0305" rpy="-0.523599 1.5708 0"/>
      <geometry>
        <mesh filename="package://hexapod_description/meshes/top_tie.stl"/>
      </geometry>
    </collision>
    <!-- Part servo_wheel_27 -->
    <visual>
      <origin xyz="9.71445e-17 0 -0.0025" rpy="3.14159 -8.86587e-16 -2.61799"/>
      <geometry>
        <mesh filename="package://hexapod_description/meshes/servo_wheel.stl"/>
      </geometry>
      <material name="servo_wheel_27_material">
        <color rgba="0.647059 0.647059 0.647059 1"/>
      </material>
    </visual>
    <collision>
      <origin xyz="9.71445e-17 0 -0.0025" rpy="3.14159 -8.86587e-16 -2.61799"/>
      <geometry>
        <mesh filename="package://hexapod_description/meshes/servo_wheel.stl"/>
      </geometry>
    </collision>
    <!-- Part servo_14 -->
    <visual>
      <origin xyz="0.0144532 0.00996626 -0.0305" rpy="-3.14159 3.71966e-14 -2.61799"/>
      <geometry>
        <mesh filename="package://hexapod_description/meshes/servo.stl"/>
      </geometry>
      <material name="servo_14_material">
        <color rgba="0.109804 0.109804 0.105882 1"/>
      </material>
    </visual>
    <collision>
      <origin xyz="0.0144532 0.00996626 -0.0305" rpy="-3.14159 3.71966e-14 -2.61799"/>
      <geometry>
        <mesh filename="package://hexapod_description/meshes/servo.stl"/>
      </geometry>
    </collision>
    <!-- Part fixed_bracket_14 -->
    <visual>
      <origin xyz="0.0497965 0.02875 -0.0305" rpy="-2.0944 1.5708 0"/>
      <geometry>
        <mesh filename="package://hexapod_description/meshes/fixed_bracket.stl"/>
      </geometry>
      <material name="fixed_bracket_14_material">
        <color rgba="0.647059 0.647059 0.647059 1"/>
      </material>
    </visual>
    <collision>
      <origin xyz="0.0497965 0.02875 -0.0305" rpy="-2.0944 1.5708 0"/>
      <geometry>
        <mesh filename="package://hexapod_description/meshes/fixed_bracket.stl"/>
      </geometry>
    </collision>
    <!-- Part servo_wheel_28 -->
    <visual>
      <origin xyz="1.17961e-16 5.55112e-17 -0.0585" rpy="3.14159 -1.05312e-15 -2.61799"/>
      <geometry>
        <mesh filename="package://hexapod_description/meshes/servo_wheel.stl"/>
      </geometry>
      <material name="servo_wheel_28_material">
        <color rgba="0.647059 0.647059 0.647059 1"/>
      </material>
    </visual>
    <collision>
      <origin xyz="1.17961e-16 5.55112e-17 -0.0585" rpy="3.14159 -1.05312e-15 -2.61799"/>
      <geometry>
        <mesh filename="package://hexapod_description/meshes/servo_wheel.stl"/>
      </geometry>
    </collision>
  </link>
  <!-- Link foot_assembly_5 -->
  <link name="foot_assembly_5">
    <inertial>
      <origin xyz="-0.0724503 -0.00208415 -0.0306672" rpy="0 0 0"/>
      <mass value="0.633745"/>
      <inertia ixx="0.000268495" ixy="-1.4806e-05" ixz="4.28294e-06" iyy="0.00320961" iyz="-2.30165e-07" izz="0.00304658"/>
    </inertial>
    <!-- Part foot_5 -->
    <visual>
      <origin xyz="-0.04425 -1.11022e-16 -0.0305" rpy="-1.66181e-16 1.5708 0"/>
      <geometry>
        <mesh filename="package://hexapod_description/meshes/foot.stl"/>
      </geometry>
      <material name="foot_5_material">
        <color rgba="0.282353 0.54902 0.160784 1"/>
      </material>
    </visual>
    <collision>
      <origin xyz="-0.04425 -1.11022e-16 -0.0305" rpy="-1.66181e-16 1.5708 0"/>
      <geometry>
        <mesh filename="package://hexapod_description/meshes/foot.stl"/>
      </geometry>
    </collision>
    <!-- Part ir_sensor_cap_5 -->
    <visual>
      <origin xyz="-0.04425 5.66214e-15 -0.0305" rpy="-3.2437e-14 1.5708 0"/>
      <geometry>
        <mesh filename="package://hexapod_description/meshes/ir_sensor_cap.stl"/>
      </geometry>
      <material name="ir_sensor_cap_5_material">
        <color rgba="0.282353 0.54902 0.160784 1"/>
      </material>
    </visual>
    <collision>
      <origin xyz="-0.04425 5.66214e-15 -0.0305" rpy="-3.2437e-14 1.5708 0"/>
      <geometry>
        <mesh filename="package://hexapod_description/meshes/ir_sensor_cap.stl"/>
      </geometry>
    </collision>
    <!-- Part rubber_foot_5 -->
    <visual>
      <origin xyz="-0.04375 6.88338e-15 -0.03" rpy="-3.29921e-14 1.5708 0"/>
      <geometry>
        <mesh filename="package://hexapod_description/meshes/rubber_foot.stl"/>
      </geometry>
      <material name="rubber_foot_5_material">
        <color rgba="0.262745 0.282353 0.301961 1"/>
      </material>
    </visual>
    <collision>
      <origin xyz="-0.04375 6.88338e-15 -0.03" rpy="-3.29921e-14 1.5708 0"/>
      <geometry>
        <mesh filename="package://hexapod_description/meshes/rubber_foot.stl"/>
      </geometry>
    </collision>
    <!-- Part servo_wheel_29 -->
    <visual>
      <origin xyz="0 0 -0.0025" rpy="-3.14159 1.89118e-17 1.01272e-16"/>
      <geometry>
        <mesh filename="package://hexapod_description/meshes/servo_wheel.stl"/>
      </geometry>
      <material name="servo_wheel_29_material">
        <color rgba="0.647059 0.647059 0.647059 1"/>
      </material>
    </visual>
    <collision>
      <origin xyz="0 0 -0.0025" rpy="-3.14159 1.89118e-17 1.01272e-16"/>
      <geometry>
        <mesh filename="package://hexapod_description/meshes/servo_wheel.stl"/>
      </geometry>
    </collision>
    <!-- Part servo_15 -->
    <visual>
      <origin xyz="-0.0175 -0.00140442 -0.0305" rpy="-3.14159 6.94034e-17 1.59676e-16"/>
      <geometry>
        <mesh filename="package://hexapod_description/meshes/servo.stl"/>
      </geometry>
      <material name="servo_15_material">
        <color rgba="0.109804 0.109804 0.105882 1"/>
      </material>
    </visual>
    <collision>
      <origin xyz="-0.0175 -0.00140442 -0.0305" rpy="-3.14159 6.94034e-17 1.59676e-16"/>
      <geometry>
        <mesh filename="package://hexapod_description/meshes/servo.stl"/>
      </geometry>
    </collision>
    <!-- Part fixed_bracket_15 -->
    <visual>
      <origin xyz="-0.0575 -5.55112e-17 -0.0305" rpy="1.5708 1.5708 0"/>
      <geometry>
        <mesh filename="package://hexapod_description/meshes/fixed_bracket.stl"/>
      </geometry>
      <material name="fixed_bracket_15_material">
        <color rgba="0.647059 0.647059 0.647059 1"/>
      </material>
    </visual>
    <collision>
      <origin xyz="-0.0575 -5.55112e-17 -0.0305" rpy="1.5708 1.5708 0"/>
      <geometry>
        <mesh filename="package://hexapod_description/meshes/fixed_bracket.stl"/>
      </geometry>
    </collision>
    <!-- Part servo_wheel_30 -->
    <visual>
      <origin xyz="0 -5.55112e-17 -0.0585" rpy="-3.14159 -3.40141e-16 -3.13705e-16"/>
      <geometry>
        <mesh filename="package://hexapod_description/meshes/servo_wheel.stl"/>
      </geometry>
      <material name="servo_wheel_30_material">
        <color rgba="0.647059 0.647059 0.647059 1"/>
      </material>
    </visual>
    <collision>
      <origin xyz="0 -5.55112e-17 -0.0585" rpy="-3.14159 -3.40141e-16 -3.13705e-16"/>
      <geometry>
        <mesh filename="package://hexapod_description/meshes/servo_wheel.stl"/>
      </geometry>
    </collision>
  </link>
  <!-- Joint from ties_assembly_5 to foot_assembly_5 -->
  <joint name="foot_5" type="revolute">
    <origin xyz="0.165999 0.0960821 -0.000790548" rpy="1.02679e-15 1.24004e-16 1.91986"/>
    <parent link="ties_assembly_5"/>
    <child link="foot_assembly_5"/>
    <axis xyz="0 0 1"/>
    <limit effort="10" velocity="10" lower="-0.349066" upper="3.83972"/>
  </joint>
  <!-- Joint from hip_assembly_5 to ties_assembly_5 -->
  <joint name="ties_5" type="revolute">
    <origin xyz="0.0925 -0.0311167 -0.0305" rpy="1.5708 -7.65103e-16 -1.70903e-16"/>
    <parent link="hip_assembly_5"/>
    <child link="ties_assembly_5"/>
    <axis xyz="0 0 1"/>
    <limit effort="10" velocity="10" lower="-2.26893" upper="1.22173"/>
  </joint>
  <!-- Joint from base_link to hip_assembly_5 -->
  <joint name="hip_5" type="revolute">
    <origin xyz="-0.458237 -0.595471 0.387526" rpy="5.12814e-14 -1.59069e-14 -0.610865"/>
    <parent link="base_link"/>
    <child link="hip_assembly_5"/>
    <axis xyz="0 0 1"/>
    <limit effort="10" velocity="10" lower="-1.5708" upper="1.5708"/>
  </joint>
  <!-- Link hip_assembly_6 -->
  <link name="hip_assembly_6">
    <inertial>
      <origin xyz="-0.0268487 -0.000325484 -0.0302141" rpy="0 0 0"/>
      <mass value="0.365356"/>
      <inertia ixx="0.000168136" ixy="-2.8417e-07" ixz="3.2467e-06" iyy="0.000312332" iyz="-9.42575e-07" izz="0.000312341"/>
    </inertial>
    <!-- Part hip_6 -->
    <visual>
      <origin xyz="-0.0575 -0.0005 -0.0045" rpy="8.33396e-16 -1.4225e-15 5.68213e-16"/>
      <geometry>
        <mesh filename="package://hexapod_description/meshes/hip.stl"/>
      </geometry>
      <material name="hip_6_material">
        <color rgba="0.282353 0.54902 0.160784 1"/>
      </material>
    </visual>
    <collision>
      <origin xyz="-0.0575 -0.0005 -0.0045" rpy="8.33396e-16 -1.4225e-15 5.68213e-16"/>
      <geometry>
        <mesh filename="package://hexapod_description/meshes/hip.stl"/>
      </geometry>
    </collision>
    <!-- Part mobile_bracket_17 -->
    <visual>
      <origin xyz="-0.0575 1.11022e-16 -0.0305" rpy="-1.35775e-15 -1.36122e-15 1.5708"/>
      <geometry>
        <mesh filename="package://hexapod_description/meshes/mobile_bracket.stl"/>
      </geometry>
      <material name="mobile_bracket_17_material">
        <color rgba="0.647059 0.647059 0.647059 1"/>
      </material>
    </visual>
    <collision>
      <origin xyz="-0.0575 1.11022e-16 -0.0305" rpy="-1.35775e-15 -1.36122e-15 1.5708"/>
      <geometry>
        <mesh filename="package://hexapod_description/meshes/mobile_bracket.stl"/>
      </geometry>
    </collision>
    <!-- Part servo_wheel_31 -->
    <visual>
      <origin xyz="0 0 -0.0025" rpy="3.14159 -1.53074e-30 -4.69946e-17"/>
      <geometry>
        <mesh filename="package://hexapod_description/meshes/servo_wheel.stl"/>
      </geometry>
      <material name="servo_wheel_31_material">
        <color rgba="0.647059 0.647059 0.647059 1"/>
      </material>
    </visual>
    <collision>
      <origin xyz="0 0 -0.0025" rpy="3.14159 -1.53074e-30 -4.69946e-17"/>
      <geometry>
        <mesh filename="package://hexapod_description/meshes/servo_wheel.stl"/>
      </geometry>
    </collision>
    <!-- Part servo_16 -->
    <visual>
      <origin xyz="-0.0175 -0.00140442 -0.0305" rpy="-3.14159 -2.75961e-16 4.472e-16"/>
      <geometry>
        <mesh filename="package://hexapod_description/meshes/servo.stl"/>
      </geometry>
      <material name="servo_16_material">
        <color rgba="0.109804 0.109804 0.105882 1"/>
      </material>
    </visual>
    <collision>
      <origin xyz="-0.0175 -0.00140442 -0.0305" rpy="-3.14159 -2.75961e-16 4.472e-16"/>
      <geometry>
        <mesh filename="package://hexapod_description/meshes/servo.stl"/>
      </geometry>
    </collision>
    <!-- Part fixed_bracket_16 -->
    <visual>
      <origin xyz="-0.0575 2.77556e-17 -0.0305" rpy="1.5708 1.5708 0"/>
      <geometry>
        <mesh filename="package://hexapod_description/meshes/fixed_bracket.stl"/>
      </geometry>
      <material name="fixed_bracket_16_material">
        <color rgba="0.647059 0.647059 0.647059 1"/>
      </material>
    </visual>
    <collision>
      <origin xyz="-0.0575 2.77556e-17 -0.0305" rpy="1.5708 1.5708 0"/>
      <geometry>
        <mesh filename="package://hexapod_description/meshes/fixed_bracket.stl"/>
      </geometry>
    </collision>
    <!-- Part servo_wheel_32 -->
    <visual>
      <origin xyz="0 0 -0.0585" rpy="-3.14159 -3.43781e-16 -6.21211e-16"/>
      <geometry>
        <mesh filename="package://hexapod_description/meshes/servo_wheel.stl"/>
      </geometry>
      <material name="servo_wheel_32_material">
        <color rgba="0.647059 0.647059 0.647059 1"/>
      </material>
    </visual>
    <collision>
      <origin xyz="0 0 -0.0585" rpy="-3.14159 -3.43781e-16 -6.21211e-16"/>
      <geometry>
        <mesh filename="package://hexapod_description/meshes/servo_wheel.stl"/>
      </geometry>
    </collision>
  </link>
  <!-- Link ties_assembly_6 -->
  <link name="ties_assembly_6">
    <inertial>
      <origin xyz="0.0549718 0.0335057 -0.0309357" rpy="0 0 0"/>
      <mass value="0.589115"/>
      <inertia ixx="0.000782879" ixy="-0.000776998" ixz="9.2367e-06" iyy="0.00162431" iyz="5.57469e-06" izz="0.00187002"/>
    </inertial>
    <!-- Part mobile_bracket_18 -->
    <visual>
      <origin xyz="0.135688 0.0785821 -0.0311738" rpy="1.0472 1.5708 0"/>
      <geometry>
        <mesh filename="package://hexapod_description/meshes/mobile_bracket.stl"/>
      </geometry>
      <material name="mobile_bracket_18_material">
        <color rgba="0.647059 0.647059 0.647059 1"/>
      </material>
    </visual>
    <collision>
      <origin xyz="0.135688 0.0785821 -0.0311738" rpy="1.0472 1.5708 0"/>
      <geometry>
        <mesh filename="package://hexapod_description/meshes/mobile_bracket.stl"/>
      </geometry>
    </collision>
    <!-- Part low_tie_6 -->
    <visual>
      <origin xyz="0.0231043 0.0135821 -0.0311738" rpy="-0.523599 1.5708 0"/>
      <geometry>
        <mesh filename="package://hexapod_description/meshes/low_tie.stl"/>
      </geometry>
      <material name="low_tie_6_material">
        <color rgba="0.282353 0.54902 0.160784 1"/>
      </material>
    </visual>
    <collision>
      <origin xyz="0.0231043 0.0135821 -0.0311738" rpy="-0.523599 1.5708 0"/>
      <geometry>
        <mesh filename="package://hexapod_description/meshes/low_tie.stl"/>
      </geometry>
    </collision>
    <!-- Part top_tie_6 -->
    <visual>
      <origin xyz="0.0238157 0.01375 -0.0305" rpy="-0.523599 1.5708 0"/>
      <geometry>
        <mesh filename="package://hexapod_description/meshes/top_tie.stl"/>
      </geometry>
      <material name="top_tie_6_material">
        <color rgba="0.282353 0.54902 0.160784 1"/>
      </material>
    </visual>
    <collision>
      <origin xyz="0.0238157 0.01375 -0.0305" rpy="-0.523599 1.5708 0"/>
      <geometry>
        <mesh filename="package://hexapod_description/meshes/top_tie.stl"/>
      </geometry>
    </collision>
    <!-- Part servo_wheel_33 -->
    <visual>
      <origin xyz="2.77556e-16 0 -0.0025" rpy="3.14159 1.77948e-15 -2.61799"/>
      <geometry>
        <mesh filename="package://hexapod_description/meshes/servo_wheel.stl"/>
      </geometry>
      <material name="servo_wheel_33_material">
        <color rgba="0.647059 0.647059 0.647059 1"/>
      </material>
    </visual>
    <collision>
      <origin xyz="2.77556e-16 0 -0.0025" rpy="3.14159 1.77948e-15 -2.61799"/>
      <geometry>
        <mesh filename="package://hexapod_description/meshes/servo_wheel.stl"/>
      </geometry>
    </collision>
    <!-- Part servo_17 -->
    <visual>
      <origin xyz="0.0144532 0.00996626 -0.0305" rpy="3.14159 3.72592e-16 -2.61799"/>
      <geometry>
        <mesh filename="package://hexapod_description/meshes/servo.stl"/>
      </geometry>
      <material name="servo_17_material">
        <color rgba="0.109804 0.109804 0.105882 1"/>
      </material>
    </visual>
    <collision>
      <origin xyz="0.0144532 0.00996626 -0.0305" rpy="3.14159 3.72592e-16 -2.61799"/>
      <geometry>
        <mesh filename="package://hexapod_description/meshes/servo.stl"/>
      </geometry>
    </collision>
    <!-- Part fixed_bracket_17 -->
    <visual>
      <origin xyz="0.0497965 0.02875 -0.0305" rpy="-2.0944 1.5708 0"/>
      <geometry>
        <mesh filename="package://hexapod_description/meshes/fixed_bracket.stl"/>
      </geometry>
      <material name="fixed_bracket_17_material">
        <color rgba="0.647059 0.647059 0.647059 1"/>
      </material>
    </visual>
    <collision>
      <origin xyz="0.0497965 0.02875 -0.0305" rpy="-2.0944 1.5708 0"/>
      <geometry>
        <mesh filename="package://hexapod_description/meshes/fixed_bracket.stl"/>
      </geometry>
    </collision>
    <!-- Part servo_wheel_34 -->
    <visual>
      <origin xyz="3.88578e-16 -1.66533e-16 -0.0585" rpy="3.14159 1.92156e-16 -2.61799"/>
      <geometry>
        <mesh filename="package://hexapod_description/meshes/servo_wheel.stl"/>
      </geometry>
      <material name="servo_wheel_34_material">
        <color rgba="0.647059 0.647059 0.647059 1"/>
      </material>
    </visual>
    <collision>
      <origin xyz="3.88578e-16 -1.66533e-16 -0.0585" rpy="3.14159 1.92156e-16 -2.61799"/>
      <geometry>
        <mesh filename="package://hexapod_description/meshes/servo_wheel.stl"/>
      </geometry>
    </collision>
  </link>
  <!-- Link foot_assembly_6 -->
  <link name="foot_assembly_6">
    <inertial>
      <origin xyz="-0.0724503 -0.00208415 -0.0306672" rpy="0 0 0"/>
      <mass value="0.633745"/>
      <inertia ixx="0.000268495" ixy="-1.4806e-05" ixz="4.28294e-06" iyy="0.00320961" iyz="-2.30165e-07" izz="0.00304658"/>
    </inertial>
    <!-- Part foot_6 -->
    <visual>
      <origin xyz="-0.04425 -2.77556e-17 -0.0305" rpy="-4.38605e-17 1.5708 0"/>
      <geometry>
        <mesh filename="package://hexapod_description/meshes/foot.stl"/>
      </geometry>
      <material name="foot_6_material">
        <color rgba="0.282353 0.54902 0.160784 1"/>
      </material>
    </visual>
    <collision>
      <origin xyz="-0.04425 -2.77556e-17 -0.0305" rpy="-4.38605e-17 1.5708 0"/>
      <geometry>
        <mesh filename="package://hexapod_description/meshes/foot.stl"/>
      </geometry>
    </collision>
    <!-- Part ir_sensor_cap_6 -->
    <visual>
      <origin xyz="-0.04425 -1.94289e-16 -0.0305" rpy="5.17038e-16 1.5708 0"/>
      <geometry>
        <mesh filename="package://hexapod_description/meshes/ir_sensor_cap.stl"/>
      </geometry>
      <material name="ir_sensor_cap_6_material">
        <color rgba="0.282353 0.54902 0.160784 1"/>
      </material>
    </visual>
    <collision>
      <origin xyz="-0.04425 -1.94289e-16 -0.0305" rpy="5.17038e-16 1.5708 0"/>
      <geometry>
        <mesh filename="package://hexapod_description/meshes/ir_sensor_cap.stl"/>
      </geometry>
    </collision>
    <!-- Part rubber_foot_6 -->
    <visual>
      <origin xyz="-0.04375 -8.32667e-17 -0.03" rpy="1.16506e-17 1.5708 0"/>
      <geometry>
        <mesh filename="package://hexapod_description/meshes/rubber_foot.stl"/>
      </geometry>
      <material name="rubber_foot_6_material">
        <color rgba="0.262745 0.282353 0.301961 1"/>
      </material>
    </visual>
    <collision>
      <origin xyz="-0.04375 -8.32667e-17 -0.03" rpy="1.16506e-17 1.5708 0"/>
      <geometry>
        <mesh filename="package://hexapod_description/meshes/rubber_foot.stl"/>
      </geometry>
    </collision>
    <!-- Part servo_wheel_35 -->
    <visual>
      <origin xyz="-2.22045e-16 2.77556e-17 -0.0025" rpy="-3.14159 -1.58904e-18 2.75781e-17"/>
      <geometry>
        <mesh filename="package://hexapod_description/meshes/servo_wheel.stl"/>
      </geometry>
      <material name="servo_wheel_35_material">
        <color rgba="0.647059 0.647059 0.647059 1"/>
      </material>
    </visual>
    <collision>
      <origin xyz="-2.22045e-16 2.77556e-17 -0.0025" rpy="-3.14159 -1.58904e-18 2.75781e-17"/>
      <geometry>
        <mesh filename="package://hexapod_description/meshes/servo_wheel.stl"/>
      </geometry>
    </collision>
    <!-- Part servo_18 -->
    <visual>
      <origin xyz="-0.0175 -0.00140442 -0.0305" rpy="-3.14159 1.50175e-17 2.99536e-18"/>
      <geometry>
        <mesh filename="package://hexapod_description/meshes/servo.stl"/>
      </geometry>
      <material name="servo_18_material">
        <color rgba="0.109804 0.109804 0.105882 1"/>
      </material>
    </visual>
    <collision>
      <origin xyz="-0.0175 -0.00140442 -0.0305" rpy="-3.14159 1.50175e-17 2.99536e-18"/>
      <geometry>
        <mesh filename="package://hexapod_description/meshes/servo.stl"/>
      </geometry>
    </collision>
    <!-- Part fixed_bracket_18 -->
    <visual>
      <origin xyz="-0.0575 0 -0.0305" rpy="1.5708 1.5708 0"/>
      <geometry>
        <mesh filename="package://hexapod_description/meshes/fixed_bracket.stl"/>
      </geometry>
      <material name="fixed_bracket_18_material">
        <color rgba="0.647059 0.647059 0.647059 1"/>
      </material>
    </visual>
    <collision>
      <origin xyz="-0.0575 0 -0.0305" rpy="1.5708 1.5708 0"/>
      <geometry>
        <mesh filename="package://hexapod_description/meshes/fixed_bracket.stl"/>
      </geometry>
    </collision>
    <!-- Part servo_wheel_36 -->
    <visual>
      <origin xyz="6.66134e-16 2.77556e-17 -0.0585" rpy="-3.14159 -1.53385e-17 5.88864e-18"/>
      <geometry>
        <mesh filename="package://hexapod_description/meshes/servo_wheel.stl"/>
      </geometry>
      <material name="servo_wheel_36_material">
        <color rgba="0.647059 0.647059 0.647059 1"/>
      </material>
    </visual>
    <collision>
      <origin xyz="6.66134e-16 2.77556e-17 -0.0585" rpy="-3.14159 -1.53385e-17 5.88864e-18"/>
      <geometry>
        <mesh filename="package://hexapod_description/meshes/servo_wheel.stl"/>
      </geometry>
    </collision>
  </link>
  <!-- Joint from ties_assembly_6 to foot_assembly_6 -->
  <joint name="foot_6" type="revolute">
    <origin xyz="0.165999 0.0960821 -0.000790548" rpy="-5.03397e-15 -1.50916e-14 1.91986"/>
    <parent link="ties_assembly_6"/>
    <child link="foot_assembly_6"/>
    <axis xyz="0 0 1"/>
    <limit effort="10" velocity="10" lower="-0.349066" upper="3.83972"/>
  </joint>
  <!-- Joint from hip_assembly_6 to ties_assembly_6 -->
  <joint name="ties_6" type="revolute">
    <origin xyz="-0.0925 0.0311167 -0.0305" rpy="1.5708 1.35775e-15 3.14159"/>
    <parent link="hip_assembly_6"/>
    <child link="ties_assembly_6"/>
    <axis xyz="0 0 1"/>
    <limit effort="10" velocity="10" lower="-2.26893" upper="1.22173"/>
  </joint>
  <!-- Joint from base_link to hip_assembly_6 -->
  <joint name="hip_6" type="revolute">
    <origin xyz="-0.444485 -0.438281 0.386792" rpy="-1.15359e-14 5.31115e-14 -2.70526"/>
    <parent link="base_link"/>
    <child link="hip_assembly_6"/>
    <axis xyz="0 0 1"/>
    <limit effort="10" velocity="10" lower="-1.5708" upper="1.5708"/>
  </joint>
</robot>
