<?xml version="1.0" ?>
<!-- Generated using onshape-to-robot -->
<!-- Onshape https://cad.onshape.com/documents/026f9a33ba6a25a983a9d639/w/b83e0182bd0a887a03df3198/e/e49783848224d44e064e4a49 -->
<robot name="hexapod_description">
  <!-- Link base_link -->
  <link name="base_link">
    <inertial>
      <origin xyz="-0.616133 -0.357764 0.0379255" rpy="0 0 0"/>
      <mass value="2.24777"/>
      <inertia ixx="0.0169961" ixy="-3.37164e-05" ixz="7.57412e-05" iyy="0.0170029" iyz="0.000192289" izz="0.0239802"/>
    </inertial>
    <!-- Part mobile_bracket -->
    <visual>
      <origin xyz="-0.50963 -0.420853 0.039137" rpy="2.0944 1.5708 0"/>
      <geometry>
        <mesh filename="package://hexapod_description/meshes/mobile_bracket.stl"/>
      </geometry>
      <material name="mobile_bracket_material">
        <color rgba="0.647059 0.647059 0.647059 1"/>
      </material>
    </visual>
    <collision>
      <origin xyz="-0.50963 -0.420853 0.039137" rpy="2.0944 1.5708 0"/>
      <geometry>
        <mesh filename="package://hexapod_description/meshes/mobile_bracket.stl"/>
      </geometry>
    </collision>
    <!-- Part mobile_bracket_2 -->
    <visual>
      <origin xyz="-0.50963 -0.298063 0.039137" rpy="1.0472 1.5708 0"/>
      <geometry>
        <mesh filename="package://hexapod_description/meshes/mobile_bracket.stl"/>
      </geometry>
      <material name="mobile_bracket_2_material">
        <color rgba="0.647059 0.647059 0.647059 1"/>
      </material>
    </visual>
    <collision>
      <origin xyz="-0.50963 -0.298063 0.039137" rpy="1.0472 1.5708 0"/>
      <geometry>
        <mesh filename="package://hexapod_description/meshes/mobile_bracket.stl"/>
      </geometry>
    </collision>
    <!-- Part bottom_cover -->
    <visual>
      <origin xyz="-0.61597 -0.359458 0.00413695" rpy="3.14159 5.06521e-16 -2.0944"/>
      <geometry>
        <mesh filename="package://hexapod_description/meshes/bottom_cover.stl"/>
      </geometry>
      <material name="bottom_cover_material">
        <color rgba="0.196078 0.439216 0.0784314 1"/>
      </material>
    </visual>
    <collision>
      <origin xyz="-0.61597 -0.359458 0.00413695" rpy="3.14159 5.06521e-16 -2.0944"/>
      <geometry>
        <mesh filename="package://hexapod_description/meshes/bottom_cover.stl"/>
      </geometry>
    </collision>
    <!-- Part mobile_bracket_3 -->
    <visual>
      <origin xyz="-0.61597 -0.236668 0.039137" rpy="1.10589e-16 -1.5708 0"/>
      <geometry>
        <mesh filename="package://hexapod_description/meshes/mobile_bracket.stl"/>
      </geometry>
      <material name="mobile_bracket_3_material">
        <color rgba="0.647059 0.647059 0.647059 1"/>
      </material>
    </visual>
    <collision>
      <origin xyz="-0.61597 -0.236668 0.039137" rpy="1.10589e-16 -1.5708 0"/>
      <geometry>
        <mesh filename="package://hexapod_description/meshes/mobile_bracket.stl"/>
      </geometry>
    </collision>
    <!-- Part cover -->
    <visual>
      <origin xyz="-0.61597 -0.359458 0.074137" rpy="1.60678e-16 3.96758e-17 2.0944"/>
      <geometry>
        <mesh filename="package://hexapod_description/meshes/cover.stl"/>
      </geometry>
      <material name="cover_material">
        <color rgba="0.196078 0.439216 0.0784314 1"/>
      </material>
    </visual>
    <collision>
      <origin xyz="-0.61597 -0.359458 0.074137" rpy="1.60678e-16 3.96758e-17 2.0944"/>
      <geometry>
        <mesh filename="package://hexapod_description/meshes/cover.stl"/>
      </geometry>
    </collision>
    <!-- Part mobile_bracket_4 -->
    <visual>
      <origin xyz="-0.61597 -0.482249 0.039137" rpy="-3.14159 1.5708 0"/>
      <geometry>
        <mesh filename="package://hexapod_description/meshes/mobile_bracket.stl"/>
      </geometry>
      <material name="mobile_bracket_4_material">
        <color rgba="0.647059 0.647059 0.647059 1"/>
      </material>
    </visual>
    <collision>
      <origin xyz="-0.61597 -0.482249 0.039137" rpy="-3.14159 1.5708 0"/>
      <geometry>
        <mesh filename="package://hexapod_description/meshes/mobile_bracket.stl"/>
      </geometry>
    </collision>
    <!-- Part mobile_bracket_5 -->
    <visual>
      <origin xyz="-0.72231 -0.298063 0.039137" rpy="1.0472 -1.5708 0"/>
      <geometry>
        <mesh filename="package://hexapod_description/meshes/mobile_bracket.stl"/>
      </geometry>
      <material name="mobile_bracket_5_material">
        <color rgba="0.647059 0.647059 0.647059 1"/>
      </material>
    </visual>
    <collision>
      <origin xyz="-0.72231 -0.298063 0.039137" rpy="1.0472 -1.5708 0"/>
      <geometry>
        <mesh filename="package://hexapod_description/meshes/mobile_bracket.stl"/>
      </geometry>
    </collision>
    <!-- Part mobile_bracket_6 -->
    <visual>
      <origin xyz="-0.72231 -0.420853 0.039137" rpy="2.0944 -1.5708 0"/>
      <geometry>
        <mesh filename="package://hexapod_description/meshes/mobile_bracket.stl"/>
      </geometry>
      <material name="mobile_bracket_6_material">
        <color rgba="0.647059 0.647059 0.647059 1"/>
      </material>
    </visual>
    <collision>
      <origin xyz="-0.72231 -0.420853 0.039137" rpy="2.0944 -1.5708 0"/>
      <geometry>
        <mesh filename="package://hexapod_description/meshes/mobile_bracket.stl"/>
      </geometry>
    </collision>
    <!-- Part body -->
    <visual>
      <origin xyz="-0.61597 -0.359458 0.039137" rpy="3.14159 -4.30211e-16 2.61799"/>
      <geometry>
        <mesh filename="package://hexapod_description/meshes/body.stl"/>
      </geometry>
      <material name="body_material">
        <color rgba="0.196078 0.439216 0.0784314 1"/>
      </material>
    </visual>
    <collision>
      <origin xyz="-0.61597 -0.359458 0.039137" rpy="3.14159 -4.30211e-16 2.61799"/>
      <geometry>
        <mesh filename="package://hexapod_description/meshes/body.stl"/>
      </geometry>
    </collision>
  </link>
  <!-- Link hip_assembly -->
  <link name="hip_assembly">
    <inertial>
      <origin xyz="0.0265765 0.00382748 -0.0302141" rpy="0 0 0"/>
      <mass value="0.365356"/>
      <inertia ixx="0.000170666" ixy="-1.89365e-05" ixz="-3.34196e-06" iyy="0.000309802" iyz="5.10692e-07" izz="0.000312341"/>
    </inertial>
    <!-- Part hip -->
    <visual>
      <origin xyz="0.0569427 0.00800165 -0.0045" rpy="-1.88268e-16 -1.00764e-15 -3.01068"/>
      <geometry>
        <mesh filename="package://hexapod_description/meshes/hip.stl"/>
      </geometry>
      <material name="hip_material">
        <color rgba="0.196078 0.439216 0.0784314 1"/>
      </material>
    </visual>
    <collision>
      <origin xyz="0.0569427 0.00800165 -0.0045" rpy="-1.88268e-16 -1.00764e-15 -3.01068"/>
      <geometry>
        <mesh filename="package://hexapod_description/meshes/hip.stl"/>
      </geometry>
    </collision>
    <!-- Part mobile_bracket_7 -->
    <visual>
      <origin xyz="0.057008 0.00750593 -0.0305" rpy="-1.85393e-15 -1.54556e-15 -1.43988"/>
      <geometry>
        <mesh filename="package://hexapod_description/meshes/mobile_bracket.stl"/>
      </geometry>
      <material name="mobile_bracket_7_material">
        <color rgba="0.647059 0.647059 0.647059 1"/>
      </material>
    </visual>
    <collision>
      <origin xyz="0.057008 0.00750593 -0.0305" rpy="-1.85393e-15 -1.54556e-15 -1.43988"/>
      <geometry>
        <mesh filename="package://hexapod_description/meshes/mobile_bracket.stl"/>
      </geometry>
    </collision>
    <!-- Part servo_wheel -->
    <visual>
      <origin xyz="0 0 -0.0025" rpy="3.14159 -1.00764e-15 -3.01068"/>
      <geometry>
        <mesh filename="package://hexapod_description/meshes/servo_wheel.stl"/>
      </geometry>
      <material name="servo_wheel_material">
        <color rgba="0.647059 0.647059 0.647059 1"/>
      </material>
    </visual>
    <collision>
      <origin xyz="0 0 -0.0025" rpy="3.14159 -1.00764e-15 -3.01068"/>
      <geometry>
        <mesh filename="package://hexapod_description/meshes/servo_wheel.stl"/>
      </geometry>
    </collision>
    <!-- Part servo -->
    <visual>
      <origin xyz="0.0171669 0.00367682 -0.0305" rpy="3.14159 -1.00764e-15 -3.01068"/>
      <geometry>
        <mesh filename="package://hexapod_description/meshes/servo.stl"/>
      </geometry>
      <material name="servo_material">
        <color rgba="0.109804 0.109804 0.105882 1"/>
      </material>
    </visual>
    <collision>
      <origin xyz="0.0171669 0.00367682 -0.0305" rpy="3.14159 -1.00764e-15 -3.01068"/>
      <geometry>
        <mesh filename="package://hexapod_description/meshes/servo.stl"/>
      </geometry>
    </collision>
    <!-- Part fixed_bracket -->
    <visual>
      <origin xyz="0.057008 0.00750593 -0.0305" rpy="-1.70171 1.5708 0"/>
      <geometry>
        <mesh filename="package://hexapod_description/meshes/fixed_bracket.stl"/>
      </geometry>
      <material name="fixed_bracket_material">
        <color rgba="0.647059 0.647059 0.647059 1"/>
      </material>
    </visual>
    <collision>
      <origin xyz="0.057008 0.00750593 -0.0305" rpy="-1.70171 1.5708 0"/>
      <geometry>
        <mesh filename="package://hexapod_description/meshes/fixed_bracket.stl"/>
      </geometry>
    </collision>
    <!-- Part servo_wheel_2 -->
    <visual>
      <origin xyz="5.55112e-17 0 -0.0585" rpy="-3.14159 -9.23726e-16 -3.01068"/>
      <geometry>
        <mesh filename="package://hexapod_description/meshes/servo_wheel.stl"/>
      </geometry>
      <material name="servo_wheel_2_material">
        <color rgba="0.647059 0.647059 0.647059 1"/>
      </material>
    </visual>
    <collision>
      <origin xyz="5.55112e-17 0 -0.0585" rpy="-3.14159 -9.23726e-16 -3.01068"/>
      <geometry>
        <mesh filename="package://hexapod_description/meshes/servo_wheel.stl"/>
      </geometry>
    </collision>
  </link>
  <!-- Link ties_assembly -->
  <link name="ties_assembly">
    <inertial>
      <origin xyz="0.0375408 0.0522993 -0.0309357" rpy="0 0 0"/>
      <mass value="0.589115"/>
      <inertia ixx="0.00146927" ixy="-0.000842697" ixz="6.32936e-06" iyy="0.000937911" iyz="8.73687e-06" izz="0.00187002"/>
    </inertial>
    <!-- Part mobile_bracket_8 -->
    <visual>
      <origin xyz="0.0942703 0.125297 -0.0311738" rpy="0.64636 1.5708 0"/>
      <geometry>
        <mesh filename="package://hexapod_description/meshes/mobile_bracket.stl"/>
      </geometry>
      <material name="mobile_bracket_8_material">
        <color rgba="0.647059 0.647059 0.647059 1"/>
      </material>
    </visual>
    <collision>
      <origin xyz="0.0942703 0.125297 -0.0311738" rpy="0.64636 1.5708 0"/>
      <geometry>
        <mesh filename="package://hexapod_description/meshes/mobile_bracket.stl"/>
      </geometry>
    </collision>
    <!-- Part low_tie -->
    <visual>
      <origin xyz="0.0159733 0.0215206 -0.0311738" rpy="-0.924436 1.5708 0"/>
      <geometry>
        <mesh filename="package://hexapod_description/meshes/low_tie.stl"/>
      </geometry>
      <material name="low_tie_material">
        <color rgba="0.196078 0.439216 0.0784314 1"/>
      </material>
    </visual>
    <collision>
      <origin xyz="0.0159733 0.0215206 -0.0311738" rpy="-0.924436 1.5708 0"/>
      <geometry>
        <mesh filename="package://hexapod_description/meshes/low_tie.stl"/>
      </geometry>
    </collision>
    <!-- Part top_tie -->
    <visual>
      <origin xyz="0.0165628 0.0219527 -0.0305" rpy="-0.924436 1.5708 0"/>
      <geometry>
        <mesh filename="package://hexapod_description/meshes/top_tie.stl"/>
      </geometry>
      <material name="top_tie_material">
        <color rgba="0.196078 0.439216 0.0784314 1"/>
      </material>
    </visual>
    <collision>
      <origin xyz="0.0165628 0.0219527 -0.0305" rpy="-0.924436 1.5708 0"/>
      <geometry>
        <mesh filename="package://hexapod_description/meshes/top_tie.stl"/>
      </geometry>
    </collision>
    <!-- Part servo_wheel_3 -->
    <visual>
      <origin xyz="2.77556e-17 0 -0.0025" rpy="-3.14159 8.93969e-15 -2.21716"/>
      <geometry>
        <mesh filename="package://hexapod_description/meshes/servo_wheel.stl"/>
      </geometry>
      <material name="servo_wheel_3_material">
        <color rgba="0.647059 0.647059 0.647059 1"/>
      </material>
    </visual>
    <collision>
      <origin xyz="2.77556e-17 0 -0.0025" rpy="-3.14159 8.93969e-15 -2.21716"/>
      <geometry>
        <mesh filename="package://hexapod_description/meshes/servo_wheel.stl"/>
      </geometry>
    </collision>
    <!-- Part servo_2 -->
    <visual>
      <origin xyz="0.00941886 0.0148158 -0.0305" rpy="-3.14159 4.79712e-15 -2.21716"/>
      <geometry>
        <mesh filename="package://hexapod_description/meshes/servo.stl"/>
      </geometry>
      <material name="servo_2_material">
        <color rgba="0.109804 0.109804 0.105882 1"/>
      </material>
    </visual>
    <collision>
      <origin xyz="0.00941886 0.0148158 -0.0305" rpy="-3.14159 4.79712e-15 -2.21716"/>
      <geometry>
        <mesh filename="package://hexapod_description/meshes/servo.stl"/>
      </geometry>
    </collision>
    <!-- Part fixed_bracket_2 -->
    <visual>
      <origin xyz="0.0346314 0.0459012 -0.0305" rpy="-2.49523 1.5708 0"/>
      <geometry>
        <mesh filename="package://hexapod_description/meshes/fixed_bracket.stl"/>
      </geometry>
      <material name="fixed_bracket_2_material">
        <color rgba="0.647059 0.647059 0.647059 1"/>
      </material>
    </visual>
    <collision>
      <origin xyz="0.0346314 0.0459012 -0.0305" rpy="-2.49523 1.5708 0"/>
      <geometry>
        <mesh filename="package://hexapod_description/meshes/fixed_bracket.stl"/>
      </geometry>
    </collision>
    <!-- Part servo_wheel_4 -->
    <visual>
      <origin xyz="2.77556e-17 2.77556e-17 -0.0585" rpy="-3.14159 5.60443e-15 -2.21716"/>
      <geometry>
        <mesh filename="package://hexapod_description/meshes/servo_wheel.stl"/>
      </geometry>
      <material name="servo_wheel_4_material">
        <color rgba="0.647059 0.647059 0.647059 1"/>
      </material>
    </visual>
    <collision>
      <origin xyz="2.77556e-17 2.77556e-17 -0.0585" rpy="-3.14159 5.60443e-15 -2.21716"/>
      <geometry>
        <mesh filename="package://hexapod_description/meshes/servo_wheel.stl"/>
      </geometry>
    </collision>
  </link>
  <!-- Link foot_assembly -->
  <link name="foot_assembly">
    <inertial>
      <origin xyz="-0.0723864 -0.00208107 -0.0306673" rpy="0 0 0"/>
      <mass value="0.633453"/>
      <inertia ixx="0.000268433" ixy="-1.45368e-05" ixz="4.27618e-06" iyy="0.00320391" iyz="-2.30491e-07" izz="0.00304092"/>
    </inertial>
    <!-- Part foot -->
    <visual>
      <origin xyz="-0.04425 1.73472e-17 -0.0305" rpy="1.56877e-16 1.5708 0"/>
      <geometry>
        <mesh filename="package://hexapod_description/meshes/foot.stl"/>
      </geometry>
      <material name="foot_material">
        <color rgba="0.282353 0.54902 0.160784 1"/>
      </material>
    </visual>
    <collision>
      <origin xyz="-0.04425 1.73472e-17 -0.0305" rpy="1.56877e-16 1.5708 0"/>
      <geometry>
        <mesh filename="package://hexapod_description/meshes/foot.stl"/>
      </geometry>
    </collision>
    <!-- Part ir_sensor_cap -->
    <visual>
      <origin xyz="-0.04425 2.27249e-16 -0.0305" rpy="-1.43376e-15 1.5708 0"/>
      <geometry>
        <mesh filename="package://hexapod_description/meshes/ir_sensor_cap.stl"/>
      </geometry>
      <material name="ir_sensor_cap_material">
        <color rgba="0.282353 0.54902 0.160784 1"/>
      </material>
    </visual>
    <collision>
      <origin xyz="-0.04425 2.27249e-16 -0.0305" rpy="-1.43376e-15 1.5708 0"/>
      <geometry>
        <mesh filename="package://hexapod_description/meshes/ir_sensor_cap.stl"/>
      </geometry>
    </collision>
    <!-- Part rubber_foot -->
    <visual>
      <origin xyz="-0.04375 -9.88792e-17 -0.03" rpy="7.6286e-16 1.5708 0"/>
      <geometry>
        <mesh filename="package://hexapod_description/meshes/rubber_foot.stl"/>
      </geometry>
      <material name="rubber_foot_material">
        <color rgba="0.262745 0.282353 0.301961 1"/>
      </material>
    </visual>
    <collision>
      <origin xyz="-0.04375 -9.88792e-17 -0.03" rpy="7.6286e-16 1.5708 0"/>
      <geometry>
        <mesh filename="package://hexapod_description/meshes/rubber_foot.stl"/>
      </geometry>
    </collision>
    <!-- Part servo_wheel_5 -->
    <visual>
      <origin xyz="2.77556e-17 0 -0.0025" rpy="-3.14159 -9.46076e-18 1.45434e-17"/>
      <geometry>
        <mesh filename="package://hexapod_description/meshes/servo_wheel.stl"/>
      </geometry>
      <material name="servo_wheel_5_material">
        <color rgba="0.647059 0.647059 0.647059 1"/>
      </material>
    </visual>
    <collision>
      <origin xyz="2.77556e-17 0 -0.0025" rpy="-3.14159 -9.46076e-18 1.45434e-17"/>
      <geometry>
        <mesh filename="package://hexapod_description/meshes/servo_wheel.stl"/>
      </geometry>
    </collision>
    <!-- Part servo_3 -->
    <visual>
      <origin xyz="-0.0175 -0.00140442 -0.0305" rpy="-3.14159 1.76886e-16 -2.71369e-16"/>
      <geometry>
        <mesh filename="package://hexapod_description/meshes/servo.stl"/>
      </geometry>
      <material name="servo_3_material">
        <color rgba="0.109804 0.109804 0.105882 1"/>
      </material>
    </visual>
    <collision>
      <origin xyz="-0.0175 -0.00140442 -0.0305" rpy="-3.14159 1.76886e-16 -2.71369e-16"/>
      <geometry>
        <mesh filename="package://hexapod_description/meshes/servo.stl"/>
      </geometry>
    </collision>
    <!-- Part fixed_bracket_3 -->
    <visual>
      <origin xyz="-0.0575 -1.04083e-17 -0.0305" rpy="1.5708 1.5708 0"/>
      <geometry>
        <mesh filename="package://hexapod_description/meshes/fixed_bracket.stl"/>
      </geometry>
      <material name="fixed_bracket_3_material">
        <color rgba="0.647059 0.647059 0.647059 1"/>
      </material>
    </visual>
    <collision>
      <origin xyz="-0.0575 -1.04083e-17 -0.0305" rpy="1.5708 1.5708 0"/>
      <geometry>
        <mesh filename="package://hexapod_description/meshes/fixed_bracket.stl"/>
      </geometry>
    </collision>
    <!-- Part servo_wheel_6 -->
    <visual>
      <origin xyz="1.11022e-16 -2.94903e-17 -0.0585" rpy="3.14159 7.51594e-16 6.01771e-16"/>
      <geometry>
        <mesh filename="package://hexapod_description/meshes/servo_wheel.stl"/>
      </geometry>
      <material name="servo_wheel_6_material">
        <color rgba="0.647059 0.647059 0.647059 1"/>
      </material>
    </visual>
    <collision>
      <origin xyz="1.11022e-16 -2.94903e-17 -0.0585" rpy="3.14159 7.51594e-16 6.01771e-16"/>
      <geometry>
        <mesh filename="package://hexapod_description/meshes/servo_wheel.stl"/>
      </geometry>
    </collision>
  </link>
  <!-- Joint from ties_assembly to foot_assembly -->
  <joint name="foot_1" type="revolute">
    <origin xyz="0.11535 0.153237 -0.000790548" rpy="4.79355e-16 9.68796e-16 1.97163"/>
    <parent link="ties_assembly"/>
    <child link="foot_assembly"/>
    <axis xyz="0 0 1"/>
    <limit effort="10" velocity="10" lower="-4.44089e-16" upper="4.18879"/>
  </joint>
  <!-- Joint from hip_assembly to ties_assembly -->
  <joint name="ties_1" type="revolute">
    <origin xyz="0.0957704 -0.0187757 -0.0305" rpy="1.5708 1.85393e-15 0.130912"/>
    <parent link="hip_assembly"/>
    <child link="ties_assembly"/>
    <axis xyz="0 0 1"/>
    <limit effort="10" velocity="10" lower="-2.66977" upper="0.820893"/>
  </joint>
  <!-- Joint from base_link to hip_assembly -->
  <joint name="hip_1" type="revolute">
    <origin xyz="-0.479319 -0.438353 0.0695202" rpy="4.41736e-16 -2.00843e-17 -0.523599"/>
    <parent link="base_link"/>
    <child link="hip_assembly"/>
    <axis xyz="0 0 1"/>
    <limit effort="10" velocity="10" lower="-1.70171" upper="1.43988"/>
  </joint>
  <!-- Link hip_assembly_2 -->
  <link name="hip_assembly_2">
    <inertial>
      <origin xyz="-0.0268487 -0.000325484 -0.0302141" rpy="0 0 0"/>
      <mass value="0.365356"/>
      <inertia ixx="0.000168136" ixy="-2.8417e-07" ixz="3.2467e-06" iyy="0.000312332" iyz="-9.42575e-07" izz="0.000312341"/>
    </inertial>
    <!-- Part hip_2 -->
    <visual>
      <origin xyz="-0.0575 -0.0005 -0.0045" rpy="2.63678e-16 6.80012e-16 5.11551e-16"/>
      <geometry>
        <mesh filename="package://hexapod_description/meshes/hip.stl"/>
      </geometry>
      <material name="hip_2_material">
        <color rgba="0.196078 0.439216 0.0784314 1"/>
      </material>
    </visual>
    <collision>
      <origin xyz="-0.0575 -0.0005 -0.0045" rpy="2.63678e-16 6.80012e-16 5.11551e-16"/>
      <geometry>
        <mesh filename="package://hexapod_description/meshes/hip.stl"/>
      </geometry>
    </collision>
    <!-- Part mobile_bracket_9 -->
    <visual>
      <origin xyz="-0.0575 0 -0.0305" rpy="9.85323e-16 -4.996e-16 1.5708"/>
      <geometry>
        <mesh filename="package://hexapod_description/meshes/mobile_bracket.stl"/>
      </geometry>
      <material name="mobile_bracket_9_material">
        <color rgba="0.647059 0.647059 0.647059 1"/>
      </material>
    </visual>
    <collision>
      <origin xyz="-0.0575 0 -0.0305" rpy="9.85323e-16 -4.996e-16 1.5708"/>
      <geometry>
        <mesh filename="package://hexapod_description/meshes/mobile_bracket.stl"/>
      </geometry>
    </collision>
    <!-- Part servo_wheel_7 -->
    <visual>
      <origin xyz="0 2.77556e-17 -0.0025" rpy="-3.14159 -6.38069e-32 9.97878e-17"/>
      <geometry>
        <mesh filename="package://hexapod_description/meshes/servo_wheel.stl"/>
      </geometry>
      <material name="servo_wheel_7_material">
        <color rgba="0.647059 0.647059 0.647059 1"/>
      </material>
    </visual>
    <collision>
      <origin xyz="0 2.77556e-17 -0.0025" rpy="-3.14159 -6.38069e-32 9.97878e-17"/>
      <geometry>
        <mesh filename="package://hexapod_description/meshes/servo_wheel.stl"/>
      </geometry>
    </collision>
    <!-- Part servo_4 -->
    <visual>
      <origin xyz="-0.0175 -0.00140442 -0.0305" rpy="-3.14159 1.8735e-16 3.21238e-16"/>
      <geometry>
        <mesh filename="package://hexapod_description/meshes/servo.stl"/>
      </geometry>
      <material name="servo_4_material">
        <color rgba="0.109804 0.109804 0.105882 1"/>
      </material>
    </visual>
    <collision>
      <origin xyz="-0.0175 -0.00140442 -0.0305" rpy="-3.14159 1.8735e-16 3.21238e-16"/>
      <geometry>
        <mesh filename="package://hexapod_description/meshes/servo.stl"/>
      </geometry>
    </collision>
    <!-- Part fixed_bracket_4 -->
    <visual>
      <origin xyz="-0.0575 0 -0.0305" rpy="1.5708 1.5708 0"/>
      <geometry>
        <mesh filename="package://hexapod_description/meshes/fixed_bracket.stl"/>
      </geometry>
      <material name="fixed_bracket_4_material">
        <color rgba="0.647059 0.647059 0.647059 1"/>
      </material>
    </visual>
    <collision>
      <origin xyz="-0.0575 0 -0.0305" rpy="1.5708 1.5708 0"/>
      <geometry>
        <mesh filename="package://hexapod_description/meshes/fixed_bracket.stl"/>
      </geometry>
    </collision>
    <!-- Part servo_wheel_8 -->
    <visual>
      <origin xyz="0 -2.77556e-17 -0.0585" rpy="3.14159 -3.11556e-15 3.82586e-16"/>
      <geometry>
        <mesh filename="package://hexapod_description/meshes/servo_wheel.stl"/>
      </geometry>
      <material name="servo_wheel_8_material">
        <color rgba="0.647059 0.647059 0.647059 1"/>
      </material>
    </visual>
    <collision>
      <origin xyz="0 -2.77556e-17 -0.0585" rpy="3.14159 -3.11556e-15 3.82586e-16"/>
      <geometry>
        <mesh filename="package://hexapod_description/meshes/servo_wheel.stl"/>
      </geometry>
    </collision>
  </link>
  <!-- Link ties_assembly_2 -->
  <link name="ties_assembly_2">
    <inertial>
      <origin xyz="0.0229112 0.0601631 -0.0309357" rpy="0 0 0"/>
      <mass value="0.589115"/>
      <inertia ixx="0.00185134" ixy="-0.000600962" ixz="3.88348e-06" iyy="0.00055585" iyz="1.00654e-05" izz="0.00187002"/>
    </inertial>
    <!-- Part mobile_bracket_10 -->
    <visual>
      <origin xyz="0.059077 0.145245 -0.0311738" rpy="0.387644 1.5708 0"/>
      <geometry>
        <mesh filename="package://hexapod_description/meshes/mobile_bracket.stl"/>
      </geometry>
      <material name="mobile_bracket_10_material">
        <color rgba="0.647059 0.647059 0.647059 1"/>
      </material>
    </visual>
    <collision>
      <origin xyz="0.059077 0.145245 -0.0311738" rpy="0.387644 1.5708 0"/>
      <geometry>
        <mesh filename="package://hexapod_description/meshes/mobile_bracket.stl"/>
      </geometry>
    </collision>
    <!-- Part low_tie_2 -->
    <visual>
      <origin xyz="0.0099359 0.024891 -0.0311738" rpy="-1.18315 1.5708 0"/>
      <geometry>
        <mesh filename="package://hexapod_description/meshes/low_tie.stl"/>
      </geometry>
      <material name="low_tie_2_material">
        <color rgba="0.196078 0.439216 0.0784314 1"/>
      </material>
    </visual>
    <collision>
      <origin xyz="0.0099359 0.024891 -0.0311738" rpy="-1.18315 1.5708 0"/>
      <geometry>
        <mesh filename="package://hexapod_description/meshes/low_tie.stl"/>
      </geometry>
    </collision>
    <!-- Part top_tie_2 -->
    <visual>
      <origin xyz="0.0103952 0.0254596 -0.0305" rpy="-1.18315 1.5708 0"/>
      <geometry>
        <mesh filename="package://hexapod_description/meshes/top_tie.stl"/>
      </geometry>
      <material name="top_tie_2_material">
        <color rgba="0.196078 0.439216 0.0784314 1"/>
      </material>
    </visual>
    <collision>
      <origin xyz="0.0103952 0.0254596 -0.0305" rpy="-1.18315 1.5708 0"/>
      <geometry>
        <mesh filename="package://hexapod_description/meshes/top_tie.stl"/>
      </geometry>
    </collision>
    <!-- Part servo_wheel_9 -->
    <visual>
      <origin xyz="5.55112e-17 -6.93889e-18 -0.0025" rpy="3.14159 -6.39221e-16 -1.95844"/>
      <geometry>
        <mesh filename="package://hexapod_description/meshes/servo_wheel.stl"/>
      </geometry>
      <material name="servo_wheel_9_material">
        <color rgba="0.647059 0.647059 0.647059 1"/>
      </material>
    </visual>
    <collision>
      <origin xyz="5.55112e-17 -6.93889e-18 -0.0025" rpy="3.14159 -6.39221e-16 -1.95844"/>
      <geometry>
        <mesh filename="package://hexapod_description/meshes/servo_wheel.stl"/>
      </geometry>
    </collision>
    <!-- Part servo_5 -->
    <visual>
      <origin xyz="0.00531493 0.0167324 -0.0305" rpy="3.14159 3.81092e-16 -1.95844"/>
      <geometry>
        <mesh filename="package://hexapod_description/meshes/servo.stl"/>
      </geometry>
      <material name="servo_5_material">
        <color rgba="0.109804 0.109804 0.105882 1"/>
      </material>
    </visual>
    <collision>
      <origin xyz="0.00531493 0.0167324 -0.0305" rpy="3.14159 3.81092e-16 -1.95844"/>
      <geometry>
        <mesh filename="package://hexapod_description/meshes/servo.stl"/>
      </geometry>
    </collision>
    <!-- Part fixed_bracket_5 -->
    <visual>
      <origin xyz="0.0217355 0.0532336 -0.0305" rpy="-2.75395 1.5708 0"/>
      <geometry>
        <mesh filename="package://hexapod_description/meshes/fixed_bracket.stl"/>
      </geometry>
      <material name="fixed_bracket_5_material">
        <color rgba="0.647059 0.647059 0.647059 1"/>
      </material>
    </visual>
    <collision>
      <origin xyz="0.0217355 0.0532336 -0.0305" rpy="-2.75395 1.5708 0"/>
      <geometry>
        <mesh filename="package://hexapod_description/meshes/fixed_bracket.stl"/>
      </geometry>
    </collision>
    <!-- Part servo_wheel_10 -->
    <visual>
      <origin xyz="5.55112e-17 -9.71445e-17 -0.0585" rpy="3.14159 -2.34729e-15 -1.95844"/>
      <geometry>
        <mesh filename="package://hexapod_description/meshes/servo_wheel.stl"/>
      </geometry>
      <material name="servo_wheel_10_material">
        <color rgba="0.647059 0.647059 0.647059 1"/>
      </material>
    </visual>
    <collision>
      <origin xyz="5.55112e-17 -9.71445e-17 -0.0585" rpy="3.14159 -2.34729e-15 -1.95844"/>
      <geometry>
        <mesh filename="package://hexapod_description/meshes/servo_wheel.stl"/>
      </geometry>
    </collision>
  </link>
  <!-- Link foot_assembly_2 -->
  <link name="foot_assembly_2">
    <inertial>
      <origin xyz="-0.0723864 -0.00208107 -0.0306673" rpy="0 0 0"/>
      <mass value="0.633453"/>
      <inertia ixx="0.000268433" ixy="-1.45368e-05" ixz="4.27618e-06" iyy="0.00320391" iyz="-2.30491e-07" izz="0.00304092"/>
    </inertial>
    <!-- Part foot_2 -->
    <visual>
      <origin xyz="-0.04425 0 -0.0305" rpy="-1.33186e-16 1.5708 0"/>
      <geometry>
        <mesh filename="package://hexapod_description/meshes/foot.stl"/>
      </geometry>
      <material name="foot_2_material">
        <color rgba="0.282353 0.54902 0.160784 1"/>
      </material>
    </visual>
    <collision>
      <origin xyz="-0.04425 0 -0.0305" rpy="-1.33186e-16 1.5708 0"/>
      <geometry>
        <mesh filename="package://hexapod_description/meshes/foot.stl"/>
      </geometry>
    </collision>
    <!-- Part ir_sensor_cap_2 -->
    <visual>
      <origin xyz="-0.04425 5.55112e-17 -0.0305" rpy="-1.08347e-16 1.5708 0"/>
      <geometry>
        <mesh filename="package://hexapod_description/meshes/ir_sensor_cap.stl"/>
      </geometry>
      <material name="ir_sensor_cap_2_material">
        <color rgba="0.282353 0.54902 0.160784 1"/>
      </material>
    </visual>
    <collision>
      <origin xyz="-0.04425 5.55112e-17 -0.0305" rpy="-1.08347e-16 1.5708 0"/>
      <geometry>
        <mesh filename="package://hexapod_description/meshes/ir_sensor_cap.stl"/>
      </geometry>
    </collision>
    <!-- Part rubber_foot_2 -->
    <visual>
      <origin xyz="-0.04375 0 -0.03" rpy="-2.04033e-16 1.5708 0"/>
      <geometry>
        <mesh filename="package://hexapod_description/meshes/rubber_foot.stl"/>
      </geometry>
      <material name="rubber_foot_2_material">
        <color rgba="0.262745 0.282353 0.301961 1"/>
      </material>
    </visual>
    <collision>
      <origin xyz="-0.04375 0 -0.03" rpy="-2.04033e-16 1.5708 0"/>
      <geometry>
        <mesh filename="package://hexapod_description/meshes/rubber_foot.stl"/>
      </geometry>
    </collision>
    <!-- Part servo_wheel_11 -->
    <visual>
      <origin xyz="0 0 -0.0025" rpy="-3.14159 -2.14412e-18 -4.60747e-17"/>
      <geometry>
        <mesh filename="package://hexapod_description/meshes/servo_wheel.stl"/>
      </geometry>
      <material name="servo_wheel_11_material">
        <color rgba="0.647059 0.647059 0.647059 1"/>
      </material>
    </visual>
    <collision>
      <origin xyz="0 0 -0.0025" rpy="-3.14159 -2.14412e-18 -4.60747e-17"/>
      <geometry>
        <mesh filename="package://hexapod_description/meshes/servo_wheel.stl"/>
      </geometry>
    </collision>
    <!-- Part servo_6 -->
    <visual>
      <origin xyz="-0.0175 -0.00140442 -0.0305" rpy="-3.14159 2.0323e-16 1.32349e-16"/>
      <geometry>
        <mesh filename="package://hexapod_description/meshes/servo.stl"/>
      </geometry>
      <material name="servo_6_material">
        <color rgba="0.109804 0.109804 0.105882 1"/>
      </material>
    </visual>
    <collision>
      <origin xyz="-0.0175 -0.00140442 -0.0305" rpy="-3.14159 2.0323e-16 1.32349e-16"/>
      <geometry>
        <mesh filename="package://hexapod_description/meshes/servo.stl"/>
      </geometry>
    </collision>
    <!-- Part fixed_bracket_6 -->
    <visual>
      <origin xyz="-0.0575 2.77556e-17 -0.0305" rpy="1.5708 1.5708 0"/>
      <geometry>
        <mesh filename="package://hexapod_description/meshes/fixed_bracket.stl"/>
      </geometry>
      <material name="fixed_bracket_6_material">
        <color rgba="0.647059 0.647059 0.647059 1"/>
      </material>
    </visual>
    <collision>
      <origin xyz="-0.0575 2.77556e-17 -0.0305" rpy="1.5708 1.5708 0"/>
      <geometry>
        <mesh filename="package://hexapod_description/meshes/fixed_bracket.stl"/>
      </geometry>
    </collision>
    <!-- Part servo_wheel_12 -->
    <visual>
      <origin xyz="-5.55112e-17 -2.77556e-17 -0.0585" rpy="-3.14159 8.58787e-16 -8.81942e-17"/>
      <geometry>
        <mesh filename="package://hexapod_description/meshes/servo_wheel.stl"/>
      </geometry>
      <material name="servo_wheel_12_material">
        <color rgba="0.647059 0.647059 0.647059 1"/>
      </material>
    </visual>
    <collision>
      <origin xyz="-5.55112e-17 -2.77556e-17 -0.0585" rpy="-3.14159 8.58787e-16 -8.81942e-17"/>
      <geometry>
        <mesh filename="package://hexapod_description/meshes/servo_wheel.stl"/>
      </geometry>
    </collision>
  </link>
  <!-- Joint from ties_assembly_2 to foot_assembly_2 -->
  <joint name="foot_2" type="revolute">
    <origin xyz="0.0723072 0.177648 -0.000790548" rpy="3.49334e-15 -4.3045e-15 2.24033"/>
    <parent link="ties_assembly_2"/>
    <child link="foot_assembly_2"/>
    <axis xyz="0 0 1"/>
    <limit effort="10" velocity="10" lower="-0.0099805" upper="4.17881"/>
  </joint>
  <!-- Joint from hip_assembly_2 to ties_assembly_2 -->
  <joint name="ties_2" type="revolute">
    <origin xyz="-0.0925 0.0311167 -0.0305" rpy="1.5708 -9.85323e-16 -3.14159"/>
    <parent link="hip_assembly_2"/>
    <child link="ties_assembly_2"/>
    <axis xyz="0 0 1"/>
    <limit effort="10" velocity="10" lower="-2.92848" upper="0.562177"/>
  </joint>
  <!-- Joint from base_link to hip_assembly_2 -->
  <joint name="hip_2" type="revolute">
    <origin xyz="-0.479319 -0.280563 0.0695202" rpy="-2.65193e-15 4.96332e-16 -2.2469"/>
    <parent link="base_link"/>
    <child link="hip_assembly_2"/>
    <axis xyz="0 0 1"/>
    <limit effort="10" velocity="10" lower="-1.94189" upper="1.19971"/>
  </joint>
  <!-- Link hip_assembly_3 -->
  <link name="hip_assembly_3">
    <inertial>
      <origin xyz="-0.0268487 -0.000325484 -0.0302141" rpy="0 0 0"/>
      <mass value="0.365356"/>
      <inertia ixx="0.000168136" ixy="-2.8417e-07" ixz="3.2467e-06" iyy="0.000312332" iyz="-9.42575e-07" izz="0.000312341"/>
    </inertial>
    <!-- Part hip_3 -->
    <visual>
      <origin xyz="-0.0575 -0.0005 -0.0045" rpy="4.30211e-16 3.95517e-16 -3.61773e-16"/>
      <geometry>
        <mesh filename="package://hexapod_description/meshes/hip.stl"/>
      </geometry>
      <material name="hip_3_material">
        <color rgba="0.196078 0.439216 0.0784314 1"/>
      </material>
    </visual>
    <collision>
      <origin xyz="-0.0575 -0.0005 -0.0045" rpy="4.30211e-16 3.95517e-16 -3.61773e-16"/>
      <geometry>
        <mesh filename="package://hexapod_description/meshes/hip.stl"/>
      </geometry>
    </collision>
    <!-- Part mobile_bracket_11 -->
    <visual>
      <origin xyz="-0.0575 1.11022e-16 -0.0305" rpy="8.32667e-16 7.91034e-16 1.5708"/>
      <geometry>
        <mesh filename="package://hexapod_description/meshes/mobile_bracket.stl"/>
      </geometry>
      <material name="mobile_bracket_11_material">
        <color rgba="0.647059 0.647059 0.647059 1"/>
      </material>
    </visual>
    <collision>
      <origin xyz="-0.0575 1.11022e-16 -0.0305" rpy="8.32667e-16 7.91034e-16 1.5708"/>
      <geometry>
        <mesh filename="package://hexapod_description/meshes/mobile_bracket.stl"/>
      </geometry>
    </collision>
    <!-- Part servo_wheel_13 -->
    <visual>
      <origin xyz="-2.77556e-17 0 -0.0025" rpy="3.14159 -1.49214e-32 4.47223e-18"/>
      <geometry>
        <mesh filename="package://hexapod_description/meshes/servo_wheel.stl"/>
      </geometry>
      <material name="servo_wheel_13_material">
        <color rgba="0.647059 0.647059 0.647059 1"/>
      </material>
    </visual>
    <collision>
      <origin xyz="-2.77556e-17 0 -0.0025" rpy="3.14159 -1.49214e-32 4.47223e-18"/>
      <geometry>
        <mesh filename="package://hexapod_description/meshes/servo_wheel.stl"/>
      </geometry>
    </collision>
    <!-- Part servo_7 -->
    <visual>
      <origin xyz="-0.0175 -0.00140442 -0.0305" rpy="-3.14159 6.10623e-16 -1.19127e-17"/>
      <geometry>
        <mesh filename="package://hexapod_description/meshes/servo.stl"/>
      </geometry>
      <material name="servo_7_material">
        <color rgba="0.109804 0.109804 0.105882 1"/>
      </material>
    </visual>
    <collision>
      <origin xyz="-0.0175 -0.00140442 -0.0305" rpy="-3.14159 6.10623e-16 -1.19127e-17"/>
      <geometry>
        <mesh filename="package://hexapod_description/meshes/servo.stl"/>
      </geometry>
    </collision>
    <!-- Part fixed_bracket_7 -->
    <visual>
      <origin xyz="-0.0575 1.11022e-16 -0.0305" rpy="1.5708 1.5708 0"/>
      <geometry>
        <mesh filename="package://hexapod_description/meshes/fixed_bracket.stl"/>
      </geometry>
      <material name="fixed_bracket_7_material">
        <color rgba="0.647059 0.647059 0.647059 1"/>
      </material>
    </visual>
    <collision>
      <origin xyz="-0.0575 1.11022e-16 -0.0305" rpy="1.5708 1.5708 0"/>
      <geometry>
        <mesh filename="package://hexapod_description/meshes/fixed_bracket.stl"/>
      </geometry>
    </collision>
    <!-- Part servo_wheel_14 -->
    <visual>
      <origin xyz="-2.77556e-17 0 -0.0585" rpy="-3.14159 7.77156e-16 -1.98676e-16"/>
      <geometry>
        <mesh filename="package://hexapod_description/meshes/servo_wheel.stl"/>
      </geometry>
      <material name="servo_wheel_14_material">
        <color rgba="0.647059 0.647059 0.647059 1"/>
      </material>
    </visual>
    <collision>
      <origin xyz="-2.77556e-17 0 -0.0585" rpy="-3.14159 7.77156e-16 -1.98676e-16"/>
      <geometry>
        <mesh filename="package://hexapod_description/meshes/servo_wheel.stl"/>
      </geometry>
    </collision>
  </link>
  <!-- Link ties_assembly_3 -->
  <link name="ties_assembly_3">
    <inertial>
      <origin xyz="0.0412727 0.0494074 -0.0309357" rpy="0 0 0"/>
      <mass value="0.589115"/>
      <inertia ixx="0.00134324" ixy="-0.000872482" ixz="6.95263e-06" iyy="0.00106395" iyz="8.24953e-06" izz="0.00187002"/>
    </inertial>
    <!-- Part mobile_bracket_12 -->
    <visual>
      <origin xyz="0.103199 0.118052 -0.0311738" rpy="0.719711 1.5708 0"/>
      <geometry>
        <mesh filename="package://hexapod_description/meshes/mobile_bracket.stl"/>
      </geometry>
      <material name="mobile_bracket_12_material">
        <color rgba="0.647059 0.647059 0.647059 1"/>
      </material>
    </visual>
    <collision>
      <origin xyz="0.103199 0.118052 -0.0311738" rpy="0.719711 1.5708 0"/>
      <geometry>
        <mesh filename="package://hexapod_description/meshes/mobile_bracket.stl"/>
      </geometry>
    </collision>
    <!-- Part low_tie_3 -->
    <visual>
      <origin xyz="0.0175075 0.0202921 -0.0311738" rpy="-0.851085 1.5708 0"/>
      <geometry>
        <mesh filename="package://hexapod_description/meshes/low_tie.stl"/>
      </geometry>
      <material name="low_tie_3_material">
        <color rgba="0.196078 0.439216 0.0784314 1"/>
      </material>
    </visual>
    <collision>
      <origin xyz="0.0175075 0.0202921 -0.0311738" rpy="-0.851085 1.5708 0"/>
      <geometry>
        <mesh filename="package://hexapod_description/meshes/low_tie.stl"/>
      </geometry>
    </collision>
    <!-- Part top_tie_3 -->
    <visual>
      <origin xyz="0.0181271 0.0206799 -0.0305" rpy="-0.851085 1.5708 0"/>
      <geometry>
        <mesh filename="package://hexapod_description/meshes/top_tie.stl"/>
      </geometry>
      <material name="top_tie_3_material">
        <color rgba="0.196078 0.439216 0.0784314 1"/>
      </material>
    </visual>
    <collision>
      <origin xyz="0.0181271 0.0206799 -0.0305" rpy="-0.851085 1.5708 0"/>
      <geometry>
        <mesh filename="package://hexapod_description/meshes/top_tie.stl"/>
      </geometry>
    </collision>
    <!-- Part servo_wheel_15 -->
    <visual>
      <origin xyz="-2.77556e-17 -6.93889e-18 -0.0025" rpy="3.14159 4.28135e-15 -2.29051"/>
      <geometry>
        <mesh filename="package://hexapod_description/meshes/servo_wheel.stl"/>
      </geometry>
      <material name="servo_wheel_15_material">
        <color rgba="0.647059 0.647059 0.647059 1"/>
      </material>
    </visual>
    <collision>
      <origin xyz="-2.77556e-17 -6.93889e-18 -0.0025" rpy="3.14159 4.28135e-15 -2.29051"/>
      <geometry>
        <mesh filename="package://hexapod_description/meshes/servo_wheel.stl"/>
      </geometry>
    </collision>
    <!-- Part servo_8 -->
    <visual>
      <origin xyz="0.0104793 0.0140857 -0.0305" rpy="3.14159 3.38152e-15 -2.29051"/>
      <geometry>
        <mesh filename="package://hexapod_description/meshes/servo.stl"/>
      </geometry>
      <material name="servo_8_material">
        <color rgba="0.109804 0.109804 0.105882 1"/>
      </material>
    </visual>
    <collision>
      <origin xyz="0.0104793 0.0140857 -0.0305" rpy="3.14159 3.38152e-15 -2.29051"/>
      <geometry>
        <mesh filename="package://hexapod_description/meshes/servo.stl"/>
      </geometry>
    </collision>
    <!-- Part fixed_bracket_8 -->
    <visual>
      <origin xyz="0.0379021 0.0432398 -0.0305" rpy="-2.42188 1.5708 0"/>
      <geometry>
        <mesh filename="package://hexapod_description/meshes/fixed_bracket.stl"/>
      </geometry>
      <material name="fixed_bracket_8_material">
        <color rgba="0.647059 0.647059 0.647059 1"/>
      </material>
    </visual>
    <collision>
      <origin xyz="0.0379021 0.0432398 -0.0305" rpy="-2.42188 1.5708 0"/>
      <geometry>
        <mesh filename="package://hexapod_description/meshes/fixed_bracket.stl"/>
      </geometry>
    </collision>
    <!-- Part servo_wheel_16 -->
    <visual>
      <origin xyz="2.77556e-17 5.55112e-17 -0.0585" rpy="3.14159 1.81866e-15 -2.29051"/>
      <geometry>
        <mesh filename="package://hexapod_description/meshes/servo_wheel.stl"/>
      </geometry>
      <material name="servo_wheel_16_material">
        <color rgba="0.647059 0.647059 0.647059 1"/>
      </material>
    </visual>
    <collision>
      <origin xyz="2.77556e-17 5.55112e-17 -0.0585" rpy="3.14159 1.81866e-15 -2.29051"/>
      <geometry>
        <mesh filename="package://hexapod_description/meshes/servo_wheel.stl"/>
      </geometry>
    </collision>
  </link>
  <!-- Link foot_assembly_3 -->
  <link name="foot_assembly_3">
    <inertial>
      <origin xyz="-0.0723864 -0.00208107 -0.0306673" rpy="0 0 0"/>
      <mass value="0.633453"/>
      <inertia ixx="0.000268433" ixy="-1.45368e-05" ixz="4.27618e-06" iyy="0.00320391" iyz="-2.30491e-07" izz="0.00304092"/>
    </inertial>
    <!-- Part foot_3 -->
    <visual>
      <origin xyz="-0.04425 4.16334e-17 -0.0305" rpy="-6.13073e-16 1.5708 0"/>
      <geometry>
        <mesh filename="package://hexapod_description/meshes/foot.stl"/>
      </geometry>
      <material name="foot_3_material">
        <color rgba="0.282353 0.54902 0.160784 1"/>
      </material>
    </visual>
    <collision>
      <origin xyz="-0.04425 4.16334e-17 -0.0305" rpy="-6.13073e-16 1.5708 0"/>
      <geometry>
        <mesh filename="package://hexapod_description/meshes/foot.stl"/>
      </geometry>
    </collision>
    <!-- Part ir_sensor_cap_3 -->
    <visual>
      <origin xyz="-0.04425 1.11022e-16 -0.0305" rpy="-7.59866e-16 1.5708 0"/>
      <geometry>
        <mesh filename="package://hexapod_description/meshes/ir_sensor_cap.stl"/>
      </geometry>
      <material name="ir_sensor_cap_3_material">
        <color rgba="0.282353 0.54902 0.160784 1"/>
      </material>
    </visual>
    <collision>
      <origin xyz="-0.04425 1.11022e-16 -0.0305" rpy="-7.59866e-16 1.5708 0"/>
      <geometry>
        <mesh filename="package://hexapod_description/meshes/ir_sensor_cap.stl"/>
      </geometry>
    </collision>
    <!-- Part rubber_foot_3 -->
    <visual>
      <origin xyz="-0.04375 5.55112e-17 -0.03" rpy="-5.30421e-16 1.5708 0"/>
      <geometry>
        <mesh filename="package://hexapod_description/meshes/rubber_foot.stl"/>
      </geometry>
      <material name="rubber_foot_3_material">
        <color rgba="0.262745 0.282353 0.301961 1"/>
      </material>
    </visual>
    <collision>
      <origin xyz="-0.04375 5.55112e-17 -0.03" rpy="-5.30421e-16 1.5708 0"/>
      <geometry>
        <mesh filename="package://hexapod_description/meshes/rubber_foot.stl"/>
      </geometry>
    </collision>
    <!-- Part servo_wheel_17 -->
    <visual>
      <origin xyz="2.77556e-17 -1.38778e-17 -0.0025" rpy="3.14159 1.60836e-18 -5.55038e-17"/>
      <geometry>
        <mesh filename="package://hexapod_description/meshes/servo_wheel.stl"/>
      </geometry>
      <material name="servo_wheel_17_material">
        <color rgba="0.647059 0.647059 0.647059 1"/>
      </material>
    </visual>
    <collision>
      <origin xyz="2.77556e-17 -1.38778e-17 -0.0025" rpy="3.14159 1.60836e-18 -5.55038e-17"/>
      <geometry>
        <mesh filename="package://hexapod_description/meshes/servo_wheel.stl"/>
      </geometry>
    </collision>
    <!-- Part servo_9 -->
    <visual>
      <origin xyz="-0.0175 -0.00140442 -0.0305" rpy="3.14159 1.60478e-15 -4.61361e-16"/>
      <geometry>
        <mesh filename="package://hexapod_description/meshes/servo.stl"/>
      </geometry>
      <material name="servo_9_material">
        <color rgba="0.109804 0.109804 0.105882 1"/>
      </material>
    </visual>
    <collision>
      <origin xyz="-0.0175 -0.00140442 -0.0305" rpy="3.14159 1.60478e-15 -4.61361e-16"/>
      <geometry>
        <mesh filename="package://hexapod_description/meshes/servo.stl"/>
      </geometry>
    </collision>
    <!-- Part fixed_bracket_9 -->
    <visual>
      <origin xyz="-0.0575 2.77556e-17 -0.0305" rpy="1.5708 1.5708 0"/>
      <geometry>
        <mesh filename="package://hexapod_description/meshes/fixed_bracket.stl"/>
      </geometry>
      <material name="fixed_bracket_9_material">
        <color rgba="0.647059 0.647059 0.647059 1"/>
      </material>
    </visual>
    <collision>
      <origin xyz="-0.0575 2.77556e-17 -0.0305" rpy="1.5708 1.5708 0"/>
      <geometry>
        <mesh filename="package://hexapod_description/meshes/fixed_bracket.stl"/>
      </geometry>
    </collision>
    <!-- Part servo_wheel_18 -->
    <visual>
      <origin xyz="1.11022e-16 -4.16334e-17 -0.0585" rpy="3.14159 -2.63722e-15 -6.61187e-16"/>
      <geometry>
        <mesh filename="package://hexapod_description/meshes/servo_wheel.stl"/>
      </geometry>
      <material name="servo_wheel_18_material">
        <color rgba="0.647059 0.647059 0.647059 1"/>
      </material>
    </visual>
    <collision>
      <origin xyz="1.11022e-16 -4.16334e-17 -0.0585" rpy="3.14159 -2.63722e-15 -6.61187e-16"/>
      <geometry>
        <mesh filename="package://hexapod_description/meshes/servo_wheel.stl"/>
      </geometry>
    </collision>
  </link>
  <!-- Joint from ties_assembly_3 to foot_assembly_3 -->
  <joint name="foot_3" type="revolute">
    <origin xyz="0.12627 0.144372 -0.000790548" rpy="1.20553e-14 8.1741e-16 2.33075"/>
    <parent link="ties_assembly_3"/>
    <child link="foot_assembly_3"/>
    <axis xyz="0 0 1"/>
    <limit effort="10" velocity="10" lower="-0.432463" upper="3.75633"/>
  </joint>
  <!-- Joint from hip_assembly_3 to ties_assembly_3 -->
  <joint name="ties_3" type="revolute">
    <origin xyz="-0.0925 0.0311167 -0.0305" rpy="1.5708 -8.32667e-16 3.14159"/>
    <parent link="hip_assembly_3"/>
    <child link="ties_assembly_3"/>
    <axis xyz="0 0 1"/>
    <limit effort="10" velocity="10" lower="-2.59641" upper="0.894244"/>
  </joint>
  <!-- Joint from base_link to hip_assembly_3 -->
  <joint name="hip_3" type="revolute">
    <origin xyz="-0.61597 -0.201668 0.0702537" rpy="-2.0868e-15 1.31547e-15 -1.61555"/>
    <parent link="base_link"/>
    <child link="hip_assembly_3"/>
    <axis xyz="0 0 1"/>
    <limit effort="10" velocity="10" lower="-1.52605" upper="1.61555"/>
  </joint>
  <!-- Link hip_assembly_4 -->
  <link name="hip_assembly_4">
    <inertial>
      <origin xyz="-0.0268487 -0.000325484 -0.0302141" rpy="0 0 0"/>
      <mass value="0.365356"/>
      <inertia ixx="0.000168136" ixy="-2.8417e-07" ixz="3.2467e-06" iyy="0.000312332" iyz="-9.42575e-07" izz="0.000312341"/>
    </inertial>
    <!-- Part hip_4 -->
    <visual>
      <origin xyz="-0.0575 -0.0005 -0.0045" rpy="2.77813e-15 -9.71445e-17 -2.24995e-16"/>
      <geometry>
        <mesh filename="package://hexapod_description/meshes/hip.stl"/>
      </geometry>
      <material name="hip_4_material">
        <color rgba="0.196078 0.439216 0.0784314 1"/>
      </material>
    </visual>
    <collision>
      <origin xyz="-0.0575 -0.0005 -0.0045" rpy="2.77813e-15 -9.71445e-17 -2.24995e-16"/>
      <geometry>
        <mesh filename="package://hexapod_description/meshes/hip.stl"/>
      </geometry>
    </collision>
    <!-- Part mobile_bracket_13 -->
    <visual>
      <origin xyz="-0.0575 0 -0.0305" rpy="9.71445e-17 -1.31768e-15 1.5708"/>
      <geometry>
        <mesh filename="package://hexapod_description/meshes/mobile_bracket.stl"/>
      </geometry>
      <material name="mobile_bracket_13_material">
        <color rgba="0.647059 0.647059 0.647059 1"/>
      </material>
    </visual>
    <collision>
      <origin xyz="-0.0575 0 -0.0305" rpy="9.71445e-17 -1.31768e-15 1.5708"/>
      <geometry>
        <mesh filename="package://hexapod_description/meshes/mobile_bracket.stl"/>
      </geometry>
    </collision>
    <!-- Part servo_wheel_19 -->
    <visual>
      <origin xyz="-2.22045e-16 1.11022e-16 -0.0025" rpy="-3.14159 1.8263e-31 2.98589e-17"/>
      <geometry>
        <mesh filename="package://hexapod_description/meshes/servo_wheel.stl"/>
      </geometry>
      <material name="servo_wheel_19_material">
        <color rgba="0.647059 0.647059 0.647059 1"/>
      </material>
    </visual>
    <collision>
      <origin xyz="-2.22045e-16 1.11022e-16 -0.0025" rpy="-3.14159 1.8263e-31 2.98589e-17"/>
      <geometry>
        <mesh filename="package://hexapod_description/meshes/servo_wheel.stl"/>
      </geometry>
    </collision>
    <!-- Part servo_10 -->
    <visual>
      <origin xyz="-0.0175 -0.00140442 -0.0305" rpy="-3.14159 -2.91434e-16 -5.34443e-16"/>
      <geometry>
        <mesh filename="package://hexapod_description/meshes/servo.stl"/>
      </geometry>
      <material name="servo_10_material">
        <color rgba="0.109804 0.109804 0.105882 1"/>
      </material>
    </visual>
    <collision>
      <origin xyz="-0.0175 -0.00140442 -0.0305" rpy="-3.14159 -2.91434e-16 -5.34443e-16"/>
      <geometry>
        <mesh filename="package://hexapod_description/meshes/servo.stl"/>
      </geometry>
    </collision>
    <!-- Part fixed_bracket_10 -->
    <visual>
      <origin xyz="-0.0575 0 -0.0305" rpy="1.5708 1.5708 0"/>
      <geometry>
        <mesh filename="package://hexapod_description/meshes/fixed_bracket.stl"/>
      </geometry>
      <material name="fixed_bracket_10_material">
        <color rgba="0.647059 0.647059 0.647059 1"/>
      </material>
    </visual>
    <collision>
      <origin xyz="-0.0575 0 -0.0305" rpy="1.5708 1.5708 0"/>
      <geometry>
        <mesh filename="package://hexapod_description/meshes/fixed_bracket.stl"/>
      </geometry>
    </collision>
    <!-- Part servo_wheel_20 -->
    <visual>
      <origin xyz="-1.11022e-16 1.11022e-16 -0.0585" rpy="-3.14159 6.10623e-16 -2.00365e-16"/>
      <geometry>
        <mesh filename="package://hexapod_description/meshes/servo_wheel.stl"/>
      </geometry>
      <material name="servo_wheel_20_material">
        <color rgba="0.647059 0.647059 0.647059 1"/>
      </material>
    </visual>
    <collision>
      <origin xyz="-1.11022e-16 1.11022e-16 -0.0585" rpy="-3.14159 6.10623e-16 -2.00365e-16"/>
      <geometry>
        <mesh filename="package://hexapod_description/meshes/servo_wheel.stl"/>
      </geometry>
    </collision>
  </link>
  <!-- Link ties_assembly_4 -->
  <link name="ties_assembly_4">
    <inertial>
      <origin xyz="0.036543 0.0530013 -0.0309357" rpy="0 0 0"/>
      <mass value="0.589115"/>
      <inertia ixx="0.00150102" ixy="-0.000832024" ixz="6.16266e-06" iyy="0.000906169" iyz="8.85524e-06" izz="0.00187002"/>
    </inertial>
    <!-- Part mobile_bracket_14 -->
    <visual>
      <origin xyz="0.091879 0.127061 -0.0311738" rpy="0.627409 1.5708 0"/>
      <geometry>
        <mesh filename="package://hexapod_description/meshes/mobile_bracket.stl"/>
      </geometry>
      <material name="mobile_bracket_14_material">
        <color rgba="0.647059 0.647059 0.647059 1"/>
      </material>
    </visual>
    <collision>
      <origin xyz="0.091879 0.127061 -0.0311738" rpy="0.627409 1.5708 0"/>
      <geometry>
        <mesh filename="package://hexapod_description/meshes/mobile_bracket.stl"/>
      </geometry>
    </collision>
    <!-- Part low_tie_4 -->
    <visual>
      <origin xyz="0.0155626 0.0218195 -0.0311738" rpy="-0.943388 1.5708 0"/>
      <geometry>
        <mesh filename="package://hexapod_description/meshes/low_tie.stl"/>
      </geometry>
      <material name="low_tie_4_material">
        <color rgba="0.196078 0.439216 0.0784314 1"/>
      </material>
    </visual>
    <collision>
      <origin xyz="0.0155626 0.0218195 -0.0311738" rpy="-0.943388 1.5708 0"/>
      <geometry>
        <mesh filename="package://hexapod_description/meshes/low_tie.stl"/>
      </geometry>
    </collision>
    <!-- Part top_tie_4 -->
    <visual>
      <origin xyz="0.0161438 0.0222627 -0.0305" rpy="-0.943388 1.5708 0"/>
      <geometry>
        <mesh filename="package://hexapod_description/meshes/top_tie.stl"/>
      </geometry>
      <material name="top_tie_4_material">
        <color rgba="0.196078 0.439216 0.0784314 1"/>
      </material>
    </visual>
    <collision>
      <origin xyz="0.0161438 0.0222627 -0.0305" rpy="-0.943388 1.5708 0"/>
      <geometry>
        <mesh filename="package://hexapod_description/meshes/top_tie.stl"/>
      </geometry>
    </collision>
    <!-- Part servo_wheel_21 -->
    <visual>
      <origin xyz="0 -1.38778e-17 -0.0025" rpy="-3.14159 -3.50602e-15 -2.1982"/>
      <geometry>
        <mesh filename="package://hexapod_description/meshes/servo_wheel.stl"/>
      </geometry>
      <material name="servo_wheel_21_material">
        <color rgba="0.647059 0.647059 0.647059 1"/>
      </material>
    </visual>
    <collision>
      <origin xyz="0 -1.38778e-17 -0.0025" rpy="-3.14159 -3.50602e-15 -2.1982"/>
      <geometry>
        <mesh filename="package://hexapod_description/meshes/servo_wheel.stl"/>
      </geometry>
    </collision>
    <!-- Part servo_11 -->
    <visual>
      <origin xyz="0.0091364 0.0149916 -0.0305" rpy="3.14159 -2.38808e-15 -2.1982"/>
      <geometry>
        <mesh filename="package://hexapod_description/meshes/servo.stl"/>
      </geometry>
      <material name="servo_11_material">
        <color rgba="0.109804 0.109804 0.105882 1"/>
      </material>
    </visual>
    <collision>
      <origin xyz="0.0091364 0.0149916 -0.0305" rpy="3.14159 -2.38808e-15 -2.1982"/>
      <geometry>
        <mesh filename="package://hexapod_description/meshes/servo.stl"/>
      </geometry>
    </collision>
    <!-- Part fixed_bracket_11 -->
    <visual>
      <origin xyz="0.0337553 0.0465492 -0.0305" rpy="-2.51418 1.5708 0"/>
      <geometry>
        <mesh filename="package://hexapod_description/meshes/fixed_bracket.stl"/>
      </geometry>
      <material name="fixed_bracket_11_material">
        <color rgba="0.647059 0.647059 0.647059 1"/>
      </material>
    </visual>
    <collision>
      <origin xyz="0.0337553 0.0465492 -0.0305" rpy="-2.51418 1.5708 0"/>
      <geometry>
        <mesh filename="package://hexapod_description/meshes/fixed_bracket.stl"/>
      </geometry>
    </collision>
    <!-- Part servo_wheel_22 -->
    <visual>
      <origin xyz="1.11022e-16 -7.63278e-17 -0.0585" rpy="-3.14159 -2.5093e-15 -2.1982"/>
      <geometry>
        <mesh filename="package://hexapod_description/meshes/servo_wheel.stl"/>
      </geometry>
      <material name="servo_wheel_22_material">
        <color rgba="0.647059 0.647059 0.647059 1"/>
      </material>
    </visual>
    <collision>
      <origin xyz="1.11022e-16 -7.63278e-17 -0.0585" rpy="-3.14159 -2.5093e-15 -2.1982"/>
      <geometry>
        <mesh filename="package://hexapod_description/meshes/servo_wheel.stl"/>
      </geometry>
    </collision>
  </link>
  <!-- Link foot_assembly_4 -->
  <link name="foot_assembly_4">
    <inertial>
      <origin xyz="-0.0723864 -0.00208107 -0.0306673" rpy="0 0 0"/>
      <mass value="0.633453"/>
      <inertia ixx="0.000268433" ixy="-1.45368e-05" ixz="4.27618e-06" iyy="0.00320391" iyz="-2.30491e-07" izz="0.00304092"/>
    </inertial>
    <!-- Part foot_4 -->
    <visual>
      <origin xyz="-0.04425 1.11022e-16 -0.0305" rpy="-1.23231e-16 1.5708 0"/>
      <geometry>
        <mesh filename="package://hexapod_description/meshes/foot.stl"/>
      </geometry>
      <material name="foot_4_material">
        <color rgba="0.282353 0.54902 0.160784 1"/>
      </material>
    </visual>
    <collision>
      <origin xyz="-0.04425 1.11022e-16 -0.0305" rpy="-1.23231e-16 1.5708 0"/>
      <geometry>
        <mesh filename="package://hexapod_description/meshes/foot.stl"/>
      </geometry>
    </collision>
    <!-- Part ir_sensor_cap_4 -->
    <visual>
      <origin xyz="-0.04425 1.11022e-16 -0.0305" rpy="-2.1818e-16 1.5708 0"/>
      <geometry>
        <mesh filename="package://hexapod_description/meshes/ir_sensor_cap.stl"/>
      </geometry>
      <material name="ir_sensor_cap_4_material">
        <color rgba="0.282353 0.54902 0.160784 1"/>
      </material>
    </visual>
    <collision>
      <origin xyz="-0.04425 1.11022e-16 -0.0305" rpy="-2.1818e-16 1.5708 0"/>
      <geometry>
        <mesh filename="package://hexapod_description/meshes/ir_sensor_cap.stl"/>
      </geometry>
    </collision>
    <!-- Part rubber_foot_4 -->
    <visual>
      <origin xyz="-0.04375 0 -0.03" rpy="-7.13657e-17 1.5708 0"/>
      <geometry>
        <mesh filename="package://hexapod_description/meshes/rubber_foot.stl"/>
      </geometry>
      <material name="rubber_foot_4_material">
        <color rgba="0.262745 0.282353 0.301961 1"/>
      </material>
    </visual>
    <collision>
      <origin xyz="-0.04375 0 -0.03" rpy="-7.13657e-17 1.5708 0"/>
      <geometry>
        <mesh filename="package://hexapod_description/meshes/rubber_foot.stl"/>
      </geometry>
    </collision>
    <!-- Part servo_wheel_23 -->
    <visual>
      <origin xyz="-5.55112e-17 0 -0.0025" rpy="3.14159 2.0289e-17 2.76226e-18"/>
      <geometry>
        <mesh filename="package://hexapod_description/meshes/servo_wheel.stl"/>
      </geometry>
      <material name="servo_wheel_23_material">
        <color rgba="0.647059 0.647059 0.647059 1"/>
      </material>
    </visual>
    <collision>
      <origin xyz="-5.55112e-17 0 -0.0025" rpy="3.14159 2.0289e-17 2.76226e-18"/>
      <geometry>
        <mesh filename="package://hexapod_description/meshes/servo_wheel.stl"/>
      </geometry>
    </collision>
    <!-- Part servo_12 -->
    <visual>
      <origin xyz="-0.0175 -0.00140442 -0.0305" rpy="3.14159 9.67471e-16 1.03262e-15"/>
      <geometry>
        <mesh filename="package://hexapod_description/meshes/servo.stl"/>
      </geometry>
      <material name="servo_12_material">
        <color rgba="0.109804 0.109804 0.105882 1"/>
      </material>
    </visual>
    <collision>
      <origin xyz="-0.0175 -0.00140442 -0.0305" rpy="3.14159 9.67471e-16 1.03262e-15"/>
      <geometry>
        <mesh filename="package://hexapod_description/meshes/servo.stl"/>
      </geometry>
    </collision>
    <!-- Part fixed_bracket_12 -->
    <visual>
      <origin xyz="-0.0575 1.11022e-16 -0.0305" rpy="1.5708 1.5708 0"/>
      <geometry>
        <mesh filename="package://hexapod_description/meshes/fixed_bracket.stl"/>
      </geometry>
      <material name="fixed_bracket_12_material">
        <color rgba="0.647059 0.647059 0.647059 1"/>
      </material>
    </visual>
    <collision>
      <origin xyz="-0.0575 1.11022e-16 -0.0305" rpy="1.5708 1.5708 0"/>
      <geometry>
        <mesh filename="package://hexapod_description/meshes/fixed_bracket.stl"/>
      </geometry>
    </collision>
    <!-- Part servo_wheel_24 -->
    <visual>
      <origin xyz="1.66533e-16 2.22045e-16 -0.0585" rpy="-3.14159 4.38001e-16 4.1255e-16"/>
      <geometry>
        <mesh filename="package://hexapod_description/meshes/servo_wheel.stl"/>
      </geometry>
      <material name="servo_wheel_24_material">
        <color rgba="0.647059 0.647059 0.647059 1"/>
      </material>
    </visual>
    <collision>
      <origin xyz="1.66533e-16 2.22045e-16 -0.0585" rpy="-3.14159 4.38001e-16 4.1255e-16"/>
      <geometry>
        <mesh filename="package://hexapod_description/meshes/servo_wheel.stl"/>
      </geometry>
    </collision>
  </link>
  <!-- Joint from ties_assembly_4 to foot_assembly_4 -->
  <joint name="foot_4" type="revolute">
    <origin xyz="0.112426 0.155395 -0.000790548" rpy="2.30727e-15 -2.8566e-15 2.31531"/>
    <parent link="ties_assembly_4"/>
    <child link="foot_assembly_4"/>
    <axis xyz="0 0 1"/>
    <limit effort="10" velocity="10" lower="-0.324722" upper="3.86407"/>
  </joint>
  <!-- Joint from hip_assembly_4 to ties_assembly_4 -->
  <joint name="ties_4" type="revolute">
    <origin xyz="-0.0925 0.0311167 -0.0305" rpy="1.5708 -9.71445e-17 -3.14159"/>
    <parent link="hip_assembly_4"/>
    <child link="ties_assembly_4"/>
    <axis xyz="0 0 1"/>
    <limit effort="10" velocity="10" lower="-2.68872" upper="0.801941"/>
  </joint>
  <!-- Joint from base_link to hip_assembly_4 -->
  <joint name="hip_4" type="revolute">
    <origin xyz="-0.75262 -0.280563 0.0702537" rpy="-2.97536e-15 -4.73545e-16 -0.468195"/>
    <parent link="base_link"/>
    <child link="hip_assembly_4"/>
    <axis xyz="0 0 1"/>
    <limit effort="10" velocity="10" lower="-1.6262" upper="1.51539"/>
  </joint>
  <!-- Link hip_assembly_5 -->
  <link name="hip_assembly_5">
    <inertial>
      <origin xyz="-0.0268487 0.000325484 -0.0307859" rpy="0 0 0"/>
      <mass value="0.365356"/>
      <inertia ixx="0.000168136" ixy="2.8417e-07" ixz="-3.2467e-06" iyy="0.000312332" iyz="-9.42575e-07" izz="0.000312341"/>
    </inertial>
    <!-- Part hip_5 -->
    <visual>
      <origin xyz="-0.0575 0.0005 -0.0565" rpy="-3.14159 2.15106e-16 -1.50245e-15"/>
      <geometry>
        <mesh filename="package://hexapod_description/meshes/hip.stl"/>
      </geometry>
      <material name="hip_5_material">
        <color rgba="0.196078 0.439216 0.0784314 1"/>
      </material>
    </visual>
    <collision>
      <origin xyz="-0.0575 0.0005 -0.0565" rpy="-3.14159 2.15106e-16 -1.50245e-15"/>
      <geometry>
        <mesh filename="package://hexapod_description/meshes/hip.stl"/>
      </geometry>
    </collision>
    <!-- Part mobile_bracket_15 -->
    <visual>
      <origin xyz="-0.0575 -1.38778e-17 -0.0305" rpy="3.14159 9.15934e-16 -1.5708"/>
      <geometry>
        <mesh filename="package://hexapod_description/meshes/mobile_bracket.stl"/>
      </geometry>
      <material name="mobile_bracket_15_material">
        <color rgba="0.647059 0.647059 0.647059 1"/>
      </material>
    </visual>
    <collision>
      <origin xyz="-0.0575 -1.38778e-17 -0.0305" rpy="3.14159 9.15934e-16 -1.5708"/>
      <geometry>
        <mesh filename="package://hexapod_description/meshes/mobile_bracket.stl"/>
      </geometry>
    </collision>
    <!-- Part servo_wheel_25 -->
    <visual>
      <origin xyz="1.11022e-16 -6.93889e-17 -0.0585" rpy="2.26208e-15 -2.28983e-16 -2.91621e-16"/>
      <geometry>
        <mesh filename="package://hexapod_description/meshes/servo_wheel.stl"/>
      </geometry>
      <material name="servo_wheel_25_material">
        <color rgba="0.647059 0.647059 0.647059 1"/>
      </material>
    </visual>
    <collision>
      <origin xyz="1.11022e-16 -6.93889e-17 -0.0585" rpy="2.26208e-15 -2.28983e-16 -2.91621e-16"/>
      <geometry>
        <mesh filename="package://hexapod_description/meshes/servo_wheel.stl"/>
      </geometry>
    </collision>
    <!-- Part servo_13 -->
    <visual>
      <origin xyz="-0.0175 0.00140442 -0.0305" rpy="2.26208e-15 -2.28983e-16 -2.91621e-16"/>
      <geometry>
        <mesh filename="package://hexapod_description/meshes/servo.stl"/>
      </geometry>
      <material name="servo_13_material">
        <color rgba="0.109804 0.109804 0.105882 1"/>
      </material>
    </visual>
    <collision>
      <origin xyz="-0.0175 0.00140442 -0.0305" rpy="2.26208e-15 -2.28983e-16 -2.91621e-16"/>
      <geometry>
        <mesh filename="package://hexapod_description/meshes/servo.stl"/>
      </geometry>
    </collision>
    <!-- Part fixed_bracket_13 -->
    <visual>
      <origin xyz="-0.0575 -1.38778e-17 -0.0305" rpy="-1.5708 -1.5708 0"/>
      <geometry>
        <mesh filename="package://hexapod_description/meshes/fixed_bracket.stl"/>
      </geometry>
      <material name="fixed_bracket_13_material">
        <color rgba="0.647059 0.647059 0.647059 1"/>
      </material>
    </visual>
    <collision>
      <origin xyz="-0.0575 -1.38778e-17 -0.0305" rpy="-1.5708 -1.5708 0"/>
      <geometry>
        <mesh filename="package://hexapod_description/meshes/fixed_bracket.stl"/>
      </geometry>
    </collision>
    <!-- Part servo_wheel_26 -->
    <visual>
      <origin xyz="1.11022e-16 -2.77556e-17 -0.0025" rpy="-2.30103e-31 1.05154e-31 8.44036e-17"/>
      <geometry>
        <mesh filename="package://hexapod_description/meshes/servo_wheel.stl"/>
      </geometry>
      <material name="servo_wheel_26_material">
        <color rgba="0.647059 0.647059 0.647059 1"/>
      </material>
    </visual>
    <collision>
      <origin xyz="1.11022e-16 -2.77556e-17 -0.0025" rpy="-2.30103e-31 1.05154e-31 8.44036e-17"/>
      <geometry>
        <mesh filename="package://hexapod_description/meshes/servo_wheel.stl"/>
      </geometry>
    </collision>
  </link>
  <!-- Link ties_assembly_5 -->
  <link name="ties_assembly_5">
    <inertial>
      <origin xyz="0.027215 0.0583427 -0.0309357" rpy="0 0 0"/>
      <mass value="0.589115"/>
      <inertia ixx="0.00175756" ixy="-0.000688363" ixz="4.60338e-06" iyy="0.000649623" iyz="9.75718e-06" izz="0.00187002"/>
    </inertial>
    <!-- Part mobile_bracket_16 -->
    <visual>
      <origin xyz="0.0694572 0.140577 -0.0311738" rpy="0.460246 1.5708 0"/>
      <geometry>
        <mesh filename="package://hexapod_description/meshes/mobile_bracket.stl"/>
      </geometry>
      <material name="mobile_bracket_16_material">
        <color rgba="0.647059 0.647059 0.647059 1"/>
      </material>
    </visual>
    <collision>
      <origin xyz="0.0694572 0.140577 -0.0311738" rpy="0.460246 1.5708 0"/>
      <geometry>
        <mesh filename="package://hexapod_description/meshes/mobile_bracket.stl"/>
      </geometry>
    </collision>
    <!-- Part low_tie_5 -->
    <visual>
      <origin xyz="0.0117153 0.0241047 -0.0311738" rpy="-1.11055 1.5708 0"/>
      <geometry>
        <mesh filename="package://hexapod_description/meshes/low_tie.stl"/>
      </geometry>
      <material name="low_tie_5_material">
        <color rgba="0.196078 0.439216 0.0784314 1"/>
      </material>
    </visual>
    <collision>
      <origin xyz="0.0117153 0.0241047 -0.0311738" rpy="-1.11055 1.5708 0"/>
      <geometry>
        <mesh filename="package://hexapod_description/meshes/low_tie.stl"/>
      </geometry>
    </collision>
    <!-- Part top_tie_5 -->
    <visual>
      <origin xyz="0.0122146 0.0246384 -0.0305" rpy="-1.11055 1.5708 0"/>
      <geometry>
        <mesh filename="package://hexapod_description/meshes/top_tie.stl"/>
      </geometry>
      <material name="top_tie_5_material">
        <color rgba="0.196078 0.439216 0.0784314 1"/>
      </material>
    </visual>
    <collision>
      <origin xyz="0.0122146 0.0246384 -0.0305" rpy="-1.11055 1.5708 0"/>
      <geometry>
        <mesh filename="package://hexapod_description/meshes/top_tie.stl"/>
      </geometry>
    </collision>
    <!-- Part servo_wheel_27 -->
    <visual>
      <origin xyz="0 0 -0.0025" rpy="3.14159 -2.86356e-15 -2.03104"/>
      <geometry>
        <mesh filename="package://hexapod_description/meshes/servo_wheel.stl"/>
      </geometry>
      <material name="servo_wheel_27_material">
        <color rgba="0.647059 0.647059 0.647059 1"/>
      </material>
    </visual>
    <collision>
      <origin xyz="0 0 -0.0025" rpy="3.14159 -2.86356e-15 -2.03104"/>
      <geometry>
        <mesh filename="package://hexapod_description/meshes/servo_wheel.stl"/>
      </geometry>
    </collision>
    <!-- Part servo_14 -->
    <visual>
      <origin xyz="0.00651467 0.0163028 -0.0305" rpy="3.14159 -6.34923e-15 -2.03104"/>
      <geometry>
        <mesh filename="package://hexapod_description/meshes/servo.stl"/>
      </geometry>
      <material name="servo_14_material">
        <color rgba="0.109804 0.109804 0.105882 1"/>
      </material>
    </visual>
    <collision>
      <origin xyz="0.00651467 0.0163028 -0.0305" rpy="3.14159 -6.34923e-15 -2.03104"/>
      <geometry>
        <mesh filename="package://hexapod_description/meshes/servo.stl"/>
      </geometry>
    </collision>
    <!-- Part fixed_bracket_14 -->
    <visual>
      <origin xyz="0.0255397 0.0515167 -0.0305" rpy="-2.68135 1.5708 0"/>
      <geometry>
        <mesh filename="package://hexapod_description/meshes/fixed_bracket.stl"/>
      </geometry>
      <material name="fixed_bracket_14_material">
        <color rgba="0.647059 0.647059 0.647059 1"/>
      </material>
    </visual>
    <collision>
      <origin xyz="0.0255397 0.0515167 -0.0305" rpy="-2.68135 1.5708 0"/>
      <geometry>
        <mesh filename="package://hexapod_description/meshes/fixed_bracket.stl"/>
      </geometry>
    </collision>
    <!-- Part servo_wheel_28 -->
    <visual>
      <origin xyz="1.11022e-16 6.93889e-18 -0.0585" rpy="3.14159 -6.27159e-15 -2.03104"/>
      <geometry>
        <mesh filename="package://hexapod_description/meshes/servo_wheel.stl"/>
      </geometry>
      <material name="servo_wheel_28_material">
        <color rgba="0.647059 0.647059 0.647059 1"/>
      </material>
    </visual>
    <collision>
      <origin xyz="1.11022e-16 6.93889e-18 -0.0585" rpy="3.14159 -6.27159e-15 -2.03104"/>
      <geometry>
        <mesh filename="package://hexapod_description/meshes/servo_wheel.stl"/>
      </geometry>
    </collision>
  </link>
  <!-- Link foot_assembly_5 -->
  <link name="foot_assembly_5">
    <inertial>
      <origin xyz="-0.0723864 -0.00208107 -0.0306673" rpy="0 0 0"/>
      <mass value="0.633453"/>
      <inertia ixx="0.000268433" ixy="-1.45368e-05" ixz="4.27618e-06" iyy="0.00320391" iyz="-2.30491e-07" izz="0.00304092"/>
    </inertial>
    <!-- Part foot_5 -->
    <visual>
      <origin xyz="-0.04425 0 -0.0305" rpy="1.26144e-16 1.5708 0"/>
      <geometry>
        <mesh filename="package://hexapod_description/meshes/foot.stl"/>
      </geometry>
      <material name="foot_5_material">
        <color rgba="0.282353 0.54902 0.160784 1"/>
      </material>
    </visual>
    <collision>
      <origin xyz="-0.04425 0 -0.0305" rpy="1.26144e-16 1.5708 0"/>
      <geometry>
        <mesh filename="package://hexapod_description/meshes/foot.stl"/>
      </geometry>
    </collision>
    <!-- Part ir_sensor_cap_5 -->
    <visual>
      <origin xyz="-0.04425 0 -0.0305" rpy="5.84842e-17 1.5708 0"/>
      <geometry>
        <mesh filename="package://hexapod_description/meshes/ir_sensor_cap.stl"/>
      </geometry>
      <material name="ir_sensor_cap_5_material">
        <color rgba="0.282353 0.54902 0.160784 1"/>
      </material>
    </visual>
    <collision>
      <origin xyz="-0.04425 0 -0.0305" rpy="5.84842e-17 1.5708 0"/>
      <geometry>
        <mesh filename="package://hexapod_description/meshes/ir_sensor_cap.stl"/>
      </geometry>
    </collision>
    <!-- Part rubber_foot_5 -->
    <visual>
      <origin xyz="-0.04375 1.11022e-16 -0.03" rpy="-5.25382e-17 1.5708 0"/>
      <geometry>
        <mesh filename="package://hexapod_description/meshes/rubber_foot.stl"/>
      </geometry>
      <material name="rubber_foot_5_material">
        <color rgba="0.262745 0.282353 0.301961 1"/>
      </material>
    </visual>
    <collision>
      <origin xyz="-0.04375 1.11022e-16 -0.03" rpy="-5.25382e-17 1.5708 0"/>
      <geometry>
        <mesh filename="package://hexapod_description/meshes/rubber_foot.stl"/>
      </geometry>
    </collision>
    <!-- Part servo_wheel_29 -->
    <visual>
      <origin xyz="0 1.11022e-16 -0.0025" rpy="3.14159 5.24658e-18 -8.48218e-17"/>
      <geometry>
        <mesh filename="package://hexapod_description/meshes/servo_wheel.stl"/>
      </geometry>
      <material name="servo_wheel_29_material">
        <color rgba="0.647059 0.647059 0.647059 1"/>
      </material>
    </visual>
    <collision>
      <origin xyz="0 1.11022e-16 -0.0025" rpy="3.14159 5.24658e-18 -8.48218e-17"/>
      <geometry>
        <mesh filename="package://hexapod_description/meshes/servo_wheel.stl"/>
      </geometry>
    </collision>
    <!-- Part servo_15 -->
    <visual>
      <origin xyz="-0.0175 -0.00140442 -0.0305" rpy="-3.14159 4.64494e-15 -1.00162e-16"/>
      <geometry>
        <mesh filename="package://hexapod_description/meshes/servo.stl"/>
      </geometry>
      <material name="servo_15_material">
        <color rgba="0.109804 0.109804 0.105882 1"/>
      </material>
    </visual>
    <collision>
      <origin xyz="-0.0175 -0.00140442 -0.0305" rpy="-3.14159 4.64494e-15 -1.00162e-16"/>
      <geometry>
        <mesh filename="package://hexapod_description/meshes/servo.stl"/>
      </geometry>
    </collision>
    <!-- Part fixed_bracket_15 -->
    <visual>
      <origin xyz="-0.0575 1.11022e-16 -0.0305" rpy="1.5708 1.5708 0"/>
      <geometry>
        <mesh filename="package://hexapod_description/meshes/fixed_bracket.stl"/>
      </geometry>
      <material name="fixed_bracket_15_material">
        <color rgba="0.647059 0.647059 0.647059 1"/>
      </material>
    </visual>
    <collision>
      <origin xyz="-0.0575 1.11022e-16 -0.0305" rpy="1.5708 1.5708 0"/>
      <geometry>
        <mesh filename="package://hexapod_description/meshes/fixed_bracket.stl"/>
      </geometry>
    </collision>
    <!-- Part servo_wheel_30 -->
    <visual>
      <origin xyz="-5.55112e-17 -1.11022e-16 -0.0585" rpy="3.14159 4.62318e-15 -5.36079e-17"/>
      <geometry>
        <mesh filename="package://hexapod_description/meshes/servo_wheel.stl"/>
      </geometry>
      <material name="servo_wheel_30_material">
        <color rgba="0.647059 0.647059 0.647059 1"/>
      </material>
    </visual>
    <collision>
      <origin xyz="-5.55112e-17 -1.11022e-16 -0.0585" rpy="3.14159 4.62318e-15 -5.36079e-17"/>
      <geometry>
        <mesh filename="package://hexapod_description/meshes/servo_wheel.stl"/>
      </geometry>
    </collision>
  </link>
  <!-- Joint from ties_assembly_5 to foot_assembly_5 -->
  <joint name="foot_5" type="revolute">
    <origin xyz="0.0850031 0.171935 -0.000790548" rpy="2.73845e-15 -1.75144e-15 2.22613"/>
    <parent link="ties_assembly_5"/>
    <child link="foot_assembly_5"/>
    <axis xyz="0 0 1"/>
    <limit effort="10" velocity="10" lower="-0.0683837" upper="4.12041"/>
  </joint>
  <!-- Joint from hip_assembly_5 to ties_assembly_5 -->
  <joint name="ties_5" type="revolute">
    <origin xyz="-0.0925 -0.0311167 -0.0305" rpy="-1.5708 -1.38778e-16 3.14159"/>
    <parent link="hip_assembly_5"/>
    <child link="ties_assembly_5"/>
    <axis xyz="0 0 1"/>
    <limit effort="10" velocity="10" lower="-2.85588" upper="0.634779"/>
  </joint>
  <!-- Joint from base_link to hip_assembly_5 -->
  <joint name="hip_5" type="revolute">
    <origin xyz="-0.75262 -0.438353 0.00875367" rpy="3.14159 1.60733e-15 0.64378"/>
    <parent link="base_link"/>
    <child link="hip_assembly_5"/>
    <axis xyz="0 0 1"/>
    <limit effort="10" velocity="10" lower="-1.45061" upper="1.69098"/>
  </joint>
  <!-- Link hip_assembly_6 -->
  <link name="hip_assembly_6">
    <inertial>
      <origin xyz="-0.0268487 -0.000325484 -0.0302141" rpy="0 0 0"/>
      <mass value="0.365356"/>
      <inertia ixx="0.000168136" ixy="-2.8417e-07" ixz="3.2467e-06" iyy="0.000312332" iyz="-9.42575e-07" izz="0.000312341"/>
    </inertial>
    <!-- Part hip_6 -->
    <visual>
      <origin xyz="-0.0575 -0.0005 -0.0045" rpy="5.04248e-17 -1.10032e-17 1.50548e-15"/>
      <geometry>
        <mesh filename="package://hexapod_description/meshes/hip.stl"/>
      </geometry>
      <material name="hip_6_material">
        <color rgba="0.196078 0.439216 0.0784314 1"/>
      </material>
    </visual>
    <collision>
      <origin xyz="-0.0575 -0.0005 -0.0045" rpy="5.04248e-17 -1.10032e-17 1.50548e-15"/>
      <geometry>
        <mesh filename="package://hexapod_description/meshes/hip.stl"/>
      </geometry>
    </collision>
    <!-- Part mobile_bracket_17 -->
    <visual>
      <origin xyz="-0.0575 -3.33067e-16 -0.0305" rpy="1.18004e-15 2.26939e-16 1.5708"/>
      <geometry>
        <mesh filename="package://hexapod_description/meshes/mobile_bracket.stl"/>
      </geometry>
      <material name="mobile_bracket_17_material">
        <color rgba="0.647059 0.647059 0.647059 1"/>
      </material>
    </visual>
    <collision>
      <origin xyz="-0.0575 -3.33067e-16 -0.0305" rpy="1.18004e-15 2.26939e-16 1.5708"/>
      <geometry>
        <mesh filename="package://hexapod_description/meshes/mobile_bracket.stl"/>
      </geometry>
    </collision>
    <!-- Part servo_wheel_31 -->
    <visual>
      <origin xyz="1.11022e-16 -1.11022e-16 -0.0025" rpy="-3.14159 -9.22173e-32 -9.30697e-18"/>
      <geometry>
        <mesh filename="package://hexapod_description/meshes/servo_wheel.stl"/>
      </geometry>
      <material name="servo_wheel_31_material">
        <color rgba="0.647059 0.647059 0.647059 1"/>
      </material>
    </visual>
    <collision>
      <origin xyz="1.11022e-16 -1.11022e-16 -0.0025" rpy="-3.14159 -9.22173e-32 -9.30697e-18"/>
      <geometry>
        <mesh filename="package://hexapod_description/meshes/servo_wheel.stl"/>
      </geometry>
    </collision>
    <!-- Part servo_16 -->
    <visual>
      <origin xyz="-0.0175 -0.00140442 -0.0305" rpy="3.14159 1.18548e-17 5.34039e-16"/>
      <geometry>
        <mesh filename="package://hexapod_description/meshes/servo.stl"/>
      </geometry>
      <material name="servo_16_material">
        <color rgba="0.109804 0.109804 0.105882 1"/>
      </material>
    </visual>
    <collision>
      <origin xyz="-0.0175 -0.00140442 -0.0305" rpy="3.14159 1.18548e-17 5.34039e-16"/>
      <geometry>
        <mesh filename="package://hexapod_description/meshes/servo.stl"/>
      </geometry>
    </collision>
    <!-- Part fixed_bracket_16 -->
    <visual>
      <origin xyz="-0.0575 -3.33067e-16 -0.0305" rpy="1.5708 1.5708 0"/>
      <geometry>
        <mesh filename="package://hexapod_description/meshes/fixed_bracket.stl"/>
      </geometry>
      <material name="fixed_bracket_16_material">
        <color rgba="0.647059 0.647059 0.647059 1"/>
      </material>
    </visual>
    <collision>
      <origin xyz="-0.0575 -3.33067e-16 -0.0305" rpy="1.5708 1.5708 0"/>
      <geometry>
        <mesh filename="package://hexapod_description/meshes/fixed_bracket.stl"/>
      </geometry>
    </collision>
    <!-- Part servo_wheel_32 -->
    <visual>
      <origin xyz="1.11022e-16 -2.22045e-16 -0.0585" rpy="3.14159 1.18841e-17 -9.30697e-18"/>
      <geometry>
        <mesh filename="package://hexapod_description/meshes/servo_wheel.stl"/>
      </geometry>
      <material name="servo_wheel_32_material">
        <color rgba="0.647059 0.647059 0.647059 1"/>
      </material>
    </visual>
    <collision>
      <origin xyz="1.11022e-16 -2.22045e-16 -0.0585" rpy="3.14159 1.18841e-17 -9.30697e-18"/>
      <geometry>
        <mesh filename="package://hexapod_description/meshes/servo_wheel.stl"/>
      </geometry>
    </collision>
  </link>
  <!-- Link ties_assembly_6 -->
  <link name="ties_assembly_6">
    <inertial>
      <origin xyz="0.0571451 0.0296474 -0.0309357" rpy="0 0 0"/>
      <mass value="0.589115"/>
      <inertia ixx="0.000680279" ixy="-0.000711947" ixz="9.59808e-06" iyy="0.00172691" iyz="4.92652e-06" izz="0.00187002"/>
    </inertial>
    <!-- Part mobile_bracket_18 -->
    <visual>
      <origin xyz="0.140769 0.0690685 -0.0311738" rpy="1.116 1.5708 0"/>
      <geometry>
        <mesh filename="package://hexapod_description/meshes/mobile_bracket.stl"/>
      </geometry>
      <material name="mobile_bracket_18_material">
        <color rgba="0.647059 0.647059 0.647059 1"/>
      </material>
    </visual>
    <collision>
      <origin xyz="0.140769 0.0690685 -0.0311738" rpy="1.116 1.5708 0"/>
      <geometry>
        <mesh filename="package://hexapod_description/meshes/mobile_bracket.stl"/>
      </geometry>
    </collision>
    <!-- Part low_tie_6 -->
    <visual>
      <origin xyz="0.0239834 0.0119617 -0.0311738" rpy="-0.4548 1.5708 0"/>
      <geometry>
        <mesh filename="package://hexapod_description/meshes/low_tie.stl"/>
      </geometry>
      <material name="low_tie_6_material">
        <color rgba="0.196078 0.439216 0.0784314 1"/>
      </material>
    </visual>
    <collision>
      <origin xyz="0.0239834 0.0119617 -0.0311738" rpy="-0.4548 1.5708 0"/>
      <geometry>
        <mesh filename="package://hexapod_description/meshes/low_tie.stl"/>
      </geometry>
    </collision>
    <!-- Part top_tie_6 -->
    <visual>
      <origin xyz="0.0247046 0.0120803 -0.0305" rpy="-0.4548 1.5708 0"/>
      <geometry>
        <mesh filename="package://hexapod_description/meshes/top_tie.stl"/>
      </geometry>
      <material name="top_tie_6_material">
        <color rgba="0.196078 0.439216 0.0784314 1"/>
      </material>
    </visual>
    <collision>
      <origin xyz="0.0247046 0.0120803 -0.0305" rpy="-0.4548 1.5708 0"/>
      <geometry>
        <mesh filename="package://hexapod_description/meshes/top_tie.stl"/>
      </geometry>
    </collision>
    <!-- Part servo_wheel_33 -->
    <visual>
      <origin xyz="0 6.93889e-18 -0.0025" rpy="-3.14159 -4.42224e-15 -2.68679"/>
      <geometry>
        <mesh filename="package://hexapod_description/meshes/servo_wheel.stl"/>
      </geometry>
      <material name="servo_wheel_33_material">
        <color rgba="0.647059 0.647059 0.647059 1"/>
      </material>
    </visual>
    <collision>
      <origin xyz="0 6.93889e-18 -0.0025" rpy="-3.14159 -4.42224e-15 -2.68679"/>
      <geometry>
        <mesh filename="package://hexapod_description/meshes/servo_wheel.stl"/>
      </geometry>
    </collision>
    <!-- Part servo_17 -->
    <visual>
      <origin xyz="0.0151042 0.0089491 -0.0305" rpy="-3.14159 -4.43373e-15 -2.68679"/>
      <geometry>
        <mesh filename="package://hexapod_description/meshes/servo.stl"/>
      </geometry>
      <material name="servo_17_material">
        <color rgba="0.109804 0.109804 0.105882 1"/>
      </material>
    </visual>
    <collision>
      <origin xyz="0.0151042 0.0089491 -0.0305" rpy="-3.14159 -4.43373e-15 -2.68679"/>
      <geometry>
        <mesh filename="package://hexapod_description/meshes/servo.stl"/>
      </geometry>
    </collision>
    <!-- Part fixed_bracket_17 -->
    <visual>
      <origin xyz="0.0516551 0.0252587 -0.0305" rpy="-2.0256 1.5708 0"/>
      <geometry>
        <mesh filename="package://hexapod_description/meshes/fixed_bracket.stl"/>
      </geometry>
      <material name="fixed_bracket_17_material">
        <color rgba="0.647059 0.647059 0.647059 1"/>
      </material>
    </visual>
    <collision>
      <origin xyz="0.0516551 0.0252587 -0.0305" rpy="-2.0256 1.5708 0"/>
      <geometry>
        <mesh filename="package://hexapod_description/meshes/fixed_bracket.stl"/>
      </geometry>
    </collision>
    <!-- Part servo_wheel_34 -->
    <visual>
      <origin xyz="0 0 -0.0585" rpy="-3.14159 -4.38503e-15 -2.68679"/>
      <geometry>
        <mesh filename="package://hexapod_description/meshes/servo_wheel.stl"/>
      </geometry>
      <material name="servo_wheel_34_material">
        <color rgba="0.647059 0.647059 0.647059 1"/>
      </material>
    </visual>
    <collision>
      <origin xyz="0 0 -0.0585" rpy="-3.14159 -4.38503e-15 -2.68679"/>
      <geometry>
        <mesh filename="package://hexapod_description/meshes/servo_wheel.stl"/>
      </geometry>
    </collision>
  </link>
  <!-- Link foot_assembly_6 -->
  <link name="foot_assembly_6">
    <inertial>
      <origin xyz="-0.0723864 -0.00208107 -0.0306673" rpy="0 0 0"/>
      <mass value="0.633453"/>
      <inertia ixx="0.000268433" ixy="-1.45368e-05" ixz="4.27618e-06" iyy="0.00320391" iyz="-2.30491e-07" izz="0.00304092"/>
    </inertial>
    <!-- Part foot_6 -->
    <visual>
      <origin xyz="-0.04425 0 -0.0305" rpy="-2.3949e-16 1.5708 0"/>
      <geometry>
        <mesh filename="package://hexapod_description/meshes/foot.stl"/>
      </geometry>
      <material name="foot_6_material">
        <color rgba="0.282353 0.54902 0.160784 1"/>
      </material>
    </visual>
    <collision>
      <origin xyz="-0.04425 0 -0.0305" rpy="-2.3949e-16 1.5708 0"/>
      <geometry>
        <mesh filename="package://hexapod_description/meshes/foot.stl"/>
      </geometry>
    </collision>
    <!-- Part ir_sensor_cap_6 -->
    <visual>
      <origin xyz="-0.04425 1.11022e-15 -0.0305" rpy="-7.53114e-15 1.5708 0"/>
      <geometry>
        <mesh filename="package://hexapod_description/meshes/ir_sensor_cap.stl"/>
      </geometry>
      <material name="ir_sensor_cap_6_material">
        <color rgba="0.282353 0.54902 0.160784 1"/>
      </material>
    </visual>
    <collision>
      <origin xyz="-0.04425 1.11022e-15 -0.0305" rpy="-7.53114e-15 1.5708 0"/>
      <geometry>
        <mesh filename="package://hexapod_description/meshes/ir_sensor_cap.stl"/>
      </geometry>
    </collision>
    <!-- Part rubber_foot_6 -->
    <visual>
      <origin xyz="-0.04375 -1.11022e-15 -0.03" rpy="4.79272e-15 1.5708 0"/>
      <geometry>
        <mesh filename="package://hexapod_description/meshes/rubber_foot.stl"/>
      </geometry>
      <material name="rubber_foot_6_material">
        <color rgba="0.262745 0.282353 0.301961 1"/>
      </material>
    </visual>
    <collision>
      <origin xyz="-0.04375 -1.11022e-15 -0.03" rpy="4.79272e-15 1.5708 0"/>
      <geometry>
        <mesh filename="package://hexapod_description/meshes/rubber_foot.stl"/>
      </geometry>
    </collision>
    <!-- Part servo_wheel_35 -->
    <visual>
      <origin xyz="-1.11022e-16 -1.11022e-16 -0.0025" rpy="-3.14159 -1.04914e-18 -6.3734e-17"/>
      <geometry>
        <mesh filename="package://hexapod_description/meshes/servo_wheel.stl"/>
      </geometry>
      <material name="servo_wheel_35_material">
        <color rgba="0.647059 0.647059 0.647059 1"/>
      </material>
    </visual>
    <collision>
      <origin xyz="-1.11022e-16 -1.11022e-16 -0.0025" rpy="-3.14159 -1.04914e-18 -6.3734e-17"/>
      <geometry>
        <mesh filename="package://hexapod_description/meshes/servo_wheel.stl"/>
      </geometry>
    </collision>
    <!-- Part servo_18 -->
    <visual>
      <origin xyz="-0.0175 -0.00140442 -0.0305" rpy="-3.14159 -4.75283e-16 -1.7217e-16"/>
      <geometry>
        <mesh filename="package://hexapod_description/meshes/servo.stl"/>
      </geometry>
      <material name="servo_18_material">
        <color rgba="0.109804 0.109804 0.105882 1"/>
      </material>
    </visual>
    <collision>
      <origin xyz="-0.0175 -0.00140442 -0.0305" rpy="-3.14159 -4.75283e-16 -1.7217e-16"/>
      <geometry>
        <mesh filename="package://hexapod_description/meshes/servo.stl"/>
      </geometry>
    </collision>
    <!-- Part fixed_bracket_18 -->
    <visual>
      <origin xyz="-0.0575 -1.11022e-16 -0.0305" rpy="1.5708 1.5708 0"/>
      <geometry>
        <mesh filename="package://hexapod_description/meshes/fixed_bracket.stl"/>
      </geometry>
      <material name="fixed_bracket_18_material">
        <color rgba="0.647059 0.647059 0.647059 1"/>
      </material>
    </visual>
    <collision>
      <origin xyz="-0.0575 -1.11022e-16 -0.0305" rpy="1.5708 1.5708 0"/>
      <geometry>
        <mesh filename="package://hexapod_description/meshes/fixed_bracket.stl"/>
      </geometry>
    </collision>
    <!-- Part servo_wheel_36 -->
    <visual>
      <origin xyz="-2.77556e-16 -2.22045e-16 -0.0585" rpy="-3.14159 -4.75283e-16 -1.7217e-16"/>
      <geometry>
        <mesh filename="package://hexapod_description/meshes/servo_wheel.stl"/>
      </geometry>
      <material name="servo_wheel_36_material">
        <color rgba="0.647059 0.647059 0.647059 1"/>
      </material>
    </visual>
    <collision>
      <origin xyz="-2.77556e-16 -2.22045e-16 -0.0585" rpy="-3.14159 -4.75283e-16 -1.7217e-16"/>
      <geometry>
        <mesh filename="package://hexapod_description/meshes/servo_wheel.stl"/>
      </geometry>
    </collision>
  </link>
  <!-- Joint from ties_assembly_6 to foot_assembly_6 -->
  <joint name="foot_6" type="revolute">
    <origin xyz="0.172211 0.0844433 -0.000790548" rpy="-8.41938e-16 3.89144e-15 2.1079"/>
    <parent link="ties_assembly_6"/>
    <child link="foot_assembly_6"/>
    <axis xyz="0 0 1"/>
    <limit effort="10" velocity="10" lower="-0.605901" upper="3.58289"/>
  </joint>
  <!-- Joint from hip_assembly_6 to ties_assembly_6 -->
  <joint name="ties_6" type="revolute">
    <origin xyz="-0.0925 0.0311167 -0.0305" rpy="1.5708 -1.18004e-15 -3.14159"/>
    <parent link="hip_assembly_6"/>
    <child link="ties_assembly_6"/>
    <axis xyz="0 0 1"/>
    <limit effort="10" velocity="10" lower="-2.20013" upper="1.29053"/>
  </joint>
  <!-- Joint from base_link to hip_assembly_6 -->
  <joint name="hip_6" type="revolute">
    <origin xyz="-0.61597 -0.517249 0.0695202" rpy="1.19323e-15 -4.1531e-16 1.45631"/>
    <parent link="base_link"/>
    <child link="hip_assembly_6"/>
    <axis xyz="0 0 1"/>
    <limit effort="10" velocity="10" lower="-1.45631" upper="1.68529"/>
  </joint>
</robot>
