<?xml version="1.0" ?>
<!-- Generated using onshape-to-robot -->
<!-- Onshape https://cad.onshape.com/documents/026f9a33ba6a25a983a9d639/w/b83e0182bd0a887a03df3198/e/e49783848224d44e064e4a49 -->
<robot name="C:\Users\gata2\OneDrive\Desktop\ros\hexapod">
  <!-- Link body -->
  <link name="body">
    <inertial>
      <origin xyz="-0.196109 -0.050879 -0.0432059" rpy="0 0 0"/>
      <mass value="2.27947"/>
      <inertia ixx="0.017042" ixy="3.91907e-05" ixz="-0.000103785" iyy="0.0170877" iyz="-0.00018515" izz="0.0241407"/>
    </inertial>
    <!-- Part mobile_bracket -->
    <visual>
      <origin xyz="-0.0906126 -0.113734 -0.0437427" rpy="2.0944 1.5708 0"/>
      <geometry>
        <mesh filename="package://meshes\mobile_bracket.stl"/>
      </geometry>
      <material name="mobile_bracket_material">
        <color rgba="0.647059 0.647059 0.647059 1"/>
      </material>
    </visual>
    <collision>
      <origin xyz="-0.0906126 -0.113734 -0.0437427" rpy="2.0944 1.5708 0"/>
      <geometry>
        <mesh filename="package://meshes\mobile_bracket.stl"/>
      </geometry>
    </collision>
    <!-- Part mobile_bracket_2 -->
    <visual>
      <origin xyz="-0.0906126 0.00905613 -0.0437427" rpy="1.0472 1.5708 0"/>
      <geometry>
        <mesh filename="package://meshes\mobile_bracket.stl"/>
      </geometry>
      <material name="mobile_bracket_2_material">
        <color rgba="0.647059 0.647059 0.647059 1"/>
      </material>
    </visual>
    <collision>
      <origin xyz="-0.0906126 0.00905613 -0.0437427" rpy="1.0472 1.5708 0"/>
      <geometry>
        <mesh filename="package://meshes\mobile_bracket.stl"/>
      </geometry>
    </collision>
    <!-- Part bottom_cover -->
    <visual>
      <origin xyz="-0.196952 -0.0523392 -0.00874275" rpy="-4.30211e-16 4.94382e-16 -2.0944"/>
      <geometry>
        <mesh filename="package://meshes\bottom_cover.stl"/>
      </geometry>
      <material name="bottom_cover_material">
        <color rgba="0.196078 0.439216 0.0784314 1"/>
      </material>
    </visual>
    <collision>
      <origin xyz="-0.196952 -0.0523392 -0.00874275" rpy="-4.30211e-16 4.94382e-16 -2.0944"/>
      <geometry>
        <mesh filename="package://meshes\bottom_cover.stl"/>
      </geometry>
    </collision>
    <!-- Part mobile_bracket_3 -->
    <visual>
      <origin xyz="-0.196952 0.0704514 -0.0437427" rpy="1.10589e-16 -1.5708 0"/>
      <geometry>
        <mesh filename="package://meshes\mobile_bracket.stl"/>
      </geometry>
      <material name="mobile_bracket_3_material">
        <color rgba="0.647059 0.647059 0.647059 1"/>
      </material>
    </visual>
    <collision>
      <origin xyz="-0.196952 0.0704514 -0.0437427" rpy="1.10589e-16 -1.5708 0"/>
      <geometry>
        <mesh filename="package://meshes\mobile_bracket.stl"/>
      </geometry>
    </collision>
    <!-- Part cover -->
    <visual>
      <origin xyz="-0.196952 -0.0523392 -0.0787427" rpy="3.14159 2.42408e-16 -2.0944"/>
      <geometry>
        <mesh filename="package://meshes\cover.stl"/>
      </geometry>
      <material name="cover_material">
        <color rgba="0.196078 0.439216 0.0784314 1"/>
      </material>
    </visual>
    <collision>
      <origin xyz="-0.196952 -0.0523392 -0.0787427" rpy="3.14159 2.42408e-16 -2.0944"/>
      <geometry>
        <mesh filename="package://meshes\cover.stl"/>
      </geometry>
    </collision>
    <!-- Part mobile_bracket_4 -->
    <visual>
      <origin xyz="-0.196952 -0.17513 -0.0437427" rpy="-3.14159 1.5708 0"/>
      <geometry>
        <mesh filename="package://meshes\mobile_bracket.stl"/>
      </geometry>
      <material name="mobile_bracket_4_material">
        <color rgba="0.647059 0.647059 0.647059 1"/>
      </material>
    </visual>
    <collision>
      <origin xyz="-0.196952 -0.17513 -0.0437427" rpy="-3.14159 1.5708 0"/>
      <geometry>
        <mesh filename="package://meshes\mobile_bracket.stl"/>
      </geometry>
    </collision>
    <!-- Part mobile_bracket_5 -->
    <visual>
      <origin xyz="-0.303292 0.00905613 -0.0437427" rpy="1.0472 -1.5708 0"/>
      <geometry>
        <mesh filename="package://meshes\mobile_bracket.stl"/>
      </geometry>
      <material name="mobile_bracket_5_material">
        <color rgba="0.647059 0.647059 0.647059 1"/>
      </material>
    </visual>
    <collision>
      <origin xyz="-0.303292 0.00905613 -0.0437427" rpy="1.0472 -1.5708 0"/>
      <geometry>
        <mesh filename="package://meshes\mobile_bracket.stl"/>
      </geometry>
    </collision>
    <!-- Part mobile_bracket_6 -->
    <visual>
      <origin xyz="-0.303292 -0.113734 -0.0437427" rpy="2.0944 -1.5708 0"/>
      <geometry>
        <mesh filename="package://meshes\mobile_bracket.stl"/>
      </geometry>
      <material name="mobile_bracket_6_material">
        <color rgba="0.647059 0.647059 0.647059 1"/>
      </material>
    </visual>
    <collision>
      <origin xyz="-0.303292 -0.113734 -0.0437427" rpy="2.0944 -1.5708 0"/>
      <geometry>
        <mesh filename="package://meshes\mobile_bracket.stl"/>
      </geometry>
    </collision>
    <!-- Part body -->
    <visual>
      <origin xyz="-0.196952 -0.0523392 -0.0437427" rpy="3.14159 -4.30211e-16 2.61799"/>
      <geometry>
        <mesh filename="package://meshes\body.stl"/>
      </geometry>
      <material name="body_material">
        <color rgba="0.196078 0.439216 0.0784314 1"/>
      </material>
    </visual>
    <collision>
      <origin xyz="-0.196952 -0.0523392 -0.0437427" rpy="3.14159 -4.30211e-16 2.61799"/>
      <geometry>
        <mesh filename="package://meshes\body.stl"/>
      </geometry>
    </collision>
  </link>
  <!-- Link hip -->
  <link name="hip">
    <inertial>
      <origin xyz="0.0269089 0.00049653 -0.030132" rpy="0 0 0"/>
      <mass value="0.367257"/>
      <inertia ixx="0.000167558" ixy="-9.38193e-07" ixz="-3.64504e-06" iyy="0.000313217" iyz="1.43413e-06" izz="0.000311521"/>
    </inertial>
    <!-- Part hip -->
    <visual>
      <origin xyz="0.057495 0.00075483 -0.0045" rpy="6.40344e-16 -9.93066e-16 -3.12846"/>
      <geometry>
        <mesh filename="package://meshes\hip.stl"/>
      </geometry>
      <material name="hip_material">
        <color rgba="0.196078 0.439216 0.0784314 1"/>
      </material>
    </visual>
    <collision>
      <origin xyz="0.057495 0.00075483 -0.0045" rpy="6.40344e-16 -9.93066e-16 -3.12846"/>
      <geometry>
        <mesh filename="package://meshes\hip.stl"/>
      </geometry>
    </collision>
    <!-- Part mobile_bracket_7 -->
    <visual>
      <origin xyz="0.057495 0.00075483 -0.0305" rpy="-2.17969e-15 -4.87364e-16 -1.55767"/>
      <geometry>
        <mesh filename="package://meshes\mobile_bracket.stl"/>
      </geometry>
      <material name="mobile_bracket_7_material">
        <color rgba="0.647059 0.647059 0.647059 1"/>
      </material>
    </visual>
    <collision>
      <origin xyz="0.057495 0.00075483 -0.0305" rpy="-2.17969e-15 -4.87364e-16 -1.55767"/>
      <geometry>
        <mesh filename="package://meshes\mobile_bracket.stl"/>
      </geometry>
    </collision>
    <!-- Part servo_wheel -->
    <visual>
      <origin xyz="7.80626e-17 2.77556e-17 -0.0025" rpy="-3.14159 -1.12543e-15 -3.12846"/>
      <geometry>
        <mesh filename="package://meshes\servo_wheel.stl"/>
      </geometry>
      <material name="servo_wheel_material">
        <color rgba="0.647059 0.647059 0.647059 1"/>
      </material>
    </visual>
    <collision>
      <origin xyz="7.80626e-17 2.77556e-17 -0.0025" rpy="-3.14159 -1.12543e-15 -3.12846"/>
      <geometry>
        <mesh filename="package://meshes\servo_wheel.stl"/>
      </geometry>
    </collision>
    <!-- Part servo -->
    <visual>
      <origin xyz="0.0174801 0.00163403 -0.0305" rpy="-3.14159 -1.06559e-15 -3.12846"/>
      <geometry>
        <mesh filename="package://meshes\servo.stl"/>
      </geometry>
      <material name="servo_material">
        <color rgba="0.109804 0.109804 0.105882 1"/>
      </material>
    </visual>
    <collision>
      <origin xyz="0.0174801 0.00163403 -0.0305" rpy="-3.14159 -1.06559e-15 -3.12846"/>
      <geometry>
        <mesh filename="package://meshes\servo.stl"/>
      </geometry>
    </collision>
    <!-- Part fixed_bracket -->
    <visual>
      <origin xyz="0.057495 0.00075483 -0.0305" rpy="-1.58392 1.5708 0"/>
      <geometry>
        <mesh filename="package://meshes\fixed_bracket.stl"/>
      </geometry>
      <material name="fixed_bracket_material">
        <color rgba="0.647059 0.647059 0.647059 1"/>
      </material>
    </visual>
    <collision>
      <origin xyz="0.057495 0.00075483 -0.0305" rpy="-1.58392 1.5708 0"/>
      <geometry>
        <mesh filename="package://meshes\fixed_bracket.stl"/>
      </geometry>
    </collision>
    <!-- Part servo_wheel_2 -->
    <visual>
      <origin xyz="9.19403e-17 0 -0.0585" rpy="-3.14159 -1.04151e-15 -3.12846"/>
      <geometry>
        <mesh filename="package://meshes\servo_wheel.stl"/>
      </geometry>
      <material name="servo_wheel_2_material">
        <color rgba="0.647059 0.647059 0.647059 1"/>
      </material>
    </visual>
    <collision>
      <origin xyz="9.19403e-17 0 -0.0585" rpy="-3.14159 -1.04151e-15 -3.12846"/>
      <geometry>
        <mesh filename="package://meshes\servo_wheel.stl"/>
      </geometry>
    </collision>
  </link>
  <!-- Link ties -->
  <link name="ties">
    <inertial>
      <origin xyz="0.0327445 0.0282242 -0.0311253" rpy="0 0 0"/>
      <mass value="0.468272"/>
      <inertia ixx="0.000509114" ixy="-0.000339983" ixz="7.51677e-06" iyy="0.000630229" iyz="6.04096e-06" izz="0.000767114"/>
    </inertial>
    <!-- Part mobile_bracket_8 -->
    <visual>
      <origin xyz="0.082462 0.0689657 -0.0305" rpy="0.87429 1.5708 0"/>
      <geometry>
        <mesh filename="package://meshes\mobile_bracket.stl"/>
      </geometry>
      <material name="mobile_bracket_8_material">
        <color rgba="0.647059 0.647059 0.647059 1"/>
      </material>
    </visual>
    <collision>
      <origin xyz="0.082462 0.0689657 -0.0305" rpy="0.87429 1.5708 0"/>
      <geometry>
        <mesh filename="package://meshes\mobile_bracket.stl"/>
      </geometry>
    </collision>
    <!-- Part tie -->
    <visual>
      <origin xyz="0.0210949 0.0176424 -0.0305" rpy="-0.696506 1.5708 0"/>
      <geometry>
        <mesh filename="package://meshes\tie.stl"/>
      </geometry>
      <material name="tie_material">
        <color rgba="0.196078 0.439216 0.0784314 1"/>
      </material>
    </visual>
    <collision>
      <origin xyz="0.0210949 0.0176424 -0.0305" rpy="-0.696506 1.5708 0"/>
      <geometry>
        <mesh filename="package://meshes\tie.stl"/>
      </geometry>
    </collision>
    <!-- Part servo_wheel_3 -->
    <visual>
      <origin xyz="-4.16334e-17 -6.93889e-18 -0.0025" rpy="-3.14159 -7.95331e-15 -2.44509"/>
      <geometry>
        <mesh filename="package://meshes\servo_wheel.stl"/>
      </geometry>
      <material name="servo_wheel_3_material">
        <color rgba="0.647059 0.647059 0.647059 1"/>
      </material>
    </visual>
    <collision>
      <origin xyz="-4.16334e-17 -6.93889e-18 -0.0025" rpy="-3.14159 -7.95331e-15 -2.44509"/>
      <geometry>
        <mesh filename="package://meshes\servo_wheel.stl"/>
      </geometry>
    </collision>
    <!-- Part servo_2 -->
    <visual>
      <origin xyz="0.012523 0.0123043 -0.0305" rpy="-3.14159 -9.08255e-15 -2.44509"/>
      <geometry>
        <mesh filename="package://meshes\servo.stl"/>
      </geometry>
      <material name="servo_2_material">
        <color rgba="0.109804 0.109804 0.105882 1"/>
      </material>
    </visual>
    <collision>
      <origin xyz="0.012523 0.0123043 -0.0305" rpy="-3.14159 -9.08255e-15 -2.44509"/>
      <geometry>
        <mesh filename="package://meshes\servo.stl"/>
      </geometry>
    </collision>
    <!-- Part fixed_bracket_2 -->
    <visual>
      <origin xyz="0.0441076 0.0368886 -0.0305" rpy="-2.2673 1.5708 0"/>
      <geometry>
        <mesh filename="package://meshes\fixed_bracket.stl"/>
      </geometry>
      <material name="fixed_bracket_2_material">
        <color rgba="0.647059 0.647059 0.647059 1"/>
      </material>
    </visual>
    <collision>
      <origin xyz="0.0441076 0.0368886 -0.0305" rpy="-2.2673 1.5708 0"/>
      <geometry>
        <mesh filename="package://meshes\fixed_bracket.stl"/>
      </geometry>
    </collision>
    <!-- Part servo_wheel_4 -->
    <visual>
      <origin xyz="-6.93889e-17 -2.77556e-17 -0.0585" rpy="-3.14159 -8.57101e-15 -2.44509"/>
      <geometry>
        <mesh filename="package://meshes\servo_wheel.stl"/>
      </geometry>
      <material name="servo_wheel_4_material">
        <color rgba="0.647059 0.647059 0.647059 1"/>
      </material>
    </visual>
    <collision>
      <origin xyz="-6.93889e-17 -2.77556e-17 -0.0585" rpy="-3.14159 -8.57101e-15 -2.44509"/>
      <geometry>
        <mesh filename="package://meshes\servo_wheel.stl"/>
      </geometry>
    </collision>
  </link>
  <!-- Link foot -->
  <link name="foot">
    <inertial>
      <origin xyz="-0.0743464 -0.000710193 -0.030632" rpy="0 0 0"/>
      <mass value="0.61675"/>
      <inertia ixx="0.000244104" ixy="-1.43889e-05" ixz="2.03993e-06" iyy="0.00314722" iyz="1.38557e-07" izz="0.00298873"/>
    </inertial>
    <!-- Part rubber_foot -->
    <visual>
      <origin xyz="-0.04475 1.38778e-16 -0.0305" rpy="-2.81587e-16 1.5708 0"/>
      <geometry>
        <mesh filename="package://meshes\rubber_foot.stl"/>
      </geometry>
      <material name="rubber_foot_material">
        <color rgba="0.262745 0.282353 0.301961 1"/>
      </material>
    </visual>
    <collision>
      <origin xyz="-0.04475 1.38778e-16 -0.0305" rpy="-2.81587e-16 1.5708 0"/>
      <geometry>
        <mesh filename="package://meshes\rubber_foot.stl"/>
      </geometry>
    </collision>
    <!-- Part lower_foot -->
    <visual>
      <origin xyz="-0.04425 0 -0.0305" rpy="1.05679e-16 1.5708 0"/>
      <geometry>
        <mesh filename="package://meshes\lower_foot.stl"/>
      </geometry>
      <material name="lower_foot_material">
        <color rgba="0.282353 0.54902 0.160784 1"/>
      </material>
    </visual>
    <collision>
      <origin xyz="-0.04425 0 -0.0305" rpy="1.05679e-16 1.5708 0"/>
      <geometry>
        <mesh filename="package://meshes\lower_foot.stl"/>
      </geometry>
    </collision>
    <!-- Part weight_beam -->
    <visual>
      <origin xyz="-0.04425 2.77556e-17 -0.0305" rpy="7.72551e-17 1.5708 0"/>
      <geometry>
        <mesh filename="package://meshes\weight_beam.stl"/>
      </geometry>
      <material name="weight_beam_material">
        <color rgba="0.917647 0.917647 0.917647 1"/>
      </material>
    </visual>
    <collision>
      <origin xyz="-0.04425 2.77556e-17 -0.0305" rpy="7.72551e-17 1.5708 0"/>
      <geometry>
        <mesh filename="package://meshes\weight_beam.stl"/>
      </geometry>
    </collision>
    <!-- Part upper_foot -->
    <visual>
      <origin xyz="-0.04425 0 -0.0305" rpy="-5.21251e-17 1.5708 0"/>
      <geometry>
        <mesh filename="package://meshes\upper_foot.stl"/>
      </geometry>
      <material name="upper_foot_material">
        <color rgba="0.282353 0.54902 0.160784 1"/>
      </material>
    </visual>
    <collision>
      <origin xyz="-0.04425 0 -0.0305" rpy="-5.21251e-17 1.5708 0"/>
      <geometry>
        <mesh filename="package://meshes\upper_foot.stl"/>
      </geometry>
    </collision>
    <!-- Part servo_wheel_5 -->
    <visual>
      <origin xyz="-1.38778e-17 0 -0.0025" rpy="3.14159 -2.11584e-20 -9.07834e-18"/>
      <geometry>
        <mesh filename="package://meshes\servo_wheel.stl"/>
      </geometry>
      <material name="servo_wheel_5_material">
        <color rgba="0.647059 0.647059 0.647059 1"/>
      </material>
    </visual>
    <collision>
      <origin xyz="-1.38778e-17 0 -0.0025" rpy="3.14159 -2.11584e-20 -9.07834e-18"/>
      <geometry>
        <mesh filename="package://meshes\servo_wheel.stl"/>
      </geometry>
    </collision>
    <!-- Part servo_3 -->
    <visual>
      <origin xyz="-0.0175 -0.00140442 -0.0305" rpy="3.14159 -2.72451e-15 1.01075e-16"/>
      <geometry>
        <mesh filename="package://meshes\servo.stl"/>
      </geometry>
      <material name="servo_3_material">
        <color rgba="0.109804 0.109804 0.105882 1"/>
      </material>
    </visual>
    <collision>
      <origin xyz="-0.0175 -0.00140442 -0.0305" rpy="3.14159 -2.72451e-15 1.01075e-16"/>
      <geometry>
        <mesh filename="package://meshes\servo.stl"/>
      </geometry>
    </collision>
    <!-- Part fixed_bracket_3 -->
    <visual>
      <origin xyz="-0.0575 0 -0.0305" rpy="1.5708 1.5708 0"/>
      <geometry>
        <mesh filename="package://meshes\fixed_bracket.stl"/>
      </geometry>
      <material name="fixed_bracket_3_material">
        <color rgba="0.647059 0.647059 0.647059 1"/>
      </material>
    </visual>
    <collision>
      <origin xyz="-0.0575 0 -0.0305" rpy="1.5708 1.5708 0"/>
      <geometry>
        <mesh filename="package://meshes\fixed_bracket.stl"/>
      </geometry>
    </collision>
    <!-- Part servo_wheel_6 -->
    <visual>
      <origin xyz="1.38778e-17 2.77556e-17 -0.0585" rpy="3.14159 -2.82447e-15 -1.10484e-16"/>
      <geometry>
        <mesh filename="package://meshes\servo_wheel.stl"/>
      </geometry>
      <material name="servo_wheel_6_material">
        <color rgba="0.647059 0.647059 0.647059 1"/>
      </material>
    </visual>
    <collision>
      <origin xyz="1.38778e-17 2.77556e-17 -0.0585" rpy="3.14159 -2.82447e-15 -1.10484e-16"/>
      <geometry>
        <mesh filename="package://meshes\servo_wheel.stl"/>
      </geometry>
    </collision>
  </link>
  <!-- Joint from ties to foot -->
  <joint name="foot_1" type="revolute">
    <origin xyz="0.10931 0.0914197 -0.000116718" rpy="3.487e-15 -1.92241e-15 2.00129"/>
    <parent link="ties"/>
    <child link="foot"/>
    <axis xyz="0 0 1"/>
    <limit effort="10" velocity="10" lower="-0.25759" upper="3.9312"/>
  </joint>
  <!-- Joint from hip to ties -->
  <joint name="ties_1" type="revolute">
    <origin xyz="0.0929005 -0.0298997 -0.0305" rpy="1.5708 2.17969e-15 0.0131279"/>
    <parent link="hip"/>
    <child link="ties"/>
    <axis xyz="0 0 1"/>
    <limit effort="10" velocity="10" lower="-2.44184" upper="1.04882"/>
  </joint>
  <!-- Joint from body to hip -->
  <joint name="hip_1" type="revolute">
    <origin xyz="-0.0603017 -0.131234 -0.0133595" rpy="4.41736e-16 -2.00843e-17 -0.523599"/>
    <parent link="body"/>
    <child link="hip"/>
    <axis xyz="0 0 1"/>
    <limit effort="10" velocity="10" lower="-1.58392" upper="1.55767"/>
  </joint>
  <!-- Link hip_2 -->
  <link name="hip_2">
    <inertial>
      <origin xyz="-0.0269131 -0.000143241 -0.030132" rpy="0 0 0"/>
      <mass value="0.367257"/>
      <inertia ixx="0.000167559" ixy="9.74102e-07" ixz="3.62589e-06" iyy="0.000313217" iyz="-1.48186e-06" izz="0.000311521"/>
    </inertial>
    <!-- Part hip_2 -->
    <visual>
      <origin xyz="-0.0575 4.16334e-17 -0.0045" rpy="2.63678e-16 6.80012e-16 5.11551e-16"/>
      <geometry>
        <mesh filename="package://meshes\hip.stl"/>
      </geometry>
      <material name="hip_2_material">
        <color rgba="0.196078 0.439216 0.0784314 1"/>
      </material>
    </visual>
    <collision>
      <origin xyz="-0.0575 4.16334e-17 -0.0045" rpy="2.63678e-16 6.80012e-16 5.11551e-16"/>
      <geometry>
        <mesh filename="package://meshes\hip.stl"/>
      </geometry>
    </collision>
    <!-- Part mobile_bracket_9 -->
    <visual>
      <origin xyz="-0.0575 0 -0.0305" rpy="9.85323e-16 -4.996e-16 1.5708"/>
      <geometry>
        <mesh filename="package://meshes\mobile_bracket.stl"/>
      </geometry>
      <material name="mobile_bracket_9_material">
        <color rgba="0.647059 0.647059 0.647059 1"/>
      </material>
    </visual>
    <collision>
      <origin xyz="-0.0575 0 -0.0305" rpy="9.85323e-16 -4.996e-16 1.5708"/>
      <geometry>
        <mesh filename="package://meshes\mobile_bracket.stl"/>
      </geometry>
    </collision>
    <!-- Part servo_wheel_7 -->
    <visual>
      <origin xyz="0 0 -0.0025" rpy="-3.14159 -6.38069e-32 9.97878e-17"/>
      <geometry>
        <mesh filename="package://meshes\servo_wheel.stl"/>
      </geometry>
      <material name="servo_wheel_7_material">
        <color rgba="0.647059 0.647059 0.647059 1"/>
      </material>
    </visual>
    <collision>
      <origin xyz="0 0 -0.0025" rpy="-3.14159 -6.38069e-32 9.97878e-17"/>
      <geometry>
        <mesh filename="package://meshes\servo_wheel.stl"/>
      </geometry>
    </collision>
    <!-- Part servo_4 -->
    <visual>
      <origin xyz="-0.0175 -0.00140442 -0.0305" rpy="-3.14159 1.8735e-16 3.21238e-16"/>
      <geometry>
        <mesh filename="package://meshes\servo.stl"/>
      </geometry>
      <material name="servo_4_material">
        <color rgba="0.109804 0.109804 0.105882 1"/>
      </material>
    </visual>
    <collision>
      <origin xyz="-0.0175 -0.00140442 -0.0305" rpy="-3.14159 1.8735e-16 3.21238e-16"/>
      <geometry>
        <mesh filename="package://meshes\servo.stl"/>
      </geometry>
    </collision>
    <!-- Part fixed_bracket_4 -->
    <visual>
      <origin xyz="-0.0575 0 -0.0305" rpy="1.5708 1.5708 0"/>
      <geometry>
        <mesh filename="package://meshes\fixed_bracket.stl"/>
      </geometry>
      <material name="fixed_bracket_4_material">
        <color rgba="0.647059 0.647059 0.647059 1"/>
      </material>
    </visual>
    <collision>
      <origin xyz="-0.0575 0 -0.0305" rpy="1.5708 1.5708 0"/>
      <geometry>
        <mesh filename="package://meshes\fixed_bracket.stl"/>
      </geometry>
    </collision>
    <!-- Part servo_wheel_8 -->
    <visual>
      <origin xyz="-3.46945e-17 0 -0.0585" rpy="3.14159 -3.11556e-15 3.82586e-16"/>
      <geometry>
        <mesh filename="package://meshes\servo_wheel.stl"/>
      </geometry>
      <material name="servo_wheel_8_material">
        <color rgba="0.647059 0.647059 0.647059 1"/>
      </material>
    </visual>
    <collision>
      <origin xyz="-3.46945e-17 0 -0.0585" rpy="3.14159 -3.11556e-15 3.82586e-16"/>
      <geometry>
        <mesh filename="package://meshes\servo_wheel.stl"/>
      </geometry>
    </collision>
  </link>
  <!-- Link ties_2 -->
  <link name="ties_2">
    <inertial>
      <origin xyz="0.0157436 0.040261 -0.0311253" rpy="0 0 0"/>
      <mass value="0.468272"/>
      <inertia ixx="0.000816681" ixy="-0.000241333" ixz="3.81898e-06" iyy="0.000322662" iyz="8.85496e-06" izz="0.000767114"/>
    </inertial>
    <!-- Part mobile_bracket_10 -->
    <visual>
      <origin xyz="0.0406359 0.0995237 -0.0305" rpy="0.387644 1.5708 0"/>
      <geometry>
        <mesh filename="package://meshes\mobile_bracket.stl"/>
      </geometry>
      <material name="mobile_bracket_10_material">
        <color rgba="0.647059 0.647059 0.647059 1"/>
      </material>
    </visual>
    <collision>
      <origin xyz="0.0406359 0.0995237 -0.0305" rpy="0.387644 1.5708 0"/>
      <geometry>
        <mesh filename="package://meshes\mobile_bracket.stl"/>
      </geometry>
    </collision>
    <!-- Part tie_2 -->
    <visual>
      <origin xyz="0.0103952 0.0254596 -0.0305" rpy="-1.18315 1.5708 0"/>
      <geometry>
        <mesh filename="package://meshes\tie.stl"/>
      </geometry>
      <material name="tie_2_material">
        <color rgba="0.196078 0.439216 0.0784314 1"/>
      </material>
    </visual>
    <collision>
      <origin xyz="0.0103952 0.0254596 -0.0305" rpy="-1.18315 1.5708 0"/>
      <geometry>
        <mesh filename="package://meshes\tie.stl"/>
      </geometry>
    </collision>
    <!-- Part servo_wheel_9 -->
    <visual>
      <origin xyz="1.38778e-17 1.38778e-17 -0.0025" rpy="3.14159 -6.39221e-16 -1.95844"/>
      <geometry>
        <mesh filename="package://meshes\servo_wheel.stl"/>
      </geometry>
      <material name="servo_wheel_9_material">
        <color rgba="0.647059 0.647059 0.647059 1"/>
      </material>
    </visual>
    <collision>
      <origin xyz="1.38778e-17 1.38778e-17 -0.0025" rpy="3.14159 -6.39221e-16 -1.95844"/>
      <geometry>
        <mesh filename="package://meshes\servo_wheel.stl"/>
      </geometry>
    </collision>
    <!-- Part servo_5 -->
    <visual>
      <origin xyz="0.00531493 0.0167324 -0.0305" rpy="3.14159 3.81092e-16 -1.95844"/>
      <geometry>
        <mesh filename="package://meshes\servo.stl"/>
      </geometry>
      <material name="servo_5_material">
        <color rgba="0.109804 0.109804 0.105882 1"/>
      </material>
    </visual>
    <collision>
      <origin xyz="0.00531493 0.0167324 -0.0305" rpy="3.14159 3.81092e-16 -1.95844"/>
      <geometry>
        <mesh filename="package://meshes\servo.stl"/>
      </geometry>
    </collision>
    <!-- Part fixed_bracket_5 -->
    <visual>
      <origin xyz="0.0217355 0.0532336 -0.0305" rpy="-2.75395 1.5708 0"/>
      <geometry>
        <mesh filename="package://meshes\fixed_bracket.stl"/>
      </geometry>
      <material name="fixed_bracket_5_material">
        <color rgba="0.647059 0.647059 0.647059 1"/>
      </material>
    </visual>
    <collision>
      <origin xyz="0.0217355 0.0532336 -0.0305" rpy="-2.75395 1.5708 0"/>
      <geometry>
        <mesh filename="package://meshes\fixed_bracket.stl"/>
      </geometry>
    </collision>
    <!-- Part servo_wheel_10 -->
    <visual>
      <origin xyz="-2.77556e-17 -5.55112e-17 -0.0585" rpy="3.14159 -2.29178e-15 -1.95844"/>
      <geometry>
        <mesh filename="package://meshes\servo_wheel.stl"/>
      </geometry>
      <material name="servo_wheel_10_material">
        <color rgba="0.647059 0.647059 0.647059 1"/>
      </material>
    </visual>
    <collision>
      <origin xyz="-2.77556e-17 -5.55112e-17 -0.0585" rpy="3.14159 -2.29178e-15 -1.95844"/>
      <geometry>
        <mesh filename="package://meshes\servo_wheel.stl"/>
      </geometry>
    </collision>
  </link>
  <!-- Link foot_2 -->
  <link name="foot_2">
    <inertial>
      <origin xyz="-0.0743464 -0.000710193 -0.030632" rpy="0 0 0"/>
      <mass value="0.61675"/>
      <inertia ixx="0.000244104" ixy="-1.43889e-05" ixz="2.03993e-06" iyy="0.00314722" iyz="1.38557e-07" izz="0.00298873"/>
    </inertial>
    <!-- Part rubber_foot_2 -->
    <visual>
      <origin xyz="-0.04475 2.77556e-17 -0.0305" rpy="-8.43949e-17 1.5708 0"/>
      <geometry>
        <mesh filename="package://meshes\rubber_foot.stl"/>
      </geometry>
      <material name="rubber_foot_2_material">
        <color rgba="0.262745 0.282353 0.301961 1"/>
      </material>
    </visual>
    <collision>
      <origin xyz="-0.04475 2.77556e-17 -0.0305" rpy="-8.43949e-17 1.5708 0"/>
      <geometry>
        <mesh filename="package://meshes\rubber_foot.stl"/>
      </geometry>
    </collision>
    <!-- Part lower_foot_2 -->
    <visual>
      <origin xyz="-0.04425 -5.55112e-17 -0.0305" rpy="1.32358e-17 1.5708 0"/>
      <geometry>
        <mesh filename="package://meshes\lower_foot.stl"/>
      </geometry>
      <material name="lower_foot_2_material">
        <color rgba="0.282353 0.54902 0.160784 1"/>
      </material>
    </visual>
    <collision>
      <origin xyz="-0.04425 -5.55112e-17 -0.0305" rpy="1.32358e-17 1.5708 0"/>
      <geometry>
        <mesh filename="package://meshes\lower_foot.stl"/>
      </geometry>
    </collision>
    <!-- Part weight_beam_2 -->
    <visual>
      <origin xyz="-0.04425 -2.77556e-17 -0.0305" rpy="-7.6616e-17 1.5708 0"/>
      <geometry>
        <mesh filename="package://meshes\weight_beam.stl"/>
      </geometry>
      <material name="weight_beam_2_material">
        <color rgba="0.917647 0.917647 0.917647 1"/>
      </material>
    </visual>
    <collision>
      <origin xyz="-0.04425 -2.77556e-17 -0.0305" rpy="-7.6616e-17 1.5708 0"/>
      <geometry>
        <mesh filename="package://meshes\weight_beam.stl"/>
      </geometry>
    </collision>
    <!-- Part upper_foot_2 -->
    <visual>
      <origin xyz="-0.04425 -2.77556e-17 -0.0305" rpy="1.32358e-17 1.5708 0"/>
      <geometry>
        <mesh filename="package://meshes\upper_foot.stl"/>
      </geometry>
      <material name="upper_foot_2_material">
        <color rgba="0.282353 0.54902 0.160784 1"/>
      </material>
    </visual>
    <collision>
      <origin xyz="-0.04425 -2.77556e-17 -0.0305" rpy="1.32358e-17 1.5708 0"/>
      <geometry>
        <mesh filename="package://meshes\upper_foot.stl"/>
      </geometry>
    </collision>
    <!-- Part servo_wheel_11 -->
    <visual>
      <origin xyz="-1.73472e-17 0 -0.0025" rpy="-3.14159 -2.14412e-18 -4.60747e-17"/>
      <geometry>
        <mesh filename="package://meshes\servo_wheel.stl"/>
      </geometry>
      <material name="servo_wheel_11_material">
        <color rgba="0.647059 0.647059 0.647059 1"/>
      </material>
    </visual>
    <collision>
      <origin xyz="-1.73472e-17 0 -0.0025" rpy="-3.14159 -2.14412e-18 -4.60747e-17"/>
      <geometry>
        <mesh filename="package://meshes\servo_wheel.stl"/>
      </geometry>
    </collision>
    <!-- Part servo_6 -->
    <visual>
      <origin xyz="-0.0175 -0.00140442 -0.0305" rpy="-3.14159 2.0323e-16 1.32349e-16"/>
      <geometry>
        <mesh filename="package://meshes\servo.stl"/>
      </geometry>
      <material name="servo_6_material">
        <color rgba="0.109804 0.109804 0.105882 1"/>
      </material>
    </visual>
    <collision>
      <origin xyz="-0.0175 -0.00140442 -0.0305" rpy="-3.14159 2.0323e-16 1.32349e-16"/>
      <geometry>
        <mesh filename="package://meshes\servo.stl"/>
      </geometry>
    </collision>
    <!-- Part fixed_bracket_6 -->
    <visual>
      <origin xyz="-0.0575 0 -0.0305" rpy="1.5708 1.5708 0"/>
      <geometry>
        <mesh filename="package://meshes\fixed_bracket.stl"/>
      </geometry>
      <material name="fixed_bracket_6_material">
        <color rgba="0.647059 0.647059 0.647059 1"/>
      </material>
    </visual>
    <collision>
      <origin xyz="-0.0575 0 -0.0305" rpy="1.5708 1.5708 0"/>
      <geometry>
        <mesh filename="package://meshes\fixed_bracket.stl"/>
      </geometry>
    </collision>
    <!-- Part servo_wheel_12 -->
    <visual>
      <origin xyz="-7.28584e-17 0 -0.0585" rpy="-3.14159 8.58787e-16 -8.81942e-17"/>
      <geometry>
        <mesh filename="package://meshes\servo_wheel.stl"/>
      </geometry>
      <material name="servo_wheel_12_material">
        <color rgba="0.647059 0.647059 0.647059 1"/>
      </material>
    </visual>
    <collision>
      <origin xyz="-7.28584e-17 0 -0.0585" rpy="-3.14159 8.58787e-16 -8.81942e-17"/>
      <geometry>
        <mesh filename="package://meshes\servo_wheel.stl"/>
      </geometry>
    </collision>
  </link>
  <!-- Joint from ties_2 to foot_2 -->
  <joint name="foot_2" type="revolute">
    <origin xyz="0.0538662 0.131927 -0.000116718" rpy="3.49334e-15 -4.3045e-15 2.24033"/>
    <parent link="ties_2"/>
    <child link="foot_2"/>
    <axis xyz="0 0 1"/>
    <limit effort="10" velocity="10" lower="-0.0099805" upper="4.17881"/>
  </joint>
  <!-- Joint from hip_2 to ties_2 -->
  <joint name="ties_2" type="revolute">
    <origin xyz="-0.0925 0.0311167 -0.0305" rpy="1.5708 -9.85323e-16 -3.14159"/>
    <parent link="hip_2"/>
    <child link="ties_2"/>
    <axis xyz="0 0 1"/>
    <limit effort="10" velocity="10" lower="-2.92848" upper="0.562177"/>
  </joint>
  <!-- Joint from body to hip_2 -->
  <joint name="hip_2" type="revolute">
    <origin xyz="-0.0603017 0.0265561 -0.0133595" rpy="-2.65193e-15 4.96332e-16 -2.2469"/>
    <parent link="body"/>
    <child link="hip_2"/>
    <axis xyz="0 0 1"/>
    <limit effort="10" velocity="10" lower="-1.94189" upper="1.19971"/>
  </joint>
  <!-- Link hip_3 -->
  <link name="hip_3">
    <inertial>
      <origin xyz="-0.0269131 -0.000143241 -0.030132" rpy="0 0 0"/>
      <mass value="0.367257"/>
      <inertia ixx="0.000167559" ixy="9.74102e-07" ixz="3.62589e-06" iyy="0.000313217" iyz="-1.48186e-06" izz="0.000311521"/>
    </inertial>
    <!-- Part hip_3 -->
    <visual>
      <origin xyz="-0.0575 2.22045e-16 -0.0045" rpy="4.30211e-16 3.95517e-16 -3.61773e-16"/>
      <geometry>
        <mesh filename="package://meshes\hip.stl"/>
      </geometry>
      <material name="hip_3_material">
        <color rgba="0.196078 0.439216 0.0784314 1"/>
      </material>
    </visual>
    <collision>
      <origin xyz="-0.0575 2.22045e-16 -0.0045" rpy="4.30211e-16 3.95517e-16 -3.61773e-16"/>
      <geometry>
        <mesh filename="package://meshes\hip.stl"/>
      </geometry>
    </collision>
    <!-- Part mobile_bracket_11 -->
    <visual>
      <origin xyz="-0.0575 5.55112e-17 -0.0305" rpy="8.32667e-16 7.91034e-16 1.5708"/>
      <geometry>
        <mesh filename="package://meshes\mobile_bracket.stl"/>
      </geometry>
      <material name="mobile_bracket_11_material">
        <color rgba="0.647059 0.647059 0.647059 1"/>
      </material>
    </visual>
    <collision>
      <origin xyz="-0.0575 5.55112e-17 -0.0305" rpy="8.32667e-16 7.91034e-16 1.5708"/>
      <geometry>
        <mesh filename="package://meshes\mobile_bracket.stl"/>
      </geometry>
    </collision>
    <!-- Part servo_wheel_13 -->
    <visual>
      <origin xyz="0 2.77556e-17 -0.0025" rpy="3.14159 -1.49214e-32 4.47223e-18"/>
      <geometry>
        <mesh filename="package://meshes\servo_wheel.stl"/>
      </geometry>
      <material name="servo_wheel_13_material">
        <color rgba="0.647059 0.647059 0.647059 1"/>
      </material>
    </visual>
    <collision>
      <origin xyz="0 2.77556e-17 -0.0025" rpy="3.14159 -1.49214e-32 4.47223e-18"/>
      <geometry>
        <mesh filename="package://meshes\servo_wheel.stl"/>
      </geometry>
    </collision>
    <!-- Part servo_7 -->
    <visual>
      <origin xyz="-0.0175 -0.00140442 -0.0305" rpy="-3.14159 6.10623e-16 -1.19127e-17"/>
      <geometry>
        <mesh filename="package://meshes\servo.stl"/>
      </geometry>
      <material name="servo_7_material">
        <color rgba="0.109804 0.109804 0.105882 1"/>
      </material>
    </visual>
    <collision>
      <origin xyz="-0.0175 -0.00140442 -0.0305" rpy="-3.14159 6.10623e-16 -1.19127e-17"/>
      <geometry>
        <mesh filename="package://meshes\servo.stl"/>
      </geometry>
    </collision>
    <!-- Part fixed_bracket_7 -->
    <visual>
      <origin xyz="-0.0575 5.55112e-17 -0.0305" rpy="1.5708 1.5708 0"/>
      <geometry>
        <mesh filename="package://meshes\fixed_bracket.stl"/>
      </geometry>
      <material name="fixed_bracket_7_material">
        <color rgba="0.647059 0.647059 0.647059 1"/>
      </material>
    </visual>
    <collision>
      <origin xyz="-0.0575 5.55112e-17 -0.0305" rpy="1.5708 1.5708 0"/>
      <geometry>
        <mesh filename="package://meshes\fixed_bracket.stl"/>
      </geometry>
    </collision>
    <!-- Part servo_wheel_14 -->
    <visual>
      <origin xyz="0 0 -0.0585" rpy="-3.14159 7.77156e-16 -1.98676e-16"/>
      <geometry>
        <mesh filename="package://meshes\servo_wheel.stl"/>
      </geometry>
      <material name="servo_wheel_14_material">
        <color rgba="0.647059 0.647059 0.647059 1"/>
      </material>
    </visual>
    <collision>
      <origin xyz="0 0 -0.0585" rpy="-3.14159 7.77156e-16 -1.98676e-16"/>
      <geometry>
        <mesh filename="package://meshes\servo_wheel.stl"/>
      </geometry>
    </collision>
  </link>
  <!-- Link ties_3 -->
  <link name="ties_3">
    <inertial>
      <origin xyz="0.0280086 0.0329292 -0.0311253" rpy="0 0 0"/>
      <mass value="0.468272"/>
      <inertia ixx="0.000615427" ixy="-0.000342289" ixz="6.49705e-06" iyy="0.000523916" iyz="7.12624e-06" izz="0.000767114"/>
    </inertial>
    <!-- Part mobile_bracket_12 -->
    <visual>
      <origin xyz="0.0708605 0.0808396 -0.0305" rpy="0.719711 1.5708 0"/>
      <geometry>
        <mesh filename="package://meshes\mobile_bracket.stl"/>
      </geometry>
      <material name="mobile_bracket_12_material">
        <color rgba="0.647059 0.647059 0.647059 1"/>
      </material>
    </visual>
    <collision>
      <origin xyz="0.0708605 0.0808396 -0.0305" rpy="0.719711 1.5708 0"/>
      <geometry>
        <mesh filename="package://meshes\mobile_bracket.stl"/>
      </geometry>
    </collision>
    <!-- Part tie_3 -->
    <visual>
      <origin xyz="0.0181271 0.0206799 -0.0305" rpy="-0.851085 1.5708 0"/>
      <geometry>
        <mesh filename="package://meshes\tie.stl"/>
      </geometry>
      <material name="tie_3_material">
        <color rgba="0.196078 0.439216 0.0784314 1"/>
      </material>
    </visual>
    <collision>
      <origin xyz="0.0181271 0.0206799 -0.0305" rpy="-0.851085 1.5708 0"/>
      <geometry>
        <mesh filename="package://meshes\tie.stl"/>
      </geometry>
    </collision>
    <!-- Part servo_wheel_15 -->
    <visual>
      <origin xyz="-1.66533e-16 -1.38778e-17 -0.0025" rpy="3.14159 4.28135e-15 -2.29051"/>
      <geometry>
        <mesh filename="package://meshes\servo_wheel.stl"/>
      </geometry>
      <material name="servo_wheel_15_material">
        <color rgba="0.647059 0.647059 0.647059 1"/>
      </material>
    </visual>
    <collision>
      <origin xyz="-1.66533e-16 -1.38778e-17 -0.0025" rpy="3.14159 4.28135e-15 -2.29051"/>
      <geometry>
        <mesh filename="package://meshes\servo_wheel.stl"/>
      </geometry>
    </collision>
    <!-- Part servo_8 -->
    <visual>
      <origin xyz="0.0104793 0.0140857 -0.0305" rpy="3.14159 3.38152e-15 -2.29051"/>
      <geometry>
        <mesh filename="package://meshes\servo.stl"/>
      </geometry>
      <material name="servo_8_material">
        <color rgba="0.109804 0.109804 0.105882 1"/>
      </material>
    </visual>
    <collision>
      <origin xyz="0.0104793 0.0140857 -0.0305" rpy="3.14159 3.38152e-15 -2.29051"/>
      <geometry>
        <mesh filename="package://meshes\servo.stl"/>
      </geometry>
    </collision>
    <!-- Part fixed_bracket_8 -->
    <visual>
      <origin xyz="0.0379021 0.0432398 -0.0305" rpy="-2.42188 1.5708 0"/>
      <geometry>
        <mesh filename="package://meshes\fixed_bracket.stl"/>
      </geometry>
      <material name="fixed_bracket_8_material">
        <color rgba="0.647059 0.647059 0.647059 1"/>
      </material>
    </visual>
    <collision>
      <origin xyz="0.0379021 0.0432398 -0.0305" rpy="-2.42188 1.5708 0"/>
      <geometry>
        <mesh filename="package://meshes\fixed_bracket.stl"/>
      </geometry>
    </collision>
    <!-- Part servo_wheel_16 -->
    <visual>
      <origin xyz="-1.11022e-16 5.55112e-17 -0.0585" rpy="3.14159 1.81866e-15 -2.29051"/>
      <geometry>
        <mesh filename="package://meshes\servo_wheel.stl"/>
      </geometry>
      <material name="servo_wheel_16_material">
        <color rgba="0.647059 0.647059 0.647059 1"/>
      </material>
    </visual>
    <collision>
      <origin xyz="-1.11022e-16 5.55112e-17 -0.0585" rpy="3.14159 1.81866e-15 -2.29051"/>
      <geometry>
        <mesh filename="package://meshes\servo_wheel.stl"/>
      </geometry>
    </collision>
  </link>
  <!-- Link foot_3 -->
  <link name="foot_3">
    <inertial>
      <origin xyz="-0.0743464 -0.000710193 -0.030632" rpy="0 0 0"/>
      <mass value="0.61675"/>
      <inertia ixx="0.000244104" ixy="-1.43889e-05" ixz="2.03993e-06" iyy="0.00314722" iyz="1.38557e-07" izz="0.00298873"/>
    </inertial>
    <!-- Part rubber_foot_3 -->
    <visual>
      <origin xyz="-0.04475 5.55112e-17 -0.0305" rpy="-3.25352e-16 1.5708 0"/>
      <geometry>
        <mesh filename="package://meshes\rubber_foot.stl"/>
      </geometry>
      <material name="rubber_foot_3_material">
        <color rgba="0.262745 0.282353 0.301961 1"/>
      </material>
    </visual>
    <collision>
      <origin xyz="-0.04475 5.55112e-17 -0.0305" rpy="-3.25352e-16 1.5708 0"/>
      <geometry>
        <mesh filename="package://meshes\rubber_foot.stl"/>
      </geometry>
    </collision>
    <!-- Part lower_foot_3 -->
    <visual>
      <origin xyz="-0.04425 0 -0.0305" rpy="-3.118e-16 1.5708 0"/>
      <geometry>
        <mesh filename="package://meshes\lower_foot.stl"/>
      </geometry>
      <material name="lower_foot_3_material">
        <color rgba="0.282353 0.54902 0.160784 1"/>
      </material>
    </visual>
    <collision>
      <origin xyz="-0.04425 0 -0.0305" rpy="-3.118e-16 1.5708 0"/>
      <geometry>
        <mesh filename="package://meshes\lower_foot.stl"/>
      </geometry>
    </collision>
    <!-- Part weight_beam_3 -->
    <visual>
      <origin xyz="-0.04425 2.77556e-17 -0.0305" rpy="-2.95751e-16 1.5708 0"/>
      <geometry>
        <mesh filename="package://meshes\weight_beam.stl"/>
      </geometry>
      <material name="weight_beam_3_material">
        <color rgba="0.917647 0.917647 0.917647 1"/>
      </material>
    </visual>
    <collision>
      <origin xyz="-0.04425 2.77556e-17 -0.0305" rpy="-2.95751e-16 1.5708 0"/>
      <geometry>
        <mesh filename="package://meshes\weight_beam.stl"/>
      </geometry>
    </collision>
    <!-- Part upper_foot_3 -->
    <visual>
      <origin xyz="-0.04425 2.77556e-17 -0.0305" rpy="-2.30379e-16 1.5708 0"/>
      <geometry>
        <mesh filename="package://meshes\upper_foot.stl"/>
      </geometry>
      <material name="upper_foot_3_material">
        <color rgba="0.282353 0.54902 0.160784 1"/>
      </material>
    </visual>
    <collision>
      <origin xyz="-0.04425 2.77556e-17 -0.0305" rpy="-2.30379e-16 1.5708 0"/>
      <geometry>
        <mesh filename="package://meshes\upper_foot.stl"/>
      </geometry>
    </collision>
    <!-- Part servo_wheel_17 -->
    <visual>
      <origin xyz="-2.77556e-17 -2.77556e-17 -0.0025" rpy="-3.14159 -1.98424e-18 -2.49583e-17"/>
      <geometry>
        <mesh filename="package://meshes\servo_wheel.stl"/>
      </geometry>
      <material name="servo_wheel_17_material">
        <color rgba="0.647059 0.647059 0.647059 1"/>
      </material>
    </visual>
    <collision>
      <origin xyz="-2.77556e-17 -2.77556e-17 -0.0025" rpy="-3.14159 -1.98424e-18 -2.49583e-17"/>
      <geometry>
        <mesh filename="package://meshes\servo_wheel.stl"/>
      </geometry>
    </collision>
    <!-- Part servo_9 -->
    <visual>
      <origin xyz="-0.0175 -0.00140442 -0.0305" rpy="3.14159 1.60119e-15 -4.30816e-16"/>
      <geometry>
        <mesh filename="package://meshes\servo.stl"/>
      </geometry>
      <material name="servo_9_material">
        <color rgba="0.109804 0.109804 0.105882 1"/>
      </material>
    </visual>
    <collision>
      <origin xyz="-0.0175 -0.00140442 -0.0305" rpy="3.14159 1.60119e-15 -4.30816e-16"/>
      <geometry>
        <mesh filename="package://meshes\servo.stl"/>
      </geometry>
    </collision>
    <!-- Part fixed_bracket_9 -->
    <visual>
      <origin xyz="-0.0575 2.77556e-17 -0.0305" rpy="1.5708 1.5708 0"/>
      <geometry>
        <mesh filename="package://meshes\fixed_bracket.stl"/>
      </geometry>
      <material name="fixed_bracket_9_material">
        <color rgba="0.647059 0.647059 0.647059 1"/>
      </material>
    </visual>
    <collision>
      <origin xyz="-0.0575 2.77556e-17 -0.0305" rpy="1.5708 1.5708 0"/>
      <geometry>
        <mesh filename="package://meshes\fixed_bracket.stl"/>
      </geometry>
    </collision>
    <!-- Part servo_wheel_18 -->
    <visual>
      <origin xyz="8.32667e-17 -5.55112e-17 -0.0585" rpy="3.14159 -2.6438e-15 -3.11145e-16"/>
      <geometry>
        <mesh filename="package://meshes\servo_wheel.stl"/>
      </geometry>
      <material name="servo_wheel_18_material">
        <color rgba="0.647059 0.647059 0.647059 1"/>
      </material>
    </visual>
    <collision>
      <origin xyz="8.32667e-17 -5.55112e-17 -0.0585" rpy="3.14159 -2.6438e-15 -3.11145e-16"/>
      <geometry>
        <mesh filename="package://meshes\servo_wheel.stl"/>
      </geometry>
    </collision>
  </link>
  <!-- Joint from ties_3 to foot_3 -->
  <joint name="foot_3" type="revolute">
    <origin xyz="0.0939313 0.107159 -0.000116718" rpy="8.4718e-15 8.1741e-16 2.33075"/>
    <parent link="ties_3"/>
    <child link="foot_3"/>
    <axis xyz="0 0 1"/>
    <limit effort="10" velocity="10" lower="-0.432463" upper="3.75633"/>
  </joint>
  <!-- Joint from hip_3 to ties_3 -->
  <joint name="ties_3" type="revolute">
    <origin xyz="-0.0925 0.0311167 -0.0305" rpy="1.5708 -8.32667e-16 3.14159"/>
    <parent link="hip_3"/>
    <child link="ties_3"/>
    <axis xyz="0 0 1"/>
    <limit effort="10" velocity="10" lower="-2.59641" upper="0.894244"/>
  </joint>
  <!-- Joint from body to hip_3 -->
  <joint name="hip_3" type="revolute">
    <origin xyz="-0.196952 0.105451 -0.012626" rpy="-2.0868e-15 1.31547e-15 -1.61555"/>
    <parent link="body"/>
    <child link="hip_3"/>
    <axis xyz="0 0 1"/>
    <limit effort="10" velocity="10" lower="-1.52605" upper="1.61555"/>
  </joint>
  <!-- Link hip_4 -->
  <link name="hip_4">
    <inertial>
      <origin xyz="-0.0269131 -0.000143241 -0.030132" rpy="0 0 0"/>
      <mass value="0.367257"/>
      <inertia ixx="0.000167559" ixy="9.74102e-07" ixz="3.62589e-06" iyy="0.000313217" iyz="-1.48186e-06" izz="0.000311521"/>
    </inertial>
    <!-- Part hip_4 -->
    <visual>
      <origin xyz="-0.0575 1.38778e-16 -0.0045" rpy="2.77813e-15 -9.71445e-17 -2.24995e-16"/>
      <geometry>
        <mesh filename="package://meshes\hip.stl"/>
      </geometry>
      <material name="hip_4_material">
        <color rgba="0.196078 0.439216 0.0784314 1"/>
      </material>
    </visual>
    <collision>
      <origin xyz="-0.0575 1.38778e-16 -0.0045" rpy="2.77813e-15 -9.71445e-17 -2.24995e-16"/>
      <geometry>
        <mesh filename="package://meshes\hip.stl"/>
      </geometry>
    </collision>
    <!-- Part mobile_bracket_13 -->
    <visual>
      <origin xyz="-0.0575 8.32667e-17 -0.0305" rpy="9.71445e-17 -1.31768e-15 1.5708"/>
      <geometry>
        <mesh filename="package://meshes\mobile_bracket.stl"/>
      </geometry>
      <material name="mobile_bracket_13_material">
        <color rgba="0.647059 0.647059 0.647059 1"/>
      </material>
    </visual>
    <collision>
      <origin xyz="-0.0575 8.32667e-17 -0.0305" rpy="9.71445e-17 -1.31768e-15 1.5708"/>
      <geometry>
        <mesh filename="package://meshes\mobile_bracket.stl"/>
      </geometry>
    </collision>
    <!-- Part servo_wheel_19 -->
    <visual>
      <origin xyz="0 0 -0.0025" rpy="-3.14159 1.8263e-31 2.98589e-17"/>
      <geometry>
        <mesh filename="package://meshes\servo_wheel.stl"/>
      </geometry>
      <material name="servo_wheel_19_material">
        <color rgba="0.647059 0.647059 0.647059 1"/>
      </material>
    </visual>
    <collision>
      <origin xyz="0 0 -0.0025" rpy="-3.14159 1.8263e-31 2.98589e-17"/>
      <geometry>
        <mesh filename="package://meshes\servo_wheel.stl"/>
      </geometry>
    </collision>
    <!-- Part servo_10 -->
    <visual>
      <origin xyz="-0.0175 -0.00140442 -0.0305" rpy="-3.14159 -2.91434e-16 -5.34443e-16"/>
      <geometry>
        <mesh filename="package://meshes\servo.stl"/>
      </geometry>
      <material name="servo_10_material">
        <color rgba="0.109804 0.109804 0.105882 1"/>
      </material>
    </visual>
    <collision>
      <origin xyz="-0.0175 -0.00140442 -0.0305" rpy="-3.14159 -2.91434e-16 -5.34443e-16"/>
      <geometry>
        <mesh filename="package://meshes\servo.stl"/>
      </geometry>
    </collision>
    <!-- Part fixed_bracket_10 -->
    <visual>
      <origin xyz="-0.0575 8.32667e-17 -0.0305" rpy="1.5708 1.5708 0"/>
      <geometry>
        <mesh filename="package://meshes\fixed_bracket.stl"/>
      </geometry>
      <material name="fixed_bracket_10_material">
        <color rgba="0.647059 0.647059 0.647059 1"/>
      </material>
    </visual>
    <collision>
      <origin xyz="-0.0575 8.32667e-17 -0.0305" rpy="1.5708 1.5708 0"/>
      <geometry>
        <mesh filename="package://meshes\fixed_bracket.stl"/>
      </geometry>
    </collision>
    <!-- Part servo_wheel_20 -->
    <visual>
      <origin xyz="0 2.77556e-17 -0.0585" rpy="-3.14159 6.10623e-16 -2.00365e-16"/>
      <geometry>
        <mesh filename="package://meshes\servo_wheel.stl"/>
      </geometry>
      <material name="servo_wheel_20_material">
        <color rgba="0.647059 0.647059 0.647059 1"/>
      </material>
    </visual>
    <collision>
      <origin xyz="0 2.77556e-17 -0.0585" rpy="-3.14159 6.10623e-16 -2.00365e-16"/>
      <geometry>
        <mesh filename="package://meshes\servo_wheel.stl"/>
      </geometry>
    </collision>
  </link>
  <!-- Link ties_4 -->
  <link name="ties_4">
    <inertial>
      <origin xyz="0.0248542 0.0353706 -0.0311253" rpy="0 0 0"/>
      <mass value="0.468272"/>
      <inertia ixx="0.00067748" ixy="-0.000328075" ixz="5.81256e-06" iyy="0.000461864" iyz="7.69475e-06" izz="0.000767114"/>
    </inertial>
    <!-- Part mobile_bracket_14 -->
    <visual>
      <origin xyz="0.0631077 0.0870268 -0.0305" rpy="0.627409 1.5708 0"/>
      <geometry>
        <mesh filename="package://meshes\mobile_bracket.stl"/>
      </geometry>
      <material name="mobile_bracket_14_material">
        <color rgba="0.647059 0.647059 0.647059 1"/>
      </material>
    </visual>
    <collision>
      <origin xyz="0.0631077 0.0870268 -0.0305" rpy="0.627409 1.5708 0"/>
      <geometry>
        <mesh filename="package://meshes\mobile_bracket.stl"/>
      </geometry>
    </collision>
    <!-- Part tie_4 -->
    <visual>
      <origin xyz="0.0161438 0.0222627 -0.0305" rpy="-0.943388 1.5708 0"/>
      <geometry>
        <mesh filename="package://meshes\tie.stl"/>
      </geometry>
      <material name="tie_4_material">
        <color rgba="0.196078 0.439216 0.0784314 1"/>
      </material>
    </visual>
    <collision>
      <origin xyz="0.0161438 0.0222627 -0.0305" rpy="-0.943388 1.5708 0"/>
      <geometry>
        <mesh filename="package://meshes\tie.stl"/>
      </geometry>
    </collision>
    <!-- Part servo_wheel_21 -->
    <visual>
      <origin xyz="-1.66533e-16 -2.08167e-17 -0.0025" rpy="-3.14159 -3.50602e-15 -2.1982"/>
      <geometry>
        <mesh filename="package://meshes\servo_wheel.stl"/>
      </geometry>
      <material name="servo_wheel_21_material">
        <color rgba="0.647059 0.647059 0.647059 1"/>
      </material>
    </visual>
    <collision>
      <origin xyz="-1.66533e-16 -2.08167e-17 -0.0025" rpy="-3.14159 -3.50602e-15 -2.1982"/>
      <geometry>
        <mesh filename="package://meshes\servo_wheel.stl"/>
      </geometry>
    </collision>
    <!-- Part servo_11 -->
    <visual>
      <origin xyz="0.0091364 0.0149916 -0.0305" rpy="3.14159 -2.38808e-15 -2.1982"/>
      <geometry>
        <mesh filename="package://meshes\servo.stl"/>
      </geometry>
      <material name="servo_11_material">
        <color rgba="0.109804 0.109804 0.105882 1"/>
      </material>
    </visual>
    <collision>
      <origin xyz="0.0091364 0.0149916 -0.0305" rpy="3.14159 -2.38808e-15 -2.1982"/>
      <geometry>
        <mesh filename="package://meshes\servo.stl"/>
      </geometry>
    </collision>
    <!-- Part fixed_bracket_11 -->
    <visual>
      <origin xyz="0.0337553 0.0465492 -0.0305" rpy="-2.51418 1.5708 0"/>
      <geometry>
        <mesh filename="package://meshes\fixed_bracket.stl"/>
      </geometry>
      <material name="fixed_bracket_11_material">
        <color rgba="0.647059 0.647059 0.647059 1"/>
      </material>
    </visual>
    <collision>
      <origin xyz="0.0337553 0.0465492 -0.0305" rpy="-2.51418 1.5708 0"/>
      <geometry>
        <mesh filename="package://meshes\fixed_bracket.stl"/>
      </geometry>
    </collision>
    <!-- Part servo_wheel_22 -->
    <visual>
      <origin xyz="-5.55112e-17 -9.02056e-17 -0.0585" rpy="-3.14159 -6.76602e-15 -2.1982"/>
      <geometry>
        <mesh filename="package://meshes\servo_wheel.stl"/>
      </geometry>
      <material name="servo_wheel_22_material">
        <color rgba="0.647059 0.647059 0.647059 1"/>
      </material>
    </visual>
    <collision>
      <origin xyz="-5.55112e-17 -9.02056e-17 -0.0585" rpy="-3.14159 -6.76602e-15 -2.1982"/>
      <geometry>
        <mesh filename="package://meshes\servo_wheel.stl"/>
      </geometry>
    </collision>
  </link>
  <!-- Link foot_4 -->
  <link name="foot_4">
    <inertial>
      <origin xyz="-0.0743464 -0.000710193 -0.030632" rpy="0 0 0"/>
      <mass value="0.61675"/>
      <inertia ixx="0.000244104" ixy="-1.43889e-05" ixz="2.03993e-06" iyy="0.00314722" iyz="1.38557e-07" izz="0.00298873"/>
    </inertial>
    <!-- Part rubber_foot_4 -->
    <visual>
      <origin xyz="-0.04475 5.55112e-17 -0.0305" rpy="-7.99637e-16 1.5708 0"/>
      <geometry>
        <mesh filename="package://meshes\rubber_foot.stl"/>
      </geometry>
      <material name="rubber_foot_4_material">
        <color rgba="0.262745 0.282353 0.301961 1"/>
      </material>
    </visual>
    <collision>
      <origin xyz="-0.04475 5.55112e-17 -0.0305" rpy="-7.99637e-16 1.5708 0"/>
      <geometry>
        <mesh filename="package://meshes\rubber_foot.stl"/>
      </geometry>
    </collision>
    <!-- Part lower_foot_4 -->
    <visual>
      <origin xyz="-0.04425 -5.55112e-17 -0.0305" rpy="-2.92746e-16 1.5708 0"/>
      <geometry>
        <mesh filename="package://meshes\lower_foot.stl"/>
      </geometry>
      <material name="lower_foot_4_material">
        <color rgba="0.282353 0.54902 0.160784 1"/>
      </material>
    </visual>
    <collision>
      <origin xyz="-0.04425 -5.55112e-17 -0.0305" rpy="-2.92746e-16 1.5708 0"/>
      <geometry>
        <mesh filename="package://meshes\lower_foot.stl"/>
      </geometry>
    </collision>
    <!-- Part weight_beam_4 -->
    <visual>
      <origin xyz="-0.04425 0 -0.0305" rpy="-7.68981e-16 1.5708 0"/>
      <geometry>
        <mesh filename="package://meshes\weight_beam.stl"/>
      </geometry>
      <material name="weight_beam_4_material">
        <color rgba="0.917647 0.917647 0.917647 1"/>
      </material>
    </visual>
    <collision>
      <origin xyz="-0.04425 0 -0.0305" rpy="-7.68981e-16 1.5708 0"/>
      <geometry>
        <mesh filename="package://meshes\weight_beam.stl"/>
      </geometry>
    </collision>
    <!-- Part upper_foot_4 -->
    <visual>
      <origin xyz="-0.04425 -5.55112e-17 -0.0305" rpy="-3.12465e-16 1.5708 0"/>
      <geometry>
        <mesh filename="package://meshes\upper_foot.stl"/>
      </geometry>
      <material name="upper_foot_4_material">
        <color rgba="0.282353 0.54902 0.160784 1"/>
      </material>
    </visual>
    <collision>
      <origin xyz="-0.04425 -5.55112e-17 -0.0305" rpy="-3.12465e-16 1.5708 0"/>
      <geometry>
        <mesh filename="package://meshes\upper_foot.stl"/>
      </geometry>
    </collision>
    <!-- Part servo_wheel_23 -->
    <visual>
      <origin xyz="-5.55112e-17 0 -0.0025" rpy="3.14159 2.0289e-17 2.76226e-18"/>
      <geometry>
        <mesh filename="package://meshes\servo_wheel.stl"/>
      </geometry>
      <material name="servo_wheel_23_material">
        <color rgba="0.647059 0.647059 0.647059 1"/>
      </material>
    </visual>
    <collision>
      <origin xyz="-5.55112e-17 0 -0.0025" rpy="3.14159 2.0289e-17 2.76226e-18"/>
      <geometry>
        <mesh filename="package://meshes\servo_wheel.stl"/>
      </geometry>
    </collision>
    <!-- Part servo_12 -->
    <visual>
      <origin xyz="-0.0175 -0.00140442 -0.0305" rpy="3.14159 9.67471e-16 1.03262e-15"/>
      <geometry>
        <mesh filename="package://meshes\servo.stl"/>
      </geometry>
      <material name="servo_12_material">
        <color rgba="0.109804 0.109804 0.105882 1"/>
      </material>
    </visual>
    <collision>
      <origin xyz="-0.0175 -0.00140442 -0.0305" rpy="3.14159 9.67471e-16 1.03262e-15"/>
      <geometry>
        <mesh filename="package://meshes\servo.stl"/>
      </geometry>
    </collision>
    <!-- Part fixed_bracket_12 -->
    <visual>
      <origin xyz="-0.0575 -5.55112e-17 -0.0305" rpy="1.5708 1.5708 0"/>
      <geometry>
        <mesh filename="package://meshes\fixed_bracket.stl"/>
      </geometry>
      <material name="fixed_bracket_12_material">
        <color rgba="0.647059 0.647059 0.647059 1"/>
      </material>
    </visual>
    <collision>
      <origin xyz="-0.0575 -5.55112e-17 -0.0305" rpy="1.5708 1.5708 0"/>
      <geometry>
        <mesh filename="package://meshes\fixed_bracket.stl"/>
      </geometry>
    </collision>
    <!-- Part servo_wheel_24 -->
    <visual>
      <origin xyz="0 5.55112e-17 -0.0585" rpy="-3.14159 4.38001e-16 4.1255e-16"/>
      <geometry>
        <mesh filename="package://meshes\servo_wheel.stl"/>
      </geometry>
      <material name="servo_wheel_24_material">
        <color rgba="0.647059 0.647059 0.647059 1"/>
      </material>
    </visual>
    <collision>
      <origin xyz="0 5.55112e-17 -0.0585" rpy="-3.14159 4.38001e-16 4.1255e-16"/>
      <geometry>
        <mesh filename="package://meshes\servo_wheel.stl"/>
      </geometry>
    </collision>
  </link>
  <!-- Joint from ties_4 to foot_4 -->
  <joint name="foot_4" type="revolute">
    <origin xyz="0.0836545 0.115361 -0.000116718" rpy="2.30727e-15 -2.8566e-15 2.31531"/>
    <parent link="ties_4"/>
    <child link="foot_4"/>
    <axis xyz="0 0 1"/>
    <limit effort="10" velocity="10" lower="-0.324722" upper="3.86407"/>
  </joint>
  <!-- Joint from hip_4 to ties_4 -->
  <joint name="ties_4" type="revolute">
    <origin xyz="-0.0925 0.0311167 -0.0305" rpy="1.5708 -9.71445e-17 -3.14159"/>
    <parent link="hip_4"/>
    <child link="ties_4"/>
    <axis xyz="0 0 1"/>
    <limit effort="10" velocity="10" lower="-2.68872" upper="0.801941"/>
  </joint>
  <!-- Joint from body to hip_4 -->
  <joint name="hip_4" type="revolute">
    <origin xyz="-0.333603 0.0265561 -0.012626" rpy="-2.97536e-15 -4.73545e-16 -0.468195"/>
    <parent link="body"/>
    <child link="hip_4"/>
    <axis xyz="0 0 1"/>
    <limit effort="10" velocity="10" lower="-1.6262" upper="1.51539"/>
  </joint>
  <!-- Link hip_5 -->
  <link name="hip_5">
    <inertial>
      <origin xyz="-0.0269131 0.000143241 -0.030868" rpy="0 0 0"/>
      <mass value="0.367257"/>
      <inertia ixx="0.000167559" ixy="-9.74102e-07" ixz="-3.62589e-06" iyy="0.000313217" iyz="-1.48186e-06" izz="0.000311521"/>
    </inertial>
    <!-- Part hip_5 -->
    <visual>
      <origin xyz="-0.0575 -1.38778e-16 -0.0565" rpy="-3.14159 2.15106e-16 -1.50245e-15"/>
      <geometry>
        <mesh filename="package://meshes\hip.stl"/>
      </geometry>
      <material name="hip_5_material">
        <color rgba="0.196078 0.439216 0.0784314 1"/>
      </material>
    </visual>
    <collision>
      <origin xyz="-0.0575 -1.38778e-16 -0.0565" rpy="-3.14159 2.15106e-16 -1.50245e-15"/>
      <geometry>
        <mesh filename="package://meshes\hip.stl"/>
      </geometry>
    </collision>
    <!-- Part mobile_bracket_15 -->
    <visual>
      <origin xyz="-0.0575 1.38778e-17 -0.0305" rpy="3.14159 9.15934e-16 -1.5708"/>
      <geometry>
        <mesh filename="package://meshes\mobile_bracket.stl"/>
      </geometry>
      <material name="mobile_bracket_15_material">
        <color rgba="0.647059 0.647059 0.647059 1"/>
      </material>
    </visual>
    <collision>
      <origin xyz="-0.0575 1.38778e-17 -0.0305" rpy="3.14159 9.15934e-16 -1.5708"/>
      <geometry>
        <mesh filename="package://meshes\mobile_bracket.stl"/>
      </geometry>
    </collision>
    <!-- Part servo_wheel_25 -->
    <visual>
      <origin xyz="1.11022e-16 0 -0.0585" rpy="2.26208e-15 -2.28983e-16 -2.91621e-16"/>
      <geometry>
        <mesh filename="package://meshes\servo_wheel.stl"/>
      </geometry>
      <material name="servo_wheel_25_material">
        <color rgba="0.647059 0.647059 0.647059 1"/>
      </material>
    </visual>
    <collision>
      <origin xyz="1.11022e-16 0 -0.0585" rpy="2.26208e-15 -2.28983e-16 -2.91621e-16"/>
      <geometry>
        <mesh filename="package://meshes\servo_wheel.stl"/>
      </geometry>
    </collision>
    <!-- Part servo_13 -->
    <visual>
      <origin xyz="-0.0175 0.00140442 -0.0305" rpy="2.26208e-15 -2.28983e-16 -2.91621e-16"/>
      <geometry>
        <mesh filename="package://meshes\servo.stl"/>
      </geometry>
      <material name="servo_13_material">
        <color rgba="0.109804 0.109804 0.105882 1"/>
      </material>
    </visual>
    <collision>
      <origin xyz="-0.0175 0.00140442 -0.0305" rpy="2.26208e-15 -2.28983e-16 -2.91621e-16"/>
      <geometry>
        <mesh filename="package://meshes\servo.stl"/>
      </geometry>
    </collision>
    <!-- Part fixed_bracket_13 -->
    <visual>
      <origin xyz="-0.0575 1.38778e-17 -0.0305" rpy="-1.5708 -1.5708 0"/>
      <geometry>
        <mesh filename="package://meshes\fixed_bracket.stl"/>
      </geometry>
      <material name="fixed_bracket_13_material">
        <color rgba="0.647059 0.647059 0.647059 1"/>
      </material>
    </visual>
    <collision>
      <origin xyz="-0.0575 1.38778e-17 -0.0305" rpy="-1.5708 -1.5708 0"/>
      <geometry>
        <mesh filename="package://meshes\fixed_bracket.stl"/>
      </geometry>
    </collision>
    <!-- Part servo_wheel_26 -->
    <visual>
      <origin xyz="5.55112e-17 -1.38778e-17 -0.0025" rpy="-2.30103e-31 1.05154e-31 8.44036e-17"/>
      <geometry>
        <mesh filename="package://meshes\servo_wheel.stl"/>
      </geometry>
      <material name="servo_wheel_26_material">
        <color rgba="0.647059 0.647059 0.647059 1"/>
      </material>
    </visual>
    <collision>
      <origin xyz="5.55112e-17 -1.38778e-17 -0.0025" rpy="-2.30103e-31 1.05154e-31 8.44036e-17"/>
      <geometry>
        <mesh filename="package://meshes\servo_wheel.stl"/>
      </geometry>
    </collision>
  </link>
  <!-- Link ties_5 -->
  <link name="ties_5">
    <inertial>
      <origin xyz="0.0186226 0.0390129 -0.0311253" rpy="0 0 0"/>
      <mass value="0.468272"/>
      <inertia ixx="0.000779162" ixy="-0.000274535" ixz="4.45125e-06" iyy="0.000360181" iyz="8.55461e-06" izz="0.000767114"/>
    </inertial>
    <!-- Part mobile_bracket_16 -->
    <visual>
      <origin xyz="0.0477481 0.0963139 -0.0305" rpy="0.460246 1.5708 0"/>
      <geometry>
        <mesh filename="package://meshes\mobile_bracket.stl"/>
      </geometry>
      <material name="mobile_bracket_16_material">
        <color rgba="0.647059 0.647059 0.647059 1"/>
      </material>
    </visual>
    <collision>
      <origin xyz="0.0477481 0.0963139 -0.0305" rpy="0.460246 1.5708 0"/>
      <geometry>
        <mesh filename="package://meshes\mobile_bracket.stl"/>
      </geometry>
    </collision>
    <!-- Part tie_5 -->
    <visual>
      <origin xyz="0.0122146 0.0246384 -0.0305" rpy="-1.11055 1.5708 0"/>
      <geometry>
        <mesh filename="package://meshes\tie.stl"/>
      </geometry>
      <material name="tie_5_material">
        <color rgba="0.196078 0.439216 0.0784314 1"/>
      </material>
    </visual>
    <collision>
      <origin xyz="0.0122146 0.0246384 -0.0305" rpy="-1.11055 1.5708 0"/>
      <geometry>
        <mesh filename="package://meshes\tie.stl"/>
      </geometry>
    </collision>
    <!-- Part servo_wheel_27 -->
    <visual>
      <origin xyz="0 0 -0.0025" rpy="3.14159 -2.86356e-15 -2.03104"/>
      <geometry>
        <mesh filename="package://meshes\servo_wheel.stl"/>
      </geometry>
      <material name="servo_wheel_27_material">
        <color rgba="0.647059 0.647059 0.647059 1"/>
      </material>
    </visual>
    <collision>
      <origin xyz="0 0 -0.0025" rpy="3.14159 -2.86356e-15 -2.03104"/>
      <geometry>
        <mesh filename="package://meshes\servo_wheel.stl"/>
      </geometry>
    </collision>
    <!-- Part servo_14 -->
    <visual>
      <origin xyz="0.00651467 0.0163028 -0.0305" rpy="3.14159 -6.26043e-15 -2.03104"/>
      <geometry>
        <mesh filename="package://meshes\servo.stl"/>
      </geometry>
      <material name="servo_14_material">
        <color rgba="0.109804 0.109804 0.105882 1"/>
      </material>
    </visual>
    <collision>
      <origin xyz="0.00651467 0.0163028 -0.0305" rpy="3.14159 -6.26043e-15 -2.03104"/>
      <geometry>
        <mesh filename="package://meshes\servo.stl"/>
      </geometry>
    </collision>
    <!-- Part fixed_bracket_14 -->
    <visual>
      <origin xyz="0.0255397 0.0515167 -0.0305" rpy="-2.68135 1.5708 0"/>
      <geometry>
        <mesh filename="package://meshes\fixed_bracket.stl"/>
      </geometry>
      <material name="fixed_bracket_14_material">
        <color rgba="0.647059 0.647059 0.647059 1"/>
      </material>
    </visual>
    <collision>
      <origin xyz="0.0255397 0.0515167 -0.0305" rpy="-2.68135 1.5708 0"/>
      <geometry>
        <mesh filename="package://meshes\fixed_bracket.stl"/>
      </geometry>
    </collision>
    <!-- Part servo_wheel_28 -->
    <visual>
      <origin xyz="5.55112e-17 0 -0.0585" rpy="3.14159 -6.27159e-15 -2.03104"/>
      <geometry>
        <mesh filename="package://meshes\servo_wheel.stl"/>
      </geometry>
      <material name="servo_wheel_28_material">
        <color rgba="0.647059 0.647059 0.647059 1"/>
      </material>
    </visual>
    <collision>
      <origin xyz="5.55112e-17 0 -0.0585" rpy="3.14159 -6.27159e-15 -2.03104"/>
      <geometry>
        <mesh filename="package://meshes\servo_wheel.stl"/>
      </geometry>
    </collision>
  </link>
  <!-- Link foot_5 -->
  <link name="foot_5">
    <inertial>
      <origin xyz="-0.0743464 -0.000710193 -0.030632" rpy="0 0 0"/>
      <mass value="0.61675"/>
      <inertia ixx="0.000244104" ixy="-1.43889e-05" ixz="2.03993e-06" iyy="0.00314722" iyz="1.38557e-07" izz="0.00298873"/>
    </inertial>
    <!-- Part rubber_foot_5 -->
    <visual>
      <origin xyz="-0.04475 6.10623e-16 -0.0305" rpy="-2.40662e-15 1.5708 0"/>
      <geometry>
        <mesh filename="package://meshes\rubber_foot.stl"/>
      </geometry>
      <material name="rubber_foot_5_material">
        <color rgba="0.262745 0.282353 0.301961 1"/>
      </material>
    </visual>
    <collision>
      <origin xyz="-0.04475 6.10623e-16 -0.0305" rpy="-2.40662e-15 1.5708 0"/>
      <geometry>
        <mesh filename="package://meshes\rubber_foot.stl"/>
      </geometry>
    </collision>
    <!-- Part lower_foot_5 -->
    <visual>
      <origin xyz="-0.04425 5.55112e-17 -0.0305" rpy="3.08175e-17 1.5708 0"/>
      <geometry>
        <mesh filename="package://meshes\lower_foot.stl"/>
      </geometry>
      <material name="lower_foot_5_material">
        <color rgba="0.282353 0.54902 0.160784 1"/>
      </material>
    </visual>
    <collision>
      <origin xyz="-0.04425 5.55112e-17 -0.0305" rpy="3.08175e-17 1.5708 0"/>
      <geometry>
        <mesh filename="package://meshes\lower_foot.stl"/>
      </geometry>
    </collision>
    <!-- Part weight_beam_5 -->
    <visual>
      <origin xyz="-0.04425 5.55112e-17 -0.0305" rpy="-1.30484e-16 1.5708 0"/>
      <geometry>
        <mesh filename="package://meshes\weight_beam.stl"/>
      </geometry>
      <material name="weight_beam_5_material">
        <color rgba="0.917647 0.917647 0.917647 1"/>
      </material>
    </visual>
    <collision>
      <origin xyz="-0.04425 5.55112e-17 -0.0305" rpy="-1.30484e-16 1.5708 0"/>
      <geometry>
        <mesh filename="package://meshes\weight_beam.stl"/>
      </geometry>
    </collision>
    <!-- Part upper_foot_5 -->
    <visual>
      <origin xyz="-0.04425 5.55112e-17 -0.0305" rpy="1.00162e-16 1.5708 0"/>
      <geometry>
        <mesh filename="package://meshes\upper_foot.stl"/>
      </geometry>
      <material name="upper_foot_5_material">
        <color rgba="0.282353 0.54902 0.160784 1"/>
      </material>
    </visual>
    <collision>
      <origin xyz="-0.04425 5.55112e-17 -0.0305" rpy="1.00162e-16 1.5708 0"/>
      <geometry>
        <mesh filename="package://meshes\upper_foot.stl"/>
      </geometry>
    </collision>
    <!-- Part servo_wheel_29 -->
    <visual>
      <origin xyz="2.77556e-17 1.11022e-16 -0.0025" rpy="3.14159 5.24658e-18 -8.48218e-17"/>
      <geometry>
        <mesh filename="package://meshes\servo_wheel.stl"/>
      </geometry>
      <material name="servo_wheel_29_material">
        <color rgba="0.647059 0.647059 0.647059 1"/>
      </material>
    </visual>
    <collision>
      <origin xyz="2.77556e-17 1.11022e-16 -0.0025" rpy="3.14159 5.24658e-18 -8.48218e-17"/>
      <geometry>
        <mesh filename="package://meshes\servo_wheel.stl"/>
      </geometry>
    </collision>
    <!-- Part servo_15 -->
    <visual>
      <origin xyz="-0.0175 -0.00140442 -0.0305" rpy="-3.14159 1.49138e-16 -4.46508e-17"/>
      <geometry>
        <mesh filename="package://meshes\servo.stl"/>
      </geometry>
      <material name="servo_15_material">
        <color rgba="0.109804 0.109804 0.105882 1"/>
      </material>
    </visual>
    <collision>
      <origin xyz="-0.0175 -0.00140442 -0.0305" rpy="-3.14159 1.49138e-16 -4.46508e-17"/>
      <geometry>
        <mesh filename="package://meshes\servo.stl"/>
      </geometry>
    </collision>
    <!-- Part fixed_bracket_15 -->
    <visual>
      <origin xyz="-0.0575 5.55112e-17 -0.0305" rpy="1.5708 1.5708 0"/>
      <geometry>
        <mesh filename="package://meshes\fixed_bracket.stl"/>
      </geometry>
      <material name="fixed_bracket_15_material">
        <color rgba="0.647059 0.647059 0.647059 1"/>
      </material>
    </visual>
    <collision>
      <origin xyz="-0.0575 5.55112e-17 -0.0305" rpy="1.5708 1.5708 0"/>
      <geometry>
        <mesh filename="package://meshes\fixed_bracket.stl"/>
      </geometry>
    </collision>
    <!-- Part servo_wheel_30 -->
    <visual>
      <origin xyz="1.94289e-16 0 -0.0585" rpy="3.14159 3.93825e-16 3.03756e-16"/>
      <geometry>
        <mesh filename="package://meshes\servo_wheel.stl"/>
      </geometry>
      <material name="servo_wheel_30_material">
        <color rgba="0.647059 0.647059 0.647059 1"/>
      </material>
    </visual>
    <collision>
      <origin xyz="1.94289e-16 0 -0.0585" rpy="3.14159 3.93825e-16 3.03756e-16"/>
      <geometry>
        <mesh filename="package://meshes\servo_wheel.stl"/>
      </geometry>
    </collision>
  </link>
  <!-- Joint from ties_5 to foot_5 -->
  <joint name="foot_5" type="revolute">
    <origin xyz="0.063294 0.127672 -0.000116718" rpy="2.73845e-15 -1.75144e-15 2.22613"/>
    <parent link="ties_5"/>
    <child link="foot_5"/>
    <axis xyz="0 0 1"/>
    <limit effort="10" velocity="10" lower="-0.0683837" upper="4.12041"/>
  </joint>
  <!-- Joint from hip_5 to ties_5 -->
  <joint name="ties_5" type="revolute">
    <origin xyz="-0.0925 -0.0311167 -0.0305" rpy="-1.5708 -1.38778e-16 3.14159"/>
    <parent link="hip_5"/>
    <child link="ties_5"/>
    <axis xyz="0 0 1"/>
    <limit effort="10" velocity="10" lower="-2.85588" upper="0.634779"/>
  </joint>
  <!-- Joint from body to hip_5 -->
  <joint name="hip_5" type="revolute">
    <origin xyz="-0.333603 -0.131234 -0.074126" rpy="3.14159 1.60733e-15 0.64378"/>
    <parent link="body"/>
    <child link="hip_5"/>
    <axis xyz="0 0 1"/>
    <limit effort="10" velocity="10" lower="-1.45061" upper="1.69098"/>
  </joint>
  <!-- Link hip_6 -->
  <link name="hip_6">
    <inertial>
      <origin xyz="-0.0269131 -0.000143241 -0.030132" rpy="0 0 0"/>
      <mass value="0.367257"/>
      <inertia ixx="0.000167559" ixy="9.74102e-07" ixz="3.62589e-06" iyy="0.000313217" iyz="-1.48186e-06" izz="0.000311521"/>
    </inertial>
    <!-- Part hip_6 -->
    <visual>
      <origin xyz="-0.0575 1.94289e-16 -0.0045" rpy="-2.77556e-17 -1.45717e-16 1.66166e-15"/>
      <geometry>
        <mesh filename="package://meshes\hip.stl"/>
      </geometry>
      <material name="hip_6_material">
        <color rgba="0.196078 0.439216 0.0784314 1"/>
      </material>
    </visual>
    <collision>
      <origin xyz="-0.0575 1.94289e-16 -0.0045" rpy="-2.77556e-17 -1.45717e-16 1.66166e-15"/>
      <geometry>
        <mesh filename="package://meshes\hip.stl"/>
      </geometry>
    </collision>
    <!-- Part mobile_bracket_17 -->
    <visual>
      <origin xyz="-0.0575 4.16334e-17 -0.0305" rpy="4.16334e-17 5.27356e-16 1.5708"/>
      <geometry>
        <mesh filename="package://meshes\mobile_bracket.stl"/>
      </geometry>
      <material name="mobile_bracket_17_material">
        <color rgba="0.647059 0.647059 0.647059 1"/>
      </material>
    </visual>
    <collision>
      <origin xyz="-0.0575 4.16334e-17 -0.0305" rpy="4.16334e-17 5.27356e-16 1.5708"/>
      <geometry>
        <mesh filename="package://meshes\mobile_bracket.stl"/>
      </geometry>
    </collision>
    <!-- Part servo_wheel_31 -->
    <visual>
      <origin xyz="0 0 -0.0025" rpy="3.14159 -3.05376e-32 6.27924e-17"/>
      <geometry>
        <mesh filename="package://meshes\servo_wheel.stl"/>
      </geometry>
      <material name="servo_wheel_31_material">
        <color rgba="0.647059 0.647059 0.647059 1"/>
      </material>
    </visual>
    <collision>
      <origin xyz="0 0 -0.0025" rpy="3.14159 -3.05376e-32 6.27924e-17"/>
      <geometry>
        <mesh filename="package://meshes\servo_wheel.stl"/>
      </geometry>
    </collision>
    <!-- Part servo_16 -->
    <visual>
      <origin xyz="-0.0175 -0.00140442 -0.0305" rpy="3.14159 2.70617e-16 -9.22699e-17"/>
      <geometry>
        <mesh filename="package://meshes\servo.stl"/>
      </geometry>
      <material name="servo_16_material">
        <color rgba="0.109804 0.109804 0.105882 1"/>
      </material>
    </visual>
    <collision>
      <origin xyz="-0.0175 -0.00140442 -0.0305" rpy="3.14159 2.70617e-16 -9.22699e-17"/>
      <geometry>
        <mesh filename="package://meshes\servo.stl"/>
      </geometry>
    </collision>
    <!-- Part fixed_bracket_16 -->
    <visual>
      <origin xyz="-0.0575 4.16334e-17 -0.0305" rpy="1.5708 1.5708 0"/>
      <geometry>
        <mesh filename="package://meshes\fixed_bracket.stl"/>
      </geometry>
      <material name="fixed_bracket_16_material">
        <color rgba="0.647059 0.647059 0.647059 1"/>
      </material>
    </visual>
    <collision>
      <origin xyz="-0.0575 4.16334e-17 -0.0305" rpy="1.5708 1.5708 0"/>
      <geometry>
        <mesh filename="package://meshes\fixed_bracket.stl"/>
      </geometry>
    </collision>
    <!-- Part servo_wheel_32 -->
    <visual>
      <origin xyz="0 1.38778e-17 -0.0585" rpy="3.14159 1.1588e-15 1.65376e-15"/>
      <geometry>
        <mesh filename="package://meshes\servo_wheel.stl"/>
      </geometry>
      <material name="servo_wheel_32_material">
        <color rgba="0.647059 0.647059 0.647059 1"/>
      </material>
    </visual>
    <collision>
      <origin xyz="0 1.38778e-17 -0.0585" rpy="3.14159 1.1588e-15 1.65376e-15"/>
      <geometry>
        <mesh filename="package://meshes\servo_wheel.stl"/>
      </geometry>
    </collision>
  </link>
  <!-- Link ties_6 -->
  <link name="ties_6">
    <inertial>
      <origin xyz="0.0237566 0.036117 -0.0311253" rpy="0 0 0"/>
      <mass value="0.468272"/>
      <inertia ixx="0.000697411" ixy="-0.00032084" ixz="5.57359e-06" iyy="0.000441933" iyz="7.86957e-06" izz="0.000767114"/>
    </inertial>
    <!-- Part mobile_bracket_18 -->
    <visual>
      <origin xyz="0.0604063 0.0889232 -0.0305" rpy="0.596703 1.5708 0"/>
      <geometry>
        <mesh filename="package://meshes\mobile_bracket.stl"/>
      </geometry>
      <material name="mobile_bracket_18_material">
        <color rgba="0.647059 0.647059 0.647059 1"/>
      </material>
    </visual>
    <collision>
      <origin xyz="0.0604063 0.0889232 -0.0305" rpy="0.596703 1.5708 0"/>
      <geometry>
        <mesh filename="package://meshes\mobile_bracket.stl"/>
      </geometry>
    </collision>
    <!-- Part tie_6 -->
    <visual>
      <origin xyz="0.0154528 0.0227478 -0.0305" rpy="-0.974093 1.5708 0"/>
      <geometry>
        <mesh filename="package://meshes\tie.stl"/>
      </geometry>
      <material name="tie_6_material">
        <color rgba="0.196078 0.439216 0.0784314 1"/>
      </material>
    </visual>
    <collision>
      <origin xyz="0.0154528 0.0227478 -0.0305" rpy="-0.974093 1.5708 0"/>
      <geometry>
        <mesh filename="package://meshes\tie.stl"/>
      </geometry>
    </collision>
    <!-- Part servo_wheel_33 -->
    <visual>
      <origin xyz="-1.11022e-16 -2.77556e-17 -0.0025" rpy="3.14159 -3.21643e-15 -2.1675"/>
      <geometry>
        <mesh filename="package://meshes\servo_wheel.stl"/>
      </geometry>
      <material name="servo_wheel_33_material">
        <color rgba="0.647059 0.647059 0.647059 1"/>
      </material>
    </visual>
    <collision>
      <origin xyz="-1.11022e-16 -2.77556e-17 -0.0025" rpy="3.14159 -3.21643e-15 -2.1675"/>
      <geometry>
        <mesh filename="package://meshes\servo_wheel.stl"/>
      </geometry>
    </collision>
    <!-- Part servo_17 -->
    <visual>
      <origin xyz="0.00867185 0.015265 -0.0305" rpy="3.14159 -3.97573e-15 -2.1675"/>
      <geometry>
        <mesh filename="package://meshes\servo.stl"/>
      </geometry>
      <material name="servo_17_material">
        <color rgba="0.109804 0.109804 0.105882 1"/>
      </material>
    </visual>
    <collision>
      <origin xyz="0.00867185 0.015265 -0.0305" rpy="3.14159 -3.97573e-15 -2.1675"/>
      <geometry>
        <mesh filename="package://meshes\servo.stl"/>
      </geometry>
    </collision>
    <!-- Part fixed_bracket_17 -->
    <visual>
      <origin xyz="0.0323103 0.0475636 -0.0305" rpy="-2.54489 1.5708 0"/>
      <geometry>
        <mesh filename="package://meshes\fixed_bracket.stl"/>
      </geometry>
      <material name="fixed_bracket_17_material">
        <color rgba="0.647059 0.647059 0.647059 1"/>
      </material>
    </visual>
    <collision>
      <origin xyz="0.0323103 0.0475636 -0.0305" rpy="-2.54489 1.5708 0"/>
      <geometry>
        <mesh filename="package://meshes\fixed_bracket.stl"/>
      </geometry>
    </collision>
    <!-- Part servo_wheel_34 -->
    <visual>
      <origin xyz="0 -2.77556e-17 -0.0585" rpy="3.14159 -3.32745e-15 -2.1675"/>
      <geometry>
        <mesh filename="package://meshes\servo_wheel.stl"/>
      </geometry>
      <material name="servo_wheel_34_material">
        <color rgba="0.647059 0.647059 0.647059 1"/>
      </material>
    </visual>
    <collision>
      <origin xyz="0 -2.77556e-17 -0.0585" rpy="3.14159 -3.32745e-15 -2.1675"/>
      <geometry>
        <mesh filename="package://meshes\servo_wheel.stl"/>
      </geometry>
    </collision>
  </link>
  <!-- Link foot_6 -->
  <link name="foot_6">
    <inertial>
      <origin xyz="-0.0743464 -0.000710193 -0.030632" rpy="0 0 0"/>
      <mass value="0.61675"/>
      <inertia ixx="0.000244104" ixy="-1.43889e-05" ixz="2.03993e-06" iyy="0.00314722" iyz="1.38557e-07" izz="0.00298873"/>
    </inertial>
    <!-- Part rubber_foot_6 -->
    <visual>
      <origin xyz="-0.04475 6.66134e-16 -0.0305" rpy="-4.16022e-15 1.5708 0"/>
      <geometry>
        <mesh filename="package://meshes\rubber_foot.stl"/>
      </geometry>
      <material name="rubber_foot_6_material">
        <color rgba="0.262745 0.282353 0.301961 1"/>
      </material>
    </visual>
    <collision>
      <origin xyz="-0.04475 6.66134e-16 -0.0305" rpy="-4.16022e-15 1.5708 0"/>
      <geometry>
        <mesh filename="package://meshes\rubber_foot.stl"/>
      </geometry>
    </collision>
    <!-- Part lower_foot_6 -->
    <visual>
      <origin xyz="-0.04425 0 -0.0305" rpy="-1.40056e-15 1.5708 0"/>
      <geometry>
        <mesh filename="package://meshes\lower_foot.stl"/>
      </geometry>
      <material name="lower_foot_6_material">
        <color rgba="0.282353 0.54902 0.160784 1"/>
      </material>
    </visual>
    <collision>
      <origin xyz="-0.04425 0 -0.0305" rpy="-1.40056e-15 1.5708 0"/>
      <geometry>
        <mesh filename="package://meshes\lower_foot.stl"/>
      </geometry>
    </collision>
    <!-- Part weight_beam_6 -->
    <visual>
      <origin xyz="-0.04425 0 -0.0305" rpy="-9.89347e-16 1.5708 0"/>
      <geometry>
        <mesh filename="package://meshes\weight_beam.stl"/>
      </geometry>
      <material name="weight_beam_6_material">
        <color rgba="0.917647 0.917647 0.917647 1"/>
      </material>
    </visual>
    <collision>
      <origin xyz="-0.04425 0 -0.0305" rpy="-9.89347e-16 1.5708 0"/>
      <geometry>
        <mesh filename="package://meshes\weight_beam.stl"/>
      </geometry>
    </collision>
    <!-- Part upper_foot_6 -->
    <visual>
      <origin xyz="-0.04425 5.55112e-17 -0.0305" rpy="-6.60311e-17 1.5708 0"/>
      <geometry>
        <mesh filename="package://meshes\upper_foot.stl"/>
      </geometry>
      <material name="upper_foot_6_material">
        <color rgba="0.282353 0.54902 0.160784 1"/>
      </material>
    </visual>
    <collision>
      <origin xyz="-0.04425 5.55112e-17 -0.0305" rpy="-6.60311e-17 1.5708 0"/>
      <geometry>
        <mesh filename="package://meshes\upper_foot.stl"/>
      </geometry>
    </collision>
    <!-- Part servo_wheel_35 -->
    <visual>
      <origin xyz="0 -5.55112e-17 -0.0025" rpy="-3.14159 -1.14283e-17 -5.85735e-17"/>
      <geometry>
        <mesh filename="package://meshes\servo_wheel.stl"/>
      </geometry>
      <material name="servo_wheel_35_material">
        <color rgba="0.647059 0.647059 0.647059 1"/>
      </material>
    </visual>
    <collision>
      <origin xyz="0 -5.55112e-17 -0.0025" rpy="-3.14159 -1.14283e-17 -5.85735e-17"/>
      <geometry>
        <mesh filename="package://meshes\servo_wheel.stl"/>
      </geometry>
    </collision>
    <!-- Part servo_18 -->
    <visual>
      <origin xyz="-0.0175 -0.00140442 -0.0305" rpy="3.14159 3.62753e-15 -2.68312e-17"/>
      <geometry>
        <mesh filename="package://meshes\servo.stl"/>
      </geometry>
      <material name="servo_18_material">
        <color rgba="0.109804 0.109804 0.105882 1"/>
      </material>
    </visual>
    <collision>
      <origin xyz="-0.0175 -0.00140442 -0.0305" rpy="3.14159 3.62753e-15 -2.68312e-17"/>
      <geometry>
        <mesh filename="package://meshes\servo.stl"/>
      </geometry>
    </collision>
    <!-- Part fixed_bracket_18 -->
    <visual>
      <origin xyz="-0.0575 0 -0.0305" rpy="1.5708 1.5708 0"/>
      <geometry>
        <mesh filename="package://meshes\fixed_bracket.stl"/>
      </geometry>
      <material name="fixed_bracket_18_material">
        <color rgba="0.647059 0.647059 0.647059 1"/>
      </material>
    </visual>
    <collision>
      <origin xyz="-0.0575 0 -0.0305" rpy="1.5708 1.5708 0"/>
      <geometry>
        <mesh filename="package://meshes\fixed_bracket.stl"/>
      </geometry>
    </collision>
    <!-- Part servo_wheel_36 -->
    <visual>
      <origin xyz="-8.32667e-17 -5.55112e-17 -0.0585" rpy="3.14159 3.39489e-15 -2.87409e-16"/>
      <geometry>
        <mesh filename="package://meshes\servo_wheel.stl"/>
      </geometry>
      <material name="servo_wheel_36_material">
        <color rgba="0.647059 0.647059 0.647059 1"/>
      </material>
    </visual>
    <collision>
      <origin xyz="-8.32667e-17 -5.55112e-17 -0.0585" rpy="3.14159 3.39489e-15 -2.87409e-16"/>
      <geometry>
        <mesh filename="package://meshes\servo_wheel.stl"/>
      </geometry>
    </collision>
  </link>
  <!-- Joint from ties_6 to foot_6 -->
  <joint name="foot_6" type="revolute">
    <origin xyz="0.0800734 0.117875 -0.000116718" rpy="8.44593e-15 -9.81866e-15 2.10621"/>
    <parent link="ties_6"/>
    <child link="foot_6"/>
    <axis xyz="0 0 1"/>
    <limit effort="10" velocity="10" lower="-0.0849172" upper="4.10387"/>
  </joint>
  <!-- Joint from hip_6 to ties_6 -->
  <joint name="ties_6" type="revolute">
    <origin xyz="-0.0925 0.0311167 -0.0305" rpy="1.5708 -4.16334e-17 -3.14159"/>
    <parent link="hip_6"/>
    <child link="ties_6"/>
    <axis xyz="0 0 1"/>
    <limit effort="10" velocity="10" lower="-2.71942" upper="0.771236"/>
  </joint>
  <!-- Joint from body to hip_6 -->
  <joint name="hip_6" type="revolute">
    <origin xyz="-0.196952 -0.21013 -0.0133595" rpy="2.24932e-15 4.78472e-16 1.24985"/>
    <parent link="body"/>
    <child link="hip_6"/>
    <axis xyz="0 0 1"/>
    <limit effort="10" velocity="10" lower="-1.24985" upper="1.89174"/>
  </joint>
</robot>
